Workbook

Sheet How to Use
B2: MATH 243 (KKS Sir — Probability & ANOVA part) — TF Practice Tracker
B3: Every KKS-part question in MATH 243 All Merged Questions.pdf (22 batch = MATH 243 (22 batch).pdf), mapped to the note file and lesson that teaches it.
B5: Workflow — after you finish a note file
B6: 1. Open its tab | C6: Tabs 1–8 follow the order of your note files. Q No. runs lesson by lesson, newest year first inside each lesson.
B7: 2. Filter | C7: Use the filter arrow on Priority → ★★★ High first (2019-20 onward). Then ★★ Medium, then ★ Low.
B8: 3. Solve | C8: Open MATH 243 All Merged Questions.pdf (22 batch = MATH 243 (22 batch).pdf) at the TF Page shown. Solve on paper under exam time (≈1.5 min per mark). Do not read the note solution first.
B9: 4. Check | C9: In Notes tells you what the note has: ✔ Solved = same question worked out; ◐ Method = method / model answer you can apply; ○ Partly = notes cover most of it, finish the rest yourself.
B10: 5. Record | C10: Tick Done, pick Confidence, add the Date. Write mistakes in My Notes. Re-solve every 'Weak' row before the exam.
B11: 6. Repeats | C11: 'Same Type Also In' lists other papers with the same question type. Solve one, then try a repeat cold — that is the real test.
B13: Columns you edit (all others are fixed data)
B14: Done (col N) | C14: TRUE / FALSE. In Google Sheets: select N4 downward → Insert → Checkbox. The values stay; ticking turns the row green.
B15: Confidence (col O) | C15: Dropdown: Weak / OK / Strong. Weak rows turn the cell red.
B16: Date (col P) | C16: Date you solved it, e.g. 16-Oct-2026.
B17: My Notes (col Q) | C17: Mistakes, missing steps, formula you forgot.
B19: Legend
B20: ★★★ High | C20: Asked in 2019-20 or later (most important — current question style).
B21: ★★ Medium | C21: Older paper, but the same question type appears at least twice in TF.
B22: ★ Low | C22: Older paper, asked once.
B23: Type | C23: Numerical = calculation · Trace = tables / step-by-step simulation · Design = construct / draw · Proof = prove / disprove · Theory = explain.
B24: Course | C24: MATH 243 = current code; MATH 245 (2016-17 to 2021-22) and MATH 241 (2011-12 to 2015-16) = old Complex Variables & Statistics papers — only their statistics/probability parts are listed.
B25: Topic | C25: Note lesson title — slide PDF and slide numbers.
B26: Outside Notes tab | C26: KKS-section questions from older papers on topics not in the current slides. Check with your teacher before spending time on them.

Sheet Dashboard
A1: Progress Dashboard
A2: Updates automatically when you tick Done / set Confidence in tabs 1–8.
A4: # | B4: Note file (tab) | C4: Questions | D4: Done | E4: % Done | F4: Marks (total) | G4: Marks done | H4: High-priority left | I4: Weak | J4: Next unsolved (top of tab)
A5: 1 | B5: 1 Probability Basics | C5: =COUNTA('1 Probability Basics'!$E$4:$E$8) | D5: =COUNTIF('1 Probability Basics'!$N$4:$N$8,TRUE()) | E5: =IF(C5=0,0,D5/C5) | F5: =SUM('1 Probability Basics'!$H$4:$H$8) | G5: =SUMIF('1 Probability Basics'!$N$4:$N$8,TRUE(),'1 Probability Basics'!$H$4:$H$8) | H5: =COUNTIFS('1 Probability Basics'!$J$4:$J$8,"★★★ High",'1 Probability Basics'!$N$4:$N$8,FALSE()) | I5: =COUNTIF('1 Probability Basics'!$O$4:$O$8,"Weak") | J5: =IFERROR("Q"&INDEX('1 Probability Basics'!$A$4:$A$8,MATCH(FALSE(),'1 Probability Basics'!$N$4:$N$8,0))&" · "&INDEX('1 Probability Basics'!$B$4:$B$8,MATCH(FALSE(),'1 Probability Basics'!$N$4:$N$8,0))&" "&INDEX('1 Probability Basics'!$D$4:$D$8,MATCH(FALSE(),'1 Probability Basics'!$N$4:$N$8,0))&" · TF p."&INDEX('1 Probability Basics'!$I$4:$I$8,MATCH(FALSE(),'1 Probability Basics'!$N$4:$N$8,0)),"All done ✔")
A6: 2 | B6: 2 Conditional + Bayes | C6: =COUNTA('2 Conditional + Bayes'!$E$4:$E$10) | D6: =COUNTIF('2 Conditional + Bayes'!$N$4:$N$10,TRUE()) | E6: =IF(C6=0,0,D6/C6) | F6: =SUM('2 Conditional + Bayes'!$H$4:$H$10) | G6: =SUMIF('2 Conditional + Bayes'!$N$4:$N$10,TRUE(),'2 Conditional + Bayes'!$H$4:$H$10) | H6: =COUNTIFS('2 Conditional + Bayes'!$J$4:$J$10,"★★★ High",'2 Conditional + Bayes'!$N$4:$N$10,FALSE()) | I6: =COUNTIF('2 Conditional + Bayes'!$O$4:$O$10,"Weak") | J6: =IFERROR("Q"&INDEX('2 Conditional + Bayes'!$A$4:$A$10,MATCH(FALSE(),'2 Conditional + Bayes'!$N$4:$N$10,0))&" · "&INDEX('2 Conditional + Bayes'!$B$4:$B$10,MATCH(FALSE(),'2 Conditional + Bayes'!$N$4:$N$10,0))&" "&INDEX('2 Conditional + Bayes'!$D$4:$D$10,MATCH(FALSE(),'2 Conditional + Bayes'!$N$4:$N$10,0))&" · TF p."&INDEX('2 Conditional + Bayes'!$I$4:$I$10,MATCH(FALSE(),'2 Conditional + Bayes'!$N$4:$N$10,0)),"All done ✔")
A7: 3 | B7: 3 Random Variables | C7: =COUNTA('3 Random Variables'!$E$4:$E$14) | D7: =COUNTIF('3 Random Variables'!$N$4:$N$14,TRUE()) | E7: =IF(C7=0,0,D7/C7) | F7: =SUM('3 Random Variables'!$H$4:$H$14) | G7: =SUMIF('3 Random Variables'!$N$4:$N$14,TRUE(),'3 Random Variables'!$H$4:$H$14) | H7: =COUNTIFS('3 Random Variables'!$J$4:$J$14,"★★★ High",'3 Random Variables'!$N$4:$N$14,FALSE()) | I7: =COUNTIF('3 Random Variables'!$O$4:$O$14,"Weak") | J7: =IFERROR("Q"&INDEX('3 Random Variables'!$A$4:$A$14,MATCH(FALSE(),'3 Random Variables'!$N$4:$N$14,0))&" · "&INDEX('3 Random Variables'!$B$4:$B$14,MATCH(FALSE(),'3 Random Variables'!$N$4:$N$14,0))&" "&INDEX('3 Random Variables'!$D$4:$D$14,MATCH(FALSE(),'3 Random Variables'!$N$4:$N$14,0))&" · TF p."&INDEX('3 Random Variables'!$I$4:$I$14,MATCH(FALSE(),'3 Random Variables'!$N$4:$N$14,0)),"All done ✔")
A8: 4 | B8: 4 Joint Distributions | C8: =COUNTA('4 Joint Distributions'!$E$4:$E$7) | D8: =COUNTIF('4 Joint Distributions'!$N$4:$N$7,TRUE()) | E8: =IF(C8=0,0,D8/C8) | F8: =SUM('4 Joint Distributions'!$H$4:$H$7) | G8: =SUMIF('4 Joint Distributions'!$N$4:$N$7,TRUE(),'4 Joint Distributions'!$H$4:$H$7) | H8: =COUNTIFS('4 Joint Distributions'!$J$4:$J$7,"★★★ High",'4 Joint Distributions'!$N$4:$N$7,FALSE()) | I8: =COUNTIF('4 Joint Distributions'!$O$4:$O$7,"Weak") | J8: =IFERROR("Q"&INDEX('4 Joint Distributions'!$A$4:$A$7,MATCH(FALSE(),'4 Joint Distributions'!$N$4:$N$7,0))&" · "&INDEX('4 Joint Distributions'!$B$4:$B$7,MATCH(FALSE(),'4 Joint Distributions'!$N$4:$N$7,0))&" "&INDEX('4 Joint Distributions'!$D$4:$D$7,MATCH(FALSE(),'4 Joint Distributions'!$N$4:$N$7,0))&" · TF p."&INDEX('4 Joint Distributions'!$I$4:$I$7,MATCH(FALSE(),'4 Joint Distributions'!$N$4:$N$7,0)),"All done ✔")
A9: 5 | B9: 5 Discrete Distributions | C9: =COUNTA('5 Discrete Distributions'!$E$4:$E$19) | D9: =COUNTIF('5 Discrete Distributions'!$N$4:$N$19,TRUE()) | E9: =IF(C9=0,0,D9/C9) | F9: =SUM('5 Discrete Distributions'!$H$4:$H$19) | G9: =SUMIF('5 Discrete Distributions'!$N$4:$N$19,TRUE(),'5 Discrete Distributions'!$H$4:$H$19) | H9: =COUNTIFS('5 Discrete Distributions'!$J$4:$J$19,"★★★ High",'5 Discrete Distributions'!$N$4:$N$19,FALSE()) | I9: =COUNTIF('5 Discrete Distributions'!$O$4:$O$19,"Weak") | J9: =IFERROR("Q"&INDEX('5 Discrete Distributions'!$A$4:$A$19,MATCH(FALSE(),'5 Discrete Distributions'!$N$4:$N$19,0))&" · "&INDEX('5 Discrete Distributions'!$B$4:$B$19,MATCH(FALSE(),'5 Discrete Distributions'!$N$4:$N$19,0))&" "&INDEX('5 Discrete Distributions'!$D$4:$D$19,MATCH(FALSE(),'5 Discrete Distributions'!$N$4:$N$19,0))&" · TF p."&INDEX('5 Discrete Distributions'!$I$4:$I$19,MATCH(FALSE(),'5 Discrete Distributions'!$N$4:$N$19,0)),"All done ✔")
A10: 6 | B10: 6 Normal Distribution | C10: =COUNTA('6 Normal Distribution'!$E$4:$E$13) | D10: =COUNTIF('6 Normal Distribution'!$N$4:$N$13,TRUE()) | E10: =IF(C10=0,0,D10/C10) | F10: =SUM('6 Normal Distribution'!$H$4:$H$13) | G10: =SUMIF('6 Normal Distribution'!$N$4:$N$13,TRUE(),'6 Normal Distribution'!$H$4:$H$13) | H10: =COUNTIFS('6 Normal Distribution'!$J$4:$J$13,"★★★ High",'6 Normal Distribution'!$N$4:$N$13,FALSE()) | I10: =COUNTIF('6 Normal Distribution'!$O$4:$O$13,"Weak") | J10: =IFERROR("Q"&INDEX('6 Normal Distribution'!$A$4:$A$13,MATCH(FALSE(),'6 Normal Distribution'!$N$4:$N$13,0))&" · "&INDEX('6 Normal Distribution'!$B$4:$B$13,MATCH(FALSE(),'6 Normal Distribution'!$N$4:$N$13,0))&" "&INDEX('6 Normal Distribution'!$D$4:$D$13,MATCH(FALSE(),'6 Normal Distribution'!$N$4:$N$13,0))&" · TF p."&INDEX('6 Normal Distribution'!$I$4:$I$13,MATCH(FALSE(),'6 Normal Distribution'!$N$4:$N$13,0)),"All done ✔")
A11: 7 | B11: 7 ANOVA | C11: =COUNTA('7 ANOVA'!$E$4:$E$7) | D11: =COUNTIF('7 ANOVA'!$N$4:$N$7,TRUE()) | E11: =IF(C11=0,0,D11/C11) | F11: =SUM('7 ANOVA'!$H$4:$H$7) | G11: =SUMIF('7 ANOVA'!$N$4:$N$7,TRUE(),'7 ANOVA'!$H$4:$H$7) | H11: =COUNTIFS('7 ANOVA'!$J$4:$J$7,"★★★ High",'7 ANOVA'!$N$4:$N$7,FALSE()) | I11: =COUNTIF('7 ANOVA'!$O$4:$O$7,"Weak") | J11: =IFERROR("Q"&INDEX('7 ANOVA'!$A$4:$A$7,MATCH(FALSE(),'7 ANOVA'!$N$4:$N$7,0))&" · "&INDEX('7 ANOVA'!$B$4:$B$7,MATCH(FALSE(),'7 ANOVA'!$N$4:$N$7,0))&" "&INDEX('7 ANOVA'!$D$4:$D$7,MATCH(FALSE(),'7 ANOVA'!$N$4:$N$7,0))&" · TF p."&INDEX('7 ANOVA'!$I$4:$I$7,MATCH(FALSE(),'7 ANOVA'!$N$4:$N$7,0)),"All done ✔")
A12: 8 | B12: 8 Hypothesis Testing | C12: =COUNTA('8 Hypothesis Testing'!$E$4:$E$26) | D12: =COUNTIF('8 Hypothesis Testing'!$N$4:$N$26,TRUE()) | E12: =IF(C12=0,0,D12/C12) | F12: =SUM('8 Hypothesis Testing'!$H$4:$H$26) | G12: =SUMIF('8 Hypothesis Testing'!$N$4:$N$26,TRUE(),'8 Hypothesis Testing'!$H$4:$H$26) | H12: =COUNTIFS('8 Hypothesis Testing'!$J$4:$J$26,"★★★ High",'8 Hypothesis Testing'!$N$4:$N$26,FALSE()) | I12: =COUNTIF('8 Hypothesis Testing'!$O$4:$O$26,"Weak") | J12: =IFERROR("Q"&INDEX('8 Hypothesis Testing'!$A$4:$A$26,MATCH(FALSE(),'8 Hypothesis Testing'!$N$4:$N$26,0))&" · "&INDEX('8 Hypothesis Testing'!$B$4:$B$26,MATCH(FALSE(),'8 Hypothesis Testing'!$N$4:$N$26,0))&" "&INDEX('8 Hypothesis Testing'!$D$4:$D$26,MATCH(FALSE(),'8 Hypothesis Testing'!$N$4:$N$26,0))&" · TF p."&INDEX('8 Hypothesis Testing'!$I$4:$I$26,MATCH(FALSE(),'8 Hypothesis Testing'!$N$4:$N$26,0)),"All done ✔")
B13: TOTAL | C13: =SUM(C5:C12) | D13: =SUM(D5:D12) | E13: =IF(C13=0,0,D13/C13) | F13: =SUM(F5:F12) | G13: =SUM(G5:G12) | H13: =SUM(H5:H12) | I13: =SUM(I5:I12)
A15: Questions by year (tabs 1–8)
A16: # | B16: Year | C16: Questions | D16: Done | E16: % Done | F16: Marks (total)
A17: 1 | B17: 2023-24 | C17: =COUNTIF('1 Probability Basics'!$B$4:$B$8,$B17)+COUNTIF('2 Conditional + Bayes'!$B$4:$B$10,$B17)+COUNTIF('3 Random Variables'!$B$4:$B$14,$B17)+COUNTIF('4 Joint Distributions'!$B$4:$B$7,$B17)+COUNTIF('5 Discrete Distributions'!$B$4:$B$19,$B17)+COUNTIF('6 Normal Distribution'!$B$4:$B$13,$B17)+COUNTIF('7 ANOVA'!$B$4:$B$7,$B17)+COUNTIF('8 Hypothesis Testing'!$B$4:$B$26,$B17) | D17: =COUNTIFS('1 Probability Basics'!$B$4:$B$8,$B17,'1 Probability Basics'!$N$4:$N$8,TRUE())+COUNTIFS('2 Conditional + Bayes'!$B$4:$B$10,$B17,'2 Conditional + Bayes'!$N$4:$N$10,TRUE())+COUNTIFS('3 Random Variables'!$B$4:$B$14,$B17,'3 Random Variables'!$N$4:$N$14,TRUE())+COUNTIFS('4 Joint Distributions'!$B$4:$B$7,$B17,'4 Joint Distributions'!$N$4:$N$7,TRUE())+COUNTIFS('5 Discrete Distributions'!$B$4:$B$19,$B17,'5 Discrete Distributions'!$N$4:$N$19,TRUE())+COUNTIFS('6 Normal Distribution'!$B$4:$B$13,$B17,'6 Normal Distribution'!$N$4:$N$13,TRUE())+COUNTIFS('7 ANOVA'!$B$4:$B$7,$B17,'7 ANOVA'!$N$4:$N$7,TRUE())+COUNTIFS('8 Hypothesis Testing'!$B$4:$B$26,$B17,'8 Hypothesis Testing'!$N$4:$N$26,TRUE()) | E17: =IF(C17=0,0,D17/C17) | F17: =SUMIF('1 Probability Basics'!$B$4:$B$8,$B17,'1 Probability Basics'!$H$4:$H$8)+SUMIF('2 Conditional + Bayes'!$B$4:$B$10,$B17,'2 Conditional + Bayes'!$H$4:$H$10)+SUMIF('3 Random Variables'!$B$4:$B$14,$B17,'3 Random Variables'!$H$4:$H$14)+SUMIF('4 Joint Distributions'!$B$4:$B$7,$B17,'4 Joint Distributions'!$H$4:$H$7)+SUMIF('5 Discrete Distributions'!$B$4:$B$19,$B17,'5 Discrete Distributions'!$H$4:$H$19)+SUMIF('6 Normal Distribution'!$B$4:$B$13,$B17,'6 Normal Distribution'!$H$4:$H$13)+SUMIF('7 ANOVA'!$B$4:$B$7,$B17,'7 ANOVA'!$H$4:$H$7)+SUMIF('8 Hypothesis Testing'!$B$4:$B$26,$B17,'8 Hypothesis Testing'!$H$4:$H$26)
A18: 2 | B18: 2022-23 | C18: =COUNTIF('1 Probability Basics'!$B$4:$B$8,$B18)+COUNTIF('2 Conditional + Bayes'!$B$4:$B$10,$B18)+COUNTIF('3 Random Variables'!$B$4:$B$14,$B18)+COUNTIF('4 Joint Distributions'!$B$4:$B$7,$B18)+COUNTIF('5 Discrete Distributions'!$B$4:$B$19,$B18)+COUNTIF('6 Normal Distribution'!$B$4:$B$13,$B18)+COUNTIF('7 ANOVA'!$B$4:$B$7,$B18)+COUNTIF('8 Hypothesis Testing'!$B$4:$B$26,$B18) | D18: =COUNTIFS('1 Probability Basics'!$B$4:$B$8,$B18,'1 Probability Basics'!$N$4:$N$8,TRUE())+COUNTIFS('2 Conditional + Bayes'!$B$4:$B$10,$B18,'2 Conditional + Bayes'!$N$4:$N$10,TRUE())+COUNTIFS('3 Random Variables'!$B$4:$B$14,$B18,'3 Random Variables'!$N$4:$N$14,TRUE())+COUNTIFS('4 Joint Distributions'!$B$4:$B$7,$B18,'4 Joint Distributions'!$N$4:$N$7,TRUE())+COUNTIFS('5 Discrete Distributions'!$B$4:$B$19,$B18,'5 Discrete Distributions'!$N$4:$N$19,TRUE())+COUNTIFS('6 Normal Distribution'!$B$4:$B$13,$B18,'6 Normal Distribution'!$N$4:$N$13,TRUE())+COUNTIFS('7 ANOVA'!$B$4:$B$7,$B18,'7 ANOVA'!$N$4:$N$7,TRUE())+COUNTIFS('8 Hypothesis Testing'!$B$4:$B$26,$B18,'8 Hypothesis Testing'!$N$4:$N$26,TRUE()) | E18: =IF(C18=0,0,D18/C18) | F18: =SUMIF('1 Probability Basics'!$B$4:$B$8,$B18,'1 Probability Basics'!$H$4:$H$8)+SUMIF('2 Conditional + Bayes'!$B$4:$B$10,$B18,'2 Conditional + Bayes'!$H$4:$H$10)+SUMIF('3 Random Variables'!$B$4:$B$14,$B18,'3 Random Variables'!$H$4:$H$14)+SUMIF('4 Joint Distributions'!$B$4:$B$7,$B18,'4 Joint Distributions'!$H$4:$H$7)+SUMIF('5 Discrete Distributions'!$B$4:$B$19,$B18,'5 Discrete Distributions'!$H$4:$H$19)+SUMIF('6 Normal Distribution'!$B$4:$B$13,$B18,'6 Normal Distribution'!$H$4:$H$13)+SUMIF('7 ANOVA'!$B$4:$B$7,$B18,'7 ANOVA'!$H$4:$H$7)+SUMIF('8 Hypothesis Testing'!$B$4:$B$26,$B18,'8 Hypothesis Testing'!$H$4:$H$26)
A19: 3 | B19: 2021-22 | C19: =COUNTIF('1 Probability Basics'!$B$4:$B$8,$B19)+COUNTIF('2 Conditional + Bayes'!$B$4:$B$10,$B19)+COUNTIF('3 Random Variables'!$B$4:$B$14,$B19)+COUNTIF('4 Joint Distributions'!$B$4:$B$7,$B19)+COUNTIF('5 Discrete Distributions'!$B$4:$B$19,$B19)+COUNTIF('6 Normal Distribution'!$B$4:$B$13,$B19)+COUNTIF('7 ANOVA'!$B$4:$B$7,$B19)+COUNTIF('8 Hypothesis Testing'!$B$4:$B$26,$B19) | D19: =COUNTIFS('1 Probability Basics'!$B$4:$B$8,$B19,'1 Probability Basics'!$N$4:$N$8,TRUE())+COUNTIFS('2 Conditional + Bayes'!$B$4:$B$10,$B19,'2 Conditional + Bayes'!$N$4:$N$10,TRUE())+COUNTIFS('3 Random Variables'!$B$4:$B$14,$B19,'3 Random Variables'!$N$4:$N$14,TRUE())+COUNTIFS('4 Joint Distributions'!$B$4:$B$7,$B19,'4 Joint Distributions'!$N$4:$N$7,TRUE())+COUNTIFS('5 Discrete Distributions'!$B$4:$B$19,$B19,'5 Discrete Distributions'!$N$4:$N$19,TRUE())+COUNTIFS('6 Normal Distribution'!$B$4:$B$13,$B19,'6 Normal Distribution'!$N$4:$N$13,TRUE())+COUNTIFS('7 ANOVA'!$B$4:$B$7,$B19,'7 ANOVA'!$N$4:$N$7,TRUE())+COUNTIFS('8 Hypothesis Testing'!$B$4:$B$26,$B19,'8 Hypothesis Testing'!$N$4:$N$26,TRUE()) | E19: =IF(C19=0,0,D19/C19) | F19: =SUMIF('1 Probability Basics'!$B$4:$B$8,$B19,'1 Probability Basics'!$H$4:$H$8)+SUMIF('2 Conditional + Bayes'!$B$4:$B$10,$B19,'2 Conditional + Bayes'!$H$4:$H$10)+SUMIF('3 Random Variables'!$B$4:$B$14,$B19,'3 Random Variables'!$H$4:$H$14)+SUMIF('4 Joint Distributions'!$B$4:$B$7,$B19,'4 Joint Distributions'!$H$4:$H$7)+SUMIF('5 Discrete Distributions'!$B$4:$B$19,$B19,'5 Discrete Distributions'!$H$4:$H$19)+SUMIF('6 Normal Distribution'!$B$4:$B$13,$B19,'6 Normal Distribution'!$H$4:$H$13)+SUMIF('7 ANOVA'!$B$4:$B$7,$B19,'7 ANOVA'!$H$4:$H$7)+SUMIF('8 Hypothesis Testing'!$B$4:$B$26,$B19,'8 Hypothesis Testing'!$H$4:$H$26)
A20: 4 | B20: 2020-21 | C20: =COUNTIF('1 Probability Basics'!$B$4:$B$8,$B20)+COUNTIF('2 Conditional + Bayes'!$B$4:$B$10,$B20)+COUNTIF('3 Random Variables'!$B$4:$B$14,$B20)+COUNTIF('4 Joint Distributions'!$B$4:$B$7,$B20)+COUNTIF('5 Discrete Distributions'!$B$4:$B$19,$B20)+COUNTIF('6 Normal Distribution'!$B$4:$B$13,$B20)+COUNTIF('7 ANOVA'!$B$4:$B$7,$B20)+COUNTIF('8 Hypothesis Testing'!$B$4:$B$26,$B20) | D20: =COUNTIFS('1 Probability Basics'!$B$4:$B$8,$B20,'1 Probability Basics'!$N$4:$N$8,TRUE())+COUNTIFS('2 Conditional + Bayes'!$B$4:$B$10,$B20,'2 Conditional + Bayes'!$N$4:$N$10,TRUE())+COUNTIFS('3 Random Variables'!$B$4:$B$14,$B20,'3 Random Variables'!$N$4:$N$14,TRUE())+COUNTIFS('4 Joint Distributions'!$B$4:$B$7,$B20,'4 Joint Distributions'!$N$4:$N$7,TRUE())+COUNTIFS('5 Discrete Distributions'!$B$4:$B$19,$B20,'5 Discrete Distributions'!$N$4:$N$19,TRUE())+COUNTIFS('6 Normal Distribution'!$B$4:$B$13,$B20,'6 Normal Distribution'!$N$4:$N$13,TRUE())+COUNTIFS('7 ANOVA'!$B$4:$B$7,$B20,'7 ANOVA'!$N$4:$N$7,TRUE())+COUNTIFS('8 Hypothesis Testing'!$B$4:$B$26,$B20,'8 Hypothesis Testing'!$N$4:$N$26,TRUE()) | E20: =IF(C20=0,0,D20/C20) | F20: =SUMIF('1 Probability Basics'!$B$4:$B$8,$B20,'1 Probability Basics'!$H$4:$H$8)+SUMIF('2 Conditional + Bayes'!$B$4:$B$10,$B20,'2 Conditional + Bayes'!$H$4:$H$10)+SUMIF('3 Random Variables'!$B$4:$B$14,$B20,'3 Random Variables'!$H$4:$H$14)+SUMIF('4 Joint Distributions'!$B$4:$B$7,$B20,'4 Joint Distributions'!$H$4:$H$7)+SUMIF('5 Discrete Distributions'!$B$4:$B$19,$B20,'5 Discrete Distributions'!$H$4:$H$19)+SUMIF('6 Normal Distribution'!$B$4:$B$13,$B20,'6 Normal Distribution'!$H$4:$H$13)+SUMIF('7 ANOVA'!$B$4:$B$7,$B20,'7 ANOVA'!$H$4:$H$7)+SUMIF('8 Hypothesis Testing'!$B$4:$B$26,$B20,'8 Hypothesis Testing'!$H$4:$H$26)
A21: 5 | B21: 2019-20 | C21: =COUNTIF('1 Probability Basics'!$B$4:$B$8,$B21)+COUNTIF('2 Conditional + Bayes'!$B$4:$B$10,$B21)+COUNTIF('3 Random Variables'!$B$4:$B$14,$B21)+COUNTIF('4 Joint Distributions'!$B$4:$B$7,$B21)+COUNTIF('5 Discrete Distributions'!$B$4:$B$19,$B21)+COUNTIF('6 Normal Distribution'!$B$4:$B$13,$B21)+COUNTIF('7 ANOVA'!$B$4:$B$7,$B21)+COUNTIF('8 Hypothesis Testing'!$B$4:$B$26,$B21) | D21: =COUNTIFS('1 Probability Basics'!$B$4:$B$8,$B21,'1 Probability Basics'!$N$4:$N$8,TRUE())+COUNTIFS('2 Conditional + Bayes'!$B$4:$B$10,$B21,'2 Conditional + Bayes'!$N$4:$N$10,TRUE())+COUNTIFS('3 Random Variables'!$B$4:$B$14,$B21,'3 Random Variables'!$N$4:$N$14,TRUE())+COUNTIFS('4 Joint Distributions'!$B$4:$B$7,$B21,'4 Joint Distributions'!$N$4:$N$7,TRUE())+COUNTIFS('5 Discrete Distributions'!$B$4:$B$19,$B21,'5 Discrete Distributions'!$N$4:$N$19,TRUE())+COUNTIFS('6 Normal Distribution'!$B$4:$B$13,$B21,'6 Normal Distribution'!$N$4:$N$13,TRUE())+COUNTIFS('7 ANOVA'!$B$4:$B$7,$B21,'7 ANOVA'!$N$4:$N$7,TRUE())+COUNTIFS('8 Hypothesis Testing'!$B$4:$B$26,$B21,'8 Hypothesis Testing'!$N$4:$N$26,TRUE()) | E21: =IF(C21=0,0,D21/C21) | F21: =SUMIF('1 Probability Basics'!$B$4:$B$8,$B21,'1 Probability Basics'!$H$4:$H$8)+SUMIF('2 Conditional + Bayes'!$B$4:$B$10,$B21,'2 Conditional + Bayes'!$H$4:$H$10)+SUMIF('3 Random Variables'!$B$4:$B$14,$B21,'3 Random Variables'!$H$4:$H$14)+SUMIF('4 Joint Distributions'!$B$4:$B$7,$B21,'4 Joint Distributions'!$H$4:$H$7)+SUMIF('5 Discrete Distributions'!$B$4:$B$19,$B21,'5 Discrete Distributions'!$H$4:$H$19)+SUMIF('6 Normal Distribution'!$B$4:$B$13,$B21,'6 Normal Distribution'!$H$4:$H$13)+SUMIF('7 ANOVA'!$B$4:$B$7,$B21,'7 ANOVA'!$H$4:$H$7)+SUMIF('8 Hypothesis Testing'!$B$4:$B$26,$B21,'8 Hypothesis Testing'!$H$4:$H$26)
A22: 6 | B22: 2018-19 | C22: =COUNTIF('1 Probability Basics'!$B$4:$B$8,$B22)+COUNTIF('2 Conditional + Bayes'!$B$4:$B$10,$B22)+COUNTIF('3 Random Variables'!$B$4:$B$14,$B22)+COUNTIF('4 Joint Distributions'!$B$4:$B$7,$B22)+COUNTIF('5 Discrete Distributions'!$B$4:$B$19,$B22)+COUNTIF('6 Normal Distribution'!$B$4:$B$13,$B22)+COUNTIF('7 ANOVA'!$B$4:$B$7,$B22)+COUNTIF('8 Hypothesis Testing'!$B$4:$B$26,$B22) | D22: =COUNTIFS('1 Probability Basics'!$B$4:$B$8,$B22,'1 Probability Basics'!$N$4:$N$8,TRUE())+COUNTIFS('2 Conditional + Bayes'!$B$4:$B$10,$B22,'2 Conditional + Bayes'!$N$4:$N$10,TRUE())+COUNTIFS('3 Random Variables'!$B$4:$B$14,$B22,'3 Random Variables'!$N$4:$N$14,TRUE())+COUNTIFS('4 Joint Distributions'!$B$4:$B$7,$B22,'4 Joint Distributions'!$N$4:$N$7,TRUE())+COUNTIFS('5 Discrete Distributions'!$B$4:$B$19,$B22,'5 Discrete Distributions'!$N$4:$N$19,TRUE())+COUNTIFS('6 Normal Distribution'!$B$4:$B$13,$B22,'6 Normal Distribution'!$N$4:$N$13,TRUE())+COUNTIFS('7 ANOVA'!$B$4:$B$7,$B22,'7 ANOVA'!$N$4:$N$7,TRUE())+COUNTIFS('8 Hypothesis Testing'!$B$4:$B$26,$B22,'8 Hypothesis Testing'!$N$4:$N$26,TRUE()) | E22: =IF(C22=0,0,D22/C22) | F22: =SUMIF('1 Probability Basics'!$B$4:$B$8,$B22,'1 Probability Basics'!$H$4:$H$8)+SUMIF('2 Conditional + Bayes'!$B$4:$B$10,$B22,'2 Conditional + Bayes'!$H$4:$H$10)+SUMIF('3 Random Variables'!$B$4:$B$14,$B22,'3 Random Variables'!$H$4:$H$14)+SUMIF('4 Joint Distributions'!$B$4:$B$7,$B22,'4 Joint Distributions'!$H$4:$H$7)+SUMIF('5 Discrete Distributions'!$B$4:$B$19,$B22,'5 Discrete Distributions'!$H$4:$H$19)+SUMIF('6 Normal Distribution'!$B$4:$B$13,$B22,'6 Normal Distribution'!$H$4:$H$13)+SUMIF('7 ANOVA'!$B$4:$B$7,$B22,'7 ANOVA'!$H$4:$H$7)+SUMIF('8 Hypothesis Testing'!$B$4:$B$26,$B22,'8 Hypothesis Testing'!$H$4:$H$26)
A23: 7 | B23: 2016-17 | C23: =COUNTIF('1 Probability Basics'!$B$4:$B$8,$B23)+COUNTIF('2 Conditional + Bayes'!$B$4:$B$10,$B23)+COUNTIF('3 Random Variables'!$B$4:$B$14,$B23)+COUNTIF('4 Joint Distributions'!$B$4:$B$7,$B23)+COUNTIF('5 Discrete Distributions'!$B$4:$B$19,$B23)+COUNTIF('6 Normal Distribution'!$B$4:$B$13,$B23)+COUNTIF('7 ANOVA'!$B$4:$B$7,$B23)+COUNTIF('8 Hypothesis Testing'!$B$4:$B$26,$B23) | D23: =COUNTIFS('1 Probability Basics'!$B$4:$B$8,$B23,'1 Probability Basics'!$N$4:$N$8,TRUE())+COUNTIFS('2 Conditional + Bayes'!$B$4:$B$10,$B23,'2 Conditional + Bayes'!$N$4:$N$10,TRUE())+COUNTIFS('3 Random Variables'!$B$4:$B$14,$B23,'3 Random Variables'!$N$4:$N$14,TRUE())+COUNTIFS('4 Joint Distributions'!$B$4:$B$7,$B23,'4 Joint Distributions'!$N$4:$N$7,TRUE())+COUNTIFS('5 Discrete Distributions'!$B$4:$B$19,$B23,'5 Discrete Distributions'!$N$4:$N$19,TRUE())+COUNTIFS('6 Normal Distribution'!$B$4:$B$13,$B23,'6 Normal Distribution'!$N$4:$N$13,TRUE())+COUNTIFS('7 ANOVA'!$B$4:$B$7,$B23,'7 ANOVA'!$N$4:$N$7,TRUE())+COUNTIFS('8 Hypothesis Testing'!$B$4:$B$26,$B23,'8 Hypothesis Testing'!$N$4:$N$26,TRUE()) | E23: =IF(C23=0,0,D23/C23) | F23: =SUMIF('1 Probability Basics'!$B$4:$B$8,$B23,'1 Probability Basics'!$H$4:$H$8)+SUMIF('2 Conditional + Bayes'!$B$4:$B$10,$B23,'2 Conditional + Bayes'!$H$4:$H$10)+SUMIF('3 Random Variables'!$B$4:$B$14,$B23,'3 Random Variables'!$H$4:$H$14)+SUMIF('4 Joint Distributions'!$B$4:$B$7,$B23,'4 Joint Distributions'!$H$4:$H$7)+SUMIF('5 Discrete Distributions'!$B$4:$B$19,$B23,'5 Discrete Distributions'!$H$4:$H$19)+SUMIF('6 Normal Distribution'!$B$4:$B$13,$B23,'6 Normal Distribution'!$H$4:$H$13)+SUMIF('7 ANOVA'!$B$4:$B$7,$B23,'7 ANOVA'!$H$4:$H$7)+SUMIF('8 Hypothesis Testing'!$B$4:$B$26,$B23,'8 Hypothesis Testing'!$H$4:$H$26)
A24: 8 | B24: 2015-16 | C24: =COUNTIF('1 Probability Basics'!$B$4:$B$8,$B24)+COUNTIF('2 Conditional + Bayes'!$B$4:$B$10,$B24)+COUNTIF('3 Random Variables'!$B$4:$B$14,$B24)+COUNTIF('4 Joint Distributions'!$B$4:$B$7,$B24)+COUNTIF('5 Discrete Distributions'!$B$4:$B$19,$B24)+COUNTIF('6 Normal Distribution'!$B$4:$B$13,$B24)+COUNTIF('7 ANOVA'!$B$4:$B$7,$B24)+COUNTIF('8 Hypothesis Testing'!$B$4:$B$26,$B24) | D24: =COUNTIFS('1 Probability Basics'!$B$4:$B$8,$B24,'1 Probability Basics'!$N$4:$N$8,TRUE())+COUNTIFS('2 Conditional + Bayes'!$B$4:$B$10,$B24,'2 Conditional + Bayes'!$N$4:$N$10,TRUE())+COUNTIFS('3 Random Variables'!$B$4:$B$14,$B24,'3 Random Variables'!$N$4:$N$14,TRUE())+COUNTIFS('4 Joint Distributions'!$B$4:$B$7,$B24,'4 Joint Distributions'!$N$4:$N$7,TRUE())+COUNTIFS('5 Discrete Distributions'!$B$4:$B$19,$B24,'5 Discrete Distributions'!$N$4:$N$19,TRUE())+COUNTIFS('6 Normal Distribution'!$B$4:$B$13,$B24,'6 Normal Distribution'!$N$4:$N$13,TRUE())+COUNTIFS('7 ANOVA'!$B$4:$B$7,$B24,'7 ANOVA'!$N$4:$N$7,TRUE())+COUNTIFS('8 Hypothesis Testing'!$B$4:$B$26,$B24,'8 Hypothesis Testing'!$N$4:$N$26,TRUE()) | E24: =IF(C24=0,0,D24/C24) | F24: =SUMIF('1 Probability Basics'!$B$4:$B$8,$B24,'1 Probability Basics'!$H$4:$H$8)+SUMIF('2 Conditional + Bayes'!$B$4:$B$10,$B24,'2 Conditional + Bayes'!$H$4:$H$10)+SUMIF('3 Random Variables'!$B$4:$B$14,$B24,'3 Random Variables'!$H$4:$H$14)+SUMIF('4 Joint Distributions'!$B$4:$B$7,$B24,'4 Joint Distributions'!$H$4:$H$7)+SUMIF('5 Discrete Distributions'!$B$4:$B$19,$B24,'5 Discrete Distributions'!$H$4:$H$19)+SUMIF('6 Normal Distribution'!$B$4:$B$13,$B24,'6 Normal Distribution'!$H$4:$H$13)+SUMIF('7 ANOVA'!$B$4:$B$7,$B24,'7 ANOVA'!$H$4:$H$7)+SUMIF('8 Hypothesis Testing'!$B$4:$B$26,$B24,'8 Hypothesis Testing'!$H$4:$H$26)
A25: 9 | B25: 2014-15 | C25: =COUNTIF('1 Probability Basics'!$B$4:$B$8,$B25)+COUNTIF('2 Conditional + Bayes'!$B$4:$B$10,$B25)+COUNTIF('3 Random Variables'!$B$4:$B$14,$B25)+COUNTIF('4 Joint Distributions'!$B$4:$B$7,$B25)+COUNTIF('5 Discrete Distributions'!$B$4:$B$19,$B25)+COUNTIF('6 Normal Distribution'!$B$4:$B$13,$B25)+COUNTIF('7 ANOVA'!$B$4:$B$7,$B25)+COUNTIF('8 Hypothesis Testing'!$B$4:$B$26,$B25) | D25: =COUNTIFS('1 Probability Basics'!$B$4:$B$8,$B25,'1 Probability Basics'!$N$4:$N$8,TRUE())+COUNTIFS('2 Conditional + Bayes'!$B$4:$B$10,$B25,'2 Conditional + Bayes'!$N$4:$N$10,TRUE())+COUNTIFS('3 Random Variables'!$B$4:$B$14,$B25,'3 Random Variables'!$N$4:$N$14,TRUE())+COUNTIFS('4 Joint Distributions'!$B$4:$B$7,$B25,'4 Joint Distributions'!$N$4:$N$7,TRUE())+COUNTIFS('5 Discrete Distributions'!$B$4:$B$19,$B25,'5 Discrete Distributions'!$N$4:$N$19,TRUE())+COUNTIFS('6 Normal Distribution'!$B$4:$B$13,$B25,'6 Normal Distribution'!$N$4:$N$13,TRUE())+COUNTIFS('7 ANOVA'!$B$4:$B$7,$B25,'7 ANOVA'!$N$4:$N$7,TRUE())+COUNTIFS('8 Hypothesis Testing'!$B$4:$B$26,$B25,'8 Hypothesis Testing'!$N$4:$N$26,TRUE()) | E25: =IF(C25=0,0,D25/C25) | F25: =SUMIF('1 Probability Basics'!$B$4:$B$8,$B25,'1 Probability Basics'!$H$4:$H$8)+SUMIF('2 Conditional + Bayes'!$B$4:$B$10,$B25,'2 Conditional + Bayes'!$H$4:$H$10)+SUMIF('3 Random Variables'!$B$4:$B$14,$B25,'3 Random Variables'!$H$4:$H$14)+SUMIF('4 Joint Distributions'!$B$4:$B$7,$B25,'4 Joint Distributions'!$H$4:$H$7)+SUMIF('5 Discrete Distributions'!$B$4:$B$19,$B25,'5 Discrete Distributions'!$H$4:$H$19)+SUMIF('6 Normal Distribution'!$B$4:$B$13,$B25,'6 Normal Distribution'!$H$4:$H$13)+SUMIF('7 ANOVA'!$B$4:$B$7,$B25,'7 ANOVA'!$H$4:$H$7)+SUMIF('8 Hypothesis Testing'!$B$4:$B$26,$B25,'8 Hypothesis Testing'!$H$4:$H$26)
A26: 10 | B26: 2013-14 | C26: =COUNTIF('1 Probability Basics'!$B$4:$B$8,$B26)+COUNTIF('2 Conditional + Bayes'!$B$4:$B$10,$B26)+COUNTIF('3 Random Variables'!$B$4:$B$14,$B26)+COUNTIF('4 Joint Distributions'!$B$4:$B$7,$B26)+COUNTIF('5 Discrete Distributions'!$B$4:$B$19,$B26)+COUNTIF('6 Normal Distribution'!$B$4:$B$13,$B26)+COUNTIF('7 ANOVA'!$B$4:$B$7,$B26)+COUNTIF('8 Hypothesis Testing'!$B$4:$B$26,$B26) | D26: =COUNTIFS('1 Probability Basics'!$B$4:$B$8,$B26,'1 Probability Basics'!$N$4:$N$8,TRUE())+COUNTIFS('2 Conditional + Bayes'!$B$4:$B$10,$B26,'2 Conditional + Bayes'!$N$4:$N$10,TRUE())+COUNTIFS('3 Random Variables'!$B$4:$B$14,$B26,'3 Random Variables'!$N$4:$N$14,TRUE())+COUNTIFS('4 Joint Distributions'!$B$4:$B$7,$B26,'4 Joint Distributions'!$N$4:$N$7,TRUE())+COUNTIFS('5 Discrete Distributions'!$B$4:$B$19,$B26,'5 Discrete Distributions'!$N$4:$N$19,TRUE())+COUNTIFS('6 Normal Distribution'!$B$4:$B$13,$B26,'6 Normal Distribution'!$N$4:$N$13,TRUE())+COUNTIFS('7 ANOVA'!$B$4:$B$7,$B26,'7 ANOVA'!$N$4:$N$7,TRUE())+COUNTIFS('8 Hypothesis Testing'!$B$4:$B$26,$B26,'8 Hypothesis Testing'!$N$4:$N$26,TRUE()) | E26: =IF(C26=0,0,D26/C26) | F26: =SUMIF('1 Probability Basics'!$B$4:$B$8,$B26,'1 Probability Basics'!$H$4:$H$8)+SUMIF('2 Conditional + Bayes'!$B$4:$B$10,$B26,'2 Conditional + Bayes'!$H$4:$H$10)+SUMIF('3 Random Variables'!$B$4:$B$14,$B26,'3 Random Variables'!$H$4:$H$14)+SUMIF('4 Joint Distributions'!$B$4:$B$7,$B26,'4 Joint Distributions'!$H$4:$H$7)+SUMIF('5 Discrete Distributions'!$B$4:$B$19,$B26,'5 Discrete Distributions'!$H$4:$H$19)+SUMIF('6 Normal Distribution'!$B$4:$B$13,$B26,'6 Normal Distribution'!$H$4:$H$13)+SUMIF('7 ANOVA'!$B$4:$B$7,$B26,'7 ANOVA'!$H$4:$H$7)+SUMIF('8 Hypothesis Testing'!$B$4:$B$26,$B26,'8 Hypothesis Testing'!$H$4:$H$26)
A27: 11 | B27: 2012-13 | C27: =COUNTIF('1 Probability Basics'!$B$4:$B$8,$B27)+COUNTIF('2 Conditional + Bayes'!$B$4:$B$10,$B27)+COUNTIF('3 Random Variables'!$B$4:$B$14,$B27)+COUNTIF('4 Joint Distributions'!$B$4:$B$7,$B27)+COUNTIF('5 Discrete Distributions'!$B$4:$B$19,$B27)+COUNTIF('6 Normal Distribution'!$B$4:$B$13,$B27)+COUNTIF('7 ANOVA'!$B$4:$B$7,$B27)+COUNTIF('8 Hypothesis Testing'!$B$4:$B$26,$B27) | D27: =COUNTIFS('1 Probability Basics'!$B$4:$B$8,$B27,'1 Probability Basics'!$N$4:$N$8,TRUE())+COUNTIFS('2 Conditional + Bayes'!$B$4:$B$10,$B27,'2 Conditional + Bayes'!$N$4:$N$10,TRUE())+COUNTIFS('3 Random Variables'!$B$4:$B$14,$B27,'3 Random Variables'!$N$4:$N$14,TRUE())+COUNTIFS('4 Joint Distributions'!$B$4:$B$7,$B27,'4 Joint Distributions'!$N$4:$N$7,TRUE())+COUNTIFS('5 Discrete Distributions'!$B$4:$B$19,$B27,'5 Discrete Distributions'!$N$4:$N$19,TRUE())+COUNTIFS('6 Normal Distribution'!$B$4:$B$13,$B27,'6 Normal Distribution'!$N$4:$N$13,TRUE())+COUNTIFS('7 ANOVA'!$B$4:$B$7,$B27,'7 ANOVA'!$N$4:$N$7,TRUE())+COUNTIFS('8 Hypothesis Testing'!$B$4:$B$26,$B27,'8 Hypothesis Testing'!$N$4:$N$26,TRUE()) | E27: =IF(C27=0,0,D27/C27) | F27: =SUMIF('1 Probability Basics'!$B$4:$B$8,$B27,'1 Probability Basics'!$H$4:$H$8)+SUMIF('2 Conditional + Bayes'!$B$4:$B$10,$B27,'2 Conditional + Bayes'!$H$4:$H$10)+SUMIF('3 Random Variables'!$B$4:$B$14,$B27,'3 Random Variables'!$H$4:$H$14)+SUMIF('4 Joint Distributions'!$B$4:$B$7,$B27,'4 Joint Distributions'!$H$4:$H$7)+SUMIF('5 Discrete Distributions'!$B$4:$B$19,$B27,'5 Discrete Distributions'!$H$4:$H$19)+SUMIF('6 Normal Distribution'!$B$4:$B$13,$B27,'6 Normal Distribution'!$H$4:$H$13)+SUMIF('7 ANOVA'!$B$4:$B$7,$B27,'7 ANOVA'!$H$4:$H$7)+SUMIF('8 Hypothesis Testing'!$B$4:$B$26,$B27,'8 Hypothesis Testing'!$H$4:$H$26)
A28: 12 | B28: 2011-12 | C28: =COUNTIF('1 Probability Basics'!$B$4:$B$8,$B28)+COUNTIF('2 Conditional + Bayes'!$B$4:$B$10,$B28)+COUNTIF('3 Random Variables'!$B$4:$B$14,$B28)+COUNTIF('4 Joint Distributions'!$B$4:$B$7,$B28)+COUNTIF('5 Discrete Distributions'!$B$4:$B$19,$B28)+COUNTIF('6 Normal Distribution'!$B$4:$B$13,$B28)+COUNTIF('7 ANOVA'!$B$4:$B$7,$B28)+COUNTIF('8 Hypothesis Testing'!$B$4:$B$26,$B28) | D28: =COUNTIFS('1 Probability Basics'!$B$4:$B$8,$B28,'1 Probability Basics'!$N$4:$N$8,TRUE())+COUNTIFS('2 Conditional + Bayes'!$B$4:$B$10,$B28,'2 Conditional + Bayes'!$N$4:$N$10,TRUE())+COUNTIFS('3 Random Variables'!$B$4:$B$14,$B28,'3 Random Variables'!$N$4:$N$14,TRUE())+COUNTIFS('4 Joint Distributions'!$B$4:$B$7,$B28,'4 Joint Distributions'!$N$4:$N$7,TRUE())+COUNTIFS('5 Discrete Distributions'!$B$4:$B$19,$B28,'5 Discrete Distributions'!$N$4:$N$19,TRUE())+COUNTIFS('6 Normal Distribution'!$B$4:$B$13,$B28,'6 Normal Distribution'!$N$4:$N$13,TRUE())+COUNTIFS('7 ANOVA'!$B$4:$B$7,$B28,'7 ANOVA'!$N$4:$N$7,TRUE())+COUNTIFS('8 Hypothesis Testing'!$B$4:$B$26,$B28,'8 Hypothesis Testing'!$N$4:$N$26,TRUE()) | E28: =IF(C28=0,0,D28/C28) | F28: =SUMIF('1 Probability Basics'!$B$4:$B$8,$B28,'1 Probability Basics'!$H$4:$H$8)+SUMIF('2 Conditional + Bayes'!$B$4:$B$10,$B28,'2 Conditional + Bayes'!$H$4:$H$10)+SUMIF('3 Random Variables'!$B$4:$B$14,$B28,'3 Random Variables'!$H$4:$H$14)+SUMIF('4 Joint Distributions'!$B$4:$B$7,$B28,'4 Joint Distributions'!$H$4:$H$7)+SUMIF('5 Discrete Distributions'!$B$4:$B$19,$B28,'5 Discrete Distributions'!$H$4:$H$19)+SUMIF('6 Normal Distribution'!$B$4:$B$13,$B28,'6 Normal Distribution'!$H$4:$H$13)+SUMIF('7 ANOVA'!$B$4:$B$7,$B28,'7 ANOVA'!$H$4:$H$7)+SUMIF('8 Hypothesis Testing'!$B$4:$B$26,$B28,'8 Hypothesis Testing'!$H$4:$H$26)
B29: Shaded years = ★★★ High priority (2019-20 onward).
B30: Outside Notes: only the central-limit-theorem question (2023-24 Q6(b)) — not in any slide deck; hypothesis testing is now covered by tab 8 (Lecture-13-20- Hypothesis.pdf).
B31: Complex-variable questions of the old MATH 241/245 papers are not listed.

Sheet 1 Probability Basics
A1: Lec 1–4 — Sets, Counting, Rules, Odds, Joint Tables
A2: Note file: MATH243_KKS_Probability_Basics_Notes.docx · Solve after finishing the matching lesson. Filter Priority → ★★★ High first.
A3: Q No. | B3: Year | C3: Course | D3: Ques No. | E3: Short Question | F3: Topic (slide PDF · slides) | G3: Lesson | H3: Marks | I3: TF Page | J3: Priority | K3: Type | L3: In Notes | M3: Same Type Also In | N3: Done | O3: Confidence | P3: Date | Q3: My Notes
A4: 1 | B4: 2014-15 | C4: MATH 241 | D4: 8(a) | E4: Box of 8 red, 3 white, 9 blue; 3 drawn: P(all red), P(2 red 1 white), P(at least 1 white) | F4: Counting, classical probability — Lec 2 pp. 2–8 | G4: L2 | H4: 12 | I4: 11 | J4: ★★ Medium | K4: Numerical | L4: ✔ Solved | M4: 2013-14 7(b)(i) | N4: FALSE
A5: 2 | B5: 2013-14 | C5: MATH 241 | D5: 7(b)(i) | E5: 3 cards drawn without replacement: P(all from different suits) | F5: Counting, classical probability — Lec 2 pp. 2–8 | G5: L2 | H5: 7 | I5: 8 | J5: ★★ Medium | K5: Numerical | L5: ✔ Solved | M5: 2014-15 8(a) | N5: FALSE
A6: 3 | B6: 2023-24 | C6: MATH 243 | D6: 1(a) | E6: Can two events be mutually exclusive and independent at the same time? Justify | F6: Multiplication rule, independence, odds — Lec 2 pp. 8–9, Lec 3&4 pp. 1–6 | G6: L3 | H6: 6 | I6: 22 batch p.1 | J6: ★★★ High | K6: Theory | L6: ✔ Solved | M6: 2016-17 7(a); 2011-12 7(b)(ii) | N6: FALSE
A7: 4 | B7: 2016-17 | C7: MATH 245 | D7: 7(a) | E7: Circuit of 4 parallel paths (0.02; 0.01–0.01; 0.01–0.01; 0.02 failure probabilities): P(circuit does not operate) | F7: Multiplication rule, independence, odds — Lec 2 pp. 8–9, Lec 3&4 pp. 1–6 | G7: L3 | H7: 10 | I7: 20 | J7: ★★ Medium | K7: Numerical | L7: ✔ Solved | M7: 2023-24 1(a); 2011-12 7(b)(ii) | N7: FALSE
A8: 5 | B8: 2011-12 | C8: MATH 241 | D8: 7(b)(ii) | E8: A, B, C solve a problem with probabilities 3/7, 2/3, 4/5 independently — P(problem solved) | F8: Multiplication rule, independence, odds — Lec 2 pp. 8–9, Lec 3&4 pp. 1–6 | G8: L3 | H8: 8 | I8: 2 | J8: ★★ Medium | K8: Numerical | L8: ✔ Solved | M8: 2023-24 1(a); 2016-17 7(a) | N8: FALSE

Sheet 2 Conditional + Bayes
A1: Lec 5 — Conditional Probability and Bayes' Theorem
A2: Note file: MATH243_KKS_Conditional_Bayes_Notes.docx · Solve after finishing the matching lesson. Filter Priority → ★★★ High first.
A3: Q No. | B3: Year | C3: Course | D3: Ques No. | E3: Short Question | F3: Topic (slide PDF · slides) | G3: Lesson | H3: Marks | I3: TF Page | J3: Priority | K3: Type | L3: In Notes | M3: Same Type Also In | N3: Done | O3: Confidence | P3: Date | Q3: My Notes
A4: 1 | B4: 2018-19 | C4: MATH 245 | D4: 6(b) | E4: Picnic of 20: 5 sunburnt, 8 bitten, 10 safe: P(not bitten | sunburnt), P(sunburnt | bitten) | F4: Conditional probability — Lec 5 pp. 1–4 | G4: L5 | H4: 15 | I4: 24 | J4: ★★ Medium | K4: Numerical | L4: ✔ Solved | M4: 2015-16 8(a) | N4: FALSE
A5: 2 | B5: 2015-16 | C5: MATH 241 | D5: 8(a) | E5: TV show: P(man) 0.25, P(woman) 0.35, P(man | wife) 0.8: P(couple), P(husband | wife does not) | F5: Conditional probability — Lec 5 pp. 1–4 | G5: L5 | H5: 13 | I5: 16 | J5: ★★ Medium | K5: Numerical | L5: ✔ Solved | M5: 2018-19 6(b) | N5: FALSE
A6: 3 | B6: 2023-24 | C6: MATH 243 | D6: 1(b) | E6: Multiplication law; box A (5W, 7R) → one ball moved to box B (3W, 8R): P(red from B) | F6: Total probability, Bayes — Lec 5 pp. 4–7 | G6: L6 | H6: 12 | I6: 22 batch p.1 | J6: ★★★ High | K6: Numerical | L6: ✔ Solved | M6: 2022-23 1(a) | N6: FALSE
A7: 4 | B7: 2023-24 | C7: MATH 243 | D7: 1(c) | E7: Party support 45/40/15 %, turnout 65/80/50 %: P(A), P(B), P(C) | did not vote | F7: Total probability, Bayes — Lec 5 pp. 4–7 | G7: L6 | H7: 17 | I7: 22 batch p.1 | J7: ★★★ High | K7: Numerical | L7: ✔ Solved | M7: 2022-23 1(b); 2019-20 7(a) | N7: FALSE
A8: 5 | B8: 2022-23 | C8: MATH 243 | D8: 1(a) | E8: Bag 1 (4W, 3B) → one ball moved unseen to bag 2 (3W, 5B): P(black from bag 2) | F8: Total probability, Bayes — Lec 5 pp. 4–7 | G8: L6 | H8: 8 | I8: 47 | J8: ★★★ High | K8: Numerical | L8: ✔ Solved | M8: 2023-24 1(b) | N8: FALSE
A9: 6 | B9: 2022-23 | C9: MATH 243 | D9: 1(b) | E9: Machines B1, B2, B3 (30/45/25 %, defective 2/3/2 %): P(Bi | defective) | F9: Total probability, Bayes — Lec 5 pp. 4–7 | G9: L6 | H9: 15 | I9: 47 | J9: ★★★ High | K9: Numerical | L9: ✔ Solved | M9: 2023-24 1(c); 2019-20 7(a) | N9: FALSE
A10: 7 | B10: 2019-20 | C10: MATH 245 | D10: 7(a) | E10: Truth serum (90 % / 1 %, 5 % guilty): P(innocent | serum says guilty) | F10: Total probability, Bayes — Lec 5 pp. 4–7 | G10: L6 | H10: 17 | I10: 34 | J10: ★★★ High | K10: Numerical | L10: ✔ Solved | M10: 2023-24 1(c); 2022-23 1(b) | N10: FALSE

Sheet 3 Random Variables
A1: Lec 6, 7, 9 — pmf, pdf, CDF, Expectation, Chebyshev
A2: Note file: MATH243_KKS_Random_Variables_Notes.docx · Solve after finishing the matching lesson. Filter Priority → ★★★ High first.
A3: Q No. | B3: Year | C3: Course | D3: Ques No. | E3: Short Question | F3: Topic (slide PDF · slides) | G3: Lesson | H3: Marks | I3: TF Page | J3: Priority | K3: Type | L3: In Notes | M3: Same Type Also In | N3: Done | O3: Confidence | P3: Date | Q3: My Notes
A4: 1 | B4: 2023-24 | C4: MATH 243 | D4: 2(a) | E4: F(x) = 1 − e^{−8x}: P(wait < 12 minutes) using the CDF and using the pdf | F4: pdf, CDF, exponential — Lec 7 (+ textbook) | G4: L8 | H4: 15 | I4: 22 batch p.1 | J4: ★★★ High | K4: Numerical | L4: ✔ Solved | M4: 2022-23 1(c); 2019-20 8(b) | N4: FALSE
A5: 2 | B5: 2022-23 | C5: MATH 243 | D5: 1(c) | E5: DVD component f = (1/2000)e^{−x/2000}: CDF; P(lasts > 1000 h); P(fails before 2000 h) | F5: pdf, CDF, exponential — Lec 7 (+ textbook) | G5: L8 | H5: 12 | I5: 47 | J5: ★★★ High | K5: Numerical | L5: ✔ Solved | M5: 2023-24 2(a); 2019-20 8(b) | N5: FALSE
A6: 3 | B6: 2020-21 | C6: MATH 245 | D6: 6(b) | E6: Measurement error f = k(3 − x)², −1 ≤ x ≤ 1: k; P(X < 1/2); P(|X| > 0.8) | F6: pdf, CDF, exponential — Lec 7 (+ textbook) | G6: L8 | H6: 10 | I6: 38 | J6: ★★★ High | K6: Numerical | L6: ✔ Solved | M6: 2018-19 7(a) | N6: FALSE
A7: 4 | B7: 2019-20 | C7: MATH 245 | D7: 8(b) | E7: Fire-station calls, exponential with rate 1.8/day: five parts (15-min call, memoryless, 10-h shift, 4 shifts, 10 % point) | F7: pdf, CDF, exponential — Lec 7 (+ textbook) | G7: L8 | H7: 25 | I7: 35 | J7: ★★★ High | K7: Numerical | L7: ✔ Solved | M7: 2023-24 2(a); 2022-23 1(c) | N7: FALSE
A8: 5 | B8: 2018-19 | C8: MATH 245 | D8: 7(a) | E8: Density function and its conditions; F(x) = x/8, x²/16 piecewise: pdf, P(X ≥ 1.5), P(X ≥ 1 | X ≤ 3) | F8: pdf, CDF, exponential — Lec 7 (+ textbook) | G8: L8 | H8: 20 | I8: 24 | J8: ★★ Medium | K8: Numerical | L8: ✔ Solved | M8: 2020-21 6(b) | N8: FALSE
A9: 6 | B9: 2023-24 | C9: MATH 243 | D9: 3(a) | E9: Chebyshev's theorem; 70 jobs, 1000 applicants, mean 60, sd 6: can a score of 84 get a job? | F9: Expectation, variance, Chebyshev — Lec 9 pp. 1–5, other dist. p. 1 | G9: L9 | H9: 11 | I9: 22 batch p.2 | J9: ★★★ High | K9: Numerical | L9: ✔ Solved | M9: 2022-23 2(c) | N9: FALSE
A10: 7 | B10: 2022-23 | C10: MATH 243 | D10: 2(b) | E10: Clearance time Y = 3X − 2, X with f = (1/4)e^{−x/4}: mean and variance of Y | F10: Expectation, variance, Chebyshev — Lec 9 pp. 1–5, other dist. p. 1 | G10: L9 | H10: 10 | I10: 48 | J10: ★★★ High | K10: Numerical | L10: ✔ Solved | M10: 2020-21 8(a); 2019-20 7(b) | N10: FALSE
A11: 8 | B11: 2022-23 | C11: MATH 243 | D11: 2(c) | E11: f = 6x(1 − x): P(μ − 2σ < X < μ + 2σ) compared with Chebyshev | F11: Expectation, variance, Chebyshev — Lec 9 pp. 1–5, other dist. p. 1 | G11: L9 | H11: 10 | I11: 48 | J11: ★★★ High | K11: Numerical | L11: ✔ Solved | M11: 2023-24 3(a) | N11: FALSE
A12: 9 | B12: 2020-21 | C12: MATH 245 | D12: 8(a) | E12: Hospital stay Y = X + 4, f(x) = 32/(x + 4)³, x > 0: average stay E(Y) | F12: Expectation, variance, Chebyshev — Lec 9 pp. 1–5, other dist. p. 1 | G12: L9 | H12: 10 | I12: 38 | J12: ★★★ High | K12: Numerical | L12: ✔ Solved | M12: 2022-23 2(b); 2019-20 7(b) | N12: FALSE
A13: 10 | B13: 2019-20 | C13: MATH 245 | D13: 7(b) | E13: f(x) = e^{−x}, x > 0: expected value of g(X) = e^{2X/3} | F13: Expectation, variance, Chebyshev — Lec 9 pp. 1–5, other dist. p. 1 | G13: L9 | H13: 18 | I13: 35 | J13: ★★★ High | K13: Numerical | L13: ✔ Solved | M13: 2022-23 2(b); 2020-21 8(a) | N13: FALSE
A14: 11 | B14: 2018-19 | C14: MATH 245 | D14: 7(b) | E14: Lot of 7 (4 good, 3 defective), sample 3: expected number of good components | F14: Expectation, variance, Chebyshev — Lec 9 pp. 1–5, other dist. p. 1 | G14: L9 | H14: 15 | I14: 25 | J14: ★ Low | K14: Numerical | L14: ✔ Solved | M14: — | N14: FALSE

Sheet 4 Joint Distributions
A1: Lec 8–9 — Joint, Marginal, Conditional, Covariance
A2: Note file: MATH243_KKS_Joint_Distributions_Notes.docx · Solve after finishing the matching lesson. Filter Priority → ★★★ High first.
A3: Q No. | B3: Year | C3: Course | D3: Ques No. | E3: Short Question | F3: Topic (slide PDF · slides) | G3: Lesson | H3: Marks | I3: TF Page | J3: Priority | K3: Type | L3: In Notes | M3: Same Type Also In | N3: Done | O3: Confidence | P3: Date | Q3: My Notes
A4: 1 | B4: 2023-24 | C4: MATH 243 | D4: 2(b) | E4: Pens 3 red, 2 blue, 3 black, choose 2: joint pmf plot, P(X + Y ≤ 1), marginals, Var(X), Cov(X, Y) | F4: Joint pmf/pdf, marginals — Lec 8 pp. 1–6 | G4: L10 | H4: 20 | I4: 22 batch p.1 | J4: ★★★ High | K4: Numerical | L4: ✔ Solved | M4: — | N4: FALSE
A5: 2 | B5: 2020-21 | C5: MATH 245 | D5: 5(c) | E5: Tyre pressures f = k(x² + y²), 30 ≤ x, y < 50: k; P(30 ≤ X ≤ 40, 40 ≤ Y < 50); P(both underfilled) | F5: Joint pmf/pdf, marginals — Lec 8 pp. 1–6 | G5: L10 | H5: 10 | I5: 37 | J5: ★★★ High | K5: Numerical | L5: ✔ Solved | M5: 2022-23 2(a); 2012-13 8(a) | N5: FALSE
A6: 3 | B6: 2022-23 | C6: MATH 243 | D6: 2(a) | E6: f(x, y) = 10xy², 0 < x < y < 1: g(x), h(y), f(y|x); P(Y > 1/2 | X = 0.25) | F6: Conditional distributions, independence — Lec 8 pp. 7–11 | G6: L11 | H6: 15 | I6: 47 | J6: ★★★ High | K6: Numerical | L6: ✔ Solved | M6: 2020-21 5(c); 2012-13 8(a) | N6: FALSE
A7: 4 | B7: 2012-13 | C7: MATH 241 | D7: 8(a) | E7: Joint density (6 − x − y)/k on 0<x<2, 2<y<4: find P(1 < Y < 3 | X = 2) | F7: Conditional distributions, independence — Lec 8 pp. 7–11 | G7: L11 | H7: 18 | I7: 5 | J7: ★★ Medium | K7: Numerical | L7: ✔ Solved | M7: 2022-23 2(a); 2020-21 5(c) | N7: FALSE

Sheet 5 Discrete Distributions
A1: Lec 10–11 — Binomial, Poisson, Multinomial, Hypergeometric
A2: Note file: MATH243_KKS_Discrete_Distributions_Notes.docx · Solve after finishing the matching lesson. Filter Priority → ★★★ High first.
A3: Q No. | B3: Year | C3: Course | D3: Ques No. | E3: Short Question | F3: Topic (slide PDF · slides) | G3: Lesson | H3: Marks | I3: TF Page | J3: Priority | K3: Type | L3: In Notes | M3: Same Type Also In | N3: Done | O3: Confidence | P3: Date | Q3: My Notes
A4: 1 | B4: 2023-24 | C4: MATH 243 | D4: 3(c) | E4: P(recover) 0.4, 15 patients: P(at least 10 survive), P(3 to 8 survive), P(exactly 5 die) | F4: Binomial — Lec 10 | G4: L13 | H4: 12 | I4: 22 batch p.2 | J4: ★★★ High | K4: Numerical | L4: ✔ Solved | M4: 2020-21 7(a); 2014-15 8(b); 2013-14 7(b)(ii) | N4: FALSE
A5: 2 | B5: 2020-21 | C5: MATH 245 | D5: 7(a) | E5: Diode failure 0.03, 200 diodes: mean, variance, P(board works = no failures) | F5: Binomial — Lec 10 | G5: L13 | H5: 17 | I5: 38 | J5: ★★★ High | K5: Numerical | L5: ✔ Solved | M5: 2023-24 3(c); 2014-15 8(b); 2013-14 7(b)(ii) | N5: FALSE
A6: 3 | B6: 2014-15 | C6: MATH 241 | D6: 8(b) | E6: P(graduate) = 0.4; of 5 students: P(none), P(at least 1), P(all) | F6: Binomial — Lec 10 | G6: L13 | H6: 12 | I6: 11 | J6: ★★ Medium | K6: Numerical | L6: ✔ Solved | M6: 2023-24 3(c); 2020-21 7(a); 2013-14 7(b)(ii) | N6: FALSE
A7: 4 | B7: 2013-14 | C7: MATH 241 | D7: 7(b)(ii) | E7: 10 % defective, 12 instruments: P(at least 4 defective) | F7: Binomial — Lec 10 | G7: L13 | H7: 8 | I7: 8 | J7: ★★ Medium | K7: Numerical | L7: ✔ Solved | M7: 2023-24 3(c); 2020-21 7(a); 2014-15 8(b) | N7: FALSE
A8: 5 | B8: 2012-13 | C8: MATH 241 | D8: 6(c) | E8: Derive the mean and variance of the binomial distribution | F8: Binomial — Lec 10 | G8: L13 | H8: 10 | I8: 5 | J8: ★ Low | K8: Derivation | L8: ✔ Solved | M8: — | N8: FALSE
A9: 6 | B9: 2023-24 | C9: MATH 243 | D9: 3(b) | E9: Relation between binomial and Poisson; 0.5 calls/min: P(2 calls in 5 minutes) | F9: Poisson, binomial limit — Lec 11 | G9: L14 | H9: 12 | I9: 22 batch p.2 | J9: ★★★ High | K9: Derivation | L9: ✔ Solved | M9: 2022-23 3(a); 2016-17 8(a) | N9: FALSE
A10: 7 | B10: 2022-23 | C10: MATH 243 | D10: 3(a) | E10: Bernoulli and Poisson processes; derive the Poisson distribution | F10: Poisson, binomial limit — Lec 11 | G10: L14 | H10: 10 | I10: 48 | J10: ★★★ High | K10: Derivation | L10: ✔ Solved | M10: 2023-24 3(b); 2016-17 8(a) | N10: FALSE
A11: 8 | B11: 2022-23 | C11: MATH 243 | D11: 3(b) | E11: Variance of Poisson; 1 in 1000 returns has an error, 10,000 examined: P(6, 7 or 8 errors) | F11: Poisson, binomial limit — Lec 11 | G11: L14 | H11: 12 | I11: 48 | J11: ★★★ High | K11: Numerical | L11: ✔ Solved | M11: 2019-20 8(a); 2011-12 7(b)(i) | N11: FALSE
A12: 9 | B12: 2019-20 | C12: MATH 245 | D12: 8(a) | E12: Bubbles in glass, 1 in 1000; sample of 8000: P(fewer than 7) (Poisson approximation) | F12: Poisson, binomial limit — Lec 11 | G12: L14 | H12: 10 | I12: 35 | J12: ★★★ High | K12: Numerical | L12: ✔ Solved | M12: 2022-23 3(b); 2011-12 7(b)(i) | N12: FALSE
A13: 10 | B13: 2016-17 | C13: MATH 245 | D13: 8(a) | E13: Prove b(x; n, p) → Poisson as n → ∞, p → 0; accidents p = 0.005 over 400 days: P(exactly 1), P(at most 3) | F13: Poisson, binomial limit — Lec 11 | G13: L14 | H13: 20 | I13: 21 | J13: ★★ Medium | K13: Derivation | L13: ✔ Solved | M13: 2023-24 3(b); 2022-23 3(a) | N13: FALSE
A14: 11 | B14: 2012-13 | C14: MATH 241 | D14: 6(b) | E14: Truck tyres, 20 % blow out, next 18: P(4 to 7), P(fewer than 3), P(more than 5) by binomial and Poisson | F14: Poisson, binomial limit — Lec 11 | G14: L14 | H14: 10 | I14: 5 | J14: ★ Low | K14: Numerical | L14: ✔ Solved | M14: — | N14: FALSE
A15: 12 | B15: 2011-12 | C15: MATH 241 | D15: 7(b)(i) | E15: Insurance: P(death) = 0.0005, 1000 policies — P(5 or more claims) | F15: Poisson, binomial limit — Lec 11 | G15: L14 | H15: 7 | I15: 2 | J15: ★★ Medium | K15: Numerical | L15: ✔ Solved | M15: 2022-23 3(b); 2019-20 8(a) | N15: FALSE
A16: 13 | B16: 2021-22 | C16: MATH 245 | D16: 6(a) | E16: 500 lottery tickets, 200 pay off; buy 5: P(win back at least the cost of 3) | F16: Multinomial, hypergeometric, geometric — other dist. pp. 3–6 | G16: L15 | H16: 10 | I16: 44 | J16: ★★★ High | K16: Numerical | L16: ✔ Solved | M16: 2021-22 6(c) | N16: FALSE
A17: 14 | B17: 2021-22 | C17: MATH 245 | D17: 6(b) | E17: Delegates by air/bus/auto/train (0.4, 0.2, 0.3, 0.1): P(3, 3, 1, 2 among 9) | F17: Multinomial, hypergeometric, geometric — other dist. pp. 3–6 | G17: L15 | H17: 10 | I17: 44 | J17: ★★★ High | K17: Numerical | L17: ✔ Solved | M17: — | N17: FALSE
A18: 15 | B18: 2021-22 | C18: MATH 245 | D18: 6(c) | E18: 5 cars, 2 blemished; agency receives 3: probability distribution and F(x) of the number blemished | F18: Multinomial, hypergeometric, geometric — other dist. pp. 3–6 | G18: L15 | H18: 15 | I18: 44 | J18: ★★★ High | K18: Numerical | L18: ✔ Solved | M18: 2021-22 6(a) | N18: FALSE
A19: 16 | B19: 2020-21 | C19: MATH 245 | D19: 6(c) | E19: Valium, 2/3 of users women: 5th prescription is the first / the third for a woman | F19: Multinomial, hypergeometric, geometric — other dist. pp. 3–6 | G19: L15 | H19: 10 | I19: 38 | J19: ★★★ High | K19: Numerical | L19: ✔ Solved | M19: — | N19: FALSE

Sheet 6 Normal Distribution
A1: Lec 12 — Normal Distribution and Approximations
A2: Note file: MATH243_KKS_Normal_Distribution_Notes.docx · Solve after finishing the matching lesson. Filter Priority → ★★★ High first.
A3: Q No. | B3: Year | C3: Course | D3: Ques No. | E3: Short Question | F3: Topic (slide PDF · slides) | G3: Lesson | H3: Marks | I3: TF Page | J3: Priority | K3: Type | L3: In Notes | M3: Same Type Also In | N3: Done | O3: Confidence | P3: Date | Q3: My Notes
A4: 1 | B4: 2023-24 | C4: MATH 243 | D4: 4(a) | E4: Show mode of normal = μ; bulbs N(800, 40²): P(778 < X < 834) | F4: Normal, z table — Lec 12 pp. 1–8 | G4: L16 | H4: 11 | I4: 22 batch p.2 | J4: ★★★ High | K4: Numerical | L4: ◐ Method | M4: 2022-23 4(a) | N4: FALSE
A5: 2 | B5: 2022-23 | C5: MATH 243 | D5: 3(c) | E5: Lawyer's trip N(24, 3.8²): P(≥ 30 min), % late, slowest 15 %, P(2 of next 3 trips ≥ 30 min) | F5: Normal, z table — Lec 12 pp. 1–8 | G5: L16 | H5: 13 | I5: 48 | J5: ★★★ High | K5: Numerical | L5: ✔ Solved | M5: 2021-22 7(b); 2020-21 7(b); 2018-19 8(a); 2015-16 8(b); 2014-15 8(c) | N5: FALSE
A6: 3 | B6: 2022-23 | C6: MATH 243 | D6: 4(a) | E6: Properties of the normal curve; mean, mode and SD of the normal; mean and variance of the standard normal | F6: Normal, z table — Lec 12 pp. 1–8 | G6: L16 | H6: 10 | I6: 48 | J6: ★★★ High | K6: Derivation | L6: ◐ Method | M6: 2023-24 4(a) | N6: FALSE
A7: 4 | B7: 2021-22 | C7: MATH 245 | D7: 7(b) | E7: Ball bearings 3.0 ± 0.01 cm, N(3.0, 0.005²): how many are scrapped | F7: Normal, z table — Lec 12 pp. 1–8 | G7: L16 | H7: 15 | I7: 45 | J7: ★★★ High | K7: Numerical | L7: ✔ Solved | M7: 2022-23 3(c); 2020-21 7(b); 2018-19 8(a); 2015-16 8(b); 2014-15 8(c) | N7: FALSE
A8: 5 | B8: 2020-21 | C8: MATH 245 | D8: 7(b) | E8: Mice lifetimes N(40, 6.3²): P(> 32 months), P(37 to 49 months) | F8: Normal, z table — Lec 12 pp. 1–8 | G8: L16 | H8: 18 | I8: 38 | J8: ★★★ High | K8: Numerical | L8: ✔ Solved | M8: 2022-23 3(c); 2021-22 7(b); 2018-19 8(a); 2015-16 8(b); 2014-15 8(c) | N8: FALSE
A9: 6 | B9: 2018-19 | C9: MATH 245 | D9: 8(a) | E9: 1000 tube lights N(120, 20²): how many fail before 90 days; replacement interval so that ≤ 10 % fail | F9: Normal, z table — Lec 12 pp. 1–8 | G9: L16 | H9: 18 | I9: 25 | J9: ★★ Medium | K9: Numerical | L9: ✔ Solved | M9: 2022-23 3(c); 2021-22 7(b); 2020-21 7(b); 2015-16 8(b); 2014-15 8(c) | N9: FALSE
A10: 7 | B10: 2015-16 | C10: MATH 241 | D10: 8(b) | E10: Normal marks: 10 % under 65, 25 % above 75 — what % lie between 60 and 74 | F10: Normal, z table — Lec 12 pp. 1–8 | G10: L16 | H10: 12 | I10: 16 | J10: ★★ Medium | K10: Numerical | L10: ✔ Solved | M10: 2022-23 3(c); 2021-22 7(b); 2020-21 7(b); 2018-19 8(a); 2014-15 8(c) | N10: FALSE
A11: 8 | B11: 2014-15 | C11: MATH 241 | D11: 8(c) | E11: 2000 units/day, weight N(130, 10²): how many weigh less than 142 kg | F11: Normal, z table — Lec 12 pp. 1–8 | G11: L16 | H11: 11 | I11: 11 | J11: ★★ Medium | K11: Numerical | L11: ✔ Solved | M11: 2022-23 3(c); 2021-22 7(b); 2020-21 7(b); 2018-19 8(a); 2015-16 8(b) | N11: FALSE
A12: 9 | B12: 2016-17 | C12: MATH 245 | D12: 7(b) | E12: U-shaped part: A ~ N(10, 0.1²), B, C ~ N(2, 0.05²); gap D = A − B − C: mean, sd, P(D < 5.9) | F12: Sums of normals, x̄, normal approx. — Lec 12 pp. 6–11 (+ textbook) | G12: L17 | H12: 10 | I12: 21 | J12: ★★ Medium | K12: Numerical | L12: ✔ Solved | M12: 2016-17 7(c) | N12: FALSE
A13: 10 | B13: 2016-17 | C13: MATH 245 | D13: 7(c) | E13: 1500 bearings, mean 22.40 g, sd 0.048 g; 300 samples of 36: mean and sd of x̄ (with/without replacement); counts in ranges | F13: Sums of normals, x̄, normal approx. — Lec 12 pp. 6–11 (+ textbook) | G13: L17 | H13: 15 | I13: 21 | J13: ★★ Medium | K13: Numerical | L13: ✔ Solved | M13: 2016-17 7(b) | N13: FALSE

Sheet 7 ANOVA
A1: ANOVA (KKS Sir's part) — F-test, One-way and Two-way
A2: Note file: MATH243_KKS_ANOVA_Notes.docx · Solve after finishing the matching lesson. Filter Priority → ★★★ High first.
A3: Q No. | B3: Year | C3: Course | D3: Ques No. | E3: Short Question | F3: Topic (slide PDF · slides) | G3: Lesson | H3: Marks | I3: TF Page | J3: Priority | K3: Type | L3: In Notes | M3: Same Type Also In | N3: Done | O3: Confidence | P3: Date | Q3: My Notes
A4: 1 | B4: 2023-24 | C4: MATH 243 | D4: 8(b) | E4: Retail prices in 3 cities (4 shops each): one-way ANOVA (F0.05(2, 9) = 4.26) | F4: F-test, one-way ANOVA — ANOVA pp. 1–10 | G4: L18 | H4: 20 | I4: 22 batch p.4 | J4: ★★★ High | K4: Numerical | L4: ✔ Solved | M4: 2022-23 8(b); 2021-22 8(b) | N4: FALSE
A5: 2 | B5: 2022-23 | C5: MATH 243 | D5: 8(b) | E5: Lifetimes of 4 brands of bulbs (3 each): one-way ANOVA at 5 % and 1 % | F5: F-test, one-way ANOVA — ANOVA pp. 1–10 | G5: L18 | H5: 10 | I5: 51 | J5: ★★★ High | K5: Numerical | L5: ✔ Solved | M5: 2023-24 8(b); 2021-22 8(b) | N5: FALSE
A6: 3 | B6: 2021-22 | C6: MATH 245 | D6: 8(b) | E6: Salesmen A, B, C weekly sales: one-way ANOVA (F(2,11) = 3.98) | F6: F-test, one-way ANOVA — ANOVA pp. 1–10 | G6: L18 | H6: 18 | I6: 45 | J6: ★★★ High | K6: Numerical | L6: ✔ Solved | M6: 2023-24 8(b); 2022-23 8(b) | N6: FALSE
A7: 4 | B7: 2022-23 | C7: MATH 243 | D7: 8(c) | E7: Four corn types in five blocks: two-way ANOVA for blocks and corn types (5 %) | F7: Two-way ANOVA — textbook | G7: L19 | H7: 15 | I7: 51 | J7: ★★★ High | K7: Numerical | L7: ✔ Solved | M7: — | N7: FALSE

Sheet 8 Hypothesis Testing
A1: Lecture 13–20 — z, t, Two-sample, Proportion, χ² Tests
A2: Note file: MATH243_KKS_Hypothesis_Testing_Notes.docx · Solve after finishing the matching lesson. Filter Priority → ★★★ High first.
A3: Q No. | B3: Year | C3: Course | D3: Ques No. | E3: Short Question | F3: Topic (slide PDF · slides) | G3: Lesson | H3: Marks | I3: TF Page | J3: Priority | K3: Type | L3: In Notes | M3: Same Type Also In | N3: Done | O3: Confidence | P3: Date | Q3: My Notes
A4: 1 | B4: 2023-24 | C4: MATH 243 | D4: 7(a) | E4: Short notes: goodness of fit, one-/two-tailed tests, degrees of freedom, null/alternative hypothesis | F4: Hypotheses, errors, p-value — Hyp pp. 1–6, 11–12 | G4: L20 | H4: 10 | I4: 22 batch p.3 | J4: ★★★ High | K4: Theory | L4: ◐ Method | M4: 2022-23 7(a) | N4: FALSE
A5: 2 | B5: 2022-23 | C5: MATH 243 | D5: 7(a) | E5: Differentiate: statistic/parameter, critical/acceptance region, exact/inexact hypothesis, uni/non-directional test, level of significance/p-value | F5: Hypotheses, errors, p-value — Hyp pp. 1–6, 11–12 | G5: L20 | H5: 10 | I5: 50 | J5: ★★★ High | K5: Theory | L5: ◐ Method | M5: 2023-24 7(a) | N5: FALSE
A6: 3 | B6: 2020-21 | C6: MATH 245 | D6: 8(c) | E6: DNA paternity testing: describe Type I and Type II errors | F6: Hypotheses, errors, p-value — Hyp pp. 1–6, 11–12 | G6: L20 | H6: 10 | I6: 39 | J6: ★★★ High | K6: Theory | L6: ◐ Method | M6: — | N6: FALSE
A7: 4 | B7: 2023-24 | C7: MATH 243 | D7: 6(c) | E7: Stratified random sampling (example); delivery time claim < 120 min, σ 30, n 49, mean 100 (z = −1.645) | F7: One-sample z and t tests, CI — Hyp pp. 7–16 | G7: L21 | H7: 12 | I7: 22 batch p.3 | J7: ★★★ High | K7: Numerical | L7: ✔ Solved | M7: 2022-23 7(b); 2019-20 6(b); 2018-19 8(b); 2016-17 8(b); 2014-15 7(b) | N7: FALSE
A8: 5 | B8: 2022-23 | C8: MATH 243 | D8: 7(b) | E8: GPA: n = 40, mean 2.8, sd 0.35 vs 2.4; 99 % CI | F8: One-sample z and t tests, CI — Hyp pp. 7–16 | G8: L21 | H8: 12 | I8: 50 | J8: ★★★ High | K8: Numerical | L8: ✔ Solved | M8: 2023-24 6(c); 2019-20 6(b); 2018-19 8(b); 2016-17 8(b); 2014-15 7(b) | N8: FALSE
A9: 6 | B9: 2022-23 | C9: MATH 243 | D9: 7(c) | E9: Bank waiting time: n = 12, mean 42, sd 11.9 — is μ < 50? (t11 = 1.796) | F9: One-sample z and t tests, CI — Hyp pp. 7–16 | G9: L21 | H9: 13 | I9: 50 | J9: ★★★ High | K9: Numerical | L9: ✔ Solved | M9: 2021-22 8(a); 2020-21 8(b); 2015-16 8(c); 2013-14 8(a); 2011-12 8(a) | N9: FALSE
A10: 7 | B10: 2021-22 | C10: MATH 245 | D10: 8(a) | E10: Heights of 10 individuals: is the mean height 65? (t9 = 2.262) | F10: One-sample z and t tests, CI — Hyp pp. 7–16 | G10: L21 | H10: 17 | I10: 45 | J10: ★★★ High | K10: Numerical | L10: ✔ Solved | M10: 2022-23 7(c); 2020-21 8(b); 2015-16 8(c); 2013-14 8(a); 2011-12 8(a) | N10: FALSE
A11: 8 | B11: 2020-21 | C11: MATH 245 | D11: 8(b) | E11: Cereal sodium: n = 20, mean 244, sd 24.5 — is μ > 220? (5 %) | F11: One-sample z and t tests, CI — Hyp pp. 7–16 | G11: L21 | H11: 15 | I11: 39 | J11: ★★★ High | K11: Numerical | L11: ✔ Solved | M11: 2022-23 7(c); 2021-22 8(a); 2015-16 8(c); 2013-14 8(a); 2011-12 8(a) | N11: FALSE
A12: 9 | B12: 2019-20 | C12: MATH 245 | D12: 6(b) | E12: Mice diet: 64 mice, mean 38, sd 5.8 — is μ < 40? (P-value) | F12: One-sample z and t tests, CI — Hyp pp. 7–16 | G12: L21 | H12: 18 | I12: 34 | J12: ★★★ High | K12: Numerical | L12: ✔ Solved | M12: 2023-24 6(c); 2022-23 7(b); 2018-19 8(b); 2016-17 8(b); 2014-15 7(b) | N12: FALSE
A13: 10 | B13: 2018-19 | C13: MATH 245 | D13: 8(b) | E13: GPA: n = 40, mean 2.8, sd 0.35 vs population 2.4 (1 %); 99 % confidence interval | F13: One-sample z and t tests, CI — Hyp pp. 7–16 | G13: L21 | H13: 17 | I13: 25 | J13: ★★ Medium | K13: Numerical | L13: ✔ Solved | M13: 2023-24 6(c); 2022-23 7(b); 2019-20 6(b); 2016-17 8(b); 2014-15 7(b) | N13: FALSE
A14: 11 | B14: 2016-17 | C14: MATH 245 | D14: 8(b) | E14: 100 deaths, mean life 61.8, σ 4.9: is the mean life span greater than 60? (5 %) | F14: One-sample z and t tests, CI — Hyp pp. 7–16 | G14: L21 | H14: 15 | I14: 21 | J14: ★★ Medium | K14: Numerical | L14: ✔ Solved | M14: 2023-24 6(c); 2022-23 7(b); 2019-20 6(b); 2018-19 8(b); 2014-15 7(b) | N14: FALSE
A15: 12 | B15: 2015-16 | C15: MATH 241 | D15: 8(c) | E15: Chocolate sales: 153.7 before; 29 stores after, mean 169.4, sd 19.7 — was advertising successful? (5 %) | F15: One-sample z and t tests, CI — Hyp pp. 7–16 | G15: L21 | H15: 10 | I15: 16 | J15: ★★ Medium | K15: Numerical | L15: ✔ Solved | M15: 2022-23 7(c); 2021-22 8(a); 2020-21 8(b); 2013-14 8(a); 2011-12 8(a) | N15: FALSE
A16: 13 | B16: 2014-15 | C16: MATH 241 | D16: 7(b) | E16: Bulbs: claimed mean 4 years, σ 0.16; sample of 10 has mean 3.45 — is the claim justified? (5 %) | F16: One-sample z and t tests, CI — Hyp pp. 7–16 | G16: L21 | H16: 15 | I16: 11 | J16: ★★ Medium | K16: Numerical | L16: ✔ Solved | M16: 2023-24 6(c); 2022-23 7(b); 2019-20 6(b); 2018-19 8(b); 2016-17 8(b) | N16: FALSE
A17: 14 | B17: 2013-14 | C17: MATH 241 | D17: 8(a) | E17: 11 tins of talcum powder: can the average packing be 0.5 lb? (t-test, 5 %) | F17: One-sample z and t tests, CI — Hyp pp. 7–16 | G17: L21 | H17: 20 | I17: 8 | J17: ★★ Medium | K17: Numerical | L17: ✔ Solved | M17: 2022-23 7(c); 2021-22 8(a); 2020-21 8(b); 2015-16 8(c); 2011-12 8(a) | N17: FALSE
A18: 15 | B18: 2011-12 | C18: MATH 241 | D18: 8(a) | E18: Type I / Type II errors; t-test: 9 items, can the population mean be 47? (5%) | F18: One-sample z and t tests, CI — Hyp pp. 7–16 | G18: L21 | H18: 17 | I18: 3 | J18: ★★ Medium | K18: Numerical | L18: ✔ Solved | M18: 2022-23 7(c); 2021-22 8(a); 2020-21 8(b); 2015-16 8(c); 2013-14 8(a) | N18: FALSE
A19: 16 | B19: 2023-24 | C19: MATH 243 | D19: 7(c) | E19: Two samples of 8 and 7 weights: is the difference of means significant? (t13 = 2.16) | F19: Two-sample and paired tests — Hyp pp. 16–31 | G19: L22 | H19: 13 | I19: 22 batch p.4 | J19: ★★★ High | K19: Numerical | L19: ✔ Solved | M19: — | N19: FALSE
A20: 17 | B20: 2012-13 | C20: MATH 241 | D20: 8(b) | E20: Two supermarkets, 500 shoppers each (Tk 500, sd 80 vs Tk 440, sd 90): are mean expenditures equal? (10 %) | F20: Two-sample and paired tests — Hyp pp. 16–31 | G20: L22 | H20: 17 | I20: 5 | J20: ★ Low | K20: Numerical | L20: ✔ Solved | M20: — | N20: FALSE
A21: 18 | B21: 2023-24 | C21: MATH 243 | D21: 7(b) | E21: Machine: 16/500 imperfect before, 3/100 after overhaul — improved? (1 %) | F21: Tests for r and proportions — Hyp pp. 32–37 | G21: L23 | H21: 12 | I21: 22 batch p.3 | J21: ★★★ High | K21: Numerical | L21: ✔ Solved | M21: — | N21: FALSE
A22: 19 | B22: 2023-24 | C22: MATH 243 | D22: 8(a) | E22: Education vs job performance 3×3 table, 200 employees: χ² test (χ²0.05,4 = 9.49) | F22: χ² contingency / goodness of fit — Hyp pp. 38–44 | G22: L24 | H22: 15 | I22: 22 batch p.4 | J22: ★★★ High | K22: Numerical | L22: ✔ Solved | M22: 2022-23 8(a) | N22: FALSE
A23: 20 | B23: 2022-23 | C23: MATH 243 | D23: 8(a) | E23: Drug vs typhoid 2×2 table: χ² test of effectiveness (χ²1 = 3.84) | F23: χ² contingency / goodness of fit — Hyp pp. 38–44 | G23: L24 | H23: 10 | I23: 50 | J23: ★★★ High | K23: Numerical | L23: ✔ Solved | M23: 2023-24 8(a) | N23: FALSE
A24: 21 | B24: 2013-14 | C24: MATH 241 | D24: 8(b) | E24: 320 families with 5 children: χ² test of equal male/female births | F24: χ² contingency / goodness of fit — Hyp pp. 38–44 | G24: L24 | H24: 15 | I24: 8 | J24: ★★ Medium | K24: Numerical | L24: ✔ Solved | M24: 2012-13 7(b); 2011-12 8(b) | N24: FALSE
