Workbook

Sheet How to Use
B2: CSE 211 (Atif Sir part) — TF Practice Tracker
B3: Every Atif-part question in CSE 211 All Merged Questions.pdf (2023-24 rows: CSE 211 (22 batch).pdf), mapped to the note file and lesson that teaches it.
B5: Workflow — after you finish a note file
B6: 1. Open its tab | C6: Tabs 1–7 follow the order of your note files. Q No. runs lesson by lesson, newest year first inside each lesson.
B7: 2. Filter | C7: Use the filter arrow on Priority → ★★★ High first (2019-20 onward). Then ★★ Medium, then ★ Low.
B8: 3. Solve | C8: Open CSE 211 All Merged Questions.pdf (2023-24 rows: CSE 211 (22 batch).pdf) at the TF Page shown. Solve on paper under exam time (≈1.5 min per mark). Do not read the note solution first.
B9: 4. Check | C9: In Notes tells you what the note has: ✔ Solved = same question worked out; ◐ Method = method / model answer you can apply; ○ Partly = notes cover most of it, finish the rest yourself.
B10: 5. Record | C10: Tick Done, pick Confidence, add the Date. Write mistakes in My Notes. Re-solve every 'Weak' row before the exam.
B11: 6. Repeats | C11: 'Same Type Also In' lists other papers with the same question type. Solve one, then try a repeat cold — that is the real test.
B13: Columns you edit (all others are fixed data)
B14: Done (col N) | C14: TRUE / FALSE. In Google Sheets: select N4 downward → Insert → Checkbox. The values stay; ticking turns the row green.
B15: Confidence (col O) | C15: Dropdown: Weak / OK / Strong. Weak rows turn the cell red.
B16: Date (col P) | C16: Date you solved it, e.g. 16-Oct-2026.
B17: My Notes (col Q) | C17: Mistakes, missing steps, formula you forgot.
B19: Legend
B20: ★★★ High | C20: Asked in 2019-20 or later (most important — current question style).
B21: ★★ Medium | C21: Older paper, but the same question type appears at least twice in TF.
B22: ★ Low | C22: Older paper, asked once.
B23: Type | C23: Numerical = calculation · Trace = tables / step-by-step simulation · Design = construct / draw · Proof = prove / disprove · Theory = explain.
B24: Course | C24: Every paper in the collection carries the code CSE 211.
B25: Topic | C25: Note lesson title — slide PDF and slide numbers.
B26: Outside Notes tab | C26: Atif-section questions from older papers on topics not in the current slides. Check with your teacher before spending time on them.

Sheet Dashboard
A1: Progress Dashboard
A2: Updates automatically when you tick Done / set Confidence in tabs 1–7.
A4: # | B4: Note file (tab) | C4: Questions | D4: Done | E4: % Done | F4: Marks (total) | G4: Marks done | H4: High-priority left | I4: Weak | J4: Next unsolved (top of tab)
A5: 1 | B5: 1 Intro + CNF | C5: =COUNTA('1 Intro + CNF'!$E$4:$E$16) | D5: =COUNTIF('1 Intro + CNF'!$N$4:$N$16,TRUE()) | E5: =IF(C5=0,0,D5/C5) | F5: =SUM('1 Intro + CNF'!$H$4:$H$16) | G5: =SUMIF('1 Intro + CNF'!$N$4:$N$16,TRUE(),'1 Intro + CNF'!$H$4:$H$16) | H5: =COUNTIFS('1 Intro + CNF'!$J$4:$J$16,"★★★ High",'1 Intro + CNF'!$N$4:$N$16,FALSE()) | I5: =COUNTIF('1 Intro + CNF'!$O$4:$O$16,"Weak") | J5: =IFERROR("Q"&INDEX('1 Intro + CNF'!$A$4:$A$16,MATCH(FALSE(),'1 Intro + CNF'!$N$4:$N$16,0))&" · "&INDEX('1 Intro + CNF'!$B$4:$B$16,MATCH(FALSE(),'1 Intro + CNF'!$N$4:$N$16,0))&" "&INDEX('1 Intro + CNF'!$D$4:$D$16,MATCH(FALSE(),'1 Intro + CNF'!$N$4:$N$16,0))&" · TF p."&INDEX('1 Intro + CNF'!$I$4:$I$16,MATCH(FALSE(),'1 Intro + CNF'!$N$4:$N$16,0)),"All done ✔")
A6: 2 | B6: 2 PDA | C6: =COUNTA('2 PDA'!$E$4:$E$51) | D6: =COUNTIF('2 PDA'!$N$4:$N$51,TRUE()) | E6: =IF(C6=0,0,D6/C6) | F6: =SUM('2 PDA'!$H$4:$H$51) | G6: =SUMIF('2 PDA'!$N$4:$N$51,TRUE(),'2 PDA'!$H$4:$H$51) | H6: =COUNTIFS('2 PDA'!$J$4:$J$51,"★★★ High",'2 PDA'!$N$4:$N$51,FALSE()) | I6: =COUNTIF('2 PDA'!$O$4:$O$51,"Weak") | J6: =IFERROR("Q"&INDEX('2 PDA'!$A$4:$A$51,MATCH(FALSE(),'2 PDA'!$N$4:$N$51,0))&" · "&INDEX('2 PDA'!$B$4:$B$51,MATCH(FALSE(),'2 PDA'!$N$4:$N$51,0))&" "&INDEX('2 PDA'!$D$4:$D$51,MATCH(FALSE(),'2 PDA'!$N$4:$N$51,0))&" · TF p."&INDEX('2 PDA'!$I$4:$I$51,MATCH(FALSE(),'2 PDA'!$N$4:$N$51,0)),"All done ✔")
A7: 3 | B7: 3 TM Basics | C7: =COUNTA('3 TM Basics'!$E$4:$E$22) | D7: =COUNTIF('3 TM Basics'!$N$4:$N$22,TRUE()) | E7: =IF(C7=0,0,D7/C7) | F7: =SUM('3 TM Basics'!$H$4:$H$22) | G7: =SUMIF('3 TM Basics'!$N$4:$N$22,TRUE(),'3 TM Basics'!$H$4:$H$22) | H7: =COUNTIFS('3 TM Basics'!$J$4:$J$22,"★★★ High",'3 TM Basics'!$N$4:$N$22,FALSE()) | I7: =COUNTIF('3 TM Basics'!$O$4:$O$22,"Weak") | J7: =IFERROR("Q"&INDEX('3 TM Basics'!$A$4:$A$22,MATCH(FALSE(),'3 TM Basics'!$N$4:$N$22,0))&" · "&INDEX('3 TM Basics'!$B$4:$B$22,MATCH(FALSE(),'3 TM Basics'!$N$4:$N$22,0))&" "&INDEX('3 TM Basics'!$D$4:$D$22,MATCH(FALSE(),'3 TM Basics'!$N$4:$N$22,0))&" · TF p."&INDEX('3 TM Basics'!$I$4:$I$22,MATCH(FALSE(),'3 TM Basics'!$N$4:$N$22,0)),"All done ✔")
A8: 4 | B8: 4 TM Techniques | C8: =COUNTA('4 TM Techniques'!$E$4:$E$14) | D8: =COUNTIF('4 TM Techniques'!$N$4:$N$14,TRUE()) | E8: =IF(C8=0,0,D8/C8) | F8: =SUM('4 TM Techniques'!$H$4:$H$14) | G8: =SUMIF('4 TM Techniques'!$N$4:$N$14,TRUE(),'4 TM Techniques'!$H$4:$H$14) | H8: =COUNTIFS('4 TM Techniques'!$J$4:$J$14,"★★★ High",'4 TM Techniques'!$N$4:$N$14,FALSE()) | I8: =COUNTIF('4 TM Techniques'!$O$4:$O$14,"Weak") | J8: =IFERROR("Q"&INDEX('4 TM Techniques'!$A$4:$A$14,MATCH(FALSE(),'4 TM Techniques'!$N$4:$N$14,0))&" · "&INDEX('4 TM Techniques'!$B$4:$B$14,MATCH(FALSE(),'4 TM Techniques'!$N$4:$N$14,0))&" "&INDEX('4 TM Techniques'!$D$4:$D$14,MATCH(FALSE(),'4 TM Techniques'!$N$4:$N$14,0))&" · TF p."&INDEX('4 TM Techniques'!$I$4:$I$14,MATCH(FALSE(),'4 TM Techniques'!$N$4:$N$14,0)),"All done ✔")
A9: 5 | B9: 5 TM Variants | C9: =COUNTA('5 TM Variants'!$E$4:$E$22) | D9: =COUNTIF('5 TM Variants'!$N$4:$N$22,TRUE()) | E9: =IF(C9=0,0,D9/C9) | F9: =SUM('5 TM Variants'!$H$4:$H$22) | G9: =SUMIF('5 TM Variants'!$N$4:$N$22,TRUE(),'5 TM Variants'!$H$4:$H$22) | H9: =COUNTIFS('5 TM Variants'!$J$4:$J$22,"★★★ High",'5 TM Variants'!$N$4:$N$22,FALSE()) | I9: =COUNTIF('5 TM Variants'!$O$4:$O$22,"Weak") | J9: =IFERROR("Q"&INDEX('5 TM Variants'!$A$4:$A$22,MATCH(FALSE(),'5 TM Variants'!$N$4:$N$22,0))&" · "&INDEX('5 TM Variants'!$B$4:$B$22,MATCH(FALSE(),'5 TM Variants'!$N$4:$N$22,0))&" "&INDEX('5 TM Variants'!$D$4:$D$22,MATCH(FALSE(),'5 TM Variants'!$N$4:$N$22,0))&" · TF p."&INDEX('5 TM Variants'!$I$4:$I$22,MATCH(FALSE(),'5 TM Variants'!$N$4:$N$22,0)),"All done ✔")
A10: 6 | B10: 6 Undecidability | C10: =COUNTA('6 Undecidability'!$E$4:$E$42) | D10: =COUNTIF('6 Undecidability'!$N$4:$N$42,TRUE()) | E10: =IF(C10=0,0,D10/C10) | F10: =SUM('6 Undecidability'!$H$4:$H$42) | G10: =SUMIF('6 Undecidability'!$N$4:$N$42,TRUE(),'6 Undecidability'!$H$4:$H$42) | H10: =COUNTIFS('6 Undecidability'!$J$4:$J$42,"★★★ High",'6 Undecidability'!$N$4:$N$42,FALSE()) | I10: =COUNTIF('6 Undecidability'!$O$4:$O$42,"Weak") | J10: =IFERROR("Q"&INDEX('6 Undecidability'!$A$4:$A$42,MATCH(FALSE(),'6 Undecidability'!$N$4:$N$42,0))&" · "&INDEX('6 Undecidability'!$B$4:$B$42,MATCH(FALSE(),'6 Undecidability'!$N$4:$N$42,0))&" "&INDEX('6 Undecidability'!$D$4:$D$42,MATCH(FALSE(),'6 Undecidability'!$N$4:$N$42,0))&" · TF p."&INDEX('6 Undecidability'!$I$4:$I$42,MATCH(FALSE(),'6 Undecidability'!$N$4:$N$42,0)),"All done ✔")
A11: 7 | B11: 7 Complexity | C11: =COUNTA('7 Complexity'!$E$4:$E$20) | D11: =COUNTIF('7 Complexity'!$N$4:$N$20,TRUE()) | E11: =IF(C11=0,0,D11/C11) | F11: =SUM('7 Complexity'!$H$4:$H$20) | G11: =SUMIF('7 Complexity'!$N$4:$N$20,TRUE(),'7 Complexity'!$H$4:$H$20) | H11: =COUNTIFS('7 Complexity'!$J$4:$J$20,"★★★ High",'7 Complexity'!$N$4:$N$20,FALSE()) | I11: =COUNTIF('7 Complexity'!$O$4:$O$20,"Weak") | J11: =IFERROR("Q"&INDEX('7 Complexity'!$A$4:$A$20,MATCH(FALSE(),'7 Complexity'!$N$4:$N$20,0))&" · "&INDEX('7 Complexity'!$B$4:$B$20,MATCH(FALSE(),'7 Complexity'!$N$4:$N$20,0))&" "&INDEX('7 Complexity'!$D$4:$D$20,MATCH(FALSE(),'7 Complexity'!$N$4:$N$20,0))&" · TF p."&INDEX('7 Complexity'!$I$4:$I$20,MATCH(FALSE(),'7 Complexity'!$N$4:$N$20,0)),"All done ✔")
B12: TOTAL | C12: =SUM(C5:C11) | D12: =SUM(D5:D11) | E12: =IF(C12=0,0,D12/C12) | F12: =SUM(F5:F11) | G12: =SUM(G5:G11) | H12: =SUM(H5:H11) | I12: =SUM(I5:I11)
A14: Questions by year (tabs 1–7)
A15: # | B15: Year | C15: Questions | D15: Done | E15: % Done | F15: Marks (total)
A16: 1 | B16: 2023-24 | C16: =COUNTIF('1 Intro + CNF'!$B$4:$B$16,$B16)+COUNTIF('2 PDA'!$B$4:$B$51,$B16)+COUNTIF('3 TM Basics'!$B$4:$B$22,$B16)+COUNTIF('4 TM Techniques'!$B$4:$B$14,$B16)+COUNTIF('5 TM Variants'!$B$4:$B$22,$B16)+COUNTIF('6 Undecidability'!$B$4:$B$42,$B16)+COUNTIF('7 Complexity'!$B$4:$B$20,$B16) | D16: =COUNTIFS('1 Intro + CNF'!$B$4:$B$16,$B16,'1 Intro + CNF'!$N$4:$N$16,TRUE())+COUNTIFS('2 PDA'!$B$4:$B$51,$B16,'2 PDA'!$N$4:$N$51,TRUE())+COUNTIFS('3 TM Basics'!$B$4:$B$22,$B16,'3 TM Basics'!$N$4:$N$22,TRUE())+COUNTIFS('4 TM Techniques'!$B$4:$B$14,$B16,'4 TM Techniques'!$N$4:$N$14,TRUE())+COUNTIFS('5 TM Variants'!$B$4:$B$22,$B16,'5 TM Variants'!$N$4:$N$22,TRUE())+COUNTIFS('6 Undecidability'!$B$4:$B$42,$B16,'6 Undecidability'!$N$4:$N$42,TRUE())+COUNTIFS('7 Complexity'!$B$4:$B$20,$B16,'7 Complexity'!$N$4:$N$20,TRUE()) | E16: =IF(C16=0,0,D16/C16) | F16: =SUMIF('1 Intro + CNF'!$B$4:$B$16,$B16,'1 Intro + CNF'!$H$4:$H$16)+SUMIF('2 PDA'!$B$4:$B$51,$B16,'2 PDA'!$H$4:$H$51)+SUMIF('3 TM Basics'!$B$4:$B$22,$B16,'3 TM Basics'!$H$4:$H$22)+SUMIF('4 TM Techniques'!$B$4:$B$14,$B16,'4 TM Techniques'!$H$4:$H$14)+SUMIF('5 TM Variants'!$B$4:$B$22,$B16,'5 TM Variants'!$H$4:$H$22)+SUMIF('6 Undecidability'!$B$4:$B$42,$B16,'6 Undecidability'!$H$4:$H$42)+SUMIF('7 Complexity'!$B$4:$B$20,$B16,'7 Complexity'!$H$4:$H$20)
A17: 2 | B17: 2022-23 | C17: =COUNTIF('1 Intro + CNF'!$B$4:$B$16,$B17)+COUNTIF('2 PDA'!$B$4:$B$51,$B17)+COUNTIF('3 TM Basics'!$B$4:$B$22,$B17)+COUNTIF('4 TM Techniques'!$B$4:$B$14,$B17)+COUNTIF('5 TM Variants'!$B$4:$B$22,$B17)+COUNTIF('6 Undecidability'!$B$4:$B$42,$B17)+COUNTIF('7 Complexity'!$B$4:$B$20,$B17) | D17: =COUNTIFS('1 Intro + CNF'!$B$4:$B$16,$B17,'1 Intro + CNF'!$N$4:$N$16,TRUE())+COUNTIFS('2 PDA'!$B$4:$B$51,$B17,'2 PDA'!$N$4:$N$51,TRUE())+COUNTIFS('3 TM Basics'!$B$4:$B$22,$B17,'3 TM Basics'!$N$4:$N$22,TRUE())+COUNTIFS('4 TM Techniques'!$B$4:$B$14,$B17,'4 TM Techniques'!$N$4:$N$14,TRUE())+COUNTIFS('5 TM Variants'!$B$4:$B$22,$B17,'5 TM Variants'!$N$4:$N$22,TRUE())+COUNTIFS('6 Undecidability'!$B$4:$B$42,$B17,'6 Undecidability'!$N$4:$N$42,TRUE())+COUNTIFS('7 Complexity'!$B$4:$B$20,$B17,'7 Complexity'!$N$4:$N$20,TRUE()) | E17: =IF(C17=0,0,D17/C17) | F17: =SUMIF('1 Intro + CNF'!$B$4:$B$16,$B17,'1 Intro + CNF'!$H$4:$H$16)+SUMIF('2 PDA'!$B$4:$B$51,$B17,'2 PDA'!$H$4:$H$51)+SUMIF('3 TM Basics'!$B$4:$B$22,$B17,'3 TM Basics'!$H$4:$H$22)+SUMIF('4 TM Techniques'!$B$4:$B$14,$B17,'4 TM Techniques'!$H$4:$H$14)+SUMIF('5 TM Variants'!$B$4:$B$22,$B17,'5 TM Variants'!$H$4:$H$22)+SUMIF('6 Undecidability'!$B$4:$B$42,$B17,'6 Undecidability'!$H$4:$H$42)+SUMIF('7 Complexity'!$B$4:$B$20,$B17,'7 Complexity'!$H$4:$H$20)
A18: 3 | B18: 2021-22 | C18: =COUNTIF('1 Intro + CNF'!$B$4:$B$16,$B18)+COUNTIF('2 PDA'!$B$4:$B$51,$B18)+COUNTIF('3 TM Basics'!$B$4:$B$22,$B18)+COUNTIF('4 TM Techniques'!$B$4:$B$14,$B18)+COUNTIF('5 TM Variants'!$B$4:$B$22,$B18)+COUNTIF('6 Undecidability'!$B$4:$B$42,$B18)+COUNTIF('7 Complexity'!$B$4:$B$20,$B18) | D18: =COUNTIFS('1 Intro + CNF'!$B$4:$B$16,$B18,'1 Intro + CNF'!$N$4:$N$16,TRUE())+COUNTIFS('2 PDA'!$B$4:$B$51,$B18,'2 PDA'!$N$4:$N$51,TRUE())+COUNTIFS('3 TM Basics'!$B$4:$B$22,$B18,'3 TM Basics'!$N$4:$N$22,TRUE())+COUNTIFS('4 TM Techniques'!$B$4:$B$14,$B18,'4 TM Techniques'!$N$4:$N$14,TRUE())+COUNTIFS('5 TM Variants'!$B$4:$B$22,$B18,'5 TM Variants'!$N$4:$N$22,TRUE())+COUNTIFS('6 Undecidability'!$B$4:$B$42,$B18,'6 Undecidability'!$N$4:$N$42,TRUE())+COUNTIFS('7 Complexity'!$B$4:$B$20,$B18,'7 Complexity'!$N$4:$N$20,TRUE()) | E18: =IF(C18=0,0,D18/C18) | F18: =SUMIF('1 Intro + CNF'!$B$4:$B$16,$B18,'1 Intro + CNF'!$H$4:$H$16)+SUMIF('2 PDA'!$B$4:$B$51,$B18,'2 PDA'!$H$4:$H$51)+SUMIF('3 TM Basics'!$B$4:$B$22,$B18,'3 TM Basics'!$H$4:$H$22)+SUMIF('4 TM Techniques'!$B$4:$B$14,$B18,'4 TM Techniques'!$H$4:$H$14)+SUMIF('5 TM Variants'!$B$4:$B$22,$B18,'5 TM Variants'!$H$4:$H$22)+SUMIF('6 Undecidability'!$B$4:$B$42,$B18,'6 Undecidability'!$H$4:$H$42)+SUMIF('7 Complexity'!$B$4:$B$20,$B18,'7 Complexity'!$H$4:$H$20)
A19: 4 | B19: 2020 (Jan term) | C19: =COUNTIF('1 Intro + CNF'!$B$4:$B$16,$B19)+COUNTIF('2 PDA'!$B$4:$B$51,$B19)+COUNTIF('3 TM Basics'!$B$4:$B$22,$B19)+COUNTIF('4 TM Techniques'!$B$4:$B$14,$B19)+COUNTIF('5 TM Variants'!$B$4:$B$22,$B19)+COUNTIF('6 Undecidability'!$B$4:$B$42,$B19)+COUNTIF('7 Complexity'!$B$4:$B$20,$B19) | D19: =COUNTIFS('1 Intro + CNF'!$B$4:$B$16,$B19,'1 Intro + CNF'!$N$4:$N$16,TRUE())+COUNTIFS('2 PDA'!$B$4:$B$51,$B19,'2 PDA'!$N$4:$N$51,TRUE())+COUNTIFS('3 TM Basics'!$B$4:$B$22,$B19,'3 TM Basics'!$N$4:$N$22,TRUE())+COUNTIFS('4 TM Techniques'!$B$4:$B$14,$B19,'4 TM Techniques'!$N$4:$N$14,TRUE())+COUNTIFS('5 TM Variants'!$B$4:$B$22,$B19,'5 TM Variants'!$N$4:$N$22,TRUE())+COUNTIFS('6 Undecidability'!$B$4:$B$42,$B19,'6 Undecidability'!$N$4:$N$42,TRUE())+COUNTIFS('7 Complexity'!$B$4:$B$20,$B19,'7 Complexity'!$N$4:$N$20,TRUE()) | E19: =IF(C19=0,0,D19/C19) | F19: =SUMIF('1 Intro + CNF'!$B$4:$B$16,$B19,'1 Intro + CNF'!$H$4:$H$16)+SUMIF('2 PDA'!$B$4:$B$51,$B19,'2 PDA'!$H$4:$H$51)+SUMIF('3 TM Basics'!$B$4:$B$22,$B19,'3 TM Basics'!$H$4:$H$22)+SUMIF('4 TM Techniques'!$B$4:$B$14,$B19,'4 TM Techniques'!$H$4:$H$14)+SUMIF('5 TM Variants'!$B$4:$B$22,$B19,'5 TM Variants'!$H$4:$H$22)+SUMIF('6 Undecidability'!$B$4:$B$42,$B19,'6 Undecidability'!$H$4:$H$42)+SUMIF('7 Complexity'!$B$4:$B$20,$B19,'7 Complexity'!$H$4:$H$20)
A20: 5 | B20: 2019-20 | C20: =COUNTIF('1 Intro + CNF'!$B$4:$B$16,$B20)+COUNTIF('2 PDA'!$B$4:$B$51,$B20)+COUNTIF('3 TM Basics'!$B$4:$B$22,$B20)+COUNTIF('4 TM Techniques'!$B$4:$B$14,$B20)+COUNTIF('5 TM Variants'!$B$4:$B$22,$B20)+COUNTIF('6 Undecidability'!$B$4:$B$42,$B20)+COUNTIF('7 Complexity'!$B$4:$B$20,$B20) | D20: =COUNTIFS('1 Intro + CNF'!$B$4:$B$16,$B20,'1 Intro + CNF'!$N$4:$N$16,TRUE())+COUNTIFS('2 PDA'!$B$4:$B$51,$B20,'2 PDA'!$N$4:$N$51,TRUE())+COUNTIFS('3 TM Basics'!$B$4:$B$22,$B20,'3 TM Basics'!$N$4:$N$22,TRUE())+COUNTIFS('4 TM Techniques'!$B$4:$B$14,$B20,'4 TM Techniques'!$N$4:$N$14,TRUE())+COUNTIFS('5 TM Variants'!$B$4:$B$22,$B20,'5 TM Variants'!$N$4:$N$22,TRUE())+COUNTIFS('6 Undecidability'!$B$4:$B$42,$B20,'6 Undecidability'!$N$4:$N$42,TRUE())+COUNTIFS('7 Complexity'!$B$4:$B$20,$B20,'7 Complexity'!$N$4:$N$20,TRUE()) | E20: =IF(C20=0,0,D20/C20) | F20: =SUMIF('1 Intro + CNF'!$B$4:$B$16,$B20,'1 Intro + CNF'!$H$4:$H$16)+SUMIF('2 PDA'!$B$4:$B$51,$B20,'2 PDA'!$H$4:$H$51)+SUMIF('3 TM Basics'!$B$4:$B$22,$B20,'3 TM Basics'!$H$4:$H$22)+SUMIF('4 TM Techniques'!$B$4:$B$14,$B20,'4 TM Techniques'!$H$4:$H$14)+SUMIF('5 TM Variants'!$B$4:$B$22,$B20,'5 TM Variants'!$H$4:$H$22)+SUMIF('6 Undecidability'!$B$4:$B$42,$B20,'6 Undecidability'!$H$4:$H$42)+SUMIF('7 Complexity'!$B$4:$B$20,$B20,'7 Complexity'!$H$4:$H$20)
A21: 6 | B21: 2017-18 | C21: =COUNTIF('1 Intro + CNF'!$B$4:$B$16,$B21)+COUNTIF('2 PDA'!$B$4:$B$51,$B21)+COUNTIF('3 TM Basics'!$B$4:$B$22,$B21)+COUNTIF('4 TM Techniques'!$B$4:$B$14,$B21)+COUNTIF('5 TM Variants'!$B$4:$B$22,$B21)+COUNTIF('6 Undecidability'!$B$4:$B$42,$B21)+COUNTIF('7 Complexity'!$B$4:$B$20,$B21) | D21: =COUNTIFS('1 Intro + CNF'!$B$4:$B$16,$B21,'1 Intro + CNF'!$N$4:$N$16,TRUE())+COUNTIFS('2 PDA'!$B$4:$B$51,$B21,'2 PDA'!$N$4:$N$51,TRUE())+COUNTIFS('3 TM Basics'!$B$4:$B$22,$B21,'3 TM Basics'!$N$4:$N$22,TRUE())+COUNTIFS('4 TM Techniques'!$B$4:$B$14,$B21,'4 TM Techniques'!$N$4:$N$14,TRUE())+COUNTIFS('5 TM Variants'!$B$4:$B$22,$B21,'5 TM Variants'!$N$4:$N$22,TRUE())+COUNTIFS('6 Undecidability'!$B$4:$B$42,$B21,'6 Undecidability'!$N$4:$N$42,TRUE())+COUNTIFS('7 Complexity'!$B$4:$B$20,$B21,'7 Complexity'!$N$4:$N$20,TRUE()) | E21: =IF(C21=0,0,D21/C21) | F21: =SUMIF('1 Intro + CNF'!$B$4:$B$16,$B21,'1 Intro + CNF'!$H$4:$H$16)+SUMIF('2 PDA'!$B$4:$B$51,$B21,'2 PDA'!$H$4:$H$51)+SUMIF('3 TM Basics'!$B$4:$B$22,$B21,'3 TM Basics'!$H$4:$H$22)+SUMIF('4 TM Techniques'!$B$4:$B$14,$B21,'4 TM Techniques'!$H$4:$H$14)+SUMIF('5 TM Variants'!$B$4:$B$22,$B21,'5 TM Variants'!$H$4:$H$22)+SUMIF('6 Undecidability'!$B$4:$B$42,$B21,'6 Undecidability'!$H$4:$H$42)+SUMIF('7 Complexity'!$B$4:$B$20,$B21,'7 Complexity'!$H$4:$H$20)
A22: 7 | B22: 2016-17 | C22: =COUNTIF('1 Intro + CNF'!$B$4:$B$16,$B22)+COUNTIF('2 PDA'!$B$4:$B$51,$B22)+COUNTIF('3 TM Basics'!$B$4:$B$22,$B22)+COUNTIF('4 TM Techniques'!$B$4:$B$14,$B22)+COUNTIF('5 TM Variants'!$B$4:$B$22,$B22)+COUNTIF('6 Undecidability'!$B$4:$B$42,$B22)+COUNTIF('7 Complexity'!$B$4:$B$20,$B22) | D22: =COUNTIFS('1 Intro + CNF'!$B$4:$B$16,$B22,'1 Intro + CNF'!$N$4:$N$16,TRUE())+COUNTIFS('2 PDA'!$B$4:$B$51,$B22,'2 PDA'!$N$4:$N$51,TRUE())+COUNTIFS('3 TM Basics'!$B$4:$B$22,$B22,'3 TM Basics'!$N$4:$N$22,TRUE())+COUNTIFS('4 TM Techniques'!$B$4:$B$14,$B22,'4 TM Techniques'!$N$4:$N$14,TRUE())+COUNTIFS('5 TM Variants'!$B$4:$B$22,$B22,'5 TM Variants'!$N$4:$N$22,TRUE())+COUNTIFS('6 Undecidability'!$B$4:$B$42,$B22,'6 Undecidability'!$N$4:$N$42,TRUE())+COUNTIFS('7 Complexity'!$B$4:$B$20,$B22,'7 Complexity'!$N$4:$N$20,TRUE()) | E22: =IF(C22=0,0,D22/C22) | F22: =SUMIF('1 Intro + CNF'!$B$4:$B$16,$B22,'1 Intro + CNF'!$H$4:$H$16)+SUMIF('2 PDA'!$B$4:$B$51,$B22,'2 PDA'!$H$4:$H$51)+SUMIF('3 TM Basics'!$B$4:$B$22,$B22,'3 TM Basics'!$H$4:$H$22)+SUMIF('4 TM Techniques'!$B$4:$B$14,$B22,'4 TM Techniques'!$H$4:$H$14)+SUMIF('5 TM Variants'!$B$4:$B$22,$B22,'5 TM Variants'!$H$4:$H$22)+SUMIF('6 Undecidability'!$B$4:$B$42,$B22,'6 Undecidability'!$H$4:$H$42)+SUMIF('7 Complexity'!$B$4:$B$20,$B22,'7 Complexity'!$H$4:$H$20)
A23: 8 | B23: 2015-16 | C23: =COUNTIF('1 Intro + CNF'!$B$4:$B$16,$B23)+COUNTIF('2 PDA'!$B$4:$B$51,$B23)+COUNTIF('3 TM Basics'!$B$4:$B$22,$B23)+COUNTIF('4 TM Techniques'!$B$4:$B$14,$B23)+COUNTIF('5 TM Variants'!$B$4:$B$22,$B23)+COUNTIF('6 Undecidability'!$B$4:$B$42,$B23)+COUNTIF('7 Complexity'!$B$4:$B$20,$B23) | D23: =COUNTIFS('1 Intro + CNF'!$B$4:$B$16,$B23,'1 Intro + CNF'!$N$4:$N$16,TRUE())+COUNTIFS('2 PDA'!$B$4:$B$51,$B23,'2 PDA'!$N$4:$N$51,TRUE())+COUNTIFS('3 TM Basics'!$B$4:$B$22,$B23,'3 TM Basics'!$N$4:$N$22,TRUE())+COUNTIFS('4 TM Techniques'!$B$4:$B$14,$B23,'4 TM Techniques'!$N$4:$N$14,TRUE())+COUNTIFS('5 TM Variants'!$B$4:$B$22,$B23,'5 TM Variants'!$N$4:$N$22,TRUE())+COUNTIFS('6 Undecidability'!$B$4:$B$42,$B23,'6 Undecidability'!$N$4:$N$42,TRUE())+COUNTIFS('7 Complexity'!$B$4:$B$20,$B23,'7 Complexity'!$N$4:$N$20,TRUE()) | E23: =IF(C23=0,0,D23/C23) | F23: =SUMIF('1 Intro + CNF'!$B$4:$B$16,$B23,'1 Intro + CNF'!$H$4:$H$16)+SUMIF('2 PDA'!$B$4:$B$51,$B23,'2 PDA'!$H$4:$H$51)+SUMIF('3 TM Basics'!$B$4:$B$22,$B23,'3 TM Basics'!$H$4:$H$22)+SUMIF('4 TM Techniques'!$B$4:$B$14,$B23,'4 TM Techniques'!$H$4:$H$14)+SUMIF('5 TM Variants'!$B$4:$B$22,$B23,'5 TM Variants'!$H$4:$H$22)+SUMIF('6 Undecidability'!$B$4:$B$42,$B23,'6 Undecidability'!$H$4:$H$42)+SUMIF('7 Complexity'!$B$4:$B$20,$B23,'7 Complexity'!$H$4:$H$20)
A24: 9 | B24: 2014-15 | C24: =COUNTIF('1 Intro + CNF'!$B$4:$B$16,$B24)+COUNTIF('2 PDA'!$B$4:$B$51,$B24)+COUNTIF('3 TM Basics'!$B$4:$B$22,$B24)+COUNTIF('4 TM Techniques'!$B$4:$B$14,$B24)+COUNTIF('5 TM Variants'!$B$4:$B$22,$B24)+COUNTIF('6 Undecidability'!$B$4:$B$42,$B24)+COUNTIF('7 Complexity'!$B$4:$B$20,$B24) | D24: =COUNTIFS('1 Intro + CNF'!$B$4:$B$16,$B24,'1 Intro + CNF'!$N$4:$N$16,TRUE())+COUNTIFS('2 PDA'!$B$4:$B$51,$B24,'2 PDA'!$N$4:$N$51,TRUE())+COUNTIFS('3 TM Basics'!$B$4:$B$22,$B24,'3 TM Basics'!$N$4:$N$22,TRUE())+COUNTIFS('4 TM Techniques'!$B$4:$B$14,$B24,'4 TM Techniques'!$N$4:$N$14,TRUE())+COUNTIFS('5 TM Variants'!$B$4:$B$22,$B24,'5 TM Variants'!$N$4:$N$22,TRUE())+COUNTIFS('6 Undecidability'!$B$4:$B$42,$B24,'6 Undecidability'!$N$4:$N$42,TRUE())+COUNTIFS('7 Complexity'!$B$4:$B$20,$B24,'7 Complexity'!$N$4:$N$20,TRUE()) | E24: =IF(C24=0,0,D24/C24) | F24: =SUMIF('1 Intro + CNF'!$B$4:$B$16,$B24,'1 Intro + CNF'!$H$4:$H$16)+SUMIF('2 PDA'!$B$4:$B$51,$B24,'2 PDA'!$H$4:$H$51)+SUMIF('3 TM Basics'!$B$4:$B$22,$B24,'3 TM Basics'!$H$4:$H$22)+SUMIF('4 TM Techniques'!$B$4:$B$14,$B24,'4 TM Techniques'!$H$4:$H$14)+SUMIF('5 TM Variants'!$B$4:$B$22,$B24,'5 TM Variants'!$H$4:$H$22)+SUMIF('6 Undecidability'!$B$4:$B$42,$B24,'6 Undecidability'!$H$4:$H$42)+SUMIF('7 Complexity'!$B$4:$B$20,$B24,'7 Complexity'!$H$4:$H$20)
A25: 10 | B25: 2013-14 | C25: =COUNTIF('1 Intro + CNF'!$B$4:$B$16,$B25)+COUNTIF('2 PDA'!$B$4:$B$51,$B25)+COUNTIF('3 TM Basics'!$B$4:$B$22,$B25)+COUNTIF('4 TM Techniques'!$B$4:$B$14,$B25)+COUNTIF('5 TM Variants'!$B$4:$B$22,$B25)+COUNTIF('6 Undecidability'!$B$4:$B$42,$B25)+COUNTIF('7 Complexity'!$B$4:$B$20,$B25) | D25: =COUNTIFS('1 Intro + CNF'!$B$4:$B$16,$B25,'1 Intro + CNF'!$N$4:$N$16,TRUE())+COUNTIFS('2 PDA'!$B$4:$B$51,$B25,'2 PDA'!$N$4:$N$51,TRUE())+COUNTIFS('3 TM Basics'!$B$4:$B$22,$B25,'3 TM Basics'!$N$4:$N$22,TRUE())+COUNTIFS('4 TM Techniques'!$B$4:$B$14,$B25,'4 TM Techniques'!$N$4:$N$14,TRUE())+COUNTIFS('5 TM Variants'!$B$4:$B$22,$B25,'5 TM Variants'!$N$4:$N$22,TRUE())+COUNTIFS('6 Undecidability'!$B$4:$B$42,$B25,'6 Undecidability'!$N$4:$N$42,TRUE())+COUNTIFS('7 Complexity'!$B$4:$B$20,$B25,'7 Complexity'!$N$4:$N$20,TRUE()) | E25: =IF(C25=0,0,D25/C25) | F25: =SUMIF('1 Intro + CNF'!$B$4:$B$16,$B25,'1 Intro + CNF'!$H$4:$H$16)+SUMIF('2 PDA'!$B$4:$B$51,$B25,'2 PDA'!$H$4:$H$51)+SUMIF('3 TM Basics'!$B$4:$B$22,$B25,'3 TM Basics'!$H$4:$H$22)+SUMIF('4 TM Techniques'!$B$4:$B$14,$B25,'4 TM Techniques'!$H$4:$H$14)+SUMIF('5 TM Variants'!$B$4:$B$22,$B25,'5 TM Variants'!$H$4:$H$22)+SUMIF('6 Undecidability'!$B$4:$B$42,$B25,'6 Undecidability'!$H$4:$H$42)+SUMIF('7 Complexity'!$B$4:$B$20,$B25,'7 Complexity'!$H$4:$H$20)
A26: 11 | B26: 2012-13 | C26: =COUNTIF('1 Intro + CNF'!$B$4:$B$16,$B26)+COUNTIF('2 PDA'!$B$4:$B$51,$B26)+COUNTIF('3 TM Basics'!$B$4:$B$22,$B26)+COUNTIF('4 TM Techniques'!$B$4:$B$14,$B26)+COUNTIF('5 TM Variants'!$B$4:$B$22,$B26)+COUNTIF('6 Undecidability'!$B$4:$B$42,$B26)+COUNTIF('7 Complexity'!$B$4:$B$20,$B26) | D26: =COUNTIFS('1 Intro + CNF'!$B$4:$B$16,$B26,'1 Intro + CNF'!$N$4:$N$16,TRUE())+COUNTIFS('2 PDA'!$B$4:$B$51,$B26,'2 PDA'!$N$4:$N$51,TRUE())+COUNTIFS('3 TM Basics'!$B$4:$B$22,$B26,'3 TM Basics'!$N$4:$N$22,TRUE())+COUNTIFS('4 TM Techniques'!$B$4:$B$14,$B26,'4 TM Techniques'!$N$4:$N$14,TRUE())+COUNTIFS('5 TM Variants'!$B$4:$B$22,$B26,'5 TM Variants'!$N$4:$N$22,TRUE())+COUNTIFS('6 Undecidability'!$B$4:$B$42,$B26,'6 Undecidability'!$N$4:$N$42,TRUE())+COUNTIFS('7 Complexity'!$B$4:$B$20,$B26,'7 Complexity'!$N$4:$N$20,TRUE()) | E26: =IF(C26=0,0,D26/C26) | F26: =SUMIF('1 Intro + CNF'!$B$4:$B$16,$B26,'1 Intro + CNF'!$H$4:$H$16)+SUMIF('2 PDA'!$B$4:$B$51,$B26,'2 PDA'!$H$4:$H$51)+SUMIF('3 TM Basics'!$B$4:$B$22,$B26,'3 TM Basics'!$H$4:$H$22)+SUMIF('4 TM Techniques'!$B$4:$B$14,$B26,'4 TM Techniques'!$H$4:$H$14)+SUMIF('5 TM Variants'!$B$4:$B$22,$B26,'5 TM Variants'!$H$4:$H$22)+SUMIF('6 Undecidability'!$B$4:$B$42,$B26,'6 Undecidability'!$H$4:$H$42)+SUMIF('7 Complexity'!$B$4:$B$20,$B26,'7 Complexity'!$H$4:$H$20)
A27: 12 | B27: 2011-12 | C27: =COUNTIF('1 Intro + CNF'!$B$4:$B$16,$B27)+COUNTIF('2 PDA'!$B$4:$B$51,$B27)+COUNTIF('3 TM Basics'!$B$4:$B$22,$B27)+COUNTIF('4 TM Techniques'!$B$4:$B$14,$B27)+COUNTIF('5 TM Variants'!$B$4:$B$22,$B27)+COUNTIF('6 Undecidability'!$B$4:$B$42,$B27)+COUNTIF('7 Complexity'!$B$4:$B$20,$B27) | D27: =COUNTIFS('1 Intro + CNF'!$B$4:$B$16,$B27,'1 Intro + CNF'!$N$4:$N$16,TRUE())+COUNTIFS('2 PDA'!$B$4:$B$51,$B27,'2 PDA'!$N$4:$N$51,TRUE())+COUNTIFS('3 TM Basics'!$B$4:$B$22,$B27,'3 TM Basics'!$N$4:$N$22,TRUE())+COUNTIFS('4 TM Techniques'!$B$4:$B$14,$B27,'4 TM Techniques'!$N$4:$N$14,TRUE())+COUNTIFS('5 TM Variants'!$B$4:$B$22,$B27,'5 TM Variants'!$N$4:$N$22,TRUE())+COUNTIFS('6 Undecidability'!$B$4:$B$42,$B27,'6 Undecidability'!$N$4:$N$42,TRUE())+COUNTIFS('7 Complexity'!$B$4:$B$20,$B27,'7 Complexity'!$N$4:$N$20,TRUE()) | E27: =IF(C27=0,0,D27/C27) | F27: =SUMIF('1 Intro + CNF'!$B$4:$B$16,$B27,'1 Intro + CNF'!$H$4:$H$16)+SUMIF('2 PDA'!$B$4:$B$51,$B27,'2 PDA'!$H$4:$H$51)+SUMIF('3 TM Basics'!$B$4:$B$22,$B27,'3 TM Basics'!$H$4:$H$22)+SUMIF('4 TM Techniques'!$B$4:$B$14,$B27,'4 TM Techniques'!$H$4:$H$14)+SUMIF('5 TM Variants'!$B$4:$B$22,$B27,'5 TM Variants'!$H$4:$H$22)+SUMIF('6 Undecidability'!$B$4:$B$42,$B27,'6 Undecidability'!$H$4:$H$42)+SUMIF('7 Complexity'!$B$4:$B$20,$B27,'7 Complexity'!$H$4:$H$20)
... A32: 17 | B32: 2006-07 | C32: =COUNTIF('1 Intro + CNF'!$B$4:$B$16,$B32)+COUNTIF('2 PDA'!$B$4:$B$51,$B32)+COUNTIF('3 TM Basics'!$B$4:$B$22,$B32)+COUNTIF('4 TM Techniques'!$B$4:$B$14,$B32)+COUNTIF('5 TM Variants'!$B$4:$B$22,$B32)+COUNTIF('6 Undecidability'!$B$4:$B$42,$B32)+COUNTIF('7 Complexity'!$B$4:$B$20,$B32) | D32: =COUNTIFS('1 Intro + CNF'!$B$4:$B$16,$B32,'1 Intro + CNF'!$N$4:$N$16,TRUE())+COUNTIFS('2 PDA'!$B$4:$B$51,$B32,'2 PDA'!$N$4:$N$51,TRUE())+COUNTIFS('3 TM Basics'!$B$4:$B$22,$B32,'3 TM Basics'!$N$4:$N$22,TRUE())+COUNTIFS('4 TM Techniques'!$B$4:$B$14,$B32,'4 TM Techniques'!$N$4:$N$14,TRUE())+COUNTIFS('5 TM Variants'!$B$4:$B$22,$B32,'5 TM Variants'!$N$4:$N$22,TRUE())+COUNTIFS('6 Undecidability'!$B$4:$B$42,$B32,'6 Undecidability'!$N$4:$N$42,TRUE())+COUNTIFS('7 Complexity'!$B$4:$B$20,$B32,'7 Complexity'!$N$4:$N$20,TRUE()) | E32: =IF(C32=0,0,D32/C32) | F32: =SUMIF('1 Intro + CNF'!$B$4:$B$16,$B32,'1 Intro + CNF'!$H$4:$H$16)+SUMIF('2 PDA'!$B$4:$B$51,$B32,'2 PDA'!$H$4:$H$51)+SUMIF('3 TM Basics'!$B$4:$B$22,$B32,'3 TM Basics'!$H$4:$H$22)+SUMIF('4 TM Techniques'!$B$4:$B$14,$B32,'4 TM Techniques'!$H$4:$H$14)+SUMIF('5 TM Variants'!$B$4:$B$22,$B32,'5 TM Variants'!$H$4:$H$22)+SUMIF('6 Undecidability'!$B$4:$B$42,$B32,'6 Undecidability'!$H$4:$H$42)+SUMIF('7 Complexity'!$B$4:$B$20,$B32,'7 Complexity'!$H$4:$H$20)
B33: Shaded years = ★★★ High priority (2019-20 onward).
B34: Papers 2006-07 … 2023-24 (17 papers). The 2023-24 paper is not inside the merged PDF; its rows say '22 batch p.N' (CSE 211 (22 batch).pdf, 4 scanned pages).
B35: The paper printed 'January 2020 Term' (held 16/01/2021) is listed as '2020 (Jan term)' and counted as ★★★ High (it is newer than 2019-20); the 2019-20 paper (held 2021-22) is ★★★ too.
B36: Questions were assigned to a teacher by topic, not by section letter (older papers put the PDA/TM side in Section A).
B37: The Outside Notes tab holds 2010-11 Q12(b) (machine-schema notation of Lewis–Papadimitriou, not in the slides).

Sheet 1 Intro + CNF
A1: Lectures 1–2 — Introduction, CFG simplification, CNF, CYK
A2: Note file: CSE211_Atif_Intro_CNF_Notes.docx · Solve after finishing the matching lesson. Filter Priority → ★★★ High first.
A3: Q No. | B3: Year | C3: Course | D3: Ques No. | E3: Short Question | F3: Topic (slide PDF · slides) | G3: Lesson | H3: Marks | I3: TF Page | J3: Priority | K3: Type | L3: In Notes | M3: Same Type Also In | N3: Done | O3: Confidence | P3: Date | Q3: My Notes
A4: 1 | B4: 2008-09 | C4: CSE 211 | D4: 2(a) | E4: S→ASB|ε, A→aAS|a, B→SbS|A|bb: eliminate ε-productions | F4: Simplifying grammars — Lecture 2 CNF, sl. 19–30 | G4: L2 | H4: 7.33 | I4: 6 | J4: ★★ Medium | K4: Trace | L4: ✔ Solved | M4: 2008-09 2(b); 2008-09 2(c) | N4: FALSE
A5: 2 | B5: 2008-09 | C5: CSE 211 | D5: 2(b) | E5: Same grammar: eliminate unit productions | F5: Simplifying grammars — Lecture 2 CNF, sl. 19–30 | G5: L2 | H5: 8 | I5: 6 | J5: ★★ Medium | K5: Trace | L5: ✔ Solved | M5: 2008-09 2(a); 2008-09 2(c) | N5: FALSE
A6: 3 | B6: 2008-09 | C6: CSE 211 | D6: 2(c) | E6: Same grammar: eliminate useless symbols | F6: Simplifying grammars — Lecture 2 CNF, sl. 19–30 | G6: L2 | H6: 8 | I6: 6 | J6: ★★ Medium | K6: Trace | L6: ✔ Solved | M6: 2008-09 2(a); 2008-09 2(b) | N6: FALSE
A7: 4 | B7: 2021-22 | C7: CSE 211 | D7: 5 | E7: Convert S→A1A|B, A→0A|1A|ε, B→1 to CNF | F7: Converting to CNF — Lecture 2 CNF, sl. 2–3, 19–35 | G7: L3 | H7: 15 | I7: 47 | J7: ★★★ High | K7: Trace | L7: ✔ Solved | M7: 2017-18 7(a); 2016-17 6(b); 2014-15 5(c) | N7: FALSE
A8: 5 | B8: 2017-18 | C8: CSE 211 | D8: 7(a) | E8: Convert S→A1A|B, A→0A|1A|ε, D→00 to CNF | F8: Converting to CNF — Lecture 2 CNF, sl. 2–3, 19–35 | G8: L3 | H8: 8 | I8: 34 | J8: ★★ Medium | K8: Trace | L8: ✔ Solved | M8: 2021-22 5; 2016-17 6(b); 2014-15 5(c) | N8: FALSE
A9: 6 | B9: 2016-17 | C9: CSE 211 | D9: 6(b) | E9: Convert A→BAB|B|ε, B→00|ε to CNF | F9: Converting to CNF — Lecture 2 CNF, sl. 2–3, 19–35 | G9: L3 | H9: 10 | I9: 31 | J9: ★★ Medium | K9: Trace | L9: ✔ Solved | M9: 2021-22 5; 2017-18 7(a); 2014-15 5(c) | N9: FALSE
A10: 7 | B10: 2014-15 | C10: CSE 211 | D10: 5(c) | E10: CNF definition; convert A→BAB|B|ε, B→00|ε to CNF | F10: Converting to CNF — Lecture 2 CNF, sl. 2–3, 19–35 | G10: L3 | H10: 9.33 | I10: 23 | J10: ★★ Medium | K10: Trace | L10: ✔ Solved | M10: 2021-22 5; 2017-18 7(a); 2016-17 6(b) | N10: FALSE
A11: 8 | B11: 2023-24 | C11: CSE 211 | D11: 6 | E11: CYK: is 0010 in L(G) (S→BZ|CY|ZZ|YY …)? Describe L(G) | F11: CYK algorithm — Lecture 2 CNF, sl. 4–18 | G11: L4 | H11: 15 | I11: 22 batch p.3 | J11: ★★★ High | K11: Trace | L11: ✔ Solved | M11: 2022-23 7; 2020 (Jan term) 7; 2019-20 7; 2017-18 7(b); 2007-08 13 | N11: FALSE
A12: 9 | B12: 2022-23 | C12: CSE 211 | D12: 7 | E12: CYK: is 0100 in L(G), S→AB|AY|YA|1, A→ZA|YA|0|1, B→YA, Z→0, Y→1? | F12: CYK algorithm — Lecture 2 CNF, sl. 4–18 | G12: L4 | H12: 15 | I12: 52 | J12: ★★★ High | K12: Trace | L12: ✔ Solved | M12: 2023-24 6; 2020 (Jan term) 7; 2019-20 7; 2017-18 7(b); 2007-08 13 | N12: FALSE
A13: 10 | B13: 2020 (Jan term) | C13: CSE 211 | D13: 7 | E13: CYK: is 10011 in L(G), S→BZ|CY|ZZ|YY, B→ZA, C→YA, A→ZA|YA|0|1, Z→0, Y→1? | F13: CYK algorithm — Lecture 2 CNF, sl. 4–18 | G13: L4 | H13: 15 | I13: 38 | J13: ★★★ High | K13: Trace | L13: ✔ Solved | M13: 2023-24 6; 2022-23 7; 2019-20 7; 2017-18 7(b); 2007-08 13 | N13: FALSE
A14: 11 | B14: 2019-20 | C14: CSE 211 | D14: 7 | E14: CYK: is 01100 in L(G) (S→BZ|CY|ZZ|YY …)? Describe L(G) | F14: CYK algorithm — Lecture 2 CNF, sl. 4–18 | G14: L4 | H14: 15 | I14: 42 | J14: ★★★ High | K14: Trace | L14: ✔ Solved | M14: 2023-24 6; 2022-23 7; 2020 (Jan term) 7; 2017-18 7(b); 2007-08 13 | N14: FALSE
A15: 12 | B15: 2017-18 | C15: CSE 211 | D15: 7(b) | E15: CYK: is 01101 in the language of the CNF grammar of 7(a)? | F15: CYK algorithm — Lecture 2 CNF, sl. 4–18 | G15: L4 | H15: 7 | I15: 34 | J15: ★★ Medium | K15: Trace | L15: ✔ Solved | M15: 2023-24 6; 2022-23 7; 2020 (Jan term) 7; 2019-20 7; 2007-08 13 | N15: FALSE
A16: 13 | B16: 2007-08 | C16: CSE 211 | D16: 13 | E16: CNF definition; CYK for 'abaab' with S→AB|BC, A→BA|a, B→CC|b, C→AB|a | F16: CYK algorithm — Lecture 2 CNF, sl. 4–18 | G16: L4 | H16: 10 | I16: 5 | J16: ★★ Medium | K16: Trace | L16: ✔ Solved | M16: 2023-24 6; 2022-23 7; 2020 (Jan term) 7; 2019-20 7; 2017-18 7(b) | N16: FALSE

Sheet 2 PDA
A1: Lecture 3 — Pushdown Automata, CFG–PDA equivalence, CFL pumping lemma
A2: Note file: CSE211_Atif_PDA_Notes.docx · Solve after finishing the matching lesson. Filter Priority → ★★★ High first.
A3: Q No. | B3: Year | C3: Course | D3: Ques No. | E3: Short Question | F3: Topic (slide PDF · slides) | G3: Lesson | H3: Marks | I3: TF Page | J3: Priority | K3: Type | L3: In Notes | M3: Same Type Also In | N3: Done | O3: Confidence | P3: Date | Q3: My Notes
A4: 1 | B4: 2006-07 | C4: CSE 211 | D4: 8 | E4: Define PDA with an example; what is an instantaneous description (ID)? | F4: PDA: definition and idea — Lecture 3 PDA, sl. 2–55 | G4: L5 | H4: 10 | I4: 3 | J4: ★ Low | K4: Theory | L4: ✔ Solved | M4: — | N4: FALSE
A5: 2 | B5: 2015-16 | C5: CSE 211 | D5: 5(a) | E5: Draw the transition diagram of PDA P = ({q,p},{0,1},{Z0,X},δ,q,Z0,{p}) | F5: IDs and traces — Lecture 3 PDA, sl. 56–86 | G5: L6 | H5: 8.33 | I5: 26 | J5: ★★ Medium | K5: Design | L5: ✔ Solved | M5: 2015-16 5(b); 2010-11 13(c); 2009-10 10(b) | N5: FALSE
A6: 3 | B6: 2015-16 | C6: CSE 211 | D6: 5(b) | E6: All reachable IDs of that PDA from (q,w,Z0) for 0011, 0101, 1010 | F6: IDs and traces — Lecture 3 PDA, sl. 56–86 | G6: L6 | H6: 15 | I6: 27 | J6: ★★ Medium | K6: Trace | L6: ✔ Solved | M6: 2015-16 5(a); 2010-11 13(c); 2009-10 10(b) | N6: FALSE
A7: 4 | B7: 2010-11 | C7: CSE 211 | D7: 13(c) | E7: Run the given PDA (q1…q4, $ marker) on 1001 and 0101; what does it do? | F7: IDs and traces — Lecture 3 PDA, sl. 56–86 | G7: L6 | H7: 8 | I7: 13 | J7: ★★ Medium | K7: Trace | L7: ✔ Solved | M7: 2015-16 5(a); 2015-16 5(b); 2009-10 10(b) | N7: FALSE
A8: 5 | B8: 2023-24 | C8: CSE 211 | D8: 8 | E8: PDA for {a^n b^m c^m d^n | n ≥ 1, m ≥ 1} | F8: Designing PDAs — Lecture 3 PDA, sl. 20–55, 87–101 | G8: L7 | H8: 15 | I8: 22 batch p.3 | J8: ★★★ High | K8: Design | L8: ✔ Solved | M8: 2017-18 8 | N8: FALSE
A9: 6 | B9: 2022-23 | C9: CSE 211 | D9: 8 | E9: PDA for {a^i b^j c^k | i = j or i = k} | F9: Designing PDAs — Lecture 3 PDA, sl. 20–55, 87–101 | G9: L7 | H9: 15 | I9: 52 | J9: ★★★ High | K9: Design | L9: ✔ Solved | M9: 2020 (Jan term) 8; 2013-14 1(b) | N9: FALSE
A10: 7 | B10: 2021-22 | C10: CSE 211 | D10: 7 | E10: PDA for ARITH = legal arithmetic expressions over {a,+,∗,(,)} | F10: Designing PDAs — Lecture 3 PDA, sl. 20–55, 87–101 | G10: L7 | H10: 15 | I10: 47 | J10: ★★★ High | K10: Design | L10: ✔ Solved | M10: 2019-20 8 | N10: FALSE
A11: 8 | B11: 2020 (Jan term) | C11: CSE 211 | D11: 8 | E11: PDA for {a^i b^j c^k | i = j or i = k} | F11: Designing PDAs — Lecture 3 PDA, sl. 20–55, 87–101 | G11: L7 | H11: 15 | I11: 38 | J11: ★★★ High | K11: Design | L11: ✔ Solved | M11: 2022-23 8; 2013-14 1(b) | N11: FALSE
A12: 9 | B12: 2019-20 | C12: CSE 211 | D12: 8 | E12: PDA for ARITH = legal arithmetic expressions over {a,+,∗,(,)} | F12: Designing PDAs — Lecture 3 PDA, sl. 20–55, 87–101 | G12: L7 | H12: 15 | I12: 42 | J12: ★★★ High | K12: Design | L12: ✔ Solved | M12: 2021-22 7 | N12: FALSE
A13: 10 | B13: 2017-18 | C13: CSE 211 | D13: 8 | E13: PDA for {a^n b^n c^m d^m | n ≥ 1, m ≥ 1} | F13: Designing PDAs — Lecture 3 PDA, sl. 20–55, 87–101 | G13: L7 | H13: 15 | I13: 34 | J13: ★★ Medium | K13: Design | L13: ✔ Solved | M13: 2023-24 8 | N13: FALSE
A14: 11 | B14: 2016-17 | C14: CSE 211 | D14: 6(a) | E14: PDA for {0^n 1^m | n ≤ m ≤ 2n}; show it accepts 00111 and rejects 0011111 | F14: Designing PDAs — Lecture 3 PDA, sl. 20–55, 87–101 | G14: L7 | H14: 15 | I14: 30–31 | J14: ★★ Medium | K14: Design | L14: ✔ Solved | M14: 2009-10 10(a); 2008-09 1(i); 2007-08 5 | N14: FALSE
A15: 12 | B15: 2016-17 | C15: CSE 211 | D15: 7(b) | E15: PDA for {ww^R | w ∈ {0,1}∗} | F15: Designing PDAs — Lecture 3 PDA, sl. 20–55, 87–101 | G15: L7 | H15: 10 | I15: 31 | J15: ★★ Medium | K15: Design | L15: ✔ Solved | M15: 2010-11 13(a); 2006-07 9 | N15: FALSE
A16: 13 | B16: 2015-16 | C16: CSE 211 | D16: 6(a) | E16: PDA for {w ∈ {a,b}∗ : equal numbers of a's and b's} | F16: Designing PDAs — Lecture 3 PDA, sl. 20–55, 87–101 | G16: L7 | H16: 13 | I16: 27 | J16: ★ Low | K16: Design | L16: ✔ Solved | M16: — | N16: FALSE
A17: 14 | B17: 2014-15 | C17: CSE 211 | D17: 6(c) | E17: PDA for {wcw^R | w ∈ {a,b}∗}; trace bbcbb by configurations | F17: Designing PDAs — Lecture 3 PDA, sl. 20–55, 87–101 | G17: L7 | H17: 9.33 | I17: 23 | J17: ★ Low | K17: Design | L17: ✔ Solved | M17: — | N17: FALSE
A18: 15 | B18: 2013-14 | C18: CSE 211 | D18: 1(b) | E18: PDA for {a^i b^j c^k : i = j or j = k} | F18: Designing PDAs — Lecture 3 PDA, sl. 20–55, 87–101 | G18: L7 | H18: 7 | I18: 19 | J18: ★★ Medium | K18: Design | L18: ✔ Solved | M18: 2022-23 8; 2020 (Jan term) 8 | N18: FALSE
A19: 16 | B19: 2012-13 | C19: CSE 211 | D19: 4(a) | E19: PDA for {a^i b^j c^k : i + j = k} | F19: Designing PDAs — Lecture 3 PDA, sl. 20–55, 87–101 | G19: L7 | H19: 8 | I19: 17 | J19: ★★ Medium | K19: Design | L19: ✔ Solved | M19: 2011-12 4(a) | N19: FALSE
A20: 17 | B20: 2012-13 | C20: CSE 211 | D20: 4(c) | E20: PDA for odd-length strings over {a,b} with middle symbol a | F20: Designing PDAs — Lecture 3 PDA, sl. 20–55, 87–101 | G20: L7 | H20: 8.33 | I20: 18 | J20: ★★ Medium | K20: Design | L20: ✔ Solved | M20: 2011-12 3(c) | N20: FALSE
A21: 18 | B21: 2011-12 | C21: CSE 211 | D21: 3(c) | E21: PDA for odd-length strings over {a,b} with middle symbol a | F21: Designing PDAs — Lecture 3 PDA, sl. 20–55, 87–101 | G21: L7 | H21: 7 | I21: 15 | J21: ★★ Medium | K21: Design | L21: ✔ Solved | M21: 2012-13 4(c) | N21: FALSE
A22: 19 | B22: 2011-12 | C22: CSE 211 | D22: 4(a) | E22: PDA for {a^i b^j c^k : i + j = k} | F22: Designing PDAs — Lecture 3 PDA, sl. 20–55, 87–101 | G22: L7 | H22: 7 | I22: 15 | J22: ★★ Medium | K22: Design | L22: ✔ Solved | M22: 2012-13 4(a) | N22: FALSE
A23: 20 | B23: 2010-11 | C23: CSE 211 | D23: 13(a) | E23: Formally describe a PDA for {w ∈ {0,1}∗ | w = w^R} | F23: Designing PDAs — Lecture 3 PDA, sl. 20–55, 87–101 | G23: L7 | H23: 8 | I23: 13 | J23: ★★ Medium | K23: Design | L23: ✔ Solved | M23: 2016-17 7(b); 2006-07 9 | N23: FALSE
A24: 21 | B24: 2009-10 | C24: CSE 211 | D24: 10(a) | E24: Formal PDA definition; PDAs for {0^n1^n | n ≥ 1}, equal 0s and 1s, palindromes over {0,1} | F24: Designing PDAs — Lecture 3 PDA, sl. 20–55, 87–101 | G24: L7 | H24: 14 | I24: 9 | J24: ★★ Medium | K24: Design | L24: ✔ Solved | M24: 2016-17 6(a); 2008-09 1(i); 2007-08 5 | N24: FALSE
A25: 22 | B25: 2008-09 | C25: CSE 211 | D25: 1(i) | E25: PDA for {a^n b^2n | n > 0} or prove impossible | F25: Designing PDAs — Lecture 3 PDA, sl. 20–55, 87–101 | G25: L7 | H25: 10 | I25: 6 | J25: ★★ Medium | K25: Design | L25: ✔ Solved | M25: 2016-17 6(a); 2009-10 10(a); 2007-08 5 | N25: FALSE
A26: 23 | B26: 2007-08 | C26: CSE 211 | D26: 5 | E26: PDA for {a^i c^k (bc)^i | i, k ≥ 0} | F26: Designing PDAs — Lecture 3 PDA, sl. 20–55, 87–101 | G26: L7 | H26: 10 | I26: 5 | J26: ★★ Medium | K26: Design | L26: ✔ Solved | M26: 2016-17 6(a); 2009-10 10(a); 2008-09 1(i) | N26: FALSE
... A29: 26 | B29: 2015-16 | C29: CSE 211 | D29: 6(b) | E29: From PF (final state) build PN (empty stack) for the same L — definitions of both | F29: Final state vs empty stack — Lecture 3 PDA, sl. 102–109 | G29: L8 | H29: 10.33 | I29: 27 | J29: ★★ Medium | K29: Proof | L29: ✔ Solved | M29: 2019-20 10(a); 2007-08 6 | N29: FALSE
A30: 27 | B30: 2009-10 | C30: CSE 211 | D30: 10(b) | E30: PDA P({p,q},…,δ: (q,0,Z)→XZ, …): (i) transition diagram, (ii) convert to an empty-stack PDA for the same language | F30: Final state vs empty stack — Lecture 3 PDA, sl. 102–109 | G30: L8 | H30: 9.33 | I30: 9–10 | J30: ★★ Medium | K30: Design | L30: ✔ Solved | M30: 2015-16 5(a); 2015-16 5(b); 2010-11 13(c) | N30: FALSE
A31: 28 | B31: 2007-08 | C31: CSE 211 | D31: 6 | E31: Justify: L has a PDA accepting by final state iff it has one accepting by empty stack | F31: Final state vs empty stack — Lecture 3 PDA, sl. 102–109 | G31: L8 | H31: 10 | I31: 5 | J31: ★★ Medium | K31: Proof | L31: ✔ Solved | M31: 2019-20 10(a); 2015-16 6(b) | N31: FALSE
A32: 29 | B32: 2014-15 | C32: CSE 211 | D32: 7(a) | E32: For any PDA P there is a CFG G with L(P) = L(G) | F32: CFG ↔ PDA — Lecture 3 PDA, sl. 104, 110–122 | G32: L9 | H32: 7 | I32: 23 | J32: ★★ Medium | K32: Proof | L32: ◐ Method | M32: 2013-14 1(c); 2012-13 1(b); 2010-11 12(c) | N32: FALSE
A33: 30 | B33: 2013-14 | C33: CSE 211 | D33: 1(a) | E33: Convert E→E+T|T, T→T×F|T/F|F, F→(E)|a to a PDA | F33: CFG ↔ PDA — Lecture 3 PDA, sl. 104, 110–122 | G33: L9 | H33: 7 | I33: 19 | J33: ★★ Medium | K33: Design | L33: ✔ Solved | M33: 2012-13 1(a); 2011-12 4(b); 2010-11 12(d); 2009-10 11(a) | N33: FALSE
A34: 31 | B34: 2013-14 | C34: CSE 211 | D34: 1(c) | E34: Prove: for any PDA P there is a CFG G with L(P) = L(G) | F34: CFG ↔ PDA — Lecture 3 PDA, sl. 104, 110–122 | G34: L9 | H34: 9.33 | I34: 19 | J34: ★★ Medium | K34: Proof | L34: ◐ Method | M34: 2014-15 7(a); 2012-13 1(b); 2010-11 12(c) | N34: FALSE
A35: 32 | B35: 2012-13 | C35: CSE 211 | D35: 1(a) | E35: Formal PDA definition; PDA for S→BS|A, A→0A|ε, B→BB1|2 | F35: CFG ↔ PDA — Lecture 3 PDA, sl. 104, 110–122 | G35: L9 | H35: 10 | I35: 17 | J35: ★★ Medium | K35: Design | L35: ✔ Solved | M35: 2013-14 1(a); 2011-12 4(b); 2010-11 12(d); 2009-10 11(a) | N35: FALSE
A36: 33 | B36: 2012-13 | C36: CSE 211 | D36: 1(b) | E36: Prove a language is CFL iff some PDA accepts it | F36: CFG ↔ PDA — Lecture 3 PDA, sl. 104, 110–122 | G36: L9 | H36: 13.33 | I36: 17 | J36: ★★ Medium | K36: Proof | L36: ◐ Method | M36: 2014-15 7(a); 2013-14 1(c); 2010-11 12(c) | N36: FALSE
A37: 34 | B37: 2011-12 | C37: CSE 211 | D37: 4(b) | E37: Convert S→aTXb, T→XTS|ε, X→a|b to a PDA | F37: CFG ↔ PDA — Lecture 3 PDA, sl. 104, 110–122 | G37: L9 | H37: 8 | I37: 15 | J37: ★★ Medium | K37: Design | L37: ✔ Solved | M37: 2013-14 1(a); 2012-13 1(a); 2010-11 12(d); 2009-10 11(a) | N37: FALSE
A38: 35 | B38: 2010-11 | C38: CSE 211 | D38: 12(c) | E38: Prove: if a PDA recognizes L then L is context-free | F38: CFG ↔ PDA — Lecture 3 PDA, sl. 104, 110–122 | G38: L9 | H38: 11 | I38: 13 | J38: ★★ Medium | K38: Proof | L38: ◐ Method | M38: 2014-15 7(a); 2013-14 1(c); 2012-13 1(b) | N38: FALSE
A39: 36 | B39: 2010-11 | C39: CSE 211 | D39: 12(d) | E39: Informal description + state diagram of a PDA for S→TX, T→0T0|1T1|#X, X→0X|1X|ε | F39: CFG ↔ PDA — Lecture 3 PDA, sl. 104, 110–122 | G39: L9 | H39: 5.33 | I39: 13 | J39: ★★ Medium | K39: Design | L39: ✔ Solved | M39: 2013-14 1(a); 2012-13 1(a); 2011-12 4(b); 2009-10 11(a) | N39: FALSE
A40: 37 | B40: 2010-11 | C40: CSE 211 | D40: 13(b) | E40: Convert the PDA of 13(a) into an equivalent CFG | F40: CFG ↔ PDA — Lecture 3 PDA, sl. 104, 110–122 | G40: L9 | H40: 7.33 | I40: 13 | J40: ★★ Medium | K40: Design | L40: ✔ Solved | M40: 2009-10 11(b) | N40: FALSE
A41: 38 | B41: 2009-10 | C41: CSE 211 | D41: 11(a) | E41: Convert S→AS|A, A→0A|1B|1, B→0B|0 to a PDA accepting by empty stack | F41: CFG ↔ PDA — Lecture 3 PDA, sl. 104, 110–122 | G41: L9 | H41: 5 | I41: 10 | J41: ★★ Medium | K41: Design | L41: ✔ Solved | M41: 2013-14 1(a); 2012-13 1(a); 2011-12 4(b); 2010-11 12(d) | N41: FALSE
A42: 39 | B42: 2009-10 | C42: CSE 211 | D42: 11(b) | E42: Convert PDA δ(q,1,Z)={(q,XZ)}, δ(q,0,X)={(p,X)}, δ(p,1,X)={(p,ε)} to a CFG | F42: CFG ↔ PDA — Lecture 3 PDA, sl. 104, 110–122 | G42: L9 | H42: 13 | I42: 10 | J42: ★★ Medium | K42: Design | L42: ✔ Solved | M42: 2010-11 13(b) | N42: FALSE
...

Sheet 3 TM Basics
A1: Lecture 4 — Turing Machines: definition and design
A2: Note file: CSE211_Atif_TM_Basics_Notes.docx · Solve after finishing the matching lesson. Filter Priority → ★★★ High first.
A3: Q No. | B3: Year | C3: Course | D3: Ques No. | E3: Short Question | F3: Topic (slide PDF · slides) | G3: Lesson | H3: Marks | I3: TF Page | J3: Priority | K3: Type | L3: In Notes | M3: Same Type Also In | N3: Done | O3: Confidence | P3: Date | Q3: My Notes
A4: 1 | B4: 2013-14 | C4: CSE 211 | D4: 3(a) | E4: Can a TM write blank? Can Γ = Σ? Head in same place two steps? Single state? | F4: TM definition, IDs, language — Lecture 4 TM1, sl. 1–41, 116–123 | G4: L11 | H4: 7 | I4: 19 | J4: ★ Low | K4: Theory | L4: ✔ Solved | M4: — | N4: FALSE
A5: 2 | B5: 2008-09 | C5: CSE 211 | D5: 3(a) | E5: Formal notation of the Turing machine | F5: TM definition, IDs, language — Lecture 4 TM1, sl. 1–41, 116–123 | G5: L11 | H5: 2.33 | I5: 6 | J5: ★ Low | K5: Theory | L5: ✔ Solved | M5: — | N5: FALSE
A6: 3 | B6: 2007-08 | C6: CSE 211 | D6: 11 | E6: Recursive, RE and non-RE languages; describe L(M) for δ(q0,0)=(q0,B,R), δ(q0,1)=(q1,B,R), δ(q1,1)=(q1,B,R), δ(q1,B)=(qf,B,R) | F6: TM definition, IDs, language — Lecture 4 TM1, sl. 1–41, 116–123 | G6: L11 | H6: 10 | I6: 5 | J6: ★★ Medium | K6: Trace | L6: ✔ Solved | M6: 2006-07 12 | N6: FALSE
A7: 4 | B7: 2006-07 | C7: CSE 211 | D7: 12 | E7: Language of a TM; recursive language; describe L(M) for δ(q0,0)=(q1,1,R), δ(q0,B)=(qf,B,R), δ(q1,1)=(q0,0,R), δ(q1,B)=(qf,B,R) | F7: TM definition, IDs, language — Lecture 4 TM1, sl. 1–41, 116–123 | G7: L11 | H7: 10 | I7: 3 | J7: ★★ Medium | K7: Trace | L7: ✔ Solved | M7: 2007-08 11 | N7: FALSE
A8: 5 | B8: 2016-17 | C8: CSE 211 | D8: 6(c) | E8: TM for strings with an equal number of 0s and 1s | F8: Designing language-deciding TMs — Lecture 4 TM1, sl. 42–70 | G8: L12 | H8: 10 | I8: 31 | J8: ★★ Medium | K8: Design | L8: ✔ Solved | M8: 2015-16 7(a); 2014-15 8(b); 2013-14 2(a); 2012-13 3(b); 2010-11 11(b); 2009-10 12(a) | N8: FALSE
A9: 6 | B9: 2015-16 | C9: CSE 211 | D9: 7(a) | E9: TM for {a^n b^n c^n | n ≥ 1}; working principle | F9: Designing language-deciding TMs — Lecture 4 TM1, sl. 42–70 | G9: L12 | H9: 13 | I9: 27 | J9: ★★ Medium | K9: Design | L9: ✔ Solved | M9: 2016-17 6(c); 2014-15 8(b); 2013-14 2(a); 2012-13 3(b); 2010-11 11(b); 2009-10 12(a) | N9: FALSE
A10: 7 | B10: 2014-15 | C10: CSE 211 | D10: 8(b) | E10: State diagram of a TM deciding {w−w | w ∈ {a,b}∗} | F10: Designing language-deciding TMs — Lecture 4 TM1, sl. 42–70 | G10: L12 | H10: 7 | I10: 23 | J10: ★★ Medium | K10: Design | L10: ✔ Solved | M10: 2016-17 6(c); 2015-16 7(a); 2013-14 2(a); 2012-13 3(b); 2010-11 11(b); 2009-10 12(a) | N10: FALSE
A11: 8 | B11: 2013-14 | C11: CSE 211 | D11: 2(a) | E11: TM recognizing {0^N 1^N 0^N | N ≥ 0} | F11: Designing language-deciding TMs — Lecture 4 TM1, sl. 42–70 | G11: L12 | H11: 7 | I11: 19 | J11: ★★ Medium | K11: Design | L11: ✔ Solved | M11: 2016-17 6(c); 2015-16 7(a); 2014-15 8(b); 2012-13 3(b); 2010-11 11(b); 2009-10 12(a) | N11: FALSE
A12: 9 | B12: 2012-13 | C12: CSE 211 | D12: 3(b) | E12: High-level description and state diagram of a TM deciding {w−w−w | w ∈ {a,b}∗} | F12: Designing language-deciding TMs — Lecture 4 TM1, sl. 42–70 | G12: L12 | H12: 7 | I12: 17 | J12: ★★ Medium | K12: Design | L12: ✔ Solved | M12: 2016-17 6(c); 2015-16 7(a); 2014-15 8(b); 2013-14 2(a); 2010-11 11(b); 2009-10 12(a) | N12: FALSE
A13: 10 | B13: 2010-11 | C13: CSE 211 | D13: 11(b) | E13: TM deciding {a^(2^n) b | n ≥ 0}: state diagram and configurations on aaaab | F13: Designing language-deciding TMs — Lecture 4 TM1, sl. 42–70 | G13: L12 | H13: 8.33 | I13: 12 | J13: ★★ Medium | K13: Trace | L13: ✔ Solved | M13: 2016-17 6(c); 2015-16 7(a); 2014-15 8(b); 2013-14 2(a); 2012-13 3(b); 2009-10 12(a) | N13: FALSE
A14: 11 | B14: 2009-10 | C14: CSE 211 | D14: 12(a) | E14: Formal TM definition; TM that scans right until it finds two consecutive a's, then halts (alphabet {a,b,⊔,▷}) | F14: Designing language-deciding TMs — Lecture 4 TM1, sl. 42–70 | G14: L12 | H14: 5 | I14: 10 | J14: ★★ Medium | K14: Design | L14: ✔ Solved | M14: 2016-17 6(c); 2015-16 7(a); 2014-15 8(b); 2013-14 2(a); 2012-13 3(b); 2010-11 11(b) | N14: FALSE
A15: 12 | B15: 2009-10 | C15: CSE 211 | D15: 12(b) | E15: TM deciding {a^n c^n b^n d^n : n ≥ 0} | F15: Designing language-deciding TMs — Lecture 4 TM1, sl. 42–70 | G15: L12 | H15: 7 | I15: 10 | J15: ★★ Medium | K15: Design | L15: ✔ Solved | M15: 2016-17 6(c); 2015-16 7(a); 2014-15 8(b); 2013-14 2(a); 2012-13 3(b); 2010-11 11(b) | N15: FALSE
... A22: 19 | B22: 2011-12 | C22: CSE 211 | D22: 3(a) | E22: TM on #w: if |w| even write #0^n, else #1^n | F22: TMs computing functions — Lecture 4 TM1, sl. 71–115 | G22: L13 | H22: 8.33 | I22: 14 | J22: ★★ Medium | K22: Design | L22: ✔ Solved | M22: 2012-13 3(c) | N22: FALSE

Sheet 4 TM Techniques
A1: Lecture 5 — Programming techniques and bit-manipulation TMs
A2: Note file: CSE211_Atif_TM_Techniques_Notes.docx · Solve after finishing the matching lesson. Filter Priority → ★★★ High first.
A3: Q No. | B3: Year | C3: Course | D3: Ques No. | E3: Short Question | F3: Topic (slide PDF · slides) | G3: Lesson | H3: Marks | I3: TF Page | J3: Priority | K3: Type | L3: In Notes | M3: Same Type Also In | N3: Done | O3: Confidence | P3: Date | Q3: My Notes
A4: 1 | B4: 2011-12 | C4: CSE 211 | D4: 1(b) | E4: Proof idea: every multi-track TM has an equivalent single-track TM | F4: Storage in the state, tracks, subroutines — Lecture 5 TM2, sl. 1–83, 132–133 | G4: L14 | H4: 7 | I4: 14 | J4: ★ Low | K4: Proof | L4: ✔ Solved | M4: — | N4: FALSE
A5: 2 | B5: 2023-24 | C5: CSE 211 | D5: 9 | E5: TM writing 0 after the second c if w1 = w2, else 1 (tape w1cw2c) | F5: Bit-manipulation TMs — Lecture 5 TM2, sl. 84–131 | G5: L15 | H5: 15 | I5: 22 batch p.3 | J5: ★★★ High | K5: Design | L5: ✔ Solved | M5: 2022-23 10; 2021-22 9; 2020 (Jan term) 9; 2019-20 9; 2017-18 9; 2008-09 3(b) | N5: FALSE
A6: 3 | B6: 2022-23 | C6: CSE 211 | D6: 10 | E6: TM inserting the NOT of w after the c (tape wc) | F6: Bit-manipulation TMs — Lecture 5 TM2, sl. 84–131 | G6: L15 | H6: 15 | I6: 52 | J6: ★★★ High | K6: Design | L6: ✔ Solved | M6: 2023-24 9; 2021-22 9; 2020 (Jan term) 9; 2019-20 9; 2017-18 9; 2008-09 3(b) | N6: FALSE
A7: 4 | B7: 2021-22 | C7: CSE 211 | D7: 9 | E7: TM converting a signed-magnitude binary number to 2's complement (MSB 1) | F7: Bit-manipulation TMs — Lecture 5 TM2, sl. 84–131 | G7: L15 | H7: 15 | I7: 48 | J7: ★★★ High | K7: Design | L7: ✔ Solved | M7: 2023-24 9; 2022-23 10; 2020 (Jan term) 9; 2019-20 9; 2017-18 9; 2008-09 3(b) | N7: FALSE
A8: 5 | B8: 2020 (Jan term) | C8: CSE 211 | D8: 9 | E8: TM computing XOR of w1cw2c (result after the second c) | F8: Bit-manipulation TMs — Lecture 5 TM2, sl. 84–131 | G8: L15 | H8: 15 | I8: 38 | J8: ★★★ High | K8: Design | L8: ✔ Solved | M8: 2023-24 9; 2022-23 10; 2021-22 9; 2019-20 9; 2017-18 9; 2008-09 3(b) | N8: FALSE
A9: 6 | B9: 2019-20 | C9: CSE 211 | D9: 9 | E9: TM computing AND of w1cw2c (result after the second c) | F9: Bit-manipulation TMs — Lecture 5 TM2, sl. 84–131 | G9: L15 | H9: 15 | I9: 42 | J9: ★★★ High | K9: Design | L9: ✔ Solved | M9: 2023-24 9; 2022-23 10; 2021-22 9; 2020 (Jan term) 9; 2017-18 9; 2008-09 3(b) | N9: FALSE
A10: 7 | B10: 2017-18 | C10: CSE 211 | D10: 9 | E10: TM computing bitwise OR of N1#N2# (result after the second #) | F10: Bit-manipulation TMs — Lecture 5 TM2, sl. 84–131 | G10: L15 | H10: 15 | I10: 34 | J10: ★★ Medium | K10: Design | L10: ✔ Solved | M10: 2023-24 9; 2022-23 10; 2021-22 9; 2020 (Jan term) 9; 2019-20 9; 2008-09 3(b) | N10: FALSE
A11: 8 | B11: 2008-09 | C11: CSE 211 | D11: 3(b) | E11: TM computing bitwise XOR of two equal-length strings (0010#1011 → 1001) | F11: Bit-manipulation TMs — Lecture 5 TM2, sl. 84–131 | G11: L15 | H11: 13 | I11: 6 | J11: ★★ Medium | K11: Design | L11: ✔ Solved | M11: 2023-24 9; 2022-23 10; 2021-22 9; 2020 (Jan term) 9; 2019-20 9; 2017-18 9 | N11: FALSE
A12: 9 | B12: 2008-09 | C12: CSE 211 | D12: 3(c) | E12: Simulate the TM of 3(b) on 1011#0010 | F12: Bit-manipulation TMs — Lecture 5 TM2, sl. 84–131 | G12: L15 | H12: 8 | I12: 6 | J12: ★★ Medium | K12: Trace | L12: ✔ Solved | M12: 2023-24 9; 2022-23 10; 2021-22 9; 2020 (Jan term) 9; 2019-20 9; 2017-18 9 | N12: FALSE
A13: 10 | B13: 2007-08 | C13: CSE 211 | D13: 8 | E13: TM adding two equal-length binary numbers separated by ','; only the sum remains | F13: Bit-manipulation TMs — Lecture 5 TM2, sl. 84–131 | G13: L15 | H13: 10 | I13: 5 | J13: ★★ Medium | K13: Design | L13: ✔ Solved | M13: 2016-17 5(b); 2009-10 12(c) | N13: FALSE
A14: 11 | B14: 2006-07 | C14: CSE 211 | D14: 11 | E14: TM computing XOR of two equal-length binary numbers separated by ',' — result replaces the second number | F14: Bit-manipulation TMs — Lecture 5 TM2, sl. 84–131 | G14: L15 | H14: 10 | I14: 3 | J14: ★★ Medium | K14: Design | L14: ✔ Solved | M14: 2023-24 9; 2022-23 10; 2021-22 9; 2020 (Jan term) 9; 2019-20 9; 2017-18 9 | N14: FALSE

Sheet 5 TM Variants
A1: Lecture 6 — Variants of Turing machines, TMs vs computers
A2: Note file: CSE211_Atif_TM_Variants_Notes.docx · Solve after finishing the matching lesson. Filter Priority → ★★★ High first.
A3: Q No. | B3: Year | C3: Course | D3: Ques No. | E3: Short Question | F3: Topic (slide PDF · slides) | G3: Lesson | H3: Marks | I3: TF Page | J3: Priority | K3: Type | L3: In Notes | M3: Same Type Also In | N3: Done | O3: Confidence | P3: Date | Q3: My Notes
A4: 1 | B4: 2023-24 | C4: CSE 211 | D4: 10 | E4: Multi-tape TM; how a one-tape TM with tracks and storage simulates it | F4: Multitape TMs and simulation — Lecture 6 TM3, sl. 1–22 | G4: L16 | H4: 15 | I4: 22 batch p.3 | J4: ★★★ High | K4: Theory | L4: ✔ Solved | M4: 2019-20 10(b); 2012-13 3(a) | N4: FALSE
A5: 2 | B5: 2019-20 | C5: CSE 211 | D5: 10(b) | E5: How a one-tape TM with tracks and storage in the state simulates a multitape TM | F5: Multitape TMs and simulation — Lecture 6 TM3, sl. 1–22 | G5: L16 | H5: 7 | I5: 42 | J5: ★★★ High | K5: Theory | L5: ✔ Solved | M5: 2023-24 10; 2012-13 3(a) | N5: FALSE
A6: 3 | B6: 2015-16 | C6: CSE 211 | D6: 8(b) | E6: How multiple tracks and multiple tapes extend the TM; difference | F6: Multitape TMs and simulation — Lecture 6 TM3, sl. 1–22 | G6: L16 | H6: 10.33 | I6: 27 | J6: ★ Low | K6: Theory | L6: ◐ Method | M6: — | N6: FALSE
A7: 4 | B7: 2012-13 | C7: CSE 211 | D7: 3(a) | E7: Every multitape TM has an equivalent single-tape TM | F7: Multitape TMs and simulation — Lecture 6 TM3, sl. 1–22 | G7: L16 | H7: 8 | I7: 17 | J7: ★★ Medium | K7: Proof | L7: ✔ Solved | M7: 2023-24 10; 2019-20 10(b) | N7: FALSE
A8: 5 | B8: 2011-12 | C8: CSE 211 | D8: 2(a) | E8: 2-tape TM deciding {wcw^R | w ∈ {a,b}∗} using both tapes | F8: Multitape TMs and simulation — Lecture 6 TM3, sl. 1–22 | G8: L16 | H8: 8.33 | I8: 14 | J8: ★ Low | K8: Design | L8: ◐ Method | M8: — | N8: FALSE
A9: 6 | B9: 2010-11 | C9: CSE 211 | D9: 11(a) | E9: Single-tape TMs simulating: multitape TM, single-tape NTM, TM with 2-D tape | F9: Multitape TMs and simulation — Lecture 6 TM3, sl. 1–22 | G9: L16 | H9: 15 | I9: 12 | J9: ★★ Medium | K9: Theory | L9: ◐ Method | M9: 2007-08 9; 2006-07 13 | N9: FALSE
A10: 7 | B10: 2009-10 | C10: CSE 211 | D10: 12(c) | E10: Three-tape TM subtracting two binary integers separated by ';' (first ≥ second) | F10: Multitape TMs and simulation — Lecture 6 TM3, sl. 1–22 | G10: L16 | H10: 11.33 | I10: 10 | J10: ★★ Medium | K10: Design | L10: ○ Partly | M10: 2016-17 5(b); 2007-08 8 | N10: FALSE
A11: 8 | B11: 2006-07 | C11: CSE 211 | D11: 13 | E11: Multitape and nondeterministic TMs: do they accept languages a basic TM cannot? | F11: Multitape TMs and simulation — Lecture 6 TM3, sl. 1–22 | G11: L16 | H11: 10 | I11: 3 | J11: ★★ Medium | K11: Theory | L11: ◐ Method | M11: 2010-11 11(a); 2007-08 9 | N11: FALSE
A12: 9 | B12: 2014-15 | C12: CSE 211 | D12: 7(c) | E12: A nondeterministic TM is equivalent to a deterministic TM | F12: NTMs and restricted TMs — Lecture 6 TM3, sl. 23–39 | G12: L17 | H12: 9.33 | I12: 23 | J12: ★★ Medium | K12: Proof | L12: ✔ Solved | M12: 2013-14 3(c); 2012-13 4(b) | N12: FALSE
A13: 10 | B13: 2013-14 | C13: CSE 211 | D13: 2(b) | E13: How can a TM recognize the left end of its tape? | F13: NTMs and restricted TMs — Lecture 6 TM3, sl. 23–39 | G13: L17 | H13: 7 | I13: 19 | J13: ★★ Medium | K13: Theory | L13: ✔ Solved | M13: 2011-12 2(b) | N13: FALSE
A14: 11 | B14: 2013-14 | C14: CSE 211 | D14: 3(c) | E14: Every NTM has an equivalent deterministic TM | F14: NTMs and restricted TMs — Lecture 6 TM3, sl. 23–39 | G14: L17 | H14: 9.33 | I14: 19 | J14: ★★ Medium | K14: Proof | L14: ✔ Solved | M14: 2014-15 7(c); 2012-13 4(b) | N14: FALSE
A15: 12 | B15: 2012-13 | C15: CSE 211 | D15: 4(b) | E15: Every NTM has an equivalent deterministic TM | F15: NTMs and restricted TMs — Lecture 6 TM3, sl. 23–39 | G15: L17 | H15: 7 | I15: 18 | J15: ★★ Medium | K15: Proof | L15: ✔ Solved | M15: 2014-15 7(c); 2013-14 3(c) | N15: FALSE
A16: 13 | B16: 2011-12 | C16: CSE 211 | D16: 2(b) | E16: A language is recognized by a two-way-infinite-tape TM iff by a one-way-infinite-tape TM | F16: NTMs and restricted TMs — Lecture 6 TM3, sl. 23–39 | G16: L17 | H16: 8 | I16: 14 | J16: ★★ Medium | K16: Proof | L16: ✔ Solved | M16: 2013-14 2(b) | N16: FALSE
... A20: 17 | B20: 2020 (Jan term) | C20: CSE 211 | D20: 10 | E20: T/F: multi-track + storage simulates multitape; DTM simulates n computer steps in p(n) | F20: TMs and computers — Lecture 6 TM3, sl. 40–68 | G20: L18 | H20: 15 | I20: 38 | J20: ★★★ High | K20: Theory | L20: ✔ Solved | M20: 2022-23 11; 2021-22 10; 2017-18 10 | N20: FALSE
A21: 18 | B21: 2017-18 | C21: CSE 211 | D21: 10 | E21: T/F: multi-track 1-tape TM simulates multitape; DTM simulates NTM in poly moves; DTM simulates computer in poly moves | F21: TMs and computers — Lecture 6 TM3, sl. 40–68 | G21: L18 | H21: 15 | I21: 34–35 | J21: ★★ Medium | K21: Theory | L21: ✔ Solved | M21: 2022-23 11; 2021-22 10; 2020 (Jan term) 10 | N21: FALSE
A22: 19 | B22: 2007-08 | C22: CSE 211 | D22: 10 | E22: How a Turing machine can simulate a computer | F22: TMs and computers — Lecture 6 TM3, sl. 40–68 | G22: L18 | H22: 10 | I22: 5 | J22: ★ Low | K22: Theory | L22: ◐ Method | M22: — | N22: FALSE

Sheet 6 Undecidability
A1: Lecture 7 — Decidability and undecidability
A2: Note file: CSE211_Atif_Undecidability_Notes.docx · Solve after finishing the matching lesson. Filter Priority → ★★★ High first.
A3: Q No. | B3: Year | C3: Course | D3: Ques No. | E3: Short Question | F3: Topic (slide PDF · slides) | G3: Lesson | H3: Marks | I3: TF Page | J3: Priority | K3: Type | L3: In Notes | M3: Same Type Also In | N3: Done | O3: Confidence | P3: Date | Q3: My Notes
A4: 1 | B4: 2016-17 | C4: CSE 211 | D4: 7(a) | E4: Is {<G> | G connected undirected graph} decidable? Design + example | F4: Recursive, RE, decidable languages — Lecture 7 Undecidability, sl. 2–13 | G4: L19 | H4: 15 | I4: 31 | J4: ★★ Medium | K4: Proof | L4: ✔ Solved | M4: 2013-14 3(b) | N4: FALSE
A5: 2 | B5: 2014-15 | C5: CSE 211 | D5: 8(a) | E5: Decidable, Turing-recognizable and undecidable languages | F5: Recursive, RE, decidable languages — Lecture 7 Undecidability, sl. 2–13 | G5: L19 | H5: 7 | I5: 23 | J5: ★★ Medium | K5: Theory | L5: ✔ Solved | M5: 2010-11 12(a) | N5: FALSE
A6: 3 | B6: 2013-14 | C6: CSE 211 | D6: 3(b) | E6: A = {s}, s = 0/1 depending on life on Mars: is A decidable? | F6: Recursive, RE, decidable languages — Lecture 7 Undecidability, sl. 2–13 | G6: L19 | H6: 7 | I6: 19 | J6: ★★ Medium | K6: Theory | L6: ✔ Solved | M6: 2016-17 7(a) | N6: FALSE
A7: 4 | B7: 2013-14 | C7: CSE 211 | D7: 4(a) | E7: Prove A_DFA = {<B,w> | B is a DFA accepting w} is decidable | F7: Recursive, RE, decidable languages — Lecture 7 Undecidability, sl. 2–13 | G7: L19 | H7: 7 | I7: 20 | J7: ★★ Medium | K7: Proof | L7: ✔ Solved | M7: 2011-12 4(c) | N7: FALSE
A8: 5 | B8: 2011-12 | C8: CSE 211 | D8: 4(c) | E8: Show {<A,B,C> | A,B,C DFAs and L(C) = L(A) ∪ L(B)} is decidable | F8: Recursive, RE, decidable languages — Lecture 7 Undecidability, sl. 2–13 | G8: L19 | H8: 8.33 | I8: 15 | J8: ★★ Medium | K8: Proof | L8: ✔ Solved | M8: 2013-14 4(a) | N8: FALSE
A9: 6 | B9: 2010-11 | C9: CSE 211 | D9: 12(a) | E9: Turing-decidable vs Turing-recognizable; the three conditions for M to recognize w | F9: Recursive, RE, decidable languages — Lecture 7 Undecidability, sl. 2–13 | G9: L19 | H9: 4 | I9: 13 | J9: ★★ Medium | K9: Theory | L9: ✔ Solved | M9: 2014-15 8(a) | N9: FALSE
A10: 7 | B10: 2009-10 | C10: CSE 211 | D10: 13(a) | E10: 'The operation of a TM may never stop' — agree? Example | F10: Recursive, RE, decidable languages — Lecture 7 Undecidability, sl. 2–13 | G10: L19 | H10: 4 | I10: 10 | J10: ★ Low | K10: Theory | L10: ✔ Solved | M10: — | N10: FALSE
A11: 8 | B11: 2022-23 | C11: CSE 211 | D11: 12 | E11: Diagonalization language; prove it is not RE | F11: Counting, TM codes, L_d — Lecture 7 Undecidability, sl. 14–51 | G11: L20 | H11: 15 | I11: 52 | J11: ★★★ High | K11: Proof | L11: ✔ Solved | M11: 2017-18 11; 2007-08 12; 2006-07 4(a) | N11: FALSE
A12: 9 | B12: 2017-18 | C12: CSE 211 | D12: 11 | E12: Define diagonalization language, universal language, halting problem; show one is not RE | F12: Counting, TM codes, L_d — Lecture 7 Undecidability, sl. 14–51 | G12: L20 | H12: 15 | I12: 35 | J12: ★★ Medium | K12: Proof | L12: ✔ Solved | M12: 2022-23 12; 2007-08 12; 2006-07 4(a) | N12: FALSE
A13: 10 | B13: 2014-15 | C13: CSE 211 | D13: 7(b) | E13: The set of infinite binary sequences is not countable | F13: Counting, TM codes, L_d — Lecture 7 Undecidability, sl. 14–51 | G13: L20 | H13: 7 | I13: 23 | J13: ★★ Medium | K13: Proof | L13: ✔ Solved | M13: 2013-14 4(b); 2010-11 10(a); 2010-11 10(b) | N13: FALSE
A14: 11 | B14: 2013-14 | C14: CSE 211 | D14: 4(b) | E14: Prove the set of rational numbers is countable | F14: Counting, TM codes, L_d — Lecture 7 Undecidability, sl. 14–51 | G14: L20 | H14: 7 | I14: 20 | J14: ★★ Medium | K14: Proof | L14: ✔ Solved | M14: 2014-15 7(b); 2010-11 10(a); 2010-11 10(b) | N14: FALSE
