Workbook

Sheet How to Use
B2: CSE 211 (Hakim Sir part) — TF Practice Tracker
B3: Every Hakim-part question in CSE 211 All Merged Questions.pdf (2023-24 rows: CSE 211 (22 batch).pdf), mapped to the note file and lesson that teaches it.
B5: Workflow — after you finish a note file
B6: 1. Open its tab | C6: Tabs 1–7 follow the order of your note files. Q No. runs lesson by lesson, newest year first inside each lesson.
B7: 2. Filter | C7: Use the filter arrow on Priority → ★★★ High first (2019-20 onward). Then ★★ Medium, then ★ Low.
B8: 3. Solve | C8: Open CSE 211 All Merged Questions.pdf (2023-24 rows: CSE 211 (22 batch).pdf) at the TF Page shown. Solve on paper under exam time (≈1.5 min per mark). Do not read the note solution first.
B9: 4. Check | C9: In Notes tells you what the note has: ✔ Solved = same question worked out; ◐ Method = method / model answer you can apply; ○ Partly = notes cover most of it, finish the rest yourself.
B10: 5. Record | C10: Tick Done, pick Confidence, add the Date. Write mistakes in My Notes. Re-solve every 'Weak' row before the exam.
B11: 6. Repeats | C11: 'Same Type Also In' lists other papers with the same question type. Solve one, then try a repeat cold — that is the real test.
B13: Columns you edit (all others are fixed data)
B14: Done (col N) | C14: TRUE / FALSE. In Google Sheets: select N4 downward → Insert → Checkbox. The values stay; ticking turns the row green.
B15: Confidence (col O) | C15: Dropdown: Weak / OK / Strong. Weak rows turn the cell red.
B16: Date (col P) | C16: Date you solved it, e.g. 16-Oct-2026.
B17: My Notes (col Q) | C17: Mistakes, missing steps, formula you forgot.
B19: Legend
B20: ★★★ High | C20: Asked in 2019-20 or later (most important — current question style).
B21: ★★ Medium | C21: Older paper, but the same question type appears at least twice in TF.
B22: ★ Low | C22: Older paper, asked once.
B23: Type | C23: Numerical = calculation · Trace = tables / step-by-step simulation · Design = construct / draw · Proof = prove / disprove · Theory = explain.
B24: Course | C24: Every paper in the collection carries the code CSE 211.
B25: Topic | C25: Note lesson title — slide PDF and slide numbers.

Sheet Dashboard
A1: Progress Dashboard
A2: Updates automatically when you tick Done / set Confidence in tabs 1–7.
A4: # | B4: Note file (tab) | C4: Questions | D4: Done | E4: % Done | F4: Marks (total) | G4: Marks done | H4: High-priority left | I4: Weak | J4: Next unsolved (top of tab)
A5: 1 | B5: 1 Intro + Languages | C5: =COUNTA('1 Intro + Languages'!$E$4:$E$9) | D5: =COUNTIF('1 Intro + Languages'!$N$4:$N$9,TRUE()) | E5: =IF(C5=0,0,D5/C5) | F5: =SUM('1 Intro + Languages'!$H$4:$H$9) | G5: =SUMIF('1 Intro + Languages'!$N$4:$N$9,TRUE(),'1 Intro + Languages'!$H$4:$H$9) | H5: =COUNTIFS('1 Intro + Languages'!$J$4:$J$9,"★★★ High",'1 Intro + Languages'!$N$4:$N$9,FALSE()) | I5: =COUNTIF('1 Intro + Languages'!$O$4:$O$9,"Weak") | J5: =IFERROR("Q"&INDEX('1 Intro + Languages'!$A$4:$A$9,MATCH(FALSE(),'1 Intro + Languages'!$N$4:$N$9,0))&" · "&INDEX('1 Intro + Languages'!$B$4:$B$9,MATCH(FALSE(),'1 Intro + Languages'!$N$4:$N$9,0))&" "&INDEX('1 Intro + Languages'!$D$4:$D$9,MATCH(FALSE(),'1 Intro + Languages'!$N$4:$N$9,0))&" · TF p."&INDEX('1 Intro + Languages'!$I$4:$I$9,MATCH(FALSE(),'1 Intro + Languages'!$N$4:$N$9,0)),"All done ✔")
A6: 2 | B6: 2 DFA | C6: =COUNTA('2 DFA'!$E$4:$E$41) | D6: =COUNTIF('2 DFA'!$N$4:$N$41,TRUE()) | E6: =IF(C6=0,0,D6/C6) | F6: =SUM('2 DFA'!$H$4:$H$41) | G6: =SUMIF('2 DFA'!$N$4:$N$41,TRUE(),'2 DFA'!$H$4:$H$41) | H6: =COUNTIFS('2 DFA'!$J$4:$J$41,"★★★ High",'2 DFA'!$N$4:$N$41,FALSE()) | I6: =COUNTIF('2 DFA'!$O$4:$O$41,"Weak") | J6: =IFERROR("Q"&INDEX('2 DFA'!$A$4:$A$41,MATCH(FALSE(),'2 DFA'!$N$4:$N$41,0))&" · "&INDEX('2 DFA'!$B$4:$B$41,MATCH(FALSE(),'2 DFA'!$N$4:$N$41,0))&" "&INDEX('2 DFA'!$D$4:$D$41,MATCH(FALSE(),'2 DFA'!$N$4:$N$41,0))&" · TF p."&INDEX('2 DFA'!$I$4:$I$41,MATCH(FALSE(),'2 DFA'!$N$4:$N$41,0)),"All done ✔")
A7: 3 | B7: 3 NFA | C7: =COUNTA('3 NFA'!$E$4:$E$37) | D7: =COUNTIF('3 NFA'!$N$4:$N$37,TRUE()) | E7: =IF(C7=0,0,D7/C7) | F7: =SUM('3 NFA'!$H$4:$H$37) | G7: =SUMIF('3 NFA'!$N$4:$N$37,TRUE(),'3 NFA'!$H$4:$H$37) | H7: =COUNTIFS('3 NFA'!$J$4:$J$37,"★★★ High",'3 NFA'!$N$4:$N$37,FALSE()) | I7: =COUNTIF('3 NFA'!$O$4:$O$37,"Weak") | J7: =IFERROR("Q"&INDEX('3 NFA'!$A$4:$A$37,MATCH(FALSE(),'3 NFA'!$N$4:$N$37,0))&" · "&INDEX('3 NFA'!$B$4:$B$37,MATCH(FALSE(),'3 NFA'!$N$4:$N$37,0))&" "&INDEX('3 NFA'!$D$4:$D$37,MATCH(FALSE(),'3 NFA'!$N$4:$N$37,0))&" · TF p."&INDEX('3 NFA'!$I$4:$I$37,MATCH(FALSE(),'3 NFA'!$N$4:$N$37,0)),"All done ✔")
A8: 4 | B8: 4 Regular Languages | C8: =COUNTA('4 Regular Languages'!$E$4:$E$54) | D8: =COUNTIF('4 Regular Languages'!$N$4:$N$54,TRUE()) | E8: =IF(C8=0,0,D8/C8) | F8: =SUM('4 Regular Languages'!$H$4:$H$54) | G8: =SUMIF('4 Regular Languages'!$N$4:$N$54,TRUE(),'4 Regular Languages'!$H$4:$H$54) | H8: =COUNTIFS('4 Regular Languages'!$J$4:$J$54,"★★★ High",'4 Regular Languages'!$N$4:$N$54,FALSE()) | I8: =COUNTIF('4 Regular Languages'!$O$4:$O$54,"Weak") | J8: =IFERROR("Q"&INDEX('4 Regular Languages'!$A$4:$A$54,MATCH(FALSE(),'4 Regular Languages'!$N$4:$N$54,0))&" · "&INDEX('4 Regular Languages'!$B$4:$B$54,MATCH(FALSE(),'4 Regular Languages'!$N$4:$N$54,0))&" "&INDEX('4 Regular Languages'!$D$4:$D$54,MATCH(FALSE(),'4 Regular Languages'!$N$4:$N$54,0))&" · TF p."&INDEX('4 Regular Languages'!$I$4:$I$54,MATCH(FALSE(),'4 Regular Languages'!$N$4:$N$54,0)),"All done ✔")
A9: 5 | B9: 5 Pumping Lemma | C9: =COUNTA('5 Pumping Lemma'!$E$4:$E$31) | D9: =COUNTIF('5 Pumping Lemma'!$N$4:$N$31,TRUE()) | E9: =IF(C9=0,0,D9/C9) | F9: =SUM('5 Pumping Lemma'!$H$4:$H$31) | G9: =SUMIF('5 Pumping Lemma'!$N$4:$N$31,TRUE(),'5 Pumping Lemma'!$H$4:$H$31) | H9: =COUNTIFS('5 Pumping Lemma'!$J$4:$J$31,"★★★ High",'5 Pumping Lemma'!$N$4:$N$31,FALSE()) | I9: =COUNTIF('5 Pumping Lemma'!$O$4:$O$31,"Weak") | J9: =IFERROR("Q"&INDEX('5 Pumping Lemma'!$A$4:$A$31,MATCH(FALSE(),'5 Pumping Lemma'!$N$4:$N$31,0))&" · "&INDEX('5 Pumping Lemma'!$B$4:$B$31,MATCH(FALSE(),'5 Pumping Lemma'!$N$4:$N$31,0))&" "&INDEX('5 Pumping Lemma'!$D$4:$D$31,MATCH(FALSE(),'5 Pumping Lemma'!$N$4:$N$31,0))&" · TF p."&INDEX('5 Pumping Lemma'!$I$4:$I$31,MATCH(FALSE(),'5 Pumping Lemma'!$N$4:$N$31,0)),"All done ✔")
A10: 6 | B10: 6 CFG | C10: =COUNTA('6 CFG'!$E$4:$E$51) | D10: =COUNTIF('6 CFG'!$N$4:$N$51,TRUE()) | E10: =IF(C10=0,0,D10/C10) | F10: =SUM('6 CFG'!$H$4:$H$51) | G10: =SUMIF('6 CFG'!$N$4:$N$51,TRUE(),'6 CFG'!$H$4:$H$51) | H10: =COUNTIFS('6 CFG'!$J$4:$J$51,"★★★ High",'6 CFG'!$N$4:$N$51,FALSE()) | I10: =COUNTIF('6 CFG'!$O$4:$O$51,"Weak") | J10: =IFERROR("Q"&INDEX('6 CFG'!$A$4:$A$51,MATCH(FALSE(),'6 CFG'!$N$4:$N$51,0))&" · "&INDEX('6 CFG'!$B$4:$B$51,MATCH(FALSE(),'6 CFG'!$N$4:$N$51,0))&" "&INDEX('6 CFG'!$D$4:$D$51,MATCH(FALSE(),'6 CFG'!$N$4:$N$51,0))&" · TF p."&INDEX('6 CFG'!$I$4:$I$51,MATCH(FALSE(),'6 CFG'!$N$4:$N$51,0)),"All done ✔")
A11: 7 | B11: 7 PDA (see Atif tracker) | C11: =COUNTA('7 PDA (see Atif tracker)'!$E$4:$E$4) | D11: =COUNTIF('7 PDA (see Atif tracker)'!$N$4:$N$4,TRUE()) | E11: =IF(C11=0,0,D11/C11) | F11: =SUM('7 PDA (see Atif tracker)'!$H$4:$H$4) | G11: =SUMIF('7 PDA (see Atif tracker)'!$N$4:$N$4,TRUE(),'7 PDA (see Atif tracker)'!$H$4:$H$4) | H11: =COUNTIFS('7 PDA (see Atif tracker)'!$J$4:$J$4,"★★★ High",'7 PDA (see Atif tracker)'!$N$4:$N$4,FALSE()) | I11: =COUNTIF('7 PDA (see Atif tracker)'!$O$4:$O$4,"Weak") | J11: =IFERROR("Q"&INDEX('7 PDA (see Atif tracker)'!$A$4:$A$4,MATCH(FALSE(),'7 PDA (see Atif tracker)'!$N$4:$N$4,0))&" · "&INDEX('7 PDA (see Atif tracker)'!$B$4:$B$4,MATCH(FALSE(),'7 PDA (see Atif tracker)'!$N$4:$N$4,0))&" "&INDEX('7 PDA (see Atif tracker)'!$D$4:$D$4,MATCH(FALSE(),'7 PDA (see Atif tracker)'!$N$4:$N$4,0))&" · TF p."&INDEX('7 PDA (see Atif tracker)'!$I$4:$I$4,MATCH(FALSE(),'7 PDA (see Atif tracker)'!$N$4:$N$4,0)),"All done ✔")
B12: TOTAL | C12: =SUM(C5:C11) | D12: =SUM(D5:D11) | E12: =IF(C12=0,0,D12/C12) | F12: =SUM(F5:F11) | G12: =SUM(G5:G11) | H12: =SUM(H5:H11) | I12: =SUM(I5:I11)
A14: Questions by year (tabs 1–7)
A15: # | B15: Year | C15: Questions | D15: Done | E15: % Done | F15: Marks (total)
A16: 1 | B16: 2023-24 | C16: =COUNTIF('1 Intro + Languages'!$B$4:$B$9,$B16)+COUNTIF('2 DFA'!$B$4:$B$41,$B16)+COUNTIF('3 NFA'!$B$4:$B$37,$B16)+COUNTIF('4 Regular Languages'!$B$4:$B$54,$B16)+COUNTIF('5 Pumping Lemma'!$B$4:$B$31,$B16)+COUNTIF('6 CFG'!$B$4:$B$51,$B16)+COUNTIF('7 PDA (see Atif tracker)'!$B$4:$B$4,$B16) | D16: =COUNTIFS('1 Intro + Languages'!$B$4:$B$9,$B16,'1 Intro + Languages'!$N$4:$N$9,TRUE())+COUNTIFS('2 DFA'!$B$4:$B$41,$B16,'2 DFA'!$N$4:$N$41,TRUE())+COUNTIFS('3 NFA'!$B$4:$B$37,$B16,'3 NFA'!$N$4:$N$37,TRUE())+COUNTIFS('4 Regular Languages'!$B$4:$B$54,$B16,'4 Regular Languages'!$N$4:$N$54,TRUE())+COUNTIFS('5 Pumping Lemma'!$B$4:$B$31,$B16,'5 Pumping Lemma'!$N$4:$N$31,TRUE())+COUNTIFS('6 CFG'!$B$4:$B$51,$B16,'6 CFG'!$N$4:$N$51,TRUE())+COUNTIFS('7 PDA (see Atif tracker)'!$B$4:$B$4,$B16,'7 PDA (see Atif tracker)'!$N$4:$N$4,TRUE()) | E16: =IF(C16=0,0,D16/C16) | F16: =SUMIF('1 Intro + Languages'!$B$4:$B$9,$B16,'1 Intro + Languages'!$H$4:$H$9)+SUMIF('2 DFA'!$B$4:$B$41,$B16,'2 DFA'!$H$4:$H$41)+SUMIF('3 NFA'!$B$4:$B$37,$B16,'3 NFA'!$H$4:$H$37)+SUMIF('4 Regular Languages'!$B$4:$B$54,$B16,'4 Regular Languages'!$H$4:$H$54)+SUMIF('5 Pumping Lemma'!$B$4:$B$31,$B16,'5 Pumping Lemma'!$H$4:$H$31)+SUMIF('6 CFG'!$B$4:$B$51,$B16,'6 CFG'!$H$4:$H$51)+SUMIF('7 PDA (see Atif tracker)'!$B$4:$B$4,$B16,'7 PDA (see Atif tracker)'!$H$4:$H$4)
A17: 2 | B17: 2022-23 | C17: =COUNTIF('1 Intro + Languages'!$B$4:$B$9,$B17)+COUNTIF('2 DFA'!$B$4:$B$41,$B17)+COUNTIF('3 NFA'!$B$4:$B$37,$B17)+COUNTIF('4 Regular Languages'!$B$4:$B$54,$B17)+COUNTIF('5 Pumping Lemma'!$B$4:$B$31,$B17)+COUNTIF('6 CFG'!$B$4:$B$51,$B17)+COUNTIF('7 PDA (see Atif tracker)'!$B$4:$B$4,$B17) | D17: =COUNTIFS('1 Intro + Languages'!$B$4:$B$9,$B17,'1 Intro + Languages'!$N$4:$N$9,TRUE())+COUNTIFS('2 DFA'!$B$4:$B$41,$B17,'2 DFA'!$N$4:$N$41,TRUE())+COUNTIFS('3 NFA'!$B$4:$B$37,$B17,'3 NFA'!$N$4:$N$37,TRUE())+COUNTIFS('4 Regular Languages'!$B$4:$B$54,$B17,'4 Regular Languages'!$N$4:$N$54,TRUE())+COUNTIFS('5 Pumping Lemma'!$B$4:$B$31,$B17,'5 Pumping Lemma'!$N$4:$N$31,TRUE())+COUNTIFS('6 CFG'!$B$4:$B$51,$B17,'6 CFG'!$N$4:$N$51,TRUE())+COUNTIFS('7 PDA (see Atif tracker)'!$B$4:$B$4,$B17,'7 PDA (see Atif tracker)'!$N$4:$N$4,TRUE()) | E17: =IF(C17=0,0,D17/C17) | F17: =SUMIF('1 Intro + Languages'!$B$4:$B$9,$B17,'1 Intro + Languages'!$H$4:$H$9)+SUMIF('2 DFA'!$B$4:$B$41,$B17,'2 DFA'!$H$4:$H$41)+SUMIF('3 NFA'!$B$4:$B$37,$B17,'3 NFA'!$H$4:$H$37)+SUMIF('4 Regular Languages'!$B$4:$B$54,$B17,'4 Regular Languages'!$H$4:$H$54)+SUMIF('5 Pumping Lemma'!$B$4:$B$31,$B17,'5 Pumping Lemma'!$H$4:$H$31)+SUMIF('6 CFG'!$B$4:$B$51,$B17,'6 CFG'!$H$4:$H$51)+SUMIF('7 PDA (see Atif tracker)'!$B$4:$B$4,$B17,'7 PDA (see Atif tracker)'!$H$4:$H$4)
A18: 3 | B18: 2021-22 | C18: =COUNTIF('1 Intro + Languages'!$B$4:$B$9,$B18)+COUNTIF('2 DFA'!$B$4:$B$41,$B18)+COUNTIF('3 NFA'!$B$4:$B$37,$B18)+COUNTIF('4 Regular Languages'!$B$4:$B$54,$B18)+COUNTIF('5 Pumping Lemma'!$B$4:$B$31,$B18)+COUNTIF('6 CFG'!$B$4:$B$51,$B18)+COUNTIF('7 PDA (see Atif tracker)'!$B$4:$B$4,$B18) | D18: =COUNTIFS('1 Intro + Languages'!$B$4:$B$9,$B18,'1 Intro + Languages'!$N$4:$N$9,TRUE())+COUNTIFS('2 DFA'!$B$4:$B$41,$B18,'2 DFA'!$N$4:$N$41,TRUE())+COUNTIFS('3 NFA'!$B$4:$B$37,$B18,'3 NFA'!$N$4:$N$37,TRUE())+COUNTIFS('4 Regular Languages'!$B$4:$B$54,$B18,'4 Regular Languages'!$N$4:$N$54,TRUE())+COUNTIFS('5 Pumping Lemma'!$B$4:$B$31,$B18,'5 Pumping Lemma'!$N$4:$N$31,TRUE())+COUNTIFS('6 CFG'!$B$4:$B$51,$B18,'6 CFG'!$N$4:$N$51,TRUE())+COUNTIFS('7 PDA (see Atif tracker)'!$B$4:$B$4,$B18,'7 PDA (see Atif tracker)'!$N$4:$N$4,TRUE()) | E18: =IF(C18=0,0,D18/C18) | F18: =SUMIF('1 Intro + Languages'!$B$4:$B$9,$B18,'1 Intro + Languages'!$H$4:$H$9)+SUMIF('2 DFA'!$B$4:$B$41,$B18,'2 DFA'!$H$4:$H$41)+SUMIF('3 NFA'!$B$4:$B$37,$B18,'3 NFA'!$H$4:$H$37)+SUMIF('4 Regular Languages'!$B$4:$B$54,$B18,'4 Regular Languages'!$H$4:$H$54)+SUMIF('5 Pumping Lemma'!$B$4:$B$31,$B18,'5 Pumping Lemma'!$H$4:$H$31)+SUMIF('6 CFG'!$B$4:$B$51,$B18,'6 CFG'!$H$4:$H$51)+SUMIF('7 PDA (see Atif tracker)'!$B$4:$B$4,$B18,'7 PDA (see Atif tracker)'!$H$4:$H$4)
A19: 4 | B19: 2020 (Jan term) | C19: =COUNTIF('1 Intro + Languages'!$B$4:$B$9,$B19)+COUNTIF('2 DFA'!$B$4:$B$41,$B19)+COUNTIF('3 NFA'!$B$4:$B$37,$B19)+COUNTIF('4 Regular Languages'!$B$4:$B$54,$B19)+COUNTIF('5 Pumping Lemma'!$B$4:$B$31,$B19)+COUNTIF('6 CFG'!$B$4:$B$51,$B19)+COUNTIF('7 PDA (see Atif tracker)'!$B$4:$B$4,$B19) | D19: =COUNTIFS('1 Intro + Languages'!$B$4:$B$9,$B19,'1 Intro + Languages'!$N$4:$N$9,TRUE())+COUNTIFS('2 DFA'!$B$4:$B$41,$B19,'2 DFA'!$N$4:$N$41,TRUE())+COUNTIFS('3 NFA'!$B$4:$B$37,$B19,'3 NFA'!$N$4:$N$37,TRUE())+COUNTIFS('4 Regular Languages'!$B$4:$B$54,$B19,'4 Regular Languages'!$N$4:$N$54,TRUE())+COUNTIFS('5 Pumping Lemma'!$B$4:$B$31,$B19,'5 Pumping Lemma'!$N$4:$N$31,TRUE())+COUNTIFS('6 CFG'!$B$4:$B$51,$B19,'6 CFG'!$N$4:$N$51,TRUE())+COUNTIFS('7 PDA (see Atif tracker)'!$B$4:$B$4,$B19,'7 PDA (see Atif tracker)'!$N$4:$N$4,TRUE()) | E19: =IF(C19=0,0,D19/C19) | F19: =SUMIF('1 Intro + Languages'!$B$4:$B$9,$B19,'1 Intro + Languages'!$H$4:$H$9)+SUMIF('2 DFA'!$B$4:$B$41,$B19,'2 DFA'!$H$4:$H$41)+SUMIF('3 NFA'!$B$4:$B$37,$B19,'3 NFA'!$H$4:$H$37)+SUMIF('4 Regular Languages'!$B$4:$B$54,$B19,'4 Regular Languages'!$H$4:$H$54)+SUMIF('5 Pumping Lemma'!$B$4:$B$31,$B19,'5 Pumping Lemma'!$H$4:$H$31)+SUMIF('6 CFG'!$B$4:$B$51,$B19,'6 CFG'!$H$4:$H$51)+SUMIF('7 PDA (see Atif tracker)'!$B$4:$B$4,$B19,'7 PDA (see Atif tracker)'!$H$4:$H$4)
A20: 5 | B20: 2019-20 | C20: =COUNTIF('1 Intro + Languages'!$B$4:$B$9,$B20)+COUNTIF('2 DFA'!$B$4:$B$41,$B20)+COUNTIF('3 NFA'!$B$4:$B$37,$B20)+COUNTIF('4 Regular Languages'!$B$4:$B$54,$B20)+COUNTIF('5 Pumping Lemma'!$B$4:$B$31,$B20)+COUNTIF('6 CFG'!$B$4:$B$51,$B20)+COUNTIF('7 PDA (see Atif tracker)'!$B$4:$B$4,$B20) | D20: =COUNTIFS('1 Intro + Languages'!$B$4:$B$9,$B20,'1 Intro + Languages'!$N$4:$N$9,TRUE())+COUNTIFS('2 DFA'!$B$4:$B$41,$B20,'2 DFA'!$N$4:$N$41,TRUE())+COUNTIFS('3 NFA'!$B$4:$B$37,$B20,'3 NFA'!$N$4:$N$37,TRUE())+COUNTIFS('4 Regular Languages'!$B$4:$B$54,$B20,'4 Regular Languages'!$N$4:$N$54,TRUE())+COUNTIFS('5 Pumping Lemma'!$B$4:$B$31,$B20,'5 Pumping Lemma'!$N$4:$N$31,TRUE())+COUNTIFS('6 CFG'!$B$4:$B$51,$B20,'6 CFG'!$N$4:$N$51,TRUE())+COUNTIFS('7 PDA (see Atif tracker)'!$B$4:$B$4,$B20,'7 PDA (see Atif tracker)'!$N$4:$N$4,TRUE()) | E20: =IF(C20=0,0,D20/C20) | F20: =SUMIF('1 Intro + Languages'!$B$4:$B$9,$B20,'1 Intro + Languages'!$H$4:$H$9)+SUMIF('2 DFA'!$B$4:$B$41,$B20,'2 DFA'!$H$4:$H$41)+SUMIF('3 NFA'!$B$4:$B$37,$B20,'3 NFA'!$H$4:$H$37)+SUMIF('4 Regular Languages'!$B$4:$B$54,$B20,'4 Regular Languages'!$H$4:$H$54)+SUMIF('5 Pumping Lemma'!$B$4:$B$31,$B20,'5 Pumping Lemma'!$H$4:$H$31)+SUMIF('6 CFG'!$B$4:$B$51,$B20,'6 CFG'!$H$4:$H$51)+SUMIF('7 PDA (see Atif tracker)'!$B$4:$B$4,$B20,'7 PDA (see Atif tracker)'!$H$4:$H$4)
A21: 6 | B21: 2017-18 | C21: =COUNTIF('1 Intro + Languages'!$B$4:$B$9,$B21)+COUNTIF('2 DFA'!$B$4:$B$41,$B21)+COUNTIF('3 NFA'!$B$4:$B$37,$B21)+COUNTIF('4 Regular Languages'!$B$4:$B$54,$B21)+COUNTIF('5 Pumping Lemma'!$B$4:$B$31,$B21)+COUNTIF('6 CFG'!$B$4:$B$51,$B21)+COUNTIF('7 PDA (see Atif tracker)'!$B$4:$B$4,$B21) | D21: =COUNTIFS('1 Intro + Languages'!$B$4:$B$9,$B21,'1 Intro + Languages'!$N$4:$N$9,TRUE())+COUNTIFS('2 DFA'!$B$4:$B$41,$B21,'2 DFA'!$N$4:$N$41,TRUE())+COUNTIFS('3 NFA'!$B$4:$B$37,$B21,'3 NFA'!$N$4:$N$37,TRUE())+COUNTIFS('4 Regular Languages'!$B$4:$B$54,$B21,'4 Regular Languages'!$N$4:$N$54,TRUE())+COUNTIFS('5 Pumping Lemma'!$B$4:$B$31,$B21,'5 Pumping Lemma'!$N$4:$N$31,TRUE())+COUNTIFS('6 CFG'!$B$4:$B$51,$B21,'6 CFG'!$N$4:$N$51,TRUE())+COUNTIFS('7 PDA (see Atif tracker)'!$B$4:$B$4,$B21,'7 PDA (see Atif tracker)'!$N$4:$N$4,TRUE()) | E21: =IF(C21=0,0,D21/C21) | F21: =SUMIF('1 Intro + Languages'!$B$4:$B$9,$B21,'1 Intro + Languages'!$H$4:$H$9)+SUMIF('2 DFA'!$B$4:$B$41,$B21,'2 DFA'!$H$4:$H$41)+SUMIF('3 NFA'!$B$4:$B$37,$B21,'3 NFA'!$H$4:$H$37)+SUMIF('4 Regular Languages'!$B$4:$B$54,$B21,'4 Regular Languages'!$H$4:$H$54)+SUMIF('5 Pumping Lemma'!$B$4:$B$31,$B21,'5 Pumping Lemma'!$H$4:$H$31)+SUMIF('6 CFG'!$B$4:$B$51,$B21,'6 CFG'!$H$4:$H$51)+SUMIF('7 PDA (see Atif tracker)'!$B$4:$B$4,$B21,'7 PDA (see Atif tracker)'!$H$4:$H$4)
A22: 7 | B22: 2016-17 | C22: =COUNTIF('1 Intro + Languages'!$B$4:$B$9,$B22)+COUNTIF('2 DFA'!$B$4:$B$41,$B22)+COUNTIF('3 NFA'!$B$4:$B$37,$B22)+COUNTIF('4 Regular Languages'!$B$4:$B$54,$B22)+COUNTIF('5 Pumping Lemma'!$B$4:$B$31,$B22)+COUNTIF('6 CFG'!$B$4:$B$51,$B22)+COUNTIF('7 PDA (see Atif tracker)'!$B$4:$B$4,$B22) | D22: =COUNTIFS('1 Intro + Languages'!$B$4:$B$9,$B22,'1 Intro + Languages'!$N$4:$N$9,TRUE())+COUNTIFS('2 DFA'!$B$4:$B$41,$B22,'2 DFA'!$N$4:$N$41,TRUE())+COUNTIFS('3 NFA'!$B$4:$B$37,$B22,'3 NFA'!$N$4:$N$37,TRUE())+COUNTIFS('4 Regular Languages'!$B$4:$B$54,$B22,'4 Regular Languages'!$N$4:$N$54,TRUE())+COUNTIFS('5 Pumping Lemma'!$B$4:$B$31,$B22,'5 Pumping Lemma'!$N$4:$N$31,TRUE())+COUNTIFS('6 CFG'!$B$4:$B$51,$B22,'6 CFG'!$N$4:$N$51,TRUE())+COUNTIFS('7 PDA (see Atif tracker)'!$B$4:$B$4,$B22,'7 PDA (see Atif tracker)'!$N$4:$N$4,TRUE()) | E22: =IF(C22=0,0,D22/C22) | F22: =SUMIF('1 Intro + Languages'!$B$4:$B$9,$B22,'1 Intro + Languages'!$H$4:$H$9)+SUMIF('2 DFA'!$B$4:$B$41,$B22,'2 DFA'!$H$4:$H$41)+SUMIF('3 NFA'!$B$4:$B$37,$B22,'3 NFA'!$H$4:$H$37)+SUMIF('4 Regular Languages'!$B$4:$B$54,$B22,'4 Regular Languages'!$H$4:$H$54)+SUMIF('5 Pumping Lemma'!$B$4:$B$31,$B22,'5 Pumping Lemma'!$H$4:$H$31)+SUMIF('6 CFG'!$B$4:$B$51,$B22,'6 CFG'!$H$4:$H$51)+SUMIF('7 PDA (see Atif tracker)'!$B$4:$B$4,$B22,'7 PDA (see Atif tracker)'!$H$4:$H$4)
A23: 8 | B23: 2015-16 | C23: =COUNTIF('1 Intro + Languages'!$B$4:$B$9,$B23)+COUNTIF('2 DFA'!$B$4:$B$41,$B23)+COUNTIF('3 NFA'!$B$4:$B$37,$B23)+COUNTIF('4 Regular Languages'!$B$4:$B$54,$B23)+COUNTIF('5 Pumping Lemma'!$B$4:$B$31,$B23)+COUNTIF('6 CFG'!$B$4:$B$51,$B23)+COUNTIF('7 PDA (see Atif tracker)'!$B$4:$B$4,$B23) | D23: =COUNTIFS('1 Intro + Languages'!$B$4:$B$9,$B23,'1 Intro + Languages'!$N$4:$N$9,TRUE())+COUNTIFS('2 DFA'!$B$4:$B$41,$B23,'2 DFA'!$N$4:$N$41,TRUE())+COUNTIFS('3 NFA'!$B$4:$B$37,$B23,'3 NFA'!$N$4:$N$37,TRUE())+COUNTIFS('4 Regular Languages'!$B$4:$B$54,$B23,'4 Regular Languages'!$N$4:$N$54,TRUE())+COUNTIFS('5 Pumping Lemma'!$B$4:$B$31,$B23,'5 Pumping Lemma'!$N$4:$N$31,TRUE())+COUNTIFS('6 CFG'!$B$4:$B$51,$B23,'6 CFG'!$N$4:$N$51,TRUE())+COUNTIFS('7 PDA (see Atif tracker)'!$B$4:$B$4,$B23,'7 PDA (see Atif tracker)'!$N$4:$N$4,TRUE()) | E23: =IF(C23=0,0,D23/C23) | F23: =SUMIF('1 Intro + Languages'!$B$4:$B$9,$B23,'1 Intro + Languages'!$H$4:$H$9)+SUMIF('2 DFA'!$B$4:$B$41,$B23,'2 DFA'!$H$4:$H$41)+SUMIF('3 NFA'!$B$4:$B$37,$B23,'3 NFA'!$H$4:$H$37)+SUMIF('4 Regular Languages'!$B$4:$B$54,$B23,'4 Regular Languages'!$H$4:$H$54)+SUMIF('5 Pumping Lemma'!$B$4:$B$31,$B23,'5 Pumping Lemma'!$H$4:$H$31)+SUMIF('6 CFG'!$B$4:$B$51,$B23,'6 CFG'!$H$4:$H$51)+SUMIF('7 PDA (see Atif tracker)'!$B$4:$B$4,$B23,'7 PDA (see Atif tracker)'!$H$4:$H$4)
A24: 9 | B24: 2014-15 | C24: =COUNTIF('1 Intro + Languages'!$B$4:$B$9,$B24)+COUNTIF('2 DFA'!$B$4:$B$41,$B24)+COUNTIF('3 NFA'!$B$4:$B$37,$B24)+COUNTIF('4 Regular Languages'!$B$4:$B$54,$B24)+COUNTIF('5 Pumping Lemma'!$B$4:$B$31,$B24)+COUNTIF('6 CFG'!$B$4:$B$51,$B24)+COUNTIF('7 PDA (see Atif tracker)'!$B$4:$B$4,$B24) | D24: =COUNTIFS('1 Intro + Languages'!$B$4:$B$9,$B24,'1 Intro + Languages'!$N$4:$N$9,TRUE())+COUNTIFS('2 DFA'!$B$4:$B$41,$B24,'2 DFA'!$N$4:$N$41,TRUE())+COUNTIFS('3 NFA'!$B$4:$B$37,$B24,'3 NFA'!$N$4:$N$37,TRUE())+COUNTIFS('4 Regular Languages'!$B$4:$B$54,$B24,'4 Regular Languages'!$N$4:$N$54,TRUE())+COUNTIFS('5 Pumping Lemma'!$B$4:$B$31,$B24,'5 Pumping Lemma'!$N$4:$N$31,TRUE())+COUNTIFS('6 CFG'!$B$4:$B$51,$B24,'6 CFG'!$N$4:$N$51,TRUE())+COUNTIFS('7 PDA (see Atif tracker)'!$B$4:$B$4,$B24,'7 PDA (see Atif tracker)'!$N$4:$N$4,TRUE()) | E24: =IF(C24=0,0,D24/C24) | F24: =SUMIF('1 Intro + Languages'!$B$4:$B$9,$B24,'1 Intro + Languages'!$H$4:$H$9)+SUMIF('2 DFA'!$B$4:$B$41,$B24,'2 DFA'!$H$4:$H$41)+SUMIF('3 NFA'!$B$4:$B$37,$B24,'3 NFA'!$H$4:$H$37)+SUMIF('4 Regular Languages'!$B$4:$B$54,$B24,'4 Regular Languages'!$H$4:$H$54)+SUMIF('5 Pumping Lemma'!$B$4:$B$31,$B24,'5 Pumping Lemma'!$H$4:$H$31)+SUMIF('6 CFG'!$B$4:$B$51,$B24,'6 CFG'!$H$4:$H$51)+SUMIF('7 PDA (see Atif tracker)'!$B$4:$B$4,$B24,'7 PDA (see Atif tracker)'!$H$4:$H$4)
A25: 10 | B25: 2013-14 | C25: =COUNTIF('1 Intro + Languages'!$B$4:$B$9,$B25)+COUNTIF('2 DFA'!$B$4:$B$41,$B25)+COUNTIF('3 NFA'!$B$4:$B$37,$B25)+COUNTIF('4 Regular Languages'!$B$4:$B$54,$B25)+COUNTIF('5 Pumping Lemma'!$B$4:$B$31,$B25)+COUNTIF('6 CFG'!$B$4:$B$51,$B25)+COUNTIF('7 PDA (see Atif tracker)'!$B$4:$B$4,$B25) | D25: =COUNTIFS('1 Intro + Languages'!$B$4:$B$9,$B25,'1 Intro + Languages'!$N$4:$N$9,TRUE())+COUNTIFS('2 DFA'!$B$4:$B$41,$B25,'2 DFA'!$N$4:$N$41,TRUE())+COUNTIFS('3 NFA'!$B$4:$B$37,$B25,'3 NFA'!$N$4:$N$37,TRUE())+COUNTIFS('4 Regular Languages'!$B$4:$B$54,$B25,'4 Regular Languages'!$N$4:$N$54,TRUE())+COUNTIFS('5 Pumping Lemma'!$B$4:$B$31,$B25,'5 Pumping Lemma'!$N$4:$N$31,TRUE())+COUNTIFS('6 CFG'!$B$4:$B$51,$B25,'6 CFG'!$N$4:$N$51,TRUE())+COUNTIFS('7 PDA (see Atif tracker)'!$B$4:$B$4,$B25,'7 PDA (see Atif tracker)'!$N$4:$N$4,TRUE()) | E25: =IF(C25=0,0,D25/C25) | F25: =SUMIF('1 Intro + Languages'!$B$4:$B$9,$B25,'1 Intro + Languages'!$H$4:$H$9)+SUMIF('2 DFA'!$B$4:$B$41,$B25,'2 DFA'!$H$4:$H$41)+SUMIF('3 NFA'!$B$4:$B$37,$B25,'3 NFA'!$H$4:$H$37)+SUMIF('4 Regular Languages'!$B$4:$B$54,$B25,'4 Regular Languages'!$H$4:$H$54)+SUMIF('5 Pumping Lemma'!$B$4:$B$31,$B25,'5 Pumping Lemma'!$H$4:$H$31)+SUMIF('6 CFG'!$B$4:$B$51,$B25,'6 CFG'!$H$4:$H$51)+SUMIF('7 PDA (see Atif tracker)'!$B$4:$B$4,$B25,'7 PDA (see Atif tracker)'!$H$4:$H$4)
A26: 11 | B26: 2012-13 | C26: =COUNTIF('1 Intro + Languages'!$B$4:$B$9,$B26)+COUNTIF('2 DFA'!$B$4:$B$41,$B26)+COUNTIF('3 NFA'!$B$4:$B$37,$B26)+COUNTIF('4 Regular Languages'!$B$4:$B$54,$B26)+COUNTIF('5 Pumping Lemma'!$B$4:$B$31,$B26)+COUNTIF('6 CFG'!$B$4:$B$51,$B26)+COUNTIF('7 PDA (see Atif tracker)'!$B$4:$B$4,$B26) | D26: =COUNTIFS('1 Intro + Languages'!$B$4:$B$9,$B26,'1 Intro + Languages'!$N$4:$N$9,TRUE())+COUNTIFS('2 DFA'!$B$4:$B$41,$B26,'2 DFA'!$N$4:$N$41,TRUE())+COUNTIFS('3 NFA'!$B$4:$B$37,$B26,'3 NFA'!$N$4:$N$37,TRUE())+COUNTIFS('4 Regular Languages'!$B$4:$B$54,$B26,'4 Regular Languages'!$N$4:$N$54,TRUE())+COUNTIFS('5 Pumping Lemma'!$B$4:$B$31,$B26,'5 Pumping Lemma'!$N$4:$N$31,TRUE())+COUNTIFS('6 CFG'!$B$4:$B$51,$B26,'6 CFG'!$N$4:$N$51,TRUE())+COUNTIFS('7 PDA (see Atif tracker)'!$B$4:$B$4,$B26,'7 PDA (see Atif tracker)'!$N$4:$N$4,TRUE()) | E26: =IF(C26=0,0,D26/C26) | F26: =SUMIF('1 Intro + Languages'!$B$4:$B$9,$B26,'1 Intro + Languages'!$H$4:$H$9)+SUMIF('2 DFA'!$B$4:$B$41,$B26,'2 DFA'!$H$4:$H$41)+SUMIF('3 NFA'!$B$4:$B$37,$B26,'3 NFA'!$H$4:$H$37)+SUMIF('4 Regular Languages'!$B$4:$B$54,$B26,'4 Regular Languages'!$H$4:$H$54)+SUMIF('5 Pumping Lemma'!$B$4:$B$31,$B26,'5 Pumping Lemma'!$H$4:$H$31)+SUMIF('6 CFG'!$B$4:$B$51,$B26,'6 CFG'!$H$4:$H$51)+SUMIF('7 PDA (see Atif tracker)'!$B$4:$B$4,$B26,'7 PDA (see Atif tracker)'!$H$4:$H$4)
A27: 12 | B27: 2011-12 | C27: =COUNTIF('1 Intro + Languages'!$B$4:$B$9,$B27)+COUNTIF('2 DFA'!$B$4:$B$41,$B27)+COUNTIF('3 NFA'!$B$4:$B$37,$B27)+COUNTIF('4 Regular Languages'!$B$4:$B$54,$B27)+COUNTIF('5 Pumping Lemma'!$B$4:$B$31,$B27)+COUNTIF('6 CFG'!$B$4:$B$51,$B27)+COUNTIF('7 PDA (see Atif tracker)'!$B$4:$B$4,$B27) | D27: =COUNTIFS('1 Intro + Languages'!$B$4:$B$9,$B27,'1 Intro + Languages'!$N$4:$N$9,TRUE())+COUNTIFS('2 DFA'!$B$4:$B$41,$B27,'2 DFA'!$N$4:$N$41,TRUE())+COUNTIFS('3 NFA'!$B$4:$B$37,$B27,'3 NFA'!$N$4:$N$37,TRUE())+COUNTIFS('4 Regular Languages'!$B$4:$B$54,$B27,'4 Regular Languages'!$N$4:$N$54,TRUE())+COUNTIFS('5 Pumping Lemma'!$B$4:$B$31,$B27,'5 Pumping Lemma'!$N$4:$N$31,TRUE())+COUNTIFS('6 CFG'!$B$4:$B$51,$B27,'6 CFG'!$N$4:$N$51,TRUE())+COUNTIFS('7 PDA (see Atif tracker)'!$B$4:$B$4,$B27,'7 PDA (see Atif tracker)'!$N$4:$N$4,TRUE()) | E27: =IF(C27=0,0,D27/C27) | F27: =SUMIF('1 Intro + Languages'!$B$4:$B$9,$B27,'1 Intro + Languages'!$H$4:$H$9)+SUMIF('2 DFA'!$B$4:$B$41,$B27,'2 DFA'!$H$4:$H$41)+SUMIF('3 NFA'!$B$4:$B$37,$B27,'3 NFA'!$H$4:$H$37)+SUMIF('4 Regular Languages'!$B$4:$B$54,$B27,'4 Regular Languages'!$H$4:$H$54)+SUMIF('5 Pumping Lemma'!$B$4:$B$31,$B27,'5 Pumping Lemma'!$H$4:$H$31)+SUMIF('6 CFG'!$B$4:$B$51,$B27,'6 CFG'!$H$4:$H$51)+SUMIF('7 PDA (see Atif tracker)'!$B$4:$B$4,$B27,'7 PDA (see Atif tracker)'!$H$4:$H$4)
... A32: 17 | B32: 2006-07 | C32: =COUNTIF('1 Intro + Languages'!$B$4:$B$9,$B32)+COUNTIF('2 DFA'!$B$4:$B$41,$B32)+COUNTIF('3 NFA'!$B$4:$B$37,$B32)+COUNTIF('4 Regular Languages'!$B$4:$B$54,$B32)+COUNTIF('5 Pumping Lemma'!$B$4:$B$31,$B32)+COUNTIF('6 CFG'!$B$4:$B$51,$B32)+COUNTIF('7 PDA (see Atif tracker)'!$B$4:$B$4,$B32) | D32: =COUNTIFS('1 Intro + Languages'!$B$4:$B$9,$B32,'1 Intro + Languages'!$N$4:$N$9,TRUE())+COUNTIFS('2 DFA'!$B$4:$B$41,$B32,'2 DFA'!$N$4:$N$41,TRUE())+COUNTIFS('3 NFA'!$B$4:$B$37,$B32,'3 NFA'!$N$4:$N$37,TRUE())+COUNTIFS('4 Regular Languages'!$B$4:$B$54,$B32,'4 Regular Languages'!$N$4:$N$54,TRUE())+COUNTIFS('5 Pumping Lemma'!$B$4:$B$31,$B32,'5 Pumping Lemma'!$N$4:$N$31,TRUE())+COUNTIFS('6 CFG'!$B$4:$B$51,$B32,'6 CFG'!$N$4:$N$51,TRUE())+COUNTIFS('7 PDA (see Atif tracker)'!$B$4:$B$4,$B32,'7 PDA (see Atif tracker)'!$N$4:$N$4,TRUE()) | E32: =IF(C32=0,0,D32/C32) | F32: =SUMIF('1 Intro + Languages'!$B$4:$B$9,$B32,'1 Intro + Languages'!$H$4:$H$9)+SUMIF('2 DFA'!$B$4:$B$41,$B32,'2 DFA'!$H$4:$H$41)+SUMIF('3 NFA'!$B$4:$B$37,$B32,'3 NFA'!$H$4:$H$37)+SUMIF('4 Regular Languages'!$B$4:$B$54,$B32,'4 Regular Languages'!$H$4:$H$54)+SUMIF('5 Pumping Lemma'!$B$4:$B$31,$B32,'5 Pumping Lemma'!$H$4:$H$31)+SUMIF('6 CFG'!$B$4:$B$51,$B32,'6 CFG'!$H$4:$H$51)+SUMIF('7 PDA (see Atif tracker)'!$B$4:$B$4,$B32,'7 PDA (see Atif tracker)'!$H$4:$H$4)
B33: Shaded years = ★★★ High priority (2019-20 onward).
B34: Papers 2006-07 … 2023-24 (17 papers). The 2023-24 paper is not inside the merged PDF; its rows say '22 batch p.N' (CSE 211 (22 batch).pdf, 4 scanned pages).
B35: The paper printed 'January 2020 Term' (held 16/01/2021) is listed as '2020 (Jan term)' and counted as ★★★ High (it is newer than 2019-20); the 2019-20 paper (held 2021-22) is ★★★ too.
B36: Questions were assigned to a teacher by topic, not by section letter (older papers put the PDA/TM side in Section A).
B37: PDA questions are taught by both teachers; every PDA question sat in the Turing-machine section of its paper, so they are tracked in the Atif tracker (tab 2). Tab 7 of this workbook is intentionally empty — its note is the PDA design workshop. CFL pumping-lemma questions follow the same rule (2013-14 Q7(c) is here; later ones are Atif's).
B38: 2013-14 Q5(b): the mark is not printed on the paper (5 by the section total) — left blank.

Sheet 1 Intro + Languages
A1: Lec01–02 — Introduction & Languages
A2: Note file: CSE211_Hakim_Intro_Languages_Notes.docx · Solve after finishing the matching lesson. Filter Priority → ★★★ High first.
A3: Q No. | B3: Year | C3: Course | D3: Ques No. | E3: Short Question | F3: Topic (slide PDF · slides) | G3: Lesson | H3: Marks | I3: TF Page | J3: Priority | K3: Type | L3: In Notes | M3: Same Type Also In | N3: Done | O3: Confidence | P3: Date | Q3: My Notes
A4: 1 | B4: 2023-24 | C4: CSE 211 | D4: 1(a) | E4: Options when a problem appears computationally hard | F4: Why Theory of Computation? — Lec01 Introduction, sl. 2–53 | G4: L1 | H4: 8 | I4: 22 batch p.1 | J4: ★★★ High | K4: Theory | L4: ◐ Method | M4: 2022-23 1(a); 2021-22 1(a); 2019-20 1(b) | N4: FALSE
A5: 2 | B5: 2022-23 | C5: CSE 211 | D5: 1(a) | E5: Public and private keys in asymmetric cryptography; the role of ToC | F5: Why Theory of Computation? — Lec01 Introduction, sl. 2–53 | G5: L1 | H5: 10 | I5: 49 | J5: ★★★ High | K5: Theory | L5: ◐ Method | M5: 2023-24 1(a); 2021-22 1(a); 2019-20 1(b) | N5: FALSE
A6: 3 | B6: 2021-22 | C6: CSE 211 | D6: 1(a) | E6: Password-protected login: which central area of ToC applies? | F6: Why Theory of Computation? — Lec01 Introduction, sl. 2–53 | G6: L1 | H6: 4 | I6: 44 | J6: ★★★ High | K6: Theory | L6: ◐ Method | M6: 2023-24 1(a); 2022-23 1(a); 2019-20 1(b) | N6: FALSE
A7: 4 | B7: 2019-20 | C7: CSE 211 | D7: 1(b) | E7: A scenario that specifically needs computationally hard problems | F7: Why Theory of Computation? — Lec01 Introduction, sl. 2–53 | G7: L1 | H7: 15 | I7: 40 | J7: ★★★ High | K7: Theory | L7: ◐ Method | M7: 2023-24 1(a); 2022-23 1(a); 2021-22 1(a) | N7: FALSE
A8: 5 | B8: 2007-08 | C8: CSE 211 | D8: 1(c) | E8: How set-formers are used to define a language | F8: Alphabets, strings, languages, problems — Lec02 Languages, sl. 2–52 | G8: L2 | H8: 5.33 | I8: 4 | J8: ★ Low | K8: Theory | L8: ✔ Solved | M8: — | N8: FALSE
A9: 6 | B9: 2006-07 | C9: CSE 211 | D9: 1(c) | E9: φ and ε as languages over any alphabet — explain; are they equivalent? | F9: Alphabets, strings, languages, problems — Lec02 Languages, sl. 2–52 | G9: L2 | H9: 5.33 | I9: 1 | J9: ★ Low | K9: Theory | L9: ✔ Solved | M9: — | N9: FALSE

Sheet 2 DFA
A1: Lec03 — Deterministic Finite Automata
A2: Note file: CSE211_Hakim_DFA_Notes.docx · Solve after finishing the matching lesson. Filter Priority → ★★★ High first.
A3: Q No. | B3: Year | C3: Course | D3: Ques No. | E3: Short Question | F3: Topic (slide PDF · slides) | G3: Lesson | H3: Marks | I3: TF Page | J3: Priority | K3: Type | L3: In Notes | M3: Same Type Also In | N3: Done | O3: Confidence | P3: Date | Q3: My Notes
A4: 1 | B4: 2023-24 | C4: CSE 211 | D4: 2(c) | E4: Do accepting states affect the rows/columns of a DFA transition table? | F4: The DFA as a mathematical object — Lec03 DFA, sl. 2–20 | G4: L3 | H4: 5 | I4: 22 batch p.1 | J4: ★★★ High | K4: Theory | L4: ✔ Solved | M4: 2015-16 1(a) | N4: FALSE
A5: 2 | B5: 2019-20 | C5: CSE 211 | D5: 2(a) | E5: Role of a state in a finite automaton | F5: The DFA as a mathematical object — Lec03 DFA, sl. 2–20 | G5: L3 | H5: 5 | I5: 40 | J5: ★★★ High | K5: Theory | L5: ✔ Solved | M5: 2007-08 2(c) | N5: FALSE
A6: 3 | B6: 2015-16 | C6: CSE 211 | D6: 1(a) | E6: Formally define an FSM; formal description of F1 (Figure 1.a) | F6: The DFA as a mathematical object — Lec03 DFA, sl. 2–20 | G6: L3 | H6: 8.33 | I6: 24 | J6: ★★ Medium | K6: Theory | L6: ✔ Solved | M6: 2023-24 2(c) | N6: FALSE
A7: 4 | B7: 2007-08 | C7: CSE 211 | D7: 2(c) | E7: Most important role of states in an automaton; can it have infinite capacity? | F7: The DFA as a mathematical object — Lec03 DFA, sl. 2–20 | G7: L3 | H7: 5.33 | I7: 4 | J7: ★★ Medium | K7: Theory | L7: ✔ Solved | M7: 2019-20 2(a) | N7: FALSE
A8: 5 | B8: 2023-24 | C8: CSE 211 | D8: 2(b) | E8: Show {awa | w ∈ {a,b}∗} is regular with a DFA | F8: Designing DFAs — Lec03 DFA, sl. 21–29 | G8: L4 | H8: 15 | I8: 22 batch p.1 | J8: ★★★ High | K8: Design | L8: ✔ Solved | M8: 2022-23 1(c); 2021-22 1(b); 2011-12 5(c); 2010-11 4; 2009-10 2; 2007-08 1(b) | N8: FALSE
A9: 6 | B9: 2022-23 | C9: CSE 211 | D9: 1(c) | E9: DFA over {a,b} with neither aa nor bb; transition table | F9: Designing DFAs — Lec03 DFA, sl. 21–29 | G9: L4 | H9: 13 | I9: 49 | J9: ★★★ High | K9: Design | L9: ✔ Solved | M9: 2023-24 2(b); 2021-22 1(b); 2011-12 5(c); 2010-11 4; 2009-10 2; 2007-08 1(b) | N9: FALSE
A10: 7 | B10: 2021-22 | C10: CSE 211 | D10: 1(b) | E10: DFA (≤ 5 states) over {a,b}: begins with a, no substring aab | F10: Designing DFAs — Lec03 DFA, sl. 21–29 | G10: L4 | H10: 10 | I10: 44 | J10: ★★★ High | K10: Design | L10: ✔ Solved | M10: 2023-24 2(b); 2022-23 1(c); 2011-12 5(c); 2010-11 4; 2009-10 2; 2007-08 1(b) | N10: FALSE
A11: 8 | B11: 2019-20 | C11: CSE 211 | D11: 2(c) | E11: DFA for base-3 numbers not divisible by 4 | F11: Designing DFAs — Lec03 DFA, sl. 21–29 | G11: L4 | H11: 15 | I11: 40 | J11: ★★★ High | K11: Design | L11: ✔ Solved | M11: 2017-18 2(b); 2015-16 2(a); 2014-15 2(b); 2012-13 7(c); 2010-11 2; 2008-09 6(a) | N11: FALSE
A12: 9 | B12: 2017-18 | C12: CSE 211 | D12: 2(b) | E12: DFAs: binary starting with 1 that is a multiple of 5; a power of 2 | F12: Designing DFAs — Lec03 DFA, sl. 21–29 | G12: L4 | H12: 17 | I12: 32 | J12: ★★ Medium | K12: Design | L12: ✔ Solved | M12: 2019-20 2(c); 2015-16 2(a); 2014-15 2(b); 2012-13 7(c); 2010-11 2; 2008-09 6(a) | N12: FALSE
A13: 10 | B13: 2015-16 | C13: CSE 211 | D13: 2(a) | E13: DFA for binary numbers NOT divisible by 3, with intuition | F13: Designing DFAs — Lec03 DFA, sl. 21–29 | G13: L4 | H13: 8.33 | I13: 25 | J13: ★★ Medium | K13: Design | L13: ✔ Solved | M13: 2019-20 2(c); 2017-18 2(b); 2014-15 2(b); 2012-13 7(c); 2010-11 2; 2008-09 6(a) | N13: FALSE
A14: 11 | B14: 2014-15 | C14: CSE 211 | D14: 2(b) | E14: DFA for binary numbers divisible by 4; explain | F14: Designing DFAs — Lec03 DFA, sl. 21–29 | G14: L4 | H14: 13.33 | I14: 22 | J14: ★★ Medium | K14: Design | L14: ✔ Solved | M14: 2019-20 2(c); 2017-18 2(b); 2015-16 2(a); 2012-13 7(c); 2010-11 2; 2008-09 6(a) | N14: FALSE
A15: 12 | B15: 2012-13 | C15: CSE 211 | D15: 7(c) | E15: DFA for binary strings whose value is a multiple of 5 | F15: Designing DFAs — Lec03 DFA, sl. 21–29 | G15: L4 | H15: 8 | I15: 18 | J15: ★★ Medium | K15: Design | L15: ✔ Solved | M15: 2019-20 2(c); 2017-18 2(b); 2015-16 2(a); 2014-15 2(b); 2010-11 2; 2008-09 6(a) | N15: FALSE
A16: 13 | B16: 2011-12 | C16: CSE 211 | D16: 5(c) | E16: DFA for {w | |w| ≤ 5} over {0,1} | F16: Designing DFAs — Lec03 DFA, sl. 21–29 | G16: L4 | H16: 5.33 | I16: 15 | J16: ★★ Medium | K16: Design | L16: ✔ Solved | M16: 2023-24 2(b); 2022-23 1(c); 2021-22 1(b); 2010-11 4; 2009-10 2; 2007-08 1(b) | N16: FALSE
A17: 14 | B17: 2010-11 | C17: CSE 211 | D17: 2 | E17: DFA over {a,b} with (#a) mod 3 = 1; diagram and formal description | F17: Designing DFAs — Lec03 DFA, sl. 21–29 | G17: L4 | H17: 10 | I17: 11 | J17: ★★ Medium | K17: Design | L17: ✔ Solved | M17: 2019-20 2(c); 2017-18 2(b); 2015-16 2(a); 2014-15 2(b); 2012-13 7(c); 2008-09 6(a) | N17: FALSE
A18: 15 | B18: 2010-11 | C18: CSE 211 | D18: 4 | E18: DFA for strings over {0,1} not containing 110; regular expression | F18: Designing DFAs — Lec03 DFA, sl. 21–29 | G18: L4 | H18: 10 | I18: 11 | J18: ★★ Medium | K18: Design | L18: ✔ Solved | M18: 2023-24 2(b); 2022-23 1(c); 2021-22 1(b); 2011-12 5(c); 2009-10 2; 2007-08 1(b) | N18: FALSE
A19: 16 | B19: 2009-10 | C19: CSE 211 | D19: 2 | E19: DFA over {a,b}: the first symbol never occurs three times consecutively (abaab, baaabba accepted; abaaab, bbbaa rejected) | F19: Designing DFAs — Lec03 DFA, sl. 21–29 | G19: L4 | H19: 10 | I19: 8 | J19: ★★ Medium | K19: Design | L19: ✔ Solved | M19: 2023-24 2(b); 2022-23 1(c); 2021-22 1(b); 2011-12 5(c); 2010-11 4; 2007-08 1(b) | N19: FALSE
A20: 17 | B20: 2008-09 | C20: CSE 211 | D20: 6(a) | E20: DFA for binary strings whose value is a multiple of 3 | F20: Designing DFAs — Lec03 DFA, sl. 21–29 | G20: L4 | H20: 9 | I20: 7 | J20: ★★ Medium | K20: Design | L20: ✔ Solved | M20: 2019-20 2(c); 2017-18 2(b); 2015-16 2(a); 2014-15 2(b); 2012-13 7(c); 2010-11 2 | N20: FALSE
... A22: 19 | B22: 2006-07 | C22: CSE 211 | D22: 1(a) | E22: DFA: strings starting with 0 of odd length or starting with 1 of even length; diagram + table | F22: Designing DFAs — Lec03 DFA, sl. 21–29 | G22: L4 | H22: 10 | I22: 1 | J22: ★★ Medium | K22: Design | L22: ✔ Solved | M22: 2023-24 2(b); 2022-23 1(c); 2021-22 1(b); 2011-12 5(c); 2010-11 4; 2009-10 2 | N22: FALSE
A23: 20 | B23: 2023-24 | C23: CSE 211 | D23: 1(b) | E23: DFA over {a,b}: at most two runs of a's of length exactly three | F23: Advanced DFAs and reading DFAs — Lec03 DFA, sl. 30–42 | G23: L5 | H23: 17 | I23: 22 batch p.1 | J23: ★★★ High | K23: Design | L23: ✔ Solved | M23: 2022-23 3(a) | N23: FALSE
A24: 21 | B24: 2022-23 | C24: CSE 211 | D24: 1(b) | E24: Sum mod 3 with reset R: can a 2-state DFA (remainder 0 / non-zero) work? | F24: Advanced DFAs and reading DFAs — Lec03 DFA, sl. 30–42 | G24: L5 | H24: 12 | I24: 49 | J24: ★★★ High | K24: Theory | L24: ✔ Solved | M24: 2019-20 1(c); 2014-15 1(a); 2014-15 1(b) | N24: FALSE
A25: 22 | B25: 2022-23 | C25: CSE 211 | D25: 2(a) | E25: Describe the languages of five given finite automata (i–v) | F25: Advanced DFAs and reading DFAs — Lec03 DFA, sl. 30–42 | G25: L5 | H25: 20 | I25: 49–50 | J25: ★★★ High | K25: Theory | L25: ✔ Solved | M25: 2020 (Jan term) 2(a); 2015-16 1(b); 2015-16 1(c); 2015-16 1(d); 2015-16 1(e) | N25: FALSE
A26: 23 | B26: 2022-23 | C26: CSE 211 | D26: 3(a) | E26: DFA: no run of 0s of even length ≥ 2; design idea | F26: Advanced DFAs and reading DFAs — Lec03 DFA, sl. 30–42 | G26: L5 | H26: 15 | I26: 51 | J26: ★★★ High | K26: Design | L26: ✔ Solved | M26: 2023-24 1(b) | N26: FALSE
A27: 24 | B27: 2020 (Jan term) | C27: CSE 211 | D27: 2(a) | E27: State informally the language of the 5-state DFA (q0…q4) | F27: Advanced DFAs and reading DFAs — Lec03 DFA, sl. 30–42 | G27: L5 | H27: 7 | I27: 36 | J27: ★★★ High | K27: Theory | L27: ✔ Solved | M27: 2022-23 2(a); 2015-16 1(b); 2015-16 1(c); 2015-16 1(d); 2015-16 1(e) | N27: FALSE
A28: 25 | B28: 2019-20 | C28: CSE 211 | D28: 1(c) | E28: DFA over {0,1,2,R}: running sum, reset on R, accept if sum ≡ 1 or 2 (mod 5) | F28: Advanced DFAs and reading DFAs — Lec03 DFA, sl. 30–42 | G28: L5 | H28: 15 | I28: 40 | J28: ★★★ High | K28: Design | L28: ✔ Solved | M28: 2022-23 1(b); 2014-15 1(a); 2014-15 1(b) | N28: FALSE
A29: 26 | B29: 2016-17 | C29: CSE 211 | D29: 1(a) | E29: Xustaeter (3 colours of stones), 3 stones: state diagram; must-fail, can't-fail, might-fail states | F29: Advanced DFAs and reading DFAs — Lec03 DFA, sl. 30–42 | G29: L5 | H29: 5 | I29: 28 | J29: ★★ Medium | K29: Design | L29: ✔ Solved | M29: 2016-17 1(b); 2016-17 1(c); 2016-17 1(d) | N29: FALSE
A30: 27 | B30: 2016-17 | C30: CSE 211 | D30: 1(b) | E30: Xustaeter with 4 stones: state diagram and state classes | F30: Advanced DFAs and reading DFAs — Lec03 DFA, sl. 30–42 | G30: L5 | H30: 10 | I30: 28 | J30: ★★ Medium | K30: Design | L30: ✔ Solved | M30: 2016-17 1(a); 2016-17 1(c); 2016-17 1(d) | N30: FALSE
A31: 28 | B31: 2016-17 | C31: CSE 211 | D31: 1(c) | E31: Symmetries in the diagrams → reduced state-diagram scheme | F31: Advanced DFAs and reading DFAs — Lec03 DFA, sl. 30–42 | G31: L5 | H31: 6 | I31: 28 | J31: ★★ Medium | K31: Design | L31: ✔ Solved | M31: 2016-17 1(a); 2016-17 1(b); 2016-17 1(d) | N31: FALSE
A32: 29 | B32: 2016-17 | C32: CSE 211 | D32: 1(d) | E32: Reduced diagram for 6 stones; classify states | F32: Advanced DFAs and reading DFAs — Lec03 DFA, sl. 30–42 | G32: L5 | H32: 14 | I32: 28 | J32: ★★ Medium | K32: Design | L32: ✔ Solved | M32: 2016-17 1(a); 2016-17 1(b); 2016-17 1(c) | N32: FALSE
A33: 30 | B33: 2016-17 | C33: CSE 211 | D33: 2(a) | E33: DFA over {a,b,1,2}: #a divisible by 3 and even digit sum | F33: Advanced DFAs and reading DFAs — Lec03 DFA, sl. 30–42 | G33: L5 | H33: 17 | I33: 28 | J33: ★★ Medium | K33: Design | L33: ✔ Solved | M33: 2013-14 5(c); 2006-07 2(b) | N33: FALSE
A34: 31 | B34: 2015-16 | C34: CSE 211 | D34: 1(b) | E34: What language does F1 recognize? | F34: Advanced DFAs and reading DFAs — Lec03 DFA, sl. 30–42 | G34: L5 | H34: 4 | I34: 24 | J34: ★★ Medium | K34: Theory | L34: ✔ Solved | M34: 2022-23 2(a); 2020 (Jan term) 2(a); 2015-16 1(c); 2015-16 1(d); 2015-16 1(e) | N34: FALSE
A35: 32 | B35: 2015-16 | C35: CSE 211 | D35: 1(c) | E35: F2 = F1 plus δ(d,1) = d: language? | F35: Advanced DFAs and reading DFAs — Lec03 DFA, sl. 30–42 | G35: L5 | H35: 4 | I35: 24 | J35: ★★ Medium | K35: Theory | L35: ✔ Solved | M35: 2022-23 2(a); 2020 (Jan term) 2(a); 2015-16 1(b); 2015-16 1(d); 2015-16 1(e) | N35: FALSE
A36: 33 | B36: 2015-16 | C36: CSE 211 | D36: 1(d) | E36: Change F1 (same #states, #transitions) so that |L(F3)| = |L(F1)| + 1 — possible? | F36: Advanced DFAs and reading DFAs — Lec03 DFA, sl. 30–42 | G36: L5 | H36: 4 | I36: 24 | J36: ★★ Medium | K36: Theory | L36: ✔ Solved | M36: 2022-23 2(a); 2020 (Jan term) 2(a); 2015-16 1(b); 2015-16 1(c); 2015-16 1(e) | N36: FALSE
A37: 34 | B37: 2015-16 | C37: CSE 211 | D37: 1(e) | E37: |L(R1)| = 5 but the DFA accepts 1000 random strings — is the DFA wrong? | F37: Advanced DFAs and reading DFAs — Lec03 DFA, sl. 30–42 | G37: L5 | H37: 3 | I37: 24 | J37: ★★ Medium | K37: Theory | L37: ✔ Solved | M37: 2022-23 2(a); 2020 (Jan term) 2(a); 2015-16 1(b); 2015-16 1(c); 2015-16 1(d) | N37: FALSE
... A41: 38 | B41: 2006-07 | C41: CSE 211 | D41: 2(b) | E41: DFA for even number of 0s and odd number of 1s; verify with δ̂(q0, 11010) | F41: Advanced DFAs and reading DFAs — Lec03 DFA, sl. 30–42 | G41: L5 | H41: 8 | I41: 1 | J41: ★★ Medium | K41: Design | L41: ✔ Solved | M41: 2016-17 2(a); 2013-14 5(c) | N41: FALSE

Sheet 3 NFA
A1: Lec04 — Nondeterminism and NFAs
A2: Note file: CSE211_Hakim_NFA_Notes.docx · Solve after finishing the matching lesson. Filter Priority → ★★★ High first.
A3: Q No. | B3: Year | C3: Course | D3: Ques No. | E3: Short Question | F3: Topic (slide PDF · slides) | G3: Lesson | H3: Marks | I3: TF Page | J3: Priority | K3: Type | L3: In Notes | M3: Same Type Also In | N3: Done | O3: Confidence | P3: Date | Q3: My Notes
A4: 1 | B4: 2012-13 | C4: CSE 211 | D4: 8(a) | E4: Three differences between DFA and NFA with examples | F4: Nondeterminism and the NFA — Lec04 NFA, sl. 2–49 | G4: L6 | H4: 5 | I4: 18 | J4: ★★ Medium | K4: Theory | L4: ✔ Solved | M4: 2011-12 5(a); 2008-09 5(c) | N4: FALSE
A5: 2 | B5: 2011-12 | C5: CSE 211 | D5: 5(a) | E5: Three differences between DFA and NFA with examples | F5: Nondeterminism and the NFA — Lec04 NFA, sl. 2–49 | G5: L6 | H5: 6 | I5: 15 | J5: ★★ Medium | K5: Theory | L5: ✔ Solved | M5: 2012-13 8(a); 2008-09 5(c) | N5: FALSE
A6: 3 | B6: 2008-09 | C6: CSE 211 | D6: 5(c) | E6: Define a DFA and an NFA | F6: Nondeterminism and the NFA — Lec04 NFA, sl. 2–49 | G6: L6 | H6: 5.33 | I6: 7 | J6: ★★ Medium | K6: Theory | L6: ✔ Solved | M6: 2012-13 8(a); 2011-12 5(a) | N6: FALSE
A7: 4 | B7: 2006-07 | C7: CSE 211 | D7: 2(c) | E7: 'Nondeterministic computation is a tree of possibilities' — elaborate with example | F7: Nondeterminism and the NFA — Lec04 NFA, sl. 2–49 | G7: L6 | H7: 5.33 | I7: 1 | J7: ★ Low | K7: Theory | L7: ✔ Solved | M7: — | N7: FALSE
A8: 5 | B8: 2023-24 | C8: CSE 211 | D8: 3(a) | E8: 3-state NFA for {a^n | n ≥ 1} ∪ {b^m a^k | m, k ≥ 0}; can fewer states work? | F8: Designing NFAs — Lec04 NFA, sl. 50–70 | G8: L7 | H8: 15 | I8: 22 batch p.2 | J8: ★★★ High | K8: Design | L8: ✔ Solved | M8: 2023-24 4(a); 2022-23 4(b); 2021-22 3(b); 2020 (Jan term) 2(b); 2019-20 3(b); 2017-18 3(a) | N8: FALSE
A9: 6 | B9: 2023-24 | C9: CSE 211 | D9: 4(a) | E9: NFA for {a}∗ such that removing one edge leaves an NFA for {a} | F9: Designing NFAs — Lec04 NFA, sl. 50–70 | G9: L7 | H9: 10 | I9: 22 batch p.2 | J9: ★★★ High | K9: Design | L9: ✔ Solved | M9: 2023-24 3(a); 2022-23 4(b); 2021-22 3(b); 2020 (Jan term) 2(b); 2019-20 3(b); 2017-18 3(a) | N9: FALSE
A10: 7 | B10: 2022-23 | C10: CSE 211 | D10: 4(b) | E10: NFA: binary strings that begin and end with different symbols and have odd length | F10: Designing NFAs — Lec04 NFA, sl. 50–70 | G10: L7 | H10: 15 | I10: 51 | J10: ★★★ High | K10: Design | L10: ✔ Solved | M10: 2023-24 3(a); 2023-24 4(a); 2021-22 3(b); 2020 (Jan term) 2(b); 2019-20 3(b); 2017-18 3(a) | N10: FALSE
A11: 8 | B11: 2021-22 | C11: CSE 211 | D11: 3(b) | E11: NFA: binary strings with at least two 0s or exactly two 1s | F11: Designing NFAs — Lec04 NFA, sl. 50–70 | G11: L7 | H11: 10 | I11: 45 | J11: ★★★ High | K11: Design | L11: ✔ Solved | M11: 2023-24 3(a); 2023-24 4(a); 2022-23 4(b); 2020 (Jan term) 2(b); 2019-20 3(b); 2017-18 3(a) | N11: FALSE
A12: 9 | B12: 2020 (Jan term) | C12: CSE 211 | D12: 2(b) | E12: Equivalent NFA for the language of 2(a) | F12: Designing NFAs — Lec04 NFA, sl. 50–70 | G12: L7 | H12: 13 | I12: 36 | J12: ★★★ High | K12: Design | L12: ✔ Solved | M12: 2023-24 3(a); 2023-24 4(a); 2022-23 4(b); 2021-22 3(b); 2019-20 3(b); 2017-18 3(a) | N12: FALSE
A13: 10 | B13: 2019-20 | C13: CSE 211 | D13: 3(b) | E13: Minimal NFA for {a^n b^n | n ≤ 3} | F13: Designing NFAs — Lec04 NFA, sl. 50–70 | G13: L7 | H13: 15 | I13: 40 | J13: ★★★ High | K13: Design | L13: ✔ Solved | M13: 2023-24 3(a); 2023-24 4(a); 2022-23 4(b); 2021-22 3(b); 2020 (Jan term) 2(b); 2017-18 3(a) | N13: FALSE
A14: 11 | B14: 2017-18 | C14: CSE 211 | D14: 3(a) | E14: NFA: two 0s with a nonzero multiple-of-4 number of characters between; diagram + table | F14: Designing NFAs — Lec04 NFA, sl. 50–70 | G14: L7 | H14: 18 | I14: 32 | J14: ★★ Medium | K14: Design | L14: ✔ Solved | M14: 2023-24 3(a); 2023-24 4(a); 2022-23 4(b); 2021-22 3(b); 2020 (Jan term) 2(b); 2019-20 3(b) | N14: FALSE
A15: 12 | B15: 2016-17 | C15: CSE 211 | D15: 3(a) | E15: NFAs: final digit appeared before; final digit not appeared before; two 0s separated by a multiple of 4 positions | F15: Designing NFAs — Lec04 NFA, sl. 50–70 | G15: L7 | H15: 20 | I15: 29 | J15: ★★ Medium | K15: Design | L15: ✔ Solved | M15: 2023-24 3(a); 2023-24 4(a); 2022-23 4(b); 2021-22 3(b); 2020 (Jan term) 2(b); 2019-20 3(b) | N15: FALSE
A16: 13 | B16: 2014-15 | C16: CSE 211 | D16: 3(a) | E16: NFA: nonzero length strings with a nonzero even number of a's at the end | F16: Designing NFAs — Lec04 NFA, sl. 50–70 | G16: L7 | H16: 13.33 | I16: 22 | J16: ★★ Medium | K16: Design | L16: ✔ Solved | M16: 2023-24 3(a); 2023-24 4(a); 2022-23 4(b); 2021-22 3(b); 2020 (Jan term) 2(b); 2019-20 3(b) | N16: FALSE
A17: 14 | B17: 2013-14 | C17: CSE 211 | D17: 7(a) | E17: Eliminate all ε-transitions from the given NFA (q0…q4) | F17: ε-transitions and removing them — Lec04 NFA, sl. 71–90 | G17: L8 | H17: 9 | I17: 20 | J17: ★ Low | K17: Trace | L17: ✔ Solved | M17: — | N17: FALSE
A18: 15 | B18: 2021-22 | C18: CSE 211 | D18: 2(a) | E18: Why is DFA/NFA equivalence surprising and useful? | F18: NFA → DFA: subset construction — Lec04 NFA, sl. 91–109 | G18: L9 | H18: 4 | I18: 45 | J18: ★★★ High | K18: Theory | L18: ✔ Solved | M18: 2009-10 1; 2007-08 3(c) | N18: FALSE
A19: 16 | B19: 2021-22 | C19: CSE 211 | D19: 3(c) | E19: Convert the ε-NFA (q1, q2, q3 table) to a DFA | F19: NFA → DFA: subset construction — Lec04 NFA, sl. 91–109 | G19: L9 | H19: 9 | I19: 45–46 | J19: ★★★ High | K19: Trace | L19: ✔ Solved | M19: 2020 (Jan term) 1(c); 2020 (Jan term) 4(b); 2017-18 4(a); 2016-17 2(b); 2009-10 3; 2008-09 6(c) | N19: FALSE
A20: 17 | B20: 2020 (Jan term) | C20: CSE 211 | D20: 1(c) | E20: ε-NFA (p, q, r table): general forms of accepted strings of length ≤ 3 | F20: NFA → DFA: subset construction — Lec04 NFA, sl. 91–109 | G20: L9 | H20: 12 | I20: 36 | J20: ★★★ High | K20: Trace | L20: ✔ Solved | M20: 2021-22 3(c); 2020 (Jan term) 4(b); 2017-18 4(a); 2016-17 2(b); 2009-10 3; 2008-09 6(c) | N20: FALSE
A21: 18 | B21: 2020 (Jan term) | C21: CSE 211 | D21: 4(b) | E21: Convert the ε-NFA (q0…q10 figure) to a DFA, showing computations | F21: NFA → DFA: subset construction — Lec04 NFA, sl. 91–109 | G21: L9 | H21: 20 | I21: 37 | J21: ★★★ High | K21: Trace | L21: ✔ Solved | M21: 2021-22 3(c); 2020 (Jan term) 1(c); 2017-18 4(a); 2016-17 2(b); 2009-10 3; 2008-09 6(c) | N21: FALSE
A22: 19 | B22: 2019-20 | C22: CSE 211 | D22: 4(a) | E22: NFA with 5 states → DFA: minimum and maximum number of states | F22: NFA → DFA: subset construction — Lec04 NFA, sl. 91–109 | G22: L9 | H22: 5 | I22: 41 | J22: ★★★ High | K22: Theory | L22: ✔ Solved | M22: 2008-09 6(b) | N22: FALSE
A23: 20 | B23: 2017-18 | C23: CSE 211 | D23: 4(a) | E23: ε-NFA (p, q, r table): strings of length ≤ 3 accepted; convert to DFA | F23: NFA → DFA: subset construction — Lec04 NFA, sl. 91–109 | G23: L9 | H23: 15 | I23: 33 | J23: ★★ Medium | K23: Trace | L23: ✔ Solved | M23: 2021-22 3(c); 2020 (Jan term) 1(c); 2020 (Jan term) 4(b); 2016-17 2(b); 2009-10 3; 2008-09 6(c) | N23: FALSE
A24: 21 | B24: 2016-17 | C24: CSE 211 | D24: 2(b) | E24: Convert the ε-NFA (p, q, r, s figure) to a DFA | F24: NFA → DFA: subset construction — Lec04 NFA, sl. 91–109 | G24: L9 | H24: 8 | I24: 29 | J24: ★★ Medium | K24: Trace | L24: ✔ Solved | M24: 2021-22 3(c); 2020 (Jan term) 1(c); 2020 (Jan term) 4(b); 2017-18 4(a); 2009-10 3; 2008-09 6(c) | N24: FALSE
A25: 22 | B25: 2014-15 | C25: CSE 211 | D25: 4(a) | E25: NFA for an even number of occurrences of 01; convert to DFA (reachable part) | F25: NFA → DFA: subset construction — Lec04 NFA, sl. 91–109 | G25: L9 | H25: 11.33 | I25: 22 | J25: ★★ Medium | K25: Trace | L25: ✔ Solved | M25: 2011-12 7(b); 2010-11 3 | N25: FALSE
A26: 23 | B26: 2013-14 | C26: CSE 211 | D26: 8(b) | E26: Prove every NFA has an equivalent DFA | F26: NFA → DFA: subset construction — Lec04 NFA, sl. 91–109 | G26: L9 | H26: 10.33 | I26: 21 | J26: ★★ Medium | K26: Proof | L26: ✔ Solved | M26: 2010-11 1; 2007-08 2(a); 2006-07 2(a) | N26: FALSE
A27: 24 | B27: 2011-12 | C27: CSE 211 | D27: 7(b) | E27: Convert the NFA of 7(a) to a DFA (reachable states only) | F27: NFA → DFA: subset construction — Lec04 NFA, sl. 91–109 | G27: L9 | H27: 8 | I27: 16 | J27: ★★ Medium | K27: Trace | L27: ✔ Solved | M27: 2014-15 4(a); 2010-11 3 | N27: FALSE
A28: 25 | B28: 2010-11 | C28: CSE 211 | D28: 1 | E28: Will the DFA built from an NFA by subset construction accept the same language? Justify | F28: NFA → DFA: subset construction — Lec04 NFA, sl. 91–109 | G28: L9 | H28: 10 | I28: 11 | J28: ★★ Medium | K28: Proof | L28: ✔ Solved | M28: 2013-14 8(b); 2007-08 2(a); 2006-07 2(a) | N28: FALSE
A29: 26 | B29: 2010-11 | C29: CSE 211 | D29: 3 | E29: Convert the NFA (p,q,r,s∗,t∗ table) to a DFA using lazy evaluation | F29: NFA → DFA: subset construction — Lec04 NFA, sl. 91–109 | G29: L9 | H29: 10 | I29: 11 | J29: ★★ Medium | K29: Trace | L29: ✔ Solved | M29: 2014-15 4(a); 2011-12 7(b) | N29: FALSE
A30: 27 | B30: 2009-10 | C30: CSE 211 | D30: 1 | E30: 'Nondeterminism is an inessential feature of finite automata' — explain | F30: NFA → DFA: subset construction — Lec04 NFA, sl. 91–109 | G30: L9 | H30: 10 | I30: 8 | J30: ★★ Medium | K30: Theory | L30: ✔ Solved | M30: 2021-22 2(a); 2007-08 3(c) | N30: FALSE
A31: 28 | B31: 2009-10 | C31: CSE 211 | D31: 3 | E31: Convert the ε-NFA (q1…q5 figure) to a DFA using lazy evaluation | F31: NFA → DFA: subset construction — Lec04 NFA, sl. 91–109 | G31: L9 | H31: 10 | I31: 8 | J31: ★★ Medium | K31: Trace | L31: ✔ Solved | M31: 2021-22 3(c); 2020 (Jan term) 1(c); 2020 (Jan term) 4(b); 2017-18 4(a); 2016-17 2(b); 2008-09 6(c) | N31: FALSE
... A37: 34 | B37: 2006-07 | C37: CSE 211 | D37: 3(b) | E37: Steps to find the equivalent DFA of an ε-NFA using lazy evaluation | F37: NFA → DFA: subset construction — Lec04 NFA, sl. 91–109 | G37: L9 | H37: 8 | I37: 1 | J37: ★★ Medium | K37: Theory | L37: ✔ Solved | M37: 2021-22 3(c); 2020 (Jan term) 1(c); 2020 (Jan term) 4(b); 2017-18 4(a); 2016-17 2(b); 2009-10 3 | N37: FALSE

Sheet 4 Regular Languages
A1: Lec05 — Closure Properties and Regular Expressions
A2: Note file: CSE211_Hakim_Regular_Languages_Notes.docx · Solve after finishing the matching lesson. Filter Priority → ★★★ High first.
A3: Q No. | B3: Year | C3: Course | D3: Ques No. | E3: Short Question | F3: Topic (slide PDF · slides) | G3: Lesson | H3: Marks | I3: TF Page | J3: Priority | K3: Type | L3: In Notes | M3: Same Type Also In | N3: Done | O3: Confidence | P3: Date | Q3: My Notes
A4: 1 | B4: 2023-24 | C4: CSE 211 | D4: 1(c) | E4: NFAs for concatenation of {w | ≥ three 1s} with ∅, via the closure construction | F4: Regular operations, closure under ∪ ∘ ∗ — Lec05 Regulars, sl. 1–37 | G4: L10 | H4: 10 | I4: 22 batch p.1 | J4: ★★★ High | K4: Design | L4: ✔ Solved | M4: 2016-17 4(b); 2015-16 2(b); 2012-13 5(c); 2011-12 5(b) | N4: FALSE
A5: 2 | B5: 2023-24 | C5: CSE 211 | D5: 3(b) | E5: Star construction without a new start state — why bad; counterexample | F5: Regular operations, closure under ∪ ∘ ∗ — Lec05 Regulars, sl. 1–37 | G5: L10 | H5: 13 | I5: 22 batch p.2 | J5: ★★★ High | K5: Theory | L5: ✔ Solved | M5: 2020 (Jan term) 3(b); 2016-17 4(a) | N5: FALSE
A6: 3 | B6: 2022-23 | C6: CSE 211 | D6: 3(c) | E6: Why is the Kleene star of the empty set the empty string? | F6: Regular operations, closure under ∪ ∘ ∗ — Lec05 Regulars, sl. 1–37 | G6: L10 | H6: 8 | I6: 51 | J6: ★★★ High | K6: Theory | L6: ✔ Solved | M6: 2021-22 3(a); 2016-17 2(c) | N6: FALSE
A7: 4 | B7: 2021-22 | C7: CSE 211 | D7: 2(c) | E7: Finite or infinite: L1∗∘L2∗, L1∘(L1∪L2), L2∘L3 (L1 = {a,aa,aaa}, L2 = {a,ab,aab,aabb}, L3 = #b multiple of 3) | F7: Regular operations, closure under ∪ ∘ ∗ — Lec05 Regulars, sl. 1–37 | G7: L10 | H7: 6 | I7: 45 | J7: ★★★ High | K7: Theory | L7: ✔ Solved | M7: — | N7: FALSE
A8: 5 | B8: 2021-22 | C8: CSE 211 | D8: 3(a) | E8: Why is the Kleene star of the empty set the empty string? | F8: Regular operations, closure under ∪ ∘ ∗ — Lec05 Regulars, sl. 1–37 | G8: L10 | H8: 4 | I8: 45 | J8: ★★★ High | K8: Theory | L8: ✔ Solved | M8: 2022-23 3(c); 2016-17 2(c) | N8: FALSE
A9: 6 | B9: 2021-22 | C9: CSE 211 | D9: 4(b) | E9: Union NFA: start state, accept states, transitions from the start state — with reasons | F9: Regular operations, closure under ∪ ∘ ∗ — Lec05 Regulars, sl. 1–37 | G9: L10 | H9: 12 | I9: 46 | J9: ★★★ High | K9: Theory | L9: ✔ Solved | M9: 2019-20 3(c) | N9: FALSE
A10: 7 | B10: 2020 (Jan term) | C10: CSE 211 | D10: 3(b) | E10: Explain each case of δ in the star construction N for L1∗ | F10: Regular operations, closure under ∪ ∘ ∗ — Lec05 Regulars, sl. 1–37 | G10: L10 | H10: 20 | I10: 37 | J10: ★★★ High | K10: Theory | L10: ✔ Solved | M10: 2023-24 3(b); 2016-17 4(a) | N10: FALSE
A11: 8 | B11: 2019-20 | C11: CSE 211 | D11: 3(c) | E11: Union NFA N from N1, N2: write δ and justify each part | F11: Regular operations, closure under ∪ ∘ ∗ — Lec05 Regulars, sl. 1–37 | G11: L10 | H11: 15 | I11: 41 | J11: ★★★ High | K11: Theory | L11: ✔ Solved | M11: 2021-22 4(b) | N11: FALSE
A12: 9 | B12: 2016-17 | C12: CSE 211 | D12: 2(c) | E12: Why is the Kleene star of the empty set the empty string? | F12: Regular operations, closure under ∪ ∘ ∗ — Lec05 Regulars, sl. 1–37 | G12: L10 | H12: 10 | I12: 29 | J12: ★★ Medium | K12: Theory | L12: ✔ Solved | M12: 2022-23 3(c); 2021-22 3(a) | N12: FALSE
A13: 10 | B13: 2016-17 | C13: CSE 211 | D13: 4(a) | E13: Hasty's star construction (no new start state, old start accepting) — when does it fail? | F13: Regular operations, closure under ∪ ∘ ∗ — Lec05 Regulars, sl. 1–37 | G13: L10 | H13: 10 | I13: 30 | J13: ★★ Medium | K13: Theory | L13: ✔ Solved | M13: 2023-24 3(b); 2020 (Jan term) 3(b) | N13: FALSE
A14: 11 | B14: 2016-17 | C14: CSE 211 | D14: 4(b) | E14: Prove closure under concatenation | F14: Regular operations, closure under ∪ ∘ ∗ — Lec05 Regulars, sl. 1–37 | G14: L10 | H14: 13 | I14: 30 | J14: ★★ Medium | K14: Proof | L14: ✔ Solved | M14: 2023-24 1(c); 2015-16 2(b); 2012-13 5(c); 2011-12 5(b) | N14: FALSE
A15: 12 | B15: 2015-16 | C15: CSE 211 | D15: 2(b) | E15: Prove the regular languages are closed under the regular operations | F15: Regular operations, closure under ∪ ∘ ∗ — Lec05 Regulars, sl. 1–37 | G15: L10 | H15: 15 | I15: 25 | J15: ★★ Medium | K15: Proof | L15: ✔ Solved | M15: 2023-24 1(c); 2016-17 4(b); 2012-13 5(c); 2011-12 5(b) | N15: FALSE
A16: 13 | B16: 2012-13 | C16: CSE 211 | D16: 5(c) | E16: Define regular language; prove closure under star and concatenation | F16: Regular operations, closure under ∪ ∘ ∗ — Lec05 Regulars, sl. 1–37 | G16: L10 | H16: 10 | I16: 18 | J16: ★★ Medium | K16: Proof | L16: ✔ Solved | M16: 2023-24 1(c); 2016-17 4(b); 2015-16 2(b); 2011-12 5(b) | N16: FALSE
A17: 14 | B17: 2011-12 | C17: CSE 211 | D17: 5(b) | E17: Define regular language; prove closure under star and concatenation | F17: Regular operations, closure under ∪ ∘ ∗ — Lec05 Regulars, sl. 1–37 | G17: L10 | H17: 12 | I17: 15 | J17: ★★ Medium | K17: Proof | L17: ✔ Solved | M17: 2023-24 1(c); 2016-17 4(b); 2015-16 2(b); 2012-13 5(c) | N17: FALSE
... A24: 21 | B24: 2013-14 | C24: CSE 211 | D24: 8(a) | E24: Steps to construct a DFA for L1 ∪ L2 from DFAs M1, M2 | F24: Complement, intersection, difference, reverse — Lec05 Regulars, sl. 38–60 | G24: L11 | H24: 7 | I24: 21 | J24: ★★ Medium | K24: Theory | L24: ✔ Solved | M24: 2022-23 4(a) | N24: FALSE
A25: 22 | B25: 2023-24 | C25: CSE 211 | D25: 4(b) | E25: Which RE (A–D) gives strings with at most one occurrence of aa? Reasons | F25: Regular expressions — Lec05 Regulars, sl. 61–84 | G25: L12 | H25: 12 | I25: 22 batch p.2 | J25: ★★★ High | K25: Theory | L25: ✔ Solved | M25: 2022-23 4(c); 2021-22 3(d) | N25: FALSE
A26: 23 | B26: 2022-23 | C26: CSE 211 | D26: 4(c) | E26: Which RE (A–C) represents the 2-state DFA? Explain each option | F26: Regular expressions — Lec05 Regulars, sl. 61–84 | G26: L12 | H26: 10 | I26: 51 | J26: ★★★ High | K26: Theory | L26: ✔ Solved | M26: 2023-24 4(b); 2021-22 3(d) | N26: FALSE
A27: 24 | B27: 2021-22 | C27: CSE 211 | D27: 3(d) | E27: Which RE (A–D) gives strings with both 00 and 11? Justify each | F27: Regular expressions — Lec05 Regulars, sl. 61–84 | G27: L12 | H27: 12 | I27: 46 | J27: ★★★ High | K27: Theory | L27: ✔ Solved | M27: 2023-24 4(b); 2022-23 4(c) | N27: FALSE
A28: 25 | B28: 2020 (Jan term) | C28: CSE 211 | D28: 2(c) | E28: RE for the strings NOT in the language of 2(a) | F28: Regular expressions — Lec05 Regulars, sl. 61–84 | G28: L12 | H28: 10 | I28: 36 | J28: ★★★ High | K28: Design | L28: ✔ Solved | M28: 2019-20 4(b); 2017-18 4(b); 2016-17 3(b); 2014-15 3(b); 2012-13 6(c); 2008-09 7(b) | N28: FALSE
A29: 26 | B29: 2020 (Jan term) | C29: CSE 211 | D29: 3(a) | E29: Evaluate ∅∗∅∗∅∗∅∗, ∅∗∪{ε}, (∅∗∪1){0,1}, (11)∗∅(00)∗, (∅∗∪0){0,1,11} | F29: Regular expressions — Lec05 Regulars, sl. 61–84 | G29: L12 | H29: 10 | I29: 37 | J29: ★★★ High | K29: Trace | L29: ✔ Solved | M29: — | N29: FALSE
A30: 27 | B30: 2020 (Jan term) | C30: CSE 211 | D30: 4(a) | E30: Describe the language of (1+ε)(00∗1)∗0∗ | F30: Regular expressions — Lec05 Regulars, sl. 61–84 | G30: L12 | H30: 10 | I30: 37 | J30: ★★★ High | K30: Theory | L30: ✔ Solved | M30: 2007-08 2(b); 2006-07 4(b) | N30: FALSE
A31: 28 | B31: 2019-20 | C31: CSE 211 | D31: 2(b) | E31: Simplify ∅∗∪a∗∪b∗∪(a∪b)∗; ((a∗b∗)∗(b∗a∗)∗)∗; (a∗b)∗∪(b∗a)∗ | F31: Regular expressions — Lec05 Regulars, sl. 61–84 | G31: L12 | H31: 15 | I31: 40 | J31: ★★★ High | K31: Trace | L31: ✔ Solved | M31: — | N31: FALSE
A32: 29 | B32: 2019-20 | C32: CSE 211 | D32: 4(b) | E32: REs over {a,b}: #a divisible by 3; at most three a's; exactly one occurrence of aaa | F32: Regular expressions — Lec05 Regulars, sl. 61–84 | G32: L12 | H32: 15 | I32: 41 | J32: ★★★ High | K32: Design | L32: ✔ Solved | M32: 2020 (Jan term) 2(c); 2017-18 4(b); 2016-17 3(b); 2014-15 3(b); 2012-13 6(c); 2008-09 7(b) | N32: FALSE
A33: 30 | B33: 2017-18 | C33: CSE 211 | D33: 4(b) | E33: REs: each of a,b,c occurs; a^nb^m n≥3 m odd; (n+m) odd; vwv with |v|=2; #a mod 3 = 0 | F33: Regular expressions — Lec05 Regulars, sl. 61–84 | G33: L12 | H33: 20 | I33: 33 | J33: ★★ Medium | K33: Design | L33: ✔ Solved | M33: 2020 (Jan term) 2(c); 2019-20 4(b); 2016-17 3(b); 2014-15 3(b); 2012-13 6(c); 2008-09 7(b) | N33: FALSE
A34: 31 | B34: 2016-17 | C34: CSE 211 | D34: 3(b) | E34: REs: alternating 0s and 1s; ≥1 a and ≥1 b over {a,b,c}; every 00 before any 11 | F34: Regular expressions — Lec05 Regulars, sl. 61–84 | G34: L12 | H34: 15 | I34: 29 | J34: ★★ Medium | K34: Design | L34: ✔ Solved | M34: 2020 (Jan term) 2(c); 2019-20 4(b); 2017-18 4(b); 2014-15 3(b); 2012-13 6(c); 2008-09 7(b) | N34: FALSE
A35: 32 | B35: 2015-16 | C35: CSE 211 | D35: 3(a) | E35: DFA and RE: begins 1 ends 0; 3rd symbol 0; even 0s or exactly two 1s; not 11/111; ≥2 0s and ≤1 1 | F35: Regular expressions — Lec05 Regulars, sl. 61–84 | G35: L12 | H35: 18 | I35: 25 | J35: ★ Low | K35: Design | L35: ◐ Method | M35: — | N35: FALSE
A36: 33 | B36: 2014-15 | C36: CSE 211 | D36: 3(b) | E36: REs: decimal numbers divisible by 5 (no leading 0s); odd 0s or odd 1s; no 101 | F36: Regular expressions — Lec05 Regulars, sl. 61–84 | G36: L12 | H36: 10 | I36: 22 | J36: ★★ Medium | K36: Design | L36: ✔ Solved | M36: 2020 (Jan term) 2(c); 2019-20 4(b); 2017-18 4(b); 2016-17 3(b); 2012-13 6(c); 2008-09 7(b) | N36: FALSE
A37: 34 | B37: 2013-14 | C37: CSE 211 | D37: 5(b) | E37: Counter-example to (R1 ∪ R2)∗ = R1∗ ∪ R2∗ [mark not printed; 5 by section total] | F37: Regular expressions — Lec05 Regulars, sl. 61–84 | G37: L12 | I37: 20 | J37: ★ Low | K37: Proof | L37: ✔ Solved | M37: — | N37: FALSE
