Workbook

Sheet How to Use
B2: CSE 219 (Anik Sir part) — TF Practice Tracker
B3: Every Anik-part question in CSE 219 All Merged Questions.pdf (22-batch and EEE pages as written in TF Page), mapped to the note file and lesson that teaches it.
B5: Workflow — after you finish a note file
B6: 1. Open its tab | C6: Tabs 1–4 follow the order of your note files. Q No. runs lesson by lesson, newest year first inside each lesson.
B7: 2. Filter | C7: Use the filter arrow on Priority → ★★★ High first (2019-20 onward). Then ★★ Medium, then ★ Low.
B8: 3. Solve | C8: Open CSE 219 All Merged Questions.pdf (22-batch and EEE pages as written in TF Page) at the TF Page shown. Solve on paper under exam time (≈1.5 min per mark). Do not read the note solution first.
B9: 4. Check | C9: In Notes tells you what the note has: ✔ Solved = same question worked out; ◐ Method = method / model answer you can apply; ○ Partly = notes cover most of it, finish the rest yourself.
B10: 5. Record | C10: Tick Done, pick Confidence, add the Date. Write mistakes in My Notes. Re-solve every 'Weak' row before the exam.
B11: 6. Repeats | C11: 'Same Type Also In' lists other papers with the same question type. Solve one, then try a repeat cold — that is the real test.
B13: Columns you edit (all others are fixed data)
B14: Done (col N) | C14: TRUE / FALSE. In Google Sheets: select N4 downward → Insert → Checkbox. The values stay; ticking turns the row green.
B15: Confidence (col O) | C15: Dropdown: Weak / OK / Strong. Weak rows turn the cell red.
B16: Date (col P) | C16: Date you solved it, e.g. 16-Oct-2026.
B17: My Notes (col Q) | C17: Mistakes, missing steps, formula you forgot.
B19: Legend
B20: ★★★ High | C20: Asked in 2019-20 or later (most important — current question style).
B21: ★★ Medium | C21: Older paper, but the same question type appears at least twice in TF.
B22: ★ Low | C22: Older paper, asked once.
B23: Type | C23: Numerical = calculation · Trace = tables / step-by-step simulation · Design = construct / draw · Proof = prove / disprove · Theory = explain.
B24: Course | C24: CSE 219 = current course; EEE 211 / EEE 301 = predecessor course (same content, TF Page = 'EEE p.N' in EEE 211 - TF Questions 2023-24 to 2010-11.pdf); CSE 311 = Data Communication papers in the merged PDF (only their signals/Fourier/sampling parts are listed).
B25: Topic | C25: Note lesson title — slide PDF and slide numbers.

Sheet Dashboard
A1: Progress Dashboard
A2: Updates automatically when you tick Done / set Confidence in tabs 1–4.
A4: # | B4: Note file (tab) | C4: Questions | D4: Done | E4: % Done | F4: Marks (total) | G4: Marks done | H4: High-priority left | I4: Weak | J4: Next unsolved (top of tab)
A5: 1 | B5: 1 Signals | C5: =COUNTA('1 Signals'!$E$4:$E$21) | D5: =COUNTIF('1 Signals'!$N$4:$N$21,TRUE()) | E5: =IF(C5=0,0,D5/C5) | F5: =SUM('1 Signals'!$H$4:$H$21) | G5: =SUMIF('1 Signals'!$N$4:$N$21,TRUE(),'1 Signals'!$H$4:$H$21) | H5: =COUNTIFS('1 Signals'!$J$4:$J$21,"★★★ High",'1 Signals'!$N$4:$N$21,FALSE()) | I5: =COUNTIF('1 Signals'!$O$4:$O$21,"Weak") | J5: =IFERROR("Q"&INDEX('1 Signals'!$A$4:$A$21,MATCH(FALSE(),'1 Signals'!$N$4:$N$21,0))&" · "&INDEX('1 Signals'!$B$4:$B$21,MATCH(FALSE(),'1 Signals'!$N$4:$N$21,0))&" "&INDEX('1 Signals'!$D$4:$D$21,MATCH(FALSE(),'1 Signals'!$N$4:$N$21,0))&" · TF p."&INDEX('1 Signals'!$I$4:$I$21,MATCH(FALSE(),'1 Signals'!$N$4:$N$21,0)),"All done ✔")
A6: 2 | B6: 2 LTI + Convolution | C6: =COUNTA('2 LTI + Convolution'!$E$4:$E$24) | D6: =COUNTIF('2 LTI + Convolution'!$N$4:$N$24,TRUE()) | E6: =IF(C6=0,0,D6/C6) | F6: =SUM('2 LTI + Convolution'!$H$4:$H$24) | G6: =SUMIF('2 LTI + Convolution'!$N$4:$N$24,TRUE(),'2 LTI + Convolution'!$H$4:$H$24) | H6: =COUNTIFS('2 LTI + Convolution'!$J$4:$J$24,"★★★ High",'2 LTI + Convolution'!$N$4:$N$24,FALSE()) | I6: =COUNTIF('2 LTI + Convolution'!$O$4:$O$24,"Weak") | J6: =IFERROR("Q"&INDEX('2 LTI + Convolution'!$A$4:$A$24,MATCH(FALSE(),'2 LTI + Convolution'!$N$4:$N$24,0))&" · "&INDEX('2 LTI + Convolution'!$B$4:$B$24,MATCH(FALSE(),'2 LTI + Convolution'!$N$4:$N$24,0))&" "&INDEX('2 LTI + Convolution'!$D$4:$D$24,MATCH(FALSE(),'2 LTI + Convolution'!$N$4:$N$24,0))&" · TF p."&INDEX('2 LTI + Convolution'!$I$4:$I$24,MATCH(FALSE(),'2 LTI + Convolution'!$N$4:$N$24,0)),"All done ✔")
A7: 3 | B7: 3 Fourier Series | C7: =COUNTA('3 Fourier Series'!$E$4:$E$26) | D7: =COUNTIF('3 Fourier Series'!$N$4:$N$26,TRUE()) | E7: =IF(C7=0,0,D7/C7) | F7: =SUM('3 Fourier Series'!$H$4:$H$26) | G7: =SUMIF('3 Fourier Series'!$N$4:$N$26,TRUE(),'3 Fourier Series'!$H$4:$H$26) | H7: =COUNTIFS('3 Fourier Series'!$J$4:$J$26,"★★★ High",'3 Fourier Series'!$N$4:$N$26,FALSE()) | I7: =COUNTIF('3 Fourier Series'!$O$4:$O$26,"Weak") | J7: =IFERROR("Q"&INDEX('3 Fourier Series'!$A$4:$A$26,MATCH(FALSE(),'3 Fourier Series'!$N$4:$N$26,0))&" · "&INDEX('3 Fourier Series'!$B$4:$B$26,MATCH(FALSE(),'3 Fourier Series'!$N$4:$N$26,0))&" "&INDEX('3 Fourier Series'!$D$4:$D$26,MATCH(FALSE(),'3 Fourier Series'!$N$4:$N$26,0))&" · TF p."&INDEX('3 Fourier Series'!$I$4:$I$26,MATCH(FALSE(),'3 Fourier Series'!$N$4:$N$26,0)),"All done ✔")
A8: 4 | B8: 4 Fourier Transform | C8: =COUNTA('4 Fourier Transform'!$E$4:$E$44) | D8: =COUNTIF('4 Fourier Transform'!$N$4:$N$44,TRUE()) | E8: =IF(C8=0,0,D8/C8) | F8: =SUM('4 Fourier Transform'!$H$4:$H$44) | G8: =SUMIF('4 Fourier Transform'!$N$4:$N$44,TRUE(),'4 Fourier Transform'!$H$4:$H$44) | H8: =COUNTIFS('4 Fourier Transform'!$J$4:$J$44,"★★★ High",'4 Fourier Transform'!$N$4:$N$44,FALSE()) | I8: =COUNTIF('4 Fourier Transform'!$O$4:$O$44,"Weak") | J8: =IFERROR("Q"&INDEX('4 Fourier Transform'!$A$4:$A$44,MATCH(FALSE(),'4 Fourier Transform'!$N$4:$N$44,0))&" · "&INDEX('4 Fourier Transform'!$B$4:$B$44,MATCH(FALSE(),'4 Fourier Transform'!$N$4:$N$44,0))&" "&INDEX('4 Fourier Transform'!$D$4:$D$44,MATCH(FALSE(),'4 Fourier Transform'!$N$4:$N$44,0))&" · TF p."&INDEX('4 Fourier Transform'!$I$4:$I$44,MATCH(FALSE(),'4 Fourier Transform'!$N$4:$N$44,0)),"All done ✔")
B9: TOTAL | C9: =SUM(C5:C8) | D9: =SUM(D5:D8) | E9: =IF(C9=0,0,D9/C9) | F9: =SUM(F5:F8) | G9: =SUM(G5:G8) | H9: =SUM(H5:H8) | I9: =SUM(I5:I8)
A11: Questions by year (tabs 1–4)
A12: # | B12: Year | C12: Questions | D12: Done | E12: % Done | F12: Marks (total)
A13: 1 | B13: 2023-24 | C13: =COUNTIF('1 Signals'!$B$4:$B$21,$B13)+COUNTIF('2 LTI + Convolution'!$B$4:$B$24,$B13)+COUNTIF('3 Fourier Series'!$B$4:$B$26,$B13)+COUNTIF('4 Fourier Transform'!$B$4:$B$44,$B13) | D13: =COUNTIFS('1 Signals'!$B$4:$B$21,$B13,'1 Signals'!$N$4:$N$21,TRUE())+COUNTIFS('2 LTI + Convolution'!$B$4:$B$24,$B13,'2 LTI + Convolution'!$N$4:$N$24,TRUE())+COUNTIFS('3 Fourier Series'!$B$4:$B$26,$B13,'3 Fourier Series'!$N$4:$N$26,TRUE())+COUNTIFS('4 Fourier Transform'!$B$4:$B$44,$B13,'4 Fourier Transform'!$N$4:$N$44,TRUE()) | E13: =IF(C13=0,0,D13/C13) | F13: =SUMIF('1 Signals'!$B$4:$B$21,$B13,'1 Signals'!$H$4:$H$21)+SUMIF('2 LTI + Convolution'!$B$4:$B$24,$B13,'2 LTI + Convolution'!$H$4:$H$24)+SUMIF('3 Fourier Series'!$B$4:$B$26,$B13,'3 Fourier Series'!$H$4:$H$26)+SUMIF('4 Fourier Transform'!$B$4:$B$44,$B13,'4 Fourier Transform'!$H$4:$H$44)
A14: 2 | B14: 2022-23 | C14: =COUNTIF('1 Signals'!$B$4:$B$21,$B14)+COUNTIF('2 LTI + Convolution'!$B$4:$B$24,$B14)+COUNTIF('3 Fourier Series'!$B$4:$B$26,$B14)+COUNTIF('4 Fourier Transform'!$B$4:$B$44,$B14) | D14: =COUNTIFS('1 Signals'!$B$4:$B$21,$B14,'1 Signals'!$N$4:$N$21,TRUE())+COUNTIFS('2 LTI + Convolution'!$B$4:$B$24,$B14,'2 LTI + Convolution'!$N$4:$N$24,TRUE())+COUNTIFS('3 Fourier Series'!$B$4:$B$26,$B14,'3 Fourier Series'!$N$4:$N$26,TRUE())+COUNTIFS('4 Fourier Transform'!$B$4:$B$44,$B14,'4 Fourier Transform'!$N$4:$N$44,TRUE()) | E14: =IF(C14=0,0,D14/C14) | F14: =SUMIF('1 Signals'!$B$4:$B$21,$B14,'1 Signals'!$H$4:$H$21)+SUMIF('2 LTI + Convolution'!$B$4:$B$24,$B14,'2 LTI + Convolution'!$H$4:$H$24)+SUMIF('3 Fourier Series'!$B$4:$B$26,$B14,'3 Fourier Series'!$H$4:$H$26)+SUMIF('4 Fourier Transform'!$B$4:$B$44,$B14,'4 Fourier Transform'!$H$4:$H$44)
A15: 3 | B15: 2021-22 | C15: =COUNTIF('1 Signals'!$B$4:$B$21,$B15)+COUNTIF('2 LTI + Convolution'!$B$4:$B$24,$B15)+COUNTIF('3 Fourier Series'!$B$4:$B$26,$B15)+COUNTIF('4 Fourier Transform'!$B$4:$B$44,$B15) | D15: =COUNTIFS('1 Signals'!$B$4:$B$21,$B15,'1 Signals'!$N$4:$N$21,TRUE())+COUNTIFS('2 LTI + Convolution'!$B$4:$B$24,$B15,'2 LTI + Convolution'!$N$4:$N$24,TRUE())+COUNTIFS('3 Fourier Series'!$B$4:$B$26,$B15,'3 Fourier Series'!$N$4:$N$26,TRUE())+COUNTIFS('4 Fourier Transform'!$B$4:$B$44,$B15,'4 Fourier Transform'!$N$4:$N$44,TRUE()) | E15: =IF(C15=0,0,D15/C15) | F15: =SUMIF('1 Signals'!$B$4:$B$21,$B15,'1 Signals'!$H$4:$H$21)+SUMIF('2 LTI + Convolution'!$B$4:$B$24,$B15,'2 LTI + Convolution'!$H$4:$H$24)+SUMIF('3 Fourier Series'!$B$4:$B$26,$B15,'3 Fourier Series'!$H$4:$H$26)+SUMIF('4 Fourier Transform'!$B$4:$B$44,$B15,'4 Fourier Transform'!$H$4:$H$44)
A16: 4 | B16: 2020-21 | C16: =COUNTIF('1 Signals'!$B$4:$B$21,$B16)+COUNTIF('2 LTI + Convolution'!$B$4:$B$24,$B16)+COUNTIF('3 Fourier Series'!$B$4:$B$26,$B16)+COUNTIF('4 Fourier Transform'!$B$4:$B$44,$B16) | D16: =COUNTIFS('1 Signals'!$B$4:$B$21,$B16,'1 Signals'!$N$4:$N$21,TRUE())+COUNTIFS('2 LTI + Convolution'!$B$4:$B$24,$B16,'2 LTI + Convolution'!$N$4:$N$24,TRUE())+COUNTIFS('3 Fourier Series'!$B$4:$B$26,$B16,'3 Fourier Series'!$N$4:$N$26,TRUE())+COUNTIFS('4 Fourier Transform'!$B$4:$B$44,$B16,'4 Fourier Transform'!$N$4:$N$44,TRUE()) | E16: =IF(C16=0,0,D16/C16) | F16: =SUMIF('1 Signals'!$B$4:$B$21,$B16,'1 Signals'!$H$4:$H$21)+SUMIF('2 LTI + Convolution'!$B$4:$B$24,$B16,'2 LTI + Convolution'!$H$4:$H$24)+SUMIF('3 Fourier Series'!$B$4:$B$26,$B16,'3 Fourier Series'!$H$4:$H$26)+SUMIF('4 Fourier Transform'!$B$4:$B$44,$B16,'4 Fourier Transform'!$H$4:$H$44)
A17: 5 | B17: 2019-20 | C17: =COUNTIF('1 Signals'!$B$4:$B$21,$B17)+COUNTIF('2 LTI + Convolution'!$B$4:$B$24,$B17)+COUNTIF('3 Fourier Series'!$B$4:$B$26,$B17)+COUNTIF('4 Fourier Transform'!$B$4:$B$44,$B17) | D17: =COUNTIFS('1 Signals'!$B$4:$B$21,$B17,'1 Signals'!$N$4:$N$21,TRUE())+COUNTIFS('2 LTI + Convolution'!$B$4:$B$24,$B17,'2 LTI + Convolution'!$N$4:$N$24,TRUE())+COUNTIFS('3 Fourier Series'!$B$4:$B$26,$B17,'3 Fourier Series'!$N$4:$N$26,TRUE())+COUNTIFS('4 Fourier Transform'!$B$4:$B$44,$B17,'4 Fourier Transform'!$N$4:$N$44,TRUE()) | E17: =IF(C17=0,0,D17/C17) | F17: =SUMIF('1 Signals'!$B$4:$B$21,$B17,'1 Signals'!$H$4:$H$21)+SUMIF('2 LTI + Convolution'!$B$4:$B$24,$B17,'2 LTI + Convolution'!$H$4:$H$24)+SUMIF('3 Fourier Series'!$B$4:$B$26,$B17,'3 Fourier Series'!$H$4:$H$26)+SUMIF('4 Fourier Transform'!$B$4:$B$44,$B17,'4 Fourier Transform'!$H$4:$H$44)
A18: 6 | B18: 2018-19 | C18: =COUNTIF('1 Signals'!$B$4:$B$21,$B18)+COUNTIF('2 LTI + Convolution'!$B$4:$B$24,$B18)+COUNTIF('3 Fourier Series'!$B$4:$B$26,$B18)+COUNTIF('4 Fourier Transform'!$B$4:$B$44,$B18) | D18: =COUNTIFS('1 Signals'!$B$4:$B$21,$B18,'1 Signals'!$N$4:$N$21,TRUE())+COUNTIFS('2 LTI + Convolution'!$B$4:$B$24,$B18,'2 LTI + Convolution'!$N$4:$N$24,TRUE())+COUNTIFS('3 Fourier Series'!$B$4:$B$26,$B18,'3 Fourier Series'!$N$4:$N$26,TRUE())+COUNTIFS('4 Fourier Transform'!$B$4:$B$44,$B18,'4 Fourier Transform'!$N$4:$N$44,TRUE()) | E18: =IF(C18=0,0,D18/C18) | F18: =SUMIF('1 Signals'!$B$4:$B$21,$B18,'1 Signals'!$H$4:$H$21)+SUMIF('2 LTI + Convolution'!$B$4:$B$24,$B18,'2 LTI + Convolution'!$H$4:$H$24)+SUMIF('3 Fourier Series'!$B$4:$B$26,$B18,'3 Fourier Series'!$H$4:$H$26)+SUMIF('4 Fourier Transform'!$B$4:$B$44,$B18,'4 Fourier Transform'!$H$4:$H$44)
B19: Shaded years = ★★★ High priority (2019-20 onward).
B20: 2023-24 CSE 219 pages are in 'CSE 219 (22 batch).pdf' (TF Page '22 batch p.N').
B21: Section split: Anik Sir = signals, LTI, Fourier series/transform; Ashraf Sir = DFT/FFT, sampling, Laplace, z.

Sheet 1 Signals
A1: Lec 1–2 — Signals
A2: Note file: CSE219_Anik_Signals_Notes.docx · Solve after finishing the matching lesson. Filter Priority → ★★★ High first.
A3: Q No. | B3: Year | C3: Course | D3: Ques No. | E3: Short Question | F3: Topic (slide PDF · slides) | G3: Lesson | H3: Marks | I3: TF Page | J3: Priority | K3: Type | L3: In Notes | M3: Same Type Also In | N3: Done | O3: Confidence | P3: Date | Q3: My Notes
A4: 1 | B4: 2021-22 | C4: EEE 211 | D4: 1(b) | E4: e^{−3t} sin(2πt/3 − 4) u(t): power or energy signal? | F4: Energy and power — Lec 1, sl. 2–16 | G4: L1 | H4: 10 | I4: EEE p.12 | J4: ★★★ High | K4: Numerical | L4: ✔ Solved | M4: 2020-21 5(b) (EEE); 2018-19 6(a) (EEE) | N4: FALSE
A5: 2 | B5: 2020-21 | C5: EEE 211 | D5: 5(b) | E5: Power or energy: u(t−6)−u(−t+8); 2r(t−4)u(t) | F5: Energy and power — Lec 1, sl. 2–16 | G5: L1 | H5: 10 | I5: EEE p.20 | J5: ★★★ High | K5: Numerical | L5: ✔ Solved | M5: 2021-22 1(b) (EEE); 2018-19 6(a) (EEE) | N5: FALSE
A6: 3 | B6: 2018-19 | C6: EEE 211 | D6: 6(a) | E6: Power/energy/neither: e^{j(2πt+π/4)} + e^{−2|t|}; [u(cos t) − δ(t−kπ)]^{0.5} | F6: Energy and power — Lec 1, sl. 2–16 | G6: L1 | H6: 15 | I6: EEE p.30 | J6: ★★ Medium | K6: Numerical | L6: ◐ Method | M6: 2021-22 1(b) (EEE); 2020-21 5(b) (EEE) | N6: FALSE
A7: 4 | B7: 2023-24 | C7: CSE 219 | D7: 1(a) | E7: x(t) = 1−|t| (|t|≤1): sketch y(t) = x(−2(t−1)) + x((t+2)/2) | F7: Shift, reversal, scaling x(αt+β) — Lec 1, sl. 17–39 | G7: L2 | H7: 15 | I7: 22 batch p.1 | J7: ★★★ High | K7: Sketch | L7: ✔ Solved | M7: 2022-23 7(a)–(c); 2022-23 7(d) | N7: FALSE
A8: 5 | B8: 2022-23 | C8: CSE 219 | D8: 7(a)–(c) | E8: x(t) of Fig. 2: piecewise definition; sketch x(−2t+2) and x(−t/2+1) step by step | F8: Shift, reversal, scaling x(αt+β) — Lec 1, sl. 17–39 | G8: L2 | H8: 23 | I8: 4 | J8: ★★★ High | K8: Sketch | L8: ✔ Solved | M8: 2022-23 7(d); 2023-24 1(a) | N8: FALSE
A9: 6 | B9: 2022-23 | C9: CSE 219 | D9: 7(d) | E9: Image-editing tasks ↔ which signal operations | F9: Shift, reversal, scaling x(αt+β) — Lec 1, sl. 17–39 | G9: L2 | H9: 7 | I9: 4 | J9: ★★★ High | K9: Theory | L9: ✔ Solved | M9: 2022-23 7(a)–(c); 2023-24 1(a) | N9: FALSE
A10: 7 | B10: 2022-23 | C10: CSE 219 | D10: 5(a) | E10: f(t) = t+1 (−2..0), −t/2+1 (0..2): draw, even–odd decomposition, draw parts | F10: Even and odd parts — Lec 1, sl. 40–52 | G10: L3 | H10: 15 | I10: 2 | J10: ★★★ High | K10: Sketch | L10: ✔ Solved | M10: — | N10: FALSE
A11: 8 | B11: 2023-24 | C11: EEE 211 | D11: 1(a) | E11: Piecewise x(t): sketch x(−3t+2), x'(t), x''(t); x'(t) via δ, u, r | F11: Step, impulse, ramp, jump signals — Lec 2, sl. 2–29 | G11: L4 | H11: 11 | I11: EEE p.1 | J11: ★★★ High | K11: Sketch | L11: ✔ Solved | M11: 2022-23 5(c) (EEE); 2021-22 1(c) (EEE); 2020-21 5(a) (EEE); 2019-20 5(a) (EEE); 2018-19 6(b) (EEE) | N11: FALSE
A12: 9 | B12: 2022-23 | C12: EEE 211 | D12: 5(c) | E12: x(t) of Fig. 5(c) via elementary signals; sketch dx/dt | F12: Step, impulse, ramp, jump signals — Lec 2, sl. 2–29 | G12: L4 | H12: 10 | I12: EEE p.10 | J12: ★★★ High | K12: Sketch | L12: ✔ Solved | M12: 2023-24 1(a) (EEE); 2021-22 1(c) (EEE); 2020-21 5(a) (EEE); 2019-20 5(a) (EEE); 2018-19 6(b) (EEE) | N12: FALSE
A13: 10 | B13: 2022-23 | C13: EEE 211 | D13: 6(a) | E13: Are lim 1/(επ cosh(t/ε)) and lim sin(εt)/(πt) models of δ(t)? | F13: Step, impulse, ramp, jump signals — Lec 2, sl. 2–29 | G13: L4 | H13: 20 | I13: EEE p.10 | J13: ★★★ High | K13: Proof | L13: ✔ Solved | M13: — | N13: FALSE
A14: 11 | B14: 2021-22 | C14: EEE 211 | D14: 1(c) | E14: x = δ(t−1)+u(t)u(t−3)+u(cos t): y = ∫x; sketch y(t/2) | F14: Step, impulse, ramp, jump signals — Lec 2, sl. 2–29 | G14: L4 | H14: 15 | I14: EEE p.12 | J14: ★★★ High | K14: Sketch | L14: ✔ Solved | M14: 2023-24 1(a) (EEE); 2022-23 5(c) (EEE); 2020-21 5(a) (EEE); 2019-20 5(a) (EEE); 2018-19 6(b) (EEE) | N14: FALSE
A15: 12 | B15: 2020-21 | C15: EEE 211 | D15: 5(a) | E15: x₁, x₂ via r, u; draw x₁(t+2)r(t−2), x₂(t−2)u(−2t); x₃ via x₁ | F15: Step, impulse, ramp, jump signals — Lec 2, sl. 2–29 | G15: L4 | H15: 25 | I15: EEE p.19 | J15: ★★★ High | K15: Sketch | L15: ✔ Solved | M15: 2023-24 1(a) (EEE); 2022-23 5(c) (EEE); 2021-22 1(c) (EEE); 2019-20 5(a) (EEE); 2018-19 6(b) (EEE) | N15: FALSE
A16: 13 | B16: 2019-20 | C16: CSE 311 | D16: 2(b) | E16: Prove u(t) from δ(t) and δ(t) from u(t) | F16: Step, impulse, ramp, jump signals — Lec 2, sl. 2–29 | G16: L4 | H16: 11 | I16: 15 | J16: ★★★ High | K16: Proof | L16: ✔ Solved | M16: — | N16: FALSE
A17: 14 | B17: 2019-20 | C17: EEE 211 | D17: 5(a) | E17: Single expression for x(t) of Fig. 5(a); time-compress by 3 | F17: Step, impulse, ramp, jump signals — Lec 2, sl. 2–29 | G17: L4 | H17: 15 | I17: EEE p.24 | J17: ★★★ High | K17: Sketch | L17: ✔ Solved | M17: 2023-24 1(a) (EEE); 2022-23 5(c) (EEE); 2021-22 1(c) (EEE); 2020-21 5(a) (EEE); 2018-19 6(b) (EEE) | N17: FALSE
A18: 15 | B18: 2018-19 | C18: EEE 211 | D18: 6(b) | E18: v(t) of Fig. 6(b): steps & ramps; derivative; even and odd parts of the derivative | F18: Step, impulse, ramp, jump signals — Lec 2, sl. 2–29 | G18: L4 | H18: 20 | I18: EEE p.30 | J18: ★★ Medium | K18: Sketch | L18: ◐ Method | M18: 2023-24 1(a) (EEE); 2022-23 5(c) (EEE); 2021-22 1(c) (EEE); 2020-21 5(a) (EEE); 2019-20 5(a) (EEE) | N18: FALSE
A19: 16 | B19: 2023-24 | C19: CSE 219 | D19: 3(a) | E19: x[n] = (3−4j)e^{j13πn/7}: real/imag parts periodic? N₀; phase shift as integer time shift? | F19: Exponentials, sinusoids, periodicity — Lec 2, sl. 30–50 | G19: L5 | H19: 15 | I19: 22 batch p.2 | J19: ★★★ High | K19: Numerical | L19: ✔ Solved | M19: 2022-23 5(c); 2021-22 1(a) (EEE) | N19: FALSE
A20: 17 | B20: 2022-23 | C20: CSE 219 | D20: 5(c) | E20: Is 2cos(16πn/63 + π/3) periodic? period | F20: Exponentials, sinusoids, periodicity — Lec 2, sl. 30–50 | G20: L5 | H20: 5 | I20: 3 | J20: ★★★ High | K20: Numerical | L20: ✔ Solved | M20: 2023-24 3(a); 2021-22 1(a) (EEE) | N20: FALSE
A21: 18 | B21: 2021-22 | C21: EEE 211 | D21: 1(a) | E21: √(e^{j5πt}) + sin²(3t−π/4): periodic? period | F21: Exponentials, sinusoids, periodicity — Lec 2, sl. 30–50 | G21: L5 | H21: 10 | I21: EEE p.12 | J21: ★★★ High | K21: Numerical | L21: ✔ Solved | M21: 2022-23 5(c); 2023-24 3(a) | N21: FALSE

Sheet 2 LTI + Convolution
A1: Lec 3–4 — LTI Systems and Convolution
A2: Note file: CSE219_Anik_LTI_Convolution_Notes.docx · Solve after finishing the matching lesson. Filter Priority → ★★★ High first.
A3: Q No. | B3: Year | C3: Course | D3: Ques No. | E3: Short Question | F3: Topic (slide PDF · slides) | G3: Lesson | H3: Marks | I3: TF Page | J3: Priority | K3: Type | L3: In Notes | M3: Same Type Also In | N3: Done | O3: Confidence | P3: Date | Q3: My Notes
A4: 1 | B4: 2023-24 | C4: EEE 211 | D4: 1(b) | E4: dy/dt + t²y = (2t+3)x: linear? time-invariant? | F4: Systems: linearity, time invariance — Lec 3, sl. 2–11 | G4: L6 | H4: 7 | I4: EEE p.1 | J4: ★★★ High | K4: Proof | L4: ✔ Solved | M4: 2022-23 8(b) (EEE); 2020-21 6(a) (EEE); 2019-20 1 (EEE) | N4: FALSE
A5: 2 | B5: 2022-23 | C5: EEE 211 | D5: 5(b) | E5: LTI: x (V-shape) → y = rect; outputs for x(t−½)−x(t+½) and dx/dt | F5: Systems: linearity, time invariance — Lec 3, sl. 2–11 | G5: L6 | H5: 15 | I5: EEE p.9–10 | J5: ★★★ High | K5: Sketch | L5: ✔ Solved | M5: 2021-22 2(b) (EEE); 2018-19 7(a) (EEE) | N5: FALSE
A6: 3 | B6: 2022-23 | C6: EEE 211 | D6: 8(b) | E6: dy/dt + t²y = (2t+3)x: linear? time-invariant? | F6: Systems: linearity, time invariance — Lec 3, sl. 2–11 | G6: L6 | H6: 15 | I6: EEE p.11 | J6: ★★★ High | K6: Proof | L6: ✔ Solved | M6: 2023-24 1(b) (EEE); 2020-21 6(a) (EEE); 2019-20 1 (EEE) | N6: FALSE
A7: 4 | B7: 2021-22 | C7: EEE 211 | D7: 2(b) | E7: y₁ = x₁*h, y₂ = x₂*h (triangle, trapezoid) [rest of wording cut off — illegible] | F7: Systems: linearity, time invariance — Lec 3, sl. 2–11 | G7: L6 | H7: 18 | I7: EEE p.12 | J7: ★★★ High | K7: Sketch | L7: ◐ Method | M7: 2022-23 5(b) (EEE); 2018-19 7(a) (EEE) | N7: FALSE
A8: 5 | B8: 2020-21 | C8: EEE 211 | D8: 6(a) | E8: y = t·x(t+2): linear, causal, time-variant, memoryless, stable? | F8: Systems: linearity, time invariance — Lec 3, sl. 2–11 | G8: L6 | H8: 15 | I8: EEE p.20 | J8: ★★★ High | K8: Proof | L8: ✔ Solved | M8: 2023-24 1(b) (EEE); 2022-23 8(b) (EEE); 2019-20 1 (EEE) | N8: FALSE
A9: 6 | B9: 2019-20 | C9: EEE 211 | D9: 1 | E9: y = (1/3)∫x(τ)[δ(t−τ)+δ(t−τ+t₀)+δ(t−τ−t₀)]dτ: what it does; BIBO, linear, memoryless, causal, TI | F9: Systems: linearity, time invariance — Lec 3, sl. 2–11 | G9: L6 | H9: 35 | I9: EEE p.22 | J9: ★★★ High | K9: Proof | L9: ✔ Solved | M9: 2023-24 1(b) (EEE); 2022-23 8(b) (EEE); 2020-21 6(a) (EEE) | N9: FALSE
A10: 7 | B10: 2018-19 | C10: EEE 211 | D10: 7(a) | E10: Linear system: x (rect) → y: causal, TI, memoryless? output for u(t)+u(t−1)−2u(t−2) | F10: Systems: linearity, time invariance — Lec 3, sl. 2–11 | G10: L6 | H10: 20 | I10: EEE p.30 | J10: ★★ Medium | K10: Sketch | L10: ◐ Method | M10: 2022-23 5(b) (EEE); 2021-22 2(b) (EEE) | N10: FALSE
A11: 8 | B11: 2018-19 | C11: CSE 311 | D11: 4(b) | E11: Prove y = x*h for an LTI system using time-domain arguments only | F11: Impulse response, y = x*h derivation — Lec 3, sl. 32–57 | G11: L8 | H11: 17 | I11: 18 | J11: ★ Low | K11: Proof | L11: ✔ Solved | M11: — | N11: FALSE
A12: 9 | B12: 2023-24 | C12: CSE 219 | D12: 1(b) | E12: h₁=δ[n]−δ[n−2], h₂=u[n−1], h₃=δ[n]−δ[n−1]; (h₁+h₂)*h₃: h_eq and y for x=u[n] | F12: Convolution practice, interconnections — Lec 4, sl. 2–52 | G12: L9 | H12: 15 | I12: 22 batch p.1 | J12: ★★★ High | K12: Numerical | L12: ✔ Solved | M12: 2023-24 1(c) (EEE) | N12: FALSE
A13: 10 | B13: 2023-24 | C13: EEE 211 | D13: 1(c) | E13: Interconnection of h₁…h₅ (exponentials, δ): BIBO? y for x = e^{−t}u(t) | F13: Convolution practice, interconnections — Lec 4, sl. 2–52 | G13: L9 | H13: 17 | I13: EEE p.1 | J13: ★★★ High | K13: Numerical | L13: ✔ Solved | M13: 2023-24 1(b) | N13: FALSE
A14: 11 | B14: 2023-24 | C14: EEE 211 | D14: 2(a) | E14: Graphical convolution: x = rect on (1,2), h = triangle on (−1,1) | F14: Convolution practice, interconnections — Lec 4, sl. 2–52 | G14: L9 | H14: 18 | I14: EEE p.2 | J14: ★★★ High | K14: Numerical | L14: ✔ Solved | M14: 2022-23 7(b) (EEE); 2021-22 2(a) (EEE); 2020-21 6(b) (EEE); 2019-20 2 (EEE); 2018-19 7(b) (EEE) | N14: FALSE
A15: 12 | B15: 2022-23 | C15: EEE 211 | D15: 7(b) | E15: x(t) = h(t) = t[u(t)−u(t−1)]: y(t) for all t | F15: Convolution practice, interconnections — Lec 4, sl. 2–52 | G15: L9 | H15: 15 | I15: EEE p.11 | J15: ★★★ High | K15: Numerical | L15: ✔ Solved | M15: 2023-24 2(a) (EEE); 2021-22 2(a) (EEE); 2020-21 6(b) (EEE); 2019-20 2 (EEE); 2018-19 7(b) (EEE) | N15: FALSE
A16: 13 | B16: 2022-23 | C16: CSE 219 | D16: 8(a) | E16: Convolve x[n] = 3ⁿu[−n−1] + (1/3)ⁿu[n] with h[n] = (1/4)ⁿu[n+3] | F16: Convolution practice, interconnections — Lec 4, sl. 2–52 | G16: L9 | H16: 20 | I16: 5 | J16: ★★★ High | K16: Numerical | L16: ✔ Solved | M16: — | N16: FALSE
A17: 14 | B17: 2021-22 | C17: EEE 211 | D17: 2(a) | E17: Graphical convolution (triangle x, rectangle-plus-impulse h); analytic y | F17: Convolution practice, interconnections — Lec 4, sl. 2–52 | G17: L9 | H17: 17 | I17: EEE p.12 | J17: ★★★ High | K17: Numerical | L17: ✔ Solved | M17: 2023-24 2(a) (EEE); 2022-23 7(b) (EEE); 2020-21 6(b) (EEE); 2019-20 2 (EEE); 2018-19 7(b) (EEE) | N17: FALSE
A18: 15 | B18: 2020-21 | C18: EEE 211 | D18: 6(b) | E18: Graphical convolution x = rect(t/2), h = r(t)u(1−t) | F18: Convolution practice, interconnections — Lec 4, sl. 2–52 | G18: L9 | H18: 10 | I18: EEE p.20 | J18: ★★★ High | K18: Numerical | L18: ✔ Solved | M18: 2023-24 2(a) (EEE); 2022-23 7(b) (EEE); 2021-22 2(a) (EEE); 2019-20 2 (EEE); 2018-19 7(b) (EEE) | N18: FALSE
A19: 16 | B19: 2019-20 | C19: EEE 211 | D19: 2 | E19: x = rect (0,2), h(t+1) = triangle: causal? y = x*h; what system does; z = x−x(t−4) | F19: Convolution practice, interconnections — Lec 4, sl. 2–52 | G19: L9 | H19: 35 | I19: EEE p.22–23 | J19: ★★★ High | K19: Numerical | L19: ✔ Solved | M19: 2023-24 2(a) (EEE); 2022-23 7(b) (EEE); 2021-22 2(a) (EEE); 2020-21 6(b) (EEE); 2018-19 7(b) (EEE) | N19: FALSE
A20: 17 | B20: 2018-19 | C20: EEE 211 | D20: 7(b) | E20: h = u(t)−u(t−1), x = t²[u(t)−u(t−3)]: graphical convolution | F20: Convolution practice, interconnections — Lec 4, sl. 2–52 | G20: L9 | H20: 15 | I20: EEE p.31 | J20: ★★ Medium | K20: Numerical | L20: ✔ Solved | M20: 2023-24 2(a) (EEE); 2022-23 7(b) (EEE); 2021-22 2(a) (EEE); 2020-21 6(b) (EEE); 2019-20 2 (EEE) | N20: FALSE
A21: 18 | B21: 2023-24 | C21: EEE 211 | D21: 2(b) | E21: Impulse response of a circuit in the time domain | F21: Causality and stability — Lec 4, sl. 53–69 | G21: L10 | H21: 17 | I21: EEE p.2 | J21: ★★★ High | K21: Numerical | L21: ✔ Solved | M21: 2020-21 6(c) (EEE) | N21: FALSE
A22: 19 | B22: 2023-24 | C22: CSE 219 | D22: 3(b) | E22: Causal? stable? e^{−4t}u(3−t), e^{−6|t|}, te^{−t}u(t) | F22: Causality and stability — Lec 4, sl. 53–69 | G22: L10 | H22: 15 | I22: 22 batch p.2 | J22: ★★★ High | K22: Numerical | L22: ✔ Solved | M22: 2022-23 8(b) | N22: FALSE
A23: 20 | B23: 2022-23 | C23: CSE 219 | D23: 8(b) | E23: Causal? stable? h₁ = e^{2t}u(−2−t), h₂ = te^{−t}u(t) | F23: Causality and stability — Lec 4, sl. 53–69 | G23: L10 | H23: 10 | I23: 5 | J23: ★★★ High | K23: Numerical | L23: ✔ Solved | M23: 2023-24 3(b) | N23: FALSE
A24: 21 | B24: 2020-21 | C24: EEE 211 | D24: 6(c) | E24: Series RC, output v_R: impulse response by time-domain analysis | F24: Causality and stability — Lec 4, sl. 53–69 | G24: L10 | H24: 10 | I24: EEE p.20 | J24: ★★★ High | K24: Numerical | L24: ✔ Solved | M24: 2023-24 2(b) (EEE) | N24: FALSE

Sheet 3 Fourier Series
A1: Lec 5–6 — Fourier Series
A2: Note file: CSE219_Anik_Fourier_Series_Notes.docx · Solve after finishing the matching lesson. Filter Priority → ★★★ High first.
A3: Q No. | B3: Year | C3: Course | D3: Ques No. | E3: Short Question | F3: Topic (slide PDF · slides) | G3: Lesson | H3: Marks | I3: TF Page | J3: Priority | K3: Type | L3: In Notes | M3: Same Type Also In | N3: Done | O3: Confidence | P3: Date | Q3: My Notes
A4: 1 | B4: 2023-24 | C4: EEE 211 | D4: 7(a) | E4: Three functions pairwise orthogonal on (−1,2); A for orthonormal | F4: Fourier series idea, orthogonality — Lec 5, sl. 2–23, 44–52 | G4: L11 | H4: 10 | I4: EEE p.4–5 | J4: ★★★ High | K4: Numerical | L4: ✔ Solved | M4: 2021-22 3(b) (EEE); 2018-19 1(a) (EEE) | N4: FALSE
A5: 2 | B5: 2021-22 | C5: EEE 211 | D5: 3(b) | E5: Orthogonal set on (−2,2); orthonormalise; expand x = 1 on [0,2]; Parseval | F5: Fourier series idea, orthogonality — Lec 5, sl. 2–23, 44–52 | G5: L11 | H5: 15 | I5: EEE p.13 | J5: ★★★ High | K5: Numerical | L5: ◐ Method | M5: 2023-24 7(a) (EEE); 2018-19 1(a) (EEE) | N5: FALSE
A6: 3 | B6: 2018-19 | C6: EEE 211 | D6: 1(a) | E6: Orthogonality condition; e^{j2t}, e^{j4t} orthogonal on [0, π]? | F6: Fourier series idea, orthogonality — Lec 5, sl. 2–23, 44–52 | G6: L11 | H6: 10 | I6: EEE p.27 | J6: ★★ Medium | K6: Numerical | L6: ✔ Solved | M6: 2023-24 7(a) (EEE); 2021-22 3(b) (EEE) | N6: FALSE
A7: 4 | B7: 2022-23 | C7: EEE 211 | D7: 5(a) | E7: Compact trig FS of 2+3cos2t+4sin2t+2sin(3t+30°)−cos(7t+150°); amplitude spectrum | F7: Computing FS coefficients — Lec 5, sl. 24–43 | G7: L12 | H7: 10 | I7: EEE p.9 | J7: ★★★ High | K7: Numerical | L7: ✔ Solved | M7: 2020-21 2(b) (CSE 311); 2019-20 1(a) (CSE 311); 2018-19 1(b) (EEE) | N7: FALSE
A8: 5 | B8: 2022-23 | C8: EEE 211 | D8: 7(a) | E8: Exponential FS of the periodic waveform of Fig. 7(a) | F8: Computing FS coefficients — Lec 5, sl. 24–43 | G8: L12 | H8: 20 | I8: EEE p.11 | J8: ★★★ High | K8: Numerical | L8: ◐ Method | M8: 2019-20 8(b) (EEE) | N8: FALSE
A9: 6 | B9: 2020-21 | C9: CSE 311 | D9: 2(b) | E9: Exponential FS coefficients of sin 2πt and cos 2πt; need a full cycle? | F9: Computing FS coefficients — Lec 5, sl. 24–43 | G9: L12 | H9: 17 | I9: 12 | J9: ★★★ High | K9: Numerical | L9: ✔ Solved | M9: 2019-20 1(a) (CSE 311); 2022-23 5(a) (EEE); 2018-19 1(b) (EEE) | N9: FALSE
A10: 7 | B10: 2019-20 | C10: CSE 311 | D10: 1(a) | E10: Why cos/sin 2πf₀t has a FS; are its exp. FS coefficients real or imaginary? | F10: Computing FS coefficients — Lec 5, sl. 24–43 | G10: L12 | H10: 17 | I10: 15 | J10: ★★★ High | K10: Numerical | L10: ✔ Solved | M10: 2020-21 2(b) (CSE 311); 2022-23 5(a) (EEE); 2018-19 1(b) (EEE) | N10: FALSE
A11: 8 | B11: 2019-20 | C11: EEE 211 | D11: 8(b) | E11: Trig FS a₀, aₙ, bₙ of the triangular wave of Fig. 8(b) | F11: Computing FS coefficients — Lec 5, sl. 24–43 | G11: L12 | H11: 20 | I11: EEE p.26 | J11: ★★★ High | K11: Numerical | L11: ✔ Solved | M11: 2022-23 7(a) (EEE) | N11: FALSE
A12: 9 | B12: 2018-19 | C12: EEE 211 | D12: 1(b) | E12: x = 2+½cos(t+45°)+2cos3t−sin(4t+30°): exp FS; magnitude/phase spectra | F12: Computing FS coefficients — Lec 5, sl. 24–43 | G12: L12 | H12: 10 | I12: EEE p.27 | J12: ★★ Medium | K12: Numerical | L12: ✔ Solved | M12: 2020-21 2(b) (CSE 311); 2019-20 1(a) (CSE 311); 2022-23 5(a) (EEE) | N12: FALSE
A13: 10 | B13: 2023-24 | C13: CSE 219 | D13: 4(a) | E13: Odd square wave (±A), y = x(t−T₀/6): half-wave symmetry? | F13: FS properties and symmetry — Lec 6, sl. 2–35 | G13: L13 | H13: 5 | I13: 22 batch p.2 | J13: ★★★ High | K13: Theory | L13: ✔ Solved | M13: 2022-23 1(a) (CSE 311); 2018-19 2(b) (CSE 311) | N13: FALSE
A14: 11 | B14: 2023-24 | C14: CSE 219 | D14: 4(b)–(d) | E14: Y_k of the shifted square wave; magnitude/phase spectra to k=5; compare with trig FS | F14: FS properties and symmetry — Lec 6, sl. 2–35 | G14: L13 | H14: 25 | I14: 22 batch p.2 | J14: ★★★ High | K14: Numerical | L14: ✔ Solved | M14: 2022-23 5(d); 2020-21 7(a) (EEE) | N14: FALSE
A15: 12 | B15: 2022-23 | C15: CSE 311 | D15: 1(a) | E15: FS coefficients: even signal → real, odd → imaginary; cos 2πf₀t | F15: FS properties and symmetry — Lec 6, sl. 2–35 | G15: L13 | H15: 17 | I15: 6 | J15: ★★★ High | K15: Proof | L15: ✔ Solved | M15: 2023-24 4(a); 2018-19 2(b) (CSE 311) | N15: FALSE
A16: 13 | B16: 2022-23 | C16: CSE 219 | D16: 5(d) | E16: x(t) = Σ_{k=0}^{100} (½)^k e^{jk2πt/50}: real-valued? even? | F16: FS properties and symmetry — Lec 6, sl. 2–35 | G16: L13 | H16: 5 | I16: 3 | J16: ★★★ High | K16: Theory | L16: ✔ Solved | M16: 2023-24 4(b)–(d); 2020-21 7(a) (EEE) | N16: FALSE
A17: 14 | B17: 2018-19 | C17: CSE 311 | D17: 2(b) | E17: Even → real, odd → imaginary FS coefficients; half-cycle integration | F17: FS properties and symmetry — Lec 6, sl. 2–35 | G17: L13 | H17: 15 | I17: 18 | J17: ★★ Medium | K17: Proof | L17: ✔ Solved | M17: 2023-24 4(a); 2022-23 1(a) (CSE 311) | N17: FALSE
A18: 15 | B18: 2022-23 | C18: EEE 211 | D18: 8(a) | E18: Trig FS of the impulse train δ_{T0}(t); amplitude spectrum | F18: FS differentiation, impulse trains — Lec 6, sl. 36–72 | G18: L14 | H18: 20 | I18: EEE p.11 | J18: ★★★ High | K18: Numerical | L18: ✔ Solved | M18: 2019-20 7(a) (EEE) | N18: FALSE
A19: 16 | B19: 2020-21 | C19: EEE 211 | D19: 7(a) | E19: Triangle wave x: exp FS; y (rect train) via FS properties; amplitude spectra | F19: FS differentiation, impulse trains — Lec 6, sl. 36–72 | G19: L14 | H19: 20 | I19: EEE p.20 | J19: ★★★ High | K19: Numerical | L19: ✔ Solved | M19: 2022-23 5(d); 2023-24 4(b)–(d) | N19: FALSE
A20: 17 | B20: 2019-20 | C20: EEE 211 | D20: 7(a) | E20: Exponential FS of the two impulse trains of Fig. 7(a) | F20: FS differentiation, impulse trains — Lec 6, sl. 36–72 | G20: L14 | H20: 15 | I20: EEE p.25 | J20: ★★★ High | K20: Numerical | L20: ✔ Solved | M20: 2022-23 8(a) (EEE) | N20: FALSE
A21: 18 | B21: 2023-24 | C21: EEE 211 | D21: 7(b) | E21: Half-wave rectified sine (T=0.5 ms) → differentiator & LPF (1 kHz, gain 5): FS of y₁, y₂(t) | F21: FS multiplication, Parseval, LTI input — Lec 6, sl. 73–81 | G21: L15 | H21: 25 | I21: EEE p.5 | J21: ★★★ High | K21: Numerical | L21: ✔ Solved | M21: 2021-22 3(a) (EEE); 2020-21 7(b) (EEE); 2019-20 5(b) (EEE); 2018-19 1(c) (EEE); 2018-19 3(c) (EEE) | N21: FALSE
A22: 19 | B22: 2021-22 | C22: EEE 211 | D22: 3(a) | E22: Periodic x (T=4) = δ(t−1)+2[u(t−2)−u(t−4)] into LC–R circuit: spectra of x and y | F22: FS multiplication, Parseval, LTI input — Lec 6, sl. 73–81 | G22: L15 | H22: 20 | I22: EEE p.13 | J22: ★★★ High | K22: Numerical | L22: ✔ Solved | M22: 2023-24 7(b) (EEE); 2020-21 7(b) (EEE); 2019-20 5(b) (EEE); 2018-19 1(c) (EEE); 2018-19 3(c) (EEE) | N22: FALSE
A23: 20 | B23: 2020-21 | C23: EEE 211 | D23: 7(b) | E23: y''+3y'+2y = x'+x, x = 2cos t + 6cos 3t: spectra of y; average power | F23: FS multiplication, Parseval, LTI input — Lec 6, sl. 73–81 | G23: L15 | H23: 15 | I23: EEE p.20 | J23: ★★★ High | K23: Numerical | L23: ✔ Solved | M23: 2023-24 7(b) (EEE); 2021-22 3(a) (EEE); 2019-20 5(b) (EEE); 2018-19 1(c) (EEE); 2018-19 3(c) (EEE) | N23: FALSE
A24: 21 | B24: 2019-20 | C24: EEE 211 | D24: 5(b) | E24: Full-wave rectified sin t into RC low-pass (15 Ω, 1/5 F): H(ω), y(t) | F24: FS multiplication, Parseval, LTI input — Lec 6, sl. 73–81 | G24: L15 | H24: 20 | I24: EEE p.24 | J24: ★★★ High | K24: Numerical | L24: ✔ Solved | M24: 2023-24 7(b) (EEE); 2021-22 3(a) (EEE); 2020-21 7(b) (EEE); 2018-19 1(c) (EEE); 2018-19 3(c) (EEE) | N24: FALSE
A25: 22 | B25: 2018-19 | C25: EEE 211 | D25: 1(c) | E25: Triangular wave (T=4, A=4) into R = 100 Ω + L = 0.1 H: power in R | F25: FS multiplication, Parseval, LTI input — Lec 6, sl. 73–81 | G25: L15 | H25: 15 | I25: EEE p.27 | J25: ★★ Medium | K25: Numerical | L25: ◐ Method | M25: 2023-24 7(b) (EEE); 2021-22 3(a) (EEE); 2020-21 7(b) (EEE); 2019-20 5(b) (EEE); 2018-19 3(c) (EEE) | N25: FALSE
A26: 23 | B26: 2018-19 | C26: EEE 211 | D26: 3(c) | E26: C_n = 1 (odd n), T = 2, through band-pass H with ±π/2 phase: h(t), output | F26: FS multiplication, Parseval, LTI input — Lec 6, sl. 73–81 | G26: L15 | H26: 15 | I26: EEE p.28 | J26: ★★ Medium | K26: Numerical | L26: ◐ Method | M26: 2023-24 7(b) (EEE); 2021-22 3(a) (EEE); 2020-21 7(b) (EEE); 2019-20 5(b) (EEE); 2018-19 1(c) (EEE) | N26: FALSE

Sheet 4 Fourier Transform
A1: Lec 7 — Fourier Transform
A2: Note file: CSE219_Anik_Fourier_Transform_Notes.docx · Solve after finishing the matching lesson. Filter Priority → ★★★ High first.
A3: Q No. | B3: Year | C3: Course | D3: Ques No. | E3: Short Question | F3: Topic (slide PDF · slides) | G3: Lesson | H3: Marks | I3: TF Page | J3: Priority | K3: Type | L3: In Notes | M3: Same Type Also In | N3: Done | O3: Confidence | P3: Date | Q3: My Notes
A4: 1 | B4: 2023-24 | C4: EEE 211 | D4: 6(a) | E4: FT of the periodic impulse signal of Fig. 6(a); amplitude & phase spectra | F4: From FS to FT — Lec 7, sl. 2–18 | G4: L16 | H4: 15 | I4: EEE p.4 | J4: ★★★ High | K4: Numerical | L4: ✔ Solved | M4: 2021-22 1(a) (CSE 311); 2021-22 5(a) (EEE) | N4: FALSE
A5: 2 | B5: 2021-22 | C5: CSE 311 | D5: 1(a) | E5: FT of gate of width B and exp. FS of the periodic gate (period 2B); relate | F5: From FS to FT — Lec 7, sl. 2–18 | G5: L16 | H5: 20 | I5: 8 | J5: ★★★ High | K5: Numerical | L5: ✔ Solved | M5: 2023-24 6(a) (EEE); 2021-22 5(a) (EEE) | N5: FALSE
A6: 3 | B6: 2021-22 | C6: EEE 211 | D6: 5(a) | E6: Derive the FT as the T → ∞ limit of the FS | F6: From FS to FT — Lec 7, sl. 2–18 | G6: L16 | H6: 18 | I6: EEE p.14 | J6: ★★★ High | K6: Derivation | L6: ✔ Solved | M6: 2021-22 1(a) (CSE 311); 2023-24 6(a) (EEE) | N6: FALSE
A7: 4 | B7: 2020-21 | C7: CSE 311 | D7: 3(b) | E7: Dirichlet conditions; are they necessary? example | F7: From FS to FT — Lec 7, sl. 2–18 | G7: L16 | H7: 11 | I7: 12 | J7: ★★★ High | K7: Theory | L7: ✔ Solved | M7: — | N7: FALSE
A8: 5 | B8: 2023-24 | C8: CSE 219 | D8: 1(c) | E8: FT of rect(t); FT of rect((t−τ)/T)·cos 2πf₀t | F8: Rectangles, shifts, modulation — Lec 7, sl. 19–44 | G8: L17 | H8: 15 | I8: 22 batch p.2 | J8: ★★★ High | K8: Numerical | L8: ✔ Solved | M8: 2018-19 4(a) (CSE 311); 2023-24 5(a) (EEE); 2022-23 2(b) (EEE); 2022-23 4(a) (EEE); 2021-22 6(a) (EEE); 2020-21 1(b) (EEE); 2018-19 2(c) (EEE) | N8: FALSE
A9: 6 | B9: 2023-24 | C9: EEE 211 | D9: 5(a) | E9: Quadrature multiplexing (ω_c = 4ω_m): design H(jω); spectra u₁, u₂, v₁, v₂, y₂ | F9: Rectangles, shifts, modulation — Lec 7, sl. 19–44 | G9: L17 | H9: 20 | I9: EEE p.3–4 | J9: ★★★ High | K9: Design | L9: ✔ Solved | M9: 2023-24 1(c); 2018-19 4(a) (CSE 311); 2022-23 2(b) (EEE); 2022-23 4(a) (EEE); 2021-22 6(a) (EEE); 2020-21 1(b) (EEE); 2018-19 2(c) (EEE) | N9: FALSE
A10: 7 | B10: 2022-23 | C10: CSE 311 | D10: 1(b) | E10: Spectrum of Π(t/2B); practical spectra; how sampling changes the band | F10: Rectangles, shifts, modulation — Lec 7, sl. 19–44 | G10: L17 | H10: 18 | I10: 6 | J10: ★★★ High | K10: Numerical | L10: ✔ Solved | M10: 2022-23 6(a)–(b); 2022-23 6(c)–(d); 2023-24 2(a); 2019-20 1(b) (CSE 311) | N10: FALSE
A11: 8 | B11: 2022-23 | C11: EEE 211 | D11: 2(b) | E11: AM of a down-sampled signal, filter H_f: spectra of x, y, z; energy of z | F11: Rectangles, shifts, modulation — Lec 7, sl. 19–44 | G11: L17 | H11: 25 | I11: EEE p.8 | J11: ★★★ High | K11: Numerical | L11: ✔ Solved | M11: 2023-24 1(c); 2018-19 4(a) (CSE 311); 2023-24 5(a) (EEE); 2022-23 4(a) (EEE); 2021-22 6(a) (EEE); 2020-21 1(b) (EEE); 2018-19 2(c) (EEE) | N11: FALSE
A12: 9 | B12: 2022-23 | C12: EEE 211 | D12: 4(a) | E12: AM receiver with phase error θ, LPF gain 2: output | F12: Rectangles, shifts, modulation — Lec 7, sl. 19–44 | G12: L17 | H12: 15 | I12: EEE p.9 | J12: ★★★ High | K12: Numerical | L12: ✔ Solved | M12: 2023-24 1(c); 2018-19 4(a) (CSE 311); 2023-24 5(a) (EEE); 2022-23 2(b) (EEE); 2021-22 6(a) (EEE); 2020-21 1(b) (EEE); 2018-19 2(c) (EEE) | N12: FALSE
A13: 10 | B13: 2021-22 | C13: EEE 211 | D13: 6(a) | E13: Band-pass x_a through c = cos10t, h₁, sampler p(t), h₂: spectra x₁…x₄ | F13: Rectangles, shifts, modulation — Lec 7, sl. 19–44 | G13: L17 | H13: 20 | I13: EEE p.14–15 | J13: ★★★ High | K13: Numerical | L13: ✔ Solved | M13: 2023-24 1(c); 2018-19 4(a) (CSE 311); 2023-24 5(a) (EEE); 2022-23 2(b) (EEE); 2022-23 4(a) (EEE); 2020-21 1(b) (EEE); 2018-19 2(c) (EEE) | N13: FALSE
A14: 11 | B14: 2020-21 | C14: EEE 211 | D14: 1(b) | E14: m(t) through H₁, H₂ (Hilbert pair) × cos/sin: spectrum of y, energy by Parseval | F14: Rectangles, shifts, modulation — Lec 7, sl. 19–44 | G14: L17 | H14: 20 | I14: EEE p.17 | J14: ★★★ High | K14: Numerical | L14: ◐ Method | M14: 2023-24 1(c); 2018-19 4(a) (CSE 311); 2023-24 5(a) (EEE); 2022-23 2(b) (EEE); 2022-23 4(a) (EEE); 2021-22 6(a) (EEE); 2018-19 2(c) (EEE) | N14: FALSE
A15: 12 | B15: 2019-20 | C15: CSE 311 | D15: 2(a) | E15: Time delay ↔ linear phase; what if a voice signal lost linear phase? | F15: Rectangles, shifts, modulation — Lec 7, sl. 19–44 | G15: L17 | H15: 24 | I15: 15 | J15: ★★★ High | K15: Proof | L15: ✔ Solved | M15: 2023-24 6(c) (EEE); 2022-23 2(a) (EEE); 2020-21 1(a) (EEE) | N15: FALSE
A16: 13 | B16: 2018-19 | C16: EEE 211 | D16: 2(c) | E16: SSB generation (ω_f = ω_m): spectrum of y; h_f(t); realizable? | F16: Rectangles, shifts, modulation — Lec 7, sl. 19–44 | G16: L17 | H16: 15 | I16: EEE p.28 | J16: ★★ Medium | K16: Numerical | L16: ◐ Method | M16: 2023-24 1(c); 2018-19 4(a) (CSE 311); 2023-24 5(a) (EEE); 2022-23 2(b) (EEE); 2022-23 4(a) (EEE); 2021-22 6(a) (EEE); 2020-21 1(b) (EEE) | N16: FALSE
A17: 14 | B17: 2018-19 | C17: CSE 311 | D17: 4(a) | E17: Frequency-shifting property; FDM; dual technique | F17: Rectangles, shifts, modulation — Lec 7, sl. 19–44 | G17: L17 | H17: 18 | I17: 18 | J17: ★★ Medium | K17: Theory | L17: ✔ Solved | M17: 2023-24 1(c); 2023-24 5(a) (EEE); 2022-23 2(b) (EEE); 2022-23 4(a) (EEE); 2021-22 6(a) (EEE); 2020-21 1(b) (EEE); 2018-19 2(c) (EEE) | N17: FALSE
A18: 15 | B18: 2023-24 | C18: CSE 219 | D18: 2(a) | E18: FT of x₁ = e^{−at}u(t), then of x₂ = e^{−a|t|} | F18: FT pairs and properties — Lec 7 + textbook | G18: L18 | H18: 10 | I18: 22 batch p.2 | J18: ★★★ High | K18: Numerical | L18: ✔ Solved | M18: 2022-23 6(a)–(b); 2022-23 6(c)–(d); 2022-23 1(b) (CSE 311); 2019-20 1(b) (CSE 311) | N18: FALSE
A19: 16 | B19: 2023-24 | C19: CSE 219 | D19: 2(b) | E19: Evaluate I(a) = ∫ f²/(a²+(2πf)²)² df using Parseval | F19: FT pairs and properties — Lec 7 + textbook | G19: L18 | H19: 20 | I19: 22 batch p.2 | J19: ★★★ High | K19: Numerical | L19: ✔ Solved | M19: 2023-24 6(b) (EEE); 2018-19 2(a) (EEE) | N19: FALSE
A20: 17 | B20: 2023-24 | C20: EEE 211 | D20: 6(b) | E20: FT of sin(at)/(πt); energy by Parseval | F20: FT pairs and properties — Lec 7 + textbook | G20: L18 | H20: 10 | I20: EEE p.4 | J20: ★★★ High | K20: Numerical | L20: ✔ Solved | M20: 2023-24 2(b); 2018-19 2(a) (EEE) | N20: FALSE
A21: 18 | B21: 2023-24 | C21: EEE 211 | D21: 6(c) | E21: FT of u(t); prove the integration property | F21: FT pairs and properties — Lec 7 + textbook | G21: L18 | H21: 10 | I21: EEE p.4 | J21: ★★★ High | K21: Derivation | L21: ✔ Solved | M21: 2019-20 2(a) (CSE 311); 2022-23 2(a) (EEE); 2020-21 1(a) (EEE) | N21: FALSE
A22: 19 | B22: 2022-23 | C22: CSE 311 | D22: 2(a) | E22: Prove g*h ↔ G(f)H(f); LTI output is a convolution | F22: FT pairs and properties — Lec 7 + textbook | G22: L18 | H22: 20 | I22: 6 | J22: ★★★ High | K22: Proof | L22: ✔ Solved | M22: — | N22: FALSE
A23: 20 | B23: 2022-23 | C23: EEE 211 | D23: 2(a) | E23: Closed-form FT of x(t) (ramp 0→1, flat to 2) | F23: FT pairs and properties — Lec 7 + textbook | G23: L18 | H23: 10 | I23: EEE p.8 | J23: ★★★ High | K23: Numerical | L23: ✔ Solved | M23: 2019-20 2(a) (CSE 311); 2023-24 6(c) (EEE); 2020-21 1(a) (EEE) | N23: FALSE
A24: 21 | B24: 2022-23 | C24: CSE 219 | D24: 5(b) | E24: X(jω)=1 for |ω|<3π and X₁(jω) of Fig. 1: define X₁, inverse FT, X₁ via X, x₁ via x, x₁(t) | F24: FT pairs and properties — Lec 7 + textbook | G24: L18 | H24: 20 | I24: 2–3 | J24: ★★★ High | K24: Numerical | L24: ✔ Solved | M24: 2021-22 5(b) (EEE) | N24: FALSE
A25: 22 | B25: 2022-23 | C25: CSE 219 | D25: 6(a)–(b) | E25: f(t) = e^{−at}u(t): define f(−t); FT of f(t) and f(−t) | F25: FT pairs and properties — Lec 7 + textbook | G25: L18 | H25: 15 | I25: 3 | J25: ★★★ High | K25: Numerical | L25: ✔ Solved | M25: 2022-23 6(c)–(d); 2023-24 2(a); 2022-23 1(b) (CSE 311); 2019-20 1(b) (CSE 311) | N25: FALSE
A26: 23 | B26: 2022-23 | C26: CSE 219 | D26: 6(c)–(d) | E26: Write sign(t) using f(t), f(−t); FT of sign(t) by properties | F26: FT pairs and properties — Lec 7 + textbook | G26: L18 | H26: 15 | I26: 3 | J26: ★★★ High | K26: Numerical | L26: ✔ Solved | M26: 2022-23 6(a)–(b); 2023-24 2(a); 2022-23 1(b) (CSE 311); 2019-20 1(b) (CSE 311) | N26: FALSE
A27: 24 | B27: 2021-22 | C27: CSE 311 | D27: 3(a) | E27: Time compression ↔ frequency expansion (quantization part is comms) | F27: FT pairs and properties — Lec 7 + textbook | G27: L18 | H27: 20 | I27: 8 | J27: ★★★ High | K27: Theory | L27: ✔ Solved | M27: — | N27: FALSE
A28: 25 | B28: 2021-22 | C28: EEE 211 | D28: 5(b) | E28: Inverse FT of the piecewise-constant X(ω) of Fig. 5(b) | F28: FT pairs and properties — Lec 7 + textbook | G28: L18 | H28: 17 | I28: EEE p.14 | J28: ★★★ High | K28: Numerical | L28: ✔ Solved | M28: 2022-23 5(b) | N28: FALSE
A29: 26 | B29: 2020-21 | C29: EEE 211 | D29: 1(a) | E29: X(ω) = jω/(ω²−3jω−2): FT of (dx/dt)·cos t | F29: FT pairs and properties — Lec 7 + textbook | G29: L18 | H29: 15 | I29: EEE p.17 | J29: ★★★ High | K29: Numerical | L29: ✔ Solved | M29: 2019-20 2(a) (CSE 311); 2023-24 6(c) (EEE); 2022-23 2(a) (EEE) | N29: FALSE
A30: 27 | B30: 2019-20 | C30: CSE 311 | D30: 1(b) | E30: FT of cos/sin 2πf₀t; Dirichlet; necessity for FT existence | F30: FT pairs and properties — Lec 7 + textbook | G30: L18 | H30: 18 | I30: 15 | J30: ★★★ High | K30: Numerical | L30: ✔ Solved | M30: 2022-23 6(a)–(b); 2022-23 6(c)–(d); 2023-24 2(a); 2022-23 1(b) (CSE 311) | N30: FALSE
A31: 28 | B31: 2019-20 | C31: EEE 211 | D31: 6(b) | E31: State and prove the duality property | F31: FT pairs and properties — Lec 7 + textbook | G31: L18 | H31: 20 | I31: EEE p.25 | J31: ★★★ High | K31: Proof | L31: ✔ Solved | M31: — | N31: FALSE
A32: 29 | B32: 2018-19 | C32: EEE 211 | D32: 2(a) | E32: Prove E = (1/2π)∫|X|²dω; energy of sinc(t/2) | F32: FT pairs and properties — Lec 7 + textbook | G32: L18 | H32: 10 | I32: EEE p.27 | J32: ★★ Medium | K32: Proof | L32: ✔ Solved | M32: 2023-24 2(b); 2023-24 6(b) (EEE) | N32: FALSE
A33: 30 | B33: 2022-23 | C33: CSE 311 | D33: 2(b) | E33: Distortionless vs all-pass system; how to test distortionless | F33: LTI in frequency, filters, bandwidth — Lec 7, sl. 45–59 + textbook | G33: L19 | H33: 15 | I33: 6 | J33: ★★★ High | K33: Theory | L33: ✔ Solved | M33: 2021-22 2(a) (CSE 311); 2020-21 4(a) (CSE 311); 2018-19 1(b) (CSE 311) | N33: FALSE
A34: 31 | B34: 2021-22 | C34: CSE 311 | D34: 2(a) | E34: All-pass vs distortionless; frequency response; why ideal filters are unrealizable | F34: LTI in frequency, filters, bandwidth — Lec 7, sl. 45–59 + textbook | G34: L19 | H34: 20 | I34: 8 | J34: ★★★ High | K34: Theory | L34: ✔ Solved | M34: 2022-23 2(b) (CSE 311); 2020-21 4(a) (CSE 311); 2018-19 1(b) (CSE 311) | N34: FALSE
A35: 32 | B35: 2021-22 | C35: CSE 311 | D35: 6(a) | E35: Power spectral density; power from PSD | F35: LTI in frequency, filters, bandwidth — Lec 7, sl. 45–59 + textbook | G35: L19 | H35: 5 | I35: 10 | J35: ★★★ High | K35: Theory | L35: ✔ Solved | M35: 2020-21 2(a) (EEE) | N35: FALSE
A36: 33 | B36: 2021-22 | C36: EEE 211 | D36: 6(b) | E36: h = e^{2t}u(−t): 3-dB bandwidth, 1/e duration, product | F36: LTI in frequency, filters, bandwidth — Lec 7, sl. 45–59 + textbook | G36: L19 | H36: 15 | I36: EEE p.15 | J36: ★★★ High | K36: Numerical | L36: ✔ Solved | M36: 2020-21 2(b) (EEE); 2019-20 6(a) (EEE) | N36: FALSE
A37: 34 | B37: 2020-21 | C37: EEE 211 | D37: 2(a) | E37: PSD of Σδ(t−nT) | F37: LTI in frequency, filters, bandwidth — Lec 7, sl. 45–59 + textbook | G37: L19 | H37: 8 | I37: EEE p.17 | J37: ★★★ High | K37: Numerical | L37: ✔ Solved | M37: 2021-22 6(a) (CSE 311) | N37: FALSE
A38: 35 | B38: 2020-21 | C38: EEE 211 | D38: 2(b) | E38: 3-dB bandwidth of e^{−3t}u(t) | F38: LTI in frequency, filters, bandwidth — Lec 7, sl. 45–59 + textbook | G38: L19 | H38: 7 | I38: EEE p.17 | J38: ★★★ High | K38: Numerical | L38: ✔ Solved | M38: 2021-22 6(b) (EEE); 2019-20 6(a) (EEE) | N38: FALSE
A39: 36 | B39: 2020-21 | C39: EEE 211 | D39: 2(c) | E39: Causal y''+6y'+8y = 2x: H(ω); response to te^{−2t}u(t) | F39: LTI in frequency, filters, bandwidth — Lec 7, sl. 45–59 + textbook | G39: L19 | H39: 20 | I39: EEE p.17 | J39: ★★★ High | K39: Numerical | L39: ✔ Solved | M39: 2018-19 4(a) (EEE) | N39: FALSE
A40: 37 | B40: 2020-21 | C40: CSE 311 | D40: 4(a) | E40: Characteristics of a distortionless system and their physical meaning | F40: LTI in frequency, filters, bandwidth — Lec 7, sl. 45–59 + textbook | G40: L19 | H40: 20 | I40: 12 | J40: ★★★ High | K40: Theory | L40: ✔ Solved | M40: 2022-23 2(b) (CSE 311); 2021-22 2(a) (CSE 311); 2018-19 1(b) (CSE 311) | N40: FALSE
...
