Workbook

Sheet How to Use
B2: CSE 213 (IJ Mam part) — TF Practice Tracker
B3: Every IJ-part question in CSE 213 All Past Papers.pdf, mapped to the note file and lesson that teaches it.
B5: Workflow — after you finish a note file
B6: 1. Open its tab | C6: Tabs 1–6 follow the order of your note files. Q No. runs lesson by lesson, newest year first inside each lesson.
B7: 2. Filter | C7: Use the filter arrow on Priority → ★★★ High first (2019-20 onward). Then ★★ Medium, then ★ Low.
B8: 3. Solve | C8: Open CSE 213 All Past Papers.pdf at the TF Page shown. Solve on paper under exam time (≈1.5 min per mark). Do not read the note solution first.
B9: 4. Check | C9: In Notes tells you what the note has: ✔ Solved = same question worked out; ◐ Method = method / model answer you can apply; ○ Partly = notes cover most of it, finish the rest yourself.
B10: 5. Record | C10: Tick Done, pick Confidence, add the Date. Write mistakes in My Notes. Re-solve every 'Weak' row before the exam.
B11: 6. Repeats | C11: 'Same Type Also In' lists other papers with the same question type. Solve one, then try a repeat cold — that is the real test.
B13: Columns you edit (all others are fixed data)
B14: Done (col N) | C14: TRUE / FALSE. In Google Sheets: select N4 downward → Insert → Checkbox. The values stay; ticking turns the row green.
B15: Confidence (col O) | C15: Dropdown: Weak / OK / Strong. Weak rows turn the cell red.
B16: Date (col P) | C16: Date you solved it, e.g. 16-Oct-2026.
B17: My Notes (col Q) | C17: Mistakes, missing steps, formula you forgot.
B19: Legend
B20: ★★★ High | C20: Asked in 2019-20 or later (most important — current question style).
B21: ★★ Medium | C21: Older paper, but the same question type appears at least twice in TF.
B22: ★ Low | C22: Older paper, asked once.
B23: Type | C23: Numerical = calculation · Trace = tables / step-by-step simulation · Design = construct / draw · Proof = prove / disprove · Theory = explain.
B24: Course | C24: CSE 213 = current code (2023-24 onward); CSE 307 = old L-3/T-1 code for the same course. '2024-25' = the 22-batch paper (exam 10/05/2026, header says 2023-2024), separate file 'CSE 213 (22 batch).pdf' → TF Page '22 batch p.N'.
B25: Topic | C25: Note lesson title — slide PDF and slide numbers.
B26: Outside Notes tab | C26: IJ-section questions from older papers on topics not in the current slides. Check with your teacher before spending time on them.

Sheet Dashboard
A1: Progress Dashboard
A2: Updates automatically when you tick Done / set Confidence in tabs 1–6.
A4: # | B4: Note file (tab) | C4: Questions | D4: Done | E4: % Done | F4: Marks (total) | G4: Marks done | H4: High-priority left | I4: Weak | J4: Next unsolved (top of tab)
A5: 1 | B5: 1 Structural Patterns | C5: =COUNTA('1 Structural Patterns'!$E$4:$E$14) | D5: =COUNTIF('1 Structural Patterns'!$N$4:$N$14,TRUE()) | E5: =IF(C5=0,0,D5/C5) | F5: =SUM('1 Structural Patterns'!$H$4:$H$14) | G5: =SUMIF('1 Structural Patterns'!$N$4:$N$14,TRUE(),'1 Structural Patterns'!$H$4:$H$14) | H5: =COUNTIFS('1 Structural Patterns'!$J$4:$J$14,"★★★ High",'1 Structural Patterns'!$N$4:$N$14,FALSE()) | I5: =COUNTIF('1 Structural Patterns'!$O$4:$O$14,"Weak") | J5: =IFERROR("Q"&INDEX('1 Structural Patterns'!$A$4:$A$14,MATCH(FALSE(),'1 Structural Patterns'!$N$4:$N$14,0))&" · "&INDEX('1 Structural Patterns'!$B$4:$B$14,MATCH(FALSE(),'1 Structural Patterns'!$N$4:$N$14,0))&" "&INDEX('1 Structural Patterns'!$D$4:$D$14,MATCH(FALSE(),'1 Structural Patterns'!$N$4:$N$14,0))&" · TF p."&INDEX('1 Structural Patterns'!$I$4:$I$14,MATCH(FALSE(),'1 Structural Patterns'!$N$4:$N$14,0)),"All done ✔")
A6: 2 | B6: 2 Behavioral Patterns | C6: =COUNTA('2 Behavioral Patterns'!$E$4:$E$21) | D6: =COUNTIF('2 Behavioral Patterns'!$N$4:$N$21,TRUE()) | E6: =IF(C6=0,0,D6/C6) | F6: =SUM('2 Behavioral Patterns'!$H$4:$H$21) | G6: =SUMIF('2 Behavioral Patterns'!$N$4:$N$21,TRUE(),'2 Behavioral Patterns'!$H$4:$H$21) | H6: =COUNTIFS('2 Behavioral Patterns'!$J$4:$J$21,"★★★ High",'2 Behavioral Patterns'!$N$4:$N$21,FALSE()) | I6: =COUNTIF('2 Behavioral Patterns'!$O$4:$O$21,"Weak") | J6: =IFERROR("Q"&INDEX('2 Behavioral Patterns'!$A$4:$A$21,MATCH(FALSE(),'2 Behavioral Patterns'!$N$4:$N$21,0))&" · "&INDEX('2 Behavioral Patterns'!$B$4:$B$21,MATCH(FALSE(),'2 Behavioral Patterns'!$N$4:$N$21,0))&" "&INDEX('2 Behavioral Patterns'!$D$4:$D$21,MATCH(FALSE(),'2 Behavioral Patterns'!$N$4:$N$21,0))&" · TF p."&INDEX('2 Behavioral Patterns'!$I$4:$I$21,MATCH(FALSE(),'2 Behavioral Patterns'!$N$4:$N$21,0)),"All done ✔")
A7: 3 | B7: 3 Process + Agile | C7: =COUNTA('3 Process + Agile'!$E$4:$E$43) | D7: =COUNTIF('3 Process + Agile'!$N$4:$N$43,TRUE()) | E7: =IF(C7=0,0,D7/C7) | F7: =SUM('3 Process + Agile'!$H$4:$H$43) | G7: =SUMIF('3 Process + Agile'!$N$4:$N$43,TRUE(),'3 Process + Agile'!$H$4:$H$43) | H7: =COUNTIFS('3 Process + Agile'!$J$4:$J$43,"★★★ High",'3 Process + Agile'!$N$4:$N$43,FALSE()) | I7: =COUNTIF('3 Process + Agile'!$O$4:$O$43,"Weak") | J7: =IFERROR("Q"&INDEX('3 Process + Agile'!$A$4:$A$43,MATCH(FALSE(),'3 Process + Agile'!$N$4:$N$43,0))&" · "&INDEX('3 Process + Agile'!$B$4:$B$43,MATCH(FALSE(),'3 Process + Agile'!$N$4:$N$43,0))&" "&INDEX('3 Process + Agile'!$D$4:$D$43,MATCH(FALSE(),'3 Process + Agile'!$N$4:$N$43,0))&" · TF p."&INDEX('3 Process + Agile'!$I$4:$I$43,MATCH(FALSE(),'3 Process + Agile'!$N$4:$N$43,0)),"All done ✔")
A8: 4 | B8: 4 Unit Testing + Review | C8: =COUNTA('4 Unit Testing + Review'!$E$4:$E$19) | D8: =COUNTIF('4 Unit Testing + Review'!$N$4:$N$19,TRUE()) | E8: =IF(C8=0,0,D8/C8) | F8: =SUM('4 Unit Testing + Review'!$H$4:$H$19) | G8: =SUMIF('4 Unit Testing + Review'!$N$4:$N$19,TRUE(),'4 Unit Testing + Review'!$H$4:$H$19) | H8: =COUNTIFS('4 Unit Testing + Review'!$J$4:$J$19,"★★★ High",'4 Unit Testing + Review'!$N$4:$N$19,FALSE()) | I8: =COUNTIF('4 Unit Testing + Review'!$O$4:$O$19,"Weak") | J8: =IFERROR("Q"&INDEX('4 Unit Testing + Review'!$A$4:$A$19,MATCH(FALSE(),'4 Unit Testing + Review'!$N$4:$N$19,0))&" · "&INDEX('4 Unit Testing + Review'!$B$4:$B$19,MATCH(FALSE(),'4 Unit Testing + Review'!$N$4:$N$19,0))&" "&INDEX('4 Unit Testing + Review'!$D$4:$D$19,MATCH(FALSE(),'4 Unit Testing + Review'!$N$4:$N$19,0))&" · TF p."&INDEX('4 Unit Testing + Review'!$I$4:$I$19,MATCH(FALSE(),'4 Unit Testing + Review'!$N$4:$N$19,0)),"All done ✔")
A9: 5 | B9: 5 Refactoring | C9: =COUNTA('5 Refactoring'!$E$4:$E$12) | D9: =COUNTIF('5 Refactoring'!$N$4:$N$12,TRUE()) | E9: =IF(C9=0,0,D9/C9) | F9: =SUM('5 Refactoring'!$H$4:$H$12) | G9: =SUMIF('5 Refactoring'!$N$4:$N$12,TRUE(),'5 Refactoring'!$H$4:$H$12) | H9: =COUNTIFS('5 Refactoring'!$J$4:$J$12,"★★★ High",'5 Refactoring'!$N$4:$N$12,FALSE()) | I9: =COUNTIF('5 Refactoring'!$O$4:$O$12,"Weak") | J9: =IFERROR("Q"&INDEX('5 Refactoring'!$A$4:$A$12,MATCH(FALSE(),'5 Refactoring'!$N$4:$N$12,0))&" · "&INDEX('5 Refactoring'!$B$4:$B$12,MATCH(FALSE(),'5 Refactoring'!$N$4:$N$12,0))&" "&INDEX('5 Refactoring'!$D$4:$D$12,MATCH(FALSE(),'5 Refactoring'!$N$4:$N$12,0))&" · TF p."&INDEX('5 Refactoring'!$I$4:$I$12,MATCH(FALSE(),'5 Refactoring'!$N$4:$N$12,0)),"All done ✔")
A10: 6 | B10: 6 Ethics + Requirements | C10: =COUNTA('6 Ethics + Requirements'!$E$4:$E$19) | D10: =COUNTIF('6 Ethics + Requirements'!$N$4:$N$19,TRUE()) | E10: =IF(C10=0,0,D10/C10) | F10: =SUM('6 Ethics + Requirements'!$H$4:$H$19) | G10: =SUMIF('6 Ethics + Requirements'!$N$4:$N$19,TRUE(),'6 Ethics + Requirements'!$H$4:$H$19) | H10: =COUNTIFS('6 Ethics + Requirements'!$J$4:$J$19,"★★★ High",'6 Ethics + Requirements'!$N$4:$N$19,FALSE()) | I10: =COUNTIF('6 Ethics + Requirements'!$O$4:$O$19,"Weak") | J10: =IFERROR("Q"&INDEX('6 Ethics + Requirements'!$A$4:$A$19,MATCH(FALSE(),'6 Ethics + Requirements'!$N$4:$N$19,0))&" · "&INDEX('6 Ethics + Requirements'!$B$4:$B$19,MATCH(FALSE(),'6 Ethics + Requirements'!$N$4:$N$19,0))&" "&INDEX('6 Ethics + Requirements'!$D$4:$D$19,MATCH(FALSE(),'6 Ethics + Requirements'!$N$4:$N$19,0))&" · TF p."&INDEX('6 Ethics + Requirements'!$I$4:$I$19,MATCH(FALSE(),'6 Ethics + Requirements'!$N$4:$N$19,0)),"All done ✔")
B11: TOTAL | C11: =SUM(C5:C10) | D11: =SUM(D5:D10) | E11: =IF(C11=0,0,D11/C11) | F11: =SUM(F5:F10) | G11: =SUM(G5:G10) | H11: =SUM(H5:H10) | I11: =SUM(I5:I10)
A13: Questions by year (tabs 1–6)
A14: # | B14: Year | C14: Questions | D14: Done | E14: % Done | F14: Marks (total)
A15: 1 | B15: 2024-25 | C15: =COUNTIF('1 Structural Patterns'!$B$4:$B$14,$B15)+COUNTIF('2 Behavioral Patterns'!$B$4:$B$21,$B15)+COUNTIF('3 Process + Agile'!$B$4:$B$43,$B15)+COUNTIF('4 Unit Testing + Review'!$B$4:$B$19,$B15)+COUNTIF('5 Refactoring'!$B$4:$B$12,$B15)+COUNTIF('6 Ethics + Requirements'!$B$4:$B$19,$B15) | D15: =COUNTIFS('1 Structural Patterns'!$B$4:$B$14,$B15,'1 Structural Patterns'!$N$4:$N$14,TRUE())+COUNTIFS('2 Behavioral Patterns'!$B$4:$B$21,$B15,'2 Behavioral Patterns'!$N$4:$N$21,TRUE())+COUNTIFS('3 Process + Agile'!$B$4:$B$43,$B15,'3 Process + Agile'!$N$4:$N$43,TRUE())+COUNTIFS('4 Unit Testing + Review'!$B$4:$B$19,$B15,'4 Unit Testing + Review'!$N$4:$N$19,TRUE())+COUNTIFS('5 Refactoring'!$B$4:$B$12,$B15,'5 Refactoring'!$N$4:$N$12,TRUE())+COUNTIFS('6 Ethics + Requirements'!$B$4:$B$19,$B15,'6 Ethics + Requirements'!$N$4:$N$19,TRUE()) | E15: =IF(C15=0,0,D15/C15) | F15: =SUMIF('1 Structural Patterns'!$B$4:$B$14,$B15,'1 Structural Patterns'!$H$4:$H$14)+SUMIF('2 Behavioral Patterns'!$B$4:$B$21,$B15,'2 Behavioral Patterns'!$H$4:$H$21)+SUMIF('3 Process + Agile'!$B$4:$B$43,$B15,'3 Process + Agile'!$H$4:$H$43)+SUMIF('4 Unit Testing + Review'!$B$4:$B$19,$B15,'4 Unit Testing + Review'!$H$4:$H$19)+SUMIF('5 Refactoring'!$B$4:$B$12,$B15,'5 Refactoring'!$H$4:$H$12)+SUMIF('6 Ethics + Requirements'!$B$4:$B$19,$B15,'6 Ethics + Requirements'!$H$4:$H$19)
A16: 2 | B16: 2023-24 | C16: =COUNTIF('1 Structural Patterns'!$B$4:$B$14,$B16)+COUNTIF('2 Behavioral Patterns'!$B$4:$B$21,$B16)+COUNTIF('3 Process + Agile'!$B$4:$B$43,$B16)+COUNTIF('4 Unit Testing + Review'!$B$4:$B$19,$B16)+COUNTIF('5 Refactoring'!$B$4:$B$12,$B16)+COUNTIF('6 Ethics + Requirements'!$B$4:$B$19,$B16) | D16: =COUNTIFS('1 Structural Patterns'!$B$4:$B$14,$B16,'1 Structural Patterns'!$N$4:$N$14,TRUE())+COUNTIFS('2 Behavioral Patterns'!$B$4:$B$21,$B16,'2 Behavioral Patterns'!$N$4:$N$21,TRUE())+COUNTIFS('3 Process + Agile'!$B$4:$B$43,$B16,'3 Process + Agile'!$N$4:$N$43,TRUE())+COUNTIFS('4 Unit Testing + Review'!$B$4:$B$19,$B16,'4 Unit Testing + Review'!$N$4:$N$19,TRUE())+COUNTIFS('5 Refactoring'!$B$4:$B$12,$B16,'5 Refactoring'!$N$4:$N$12,TRUE())+COUNTIFS('6 Ethics + Requirements'!$B$4:$B$19,$B16,'6 Ethics + Requirements'!$N$4:$N$19,TRUE()) | E16: =IF(C16=0,0,D16/C16) | F16: =SUMIF('1 Structural Patterns'!$B$4:$B$14,$B16,'1 Structural Patterns'!$H$4:$H$14)+SUMIF('2 Behavioral Patterns'!$B$4:$B$21,$B16,'2 Behavioral Patterns'!$H$4:$H$21)+SUMIF('3 Process + Agile'!$B$4:$B$43,$B16,'3 Process + Agile'!$H$4:$H$43)+SUMIF('4 Unit Testing + Review'!$B$4:$B$19,$B16,'4 Unit Testing + Review'!$H$4:$H$19)+SUMIF('5 Refactoring'!$B$4:$B$12,$B16,'5 Refactoring'!$H$4:$H$12)+SUMIF('6 Ethics + Requirements'!$B$4:$B$19,$B16,'6 Ethics + Requirements'!$H$4:$H$19)
A17: 3 | B17: 2022-23 | C17: =COUNTIF('1 Structural Patterns'!$B$4:$B$14,$B17)+COUNTIF('2 Behavioral Patterns'!$B$4:$B$21,$B17)+COUNTIF('3 Process + Agile'!$B$4:$B$43,$B17)+COUNTIF('4 Unit Testing + Review'!$B$4:$B$19,$B17)+COUNTIF('5 Refactoring'!$B$4:$B$12,$B17)+COUNTIF('6 Ethics + Requirements'!$B$4:$B$19,$B17) | D17: =COUNTIFS('1 Structural Patterns'!$B$4:$B$14,$B17,'1 Structural Patterns'!$N$4:$N$14,TRUE())+COUNTIFS('2 Behavioral Patterns'!$B$4:$B$21,$B17,'2 Behavioral Patterns'!$N$4:$N$21,TRUE())+COUNTIFS('3 Process + Agile'!$B$4:$B$43,$B17,'3 Process + Agile'!$N$4:$N$43,TRUE())+COUNTIFS('4 Unit Testing + Review'!$B$4:$B$19,$B17,'4 Unit Testing + Review'!$N$4:$N$19,TRUE())+COUNTIFS('5 Refactoring'!$B$4:$B$12,$B17,'5 Refactoring'!$N$4:$N$12,TRUE())+COUNTIFS('6 Ethics + Requirements'!$B$4:$B$19,$B17,'6 Ethics + Requirements'!$N$4:$N$19,TRUE()) | E17: =IF(C17=0,0,D17/C17) | F17: =SUMIF('1 Structural Patterns'!$B$4:$B$14,$B17,'1 Structural Patterns'!$H$4:$H$14)+SUMIF('2 Behavioral Patterns'!$B$4:$B$21,$B17,'2 Behavioral Patterns'!$H$4:$H$21)+SUMIF('3 Process + Agile'!$B$4:$B$43,$B17,'3 Process + Agile'!$H$4:$H$43)+SUMIF('4 Unit Testing + Review'!$B$4:$B$19,$B17,'4 Unit Testing + Review'!$H$4:$H$19)+SUMIF('5 Refactoring'!$B$4:$B$12,$B17,'5 Refactoring'!$H$4:$H$12)+SUMIF('6 Ethics + Requirements'!$B$4:$B$19,$B17,'6 Ethics + Requirements'!$H$4:$H$19)
A18: 4 | B18: 2021-22 | C18: =COUNTIF('1 Structural Patterns'!$B$4:$B$14,$B18)+COUNTIF('2 Behavioral Patterns'!$B$4:$B$21,$B18)+COUNTIF('3 Process + Agile'!$B$4:$B$43,$B18)+COUNTIF('4 Unit Testing + Review'!$B$4:$B$19,$B18)+COUNTIF('5 Refactoring'!$B$4:$B$12,$B18)+COUNTIF('6 Ethics + Requirements'!$B$4:$B$19,$B18) | D18: =COUNTIFS('1 Structural Patterns'!$B$4:$B$14,$B18,'1 Structural Patterns'!$N$4:$N$14,TRUE())+COUNTIFS('2 Behavioral Patterns'!$B$4:$B$21,$B18,'2 Behavioral Patterns'!$N$4:$N$21,TRUE())+COUNTIFS('3 Process + Agile'!$B$4:$B$43,$B18,'3 Process + Agile'!$N$4:$N$43,TRUE())+COUNTIFS('4 Unit Testing + Review'!$B$4:$B$19,$B18,'4 Unit Testing + Review'!$N$4:$N$19,TRUE())+COUNTIFS('5 Refactoring'!$B$4:$B$12,$B18,'5 Refactoring'!$N$4:$N$12,TRUE())+COUNTIFS('6 Ethics + Requirements'!$B$4:$B$19,$B18,'6 Ethics + Requirements'!$N$4:$N$19,TRUE()) | E18: =IF(C18=0,0,D18/C18) | F18: =SUMIF('1 Structural Patterns'!$B$4:$B$14,$B18,'1 Structural Patterns'!$H$4:$H$14)+SUMIF('2 Behavioral Patterns'!$B$4:$B$21,$B18,'2 Behavioral Patterns'!$H$4:$H$21)+SUMIF('3 Process + Agile'!$B$4:$B$43,$B18,'3 Process + Agile'!$H$4:$H$43)+SUMIF('4 Unit Testing + Review'!$B$4:$B$19,$B18,'4 Unit Testing + Review'!$H$4:$H$19)+SUMIF('5 Refactoring'!$B$4:$B$12,$B18,'5 Refactoring'!$H$4:$H$12)+SUMIF('6 Ethics + Requirements'!$B$4:$B$19,$B18,'6 Ethics + Requirements'!$H$4:$H$19)
A19: 5 | B19: 2020-21 | C19: =COUNTIF('1 Structural Patterns'!$B$4:$B$14,$B19)+COUNTIF('2 Behavioral Patterns'!$B$4:$B$21,$B19)+COUNTIF('3 Process + Agile'!$B$4:$B$43,$B19)+COUNTIF('4 Unit Testing + Review'!$B$4:$B$19,$B19)+COUNTIF('5 Refactoring'!$B$4:$B$12,$B19)+COUNTIF('6 Ethics + Requirements'!$B$4:$B$19,$B19) | D19: =COUNTIFS('1 Structural Patterns'!$B$4:$B$14,$B19,'1 Structural Patterns'!$N$4:$N$14,TRUE())+COUNTIFS('2 Behavioral Patterns'!$B$4:$B$21,$B19,'2 Behavioral Patterns'!$N$4:$N$21,TRUE())+COUNTIFS('3 Process + Agile'!$B$4:$B$43,$B19,'3 Process + Agile'!$N$4:$N$43,TRUE())+COUNTIFS('4 Unit Testing + Review'!$B$4:$B$19,$B19,'4 Unit Testing + Review'!$N$4:$N$19,TRUE())+COUNTIFS('5 Refactoring'!$B$4:$B$12,$B19,'5 Refactoring'!$N$4:$N$12,TRUE())+COUNTIFS('6 Ethics + Requirements'!$B$4:$B$19,$B19,'6 Ethics + Requirements'!$N$4:$N$19,TRUE()) | E19: =IF(C19=0,0,D19/C19) | F19: =SUMIF('1 Structural Patterns'!$B$4:$B$14,$B19,'1 Structural Patterns'!$H$4:$H$14)+SUMIF('2 Behavioral Patterns'!$B$4:$B$21,$B19,'2 Behavioral Patterns'!$H$4:$H$21)+SUMIF('3 Process + Agile'!$B$4:$B$43,$B19,'3 Process + Agile'!$H$4:$H$43)+SUMIF('4 Unit Testing + Review'!$B$4:$B$19,$B19,'4 Unit Testing + Review'!$H$4:$H$19)+SUMIF('5 Refactoring'!$B$4:$B$12,$B19,'5 Refactoring'!$H$4:$H$12)+SUMIF('6 Ethics + Requirements'!$B$4:$B$19,$B19,'6 Ethics + Requirements'!$H$4:$H$19)
A20: 6 | B20: 2019-20 | C20: =COUNTIF('1 Structural Patterns'!$B$4:$B$14,$B20)+COUNTIF('2 Behavioral Patterns'!$B$4:$B$21,$B20)+COUNTIF('3 Process + Agile'!$B$4:$B$43,$B20)+COUNTIF('4 Unit Testing + Review'!$B$4:$B$19,$B20)+COUNTIF('5 Refactoring'!$B$4:$B$12,$B20)+COUNTIF('6 Ethics + Requirements'!$B$4:$B$19,$B20) | D20: =COUNTIFS('1 Structural Patterns'!$B$4:$B$14,$B20,'1 Structural Patterns'!$N$4:$N$14,TRUE())+COUNTIFS('2 Behavioral Patterns'!$B$4:$B$21,$B20,'2 Behavioral Patterns'!$N$4:$N$21,TRUE())+COUNTIFS('3 Process + Agile'!$B$4:$B$43,$B20,'3 Process + Agile'!$N$4:$N$43,TRUE())+COUNTIFS('4 Unit Testing + Review'!$B$4:$B$19,$B20,'4 Unit Testing + Review'!$N$4:$N$19,TRUE())+COUNTIFS('5 Refactoring'!$B$4:$B$12,$B20,'5 Refactoring'!$N$4:$N$12,TRUE())+COUNTIFS('6 Ethics + Requirements'!$B$4:$B$19,$B20,'6 Ethics + Requirements'!$N$4:$N$19,TRUE()) | E20: =IF(C20=0,0,D20/C20) | F20: =SUMIF('1 Structural Patterns'!$B$4:$B$14,$B20,'1 Structural Patterns'!$H$4:$H$14)+SUMIF('2 Behavioral Patterns'!$B$4:$B$21,$B20,'2 Behavioral Patterns'!$H$4:$H$21)+SUMIF('3 Process + Agile'!$B$4:$B$43,$B20,'3 Process + Agile'!$H$4:$H$43)+SUMIF('4 Unit Testing + Review'!$B$4:$B$19,$B20,'4 Unit Testing + Review'!$H$4:$H$19)+SUMIF('5 Refactoring'!$B$4:$B$12,$B20,'5 Refactoring'!$H$4:$H$12)+SUMIF('6 Ethics + Requirements'!$B$4:$B$19,$B20,'6 Ethics + Requirements'!$H$4:$H$19)
A21: 7 | B21: 2018-19 | C21: =COUNTIF('1 Structural Patterns'!$B$4:$B$14,$B21)+COUNTIF('2 Behavioral Patterns'!$B$4:$B$21,$B21)+COUNTIF('3 Process + Agile'!$B$4:$B$43,$B21)+COUNTIF('4 Unit Testing + Review'!$B$4:$B$19,$B21)+COUNTIF('5 Refactoring'!$B$4:$B$12,$B21)+COUNTIF('6 Ethics + Requirements'!$B$4:$B$19,$B21) | D21: =COUNTIFS('1 Structural Patterns'!$B$4:$B$14,$B21,'1 Structural Patterns'!$N$4:$N$14,TRUE())+COUNTIFS('2 Behavioral Patterns'!$B$4:$B$21,$B21,'2 Behavioral Patterns'!$N$4:$N$21,TRUE())+COUNTIFS('3 Process + Agile'!$B$4:$B$43,$B21,'3 Process + Agile'!$N$4:$N$43,TRUE())+COUNTIFS('4 Unit Testing + Review'!$B$4:$B$19,$B21,'4 Unit Testing + Review'!$N$4:$N$19,TRUE())+COUNTIFS('5 Refactoring'!$B$4:$B$12,$B21,'5 Refactoring'!$N$4:$N$12,TRUE())+COUNTIFS('6 Ethics + Requirements'!$B$4:$B$19,$B21,'6 Ethics + Requirements'!$N$4:$N$19,TRUE()) | E21: =IF(C21=0,0,D21/C21) | F21: =SUMIF('1 Structural Patterns'!$B$4:$B$14,$B21,'1 Structural Patterns'!$H$4:$H$14)+SUMIF('2 Behavioral Patterns'!$B$4:$B$21,$B21,'2 Behavioral Patterns'!$H$4:$H$21)+SUMIF('3 Process + Agile'!$B$4:$B$43,$B21,'3 Process + Agile'!$H$4:$H$43)+SUMIF('4 Unit Testing + Review'!$B$4:$B$19,$B21,'4 Unit Testing + Review'!$H$4:$H$19)+SUMIF('5 Refactoring'!$B$4:$B$12,$B21,'5 Refactoring'!$H$4:$H$12)+SUMIF('6 Ethics + Requirements'!$B$4:$B$19,$B21,'6 Ethics + Requirements'!$H$4:$H$19)
A22: 8 | B22: 2017-18 | C22: =COUNTIF('1 Structural Patterns'!$B$4:$B$14,$B22)+COUNTIF('2 Behavioral Patterns'!$B$4:$B$21,$B22)+COUNTIF('3 Process + Agile'!$B$4:$B$43,$B22)+COUNTIF('4 Unit Testing + Review'!$B$4:$B$19,$B22)+COUNTIF('5 Refactoring'!$B$4:$B$12,$B22)+COUNTIF('6 Ethics + Requirements'!$B$4:$B$19,$B22) | D22: =COUNTIFS('1 Structural Patterns'!$B$4:$B$14,$B22,'1 Structural Patterns'!$N$4:$N$14,TRUE())+COUNTIFS('2 Behavioral Patterns'!$B$4:$B$21,$B22,'2 Behavioral Patterns'!$N$4:$N$21,TRUE())+COUNTIFS('3 Process + Agile'!$B$4:$B$43,$B22,'3 Process + Agile'!$N$4:$N$43,TRUE())+COUNTIFS('4 Unit Testing + Review'!$B$4:$B$19,$B22,'4 Unit Testing + Review'!$N$4:$N$19,TRUE())+COUNTIFS('5 Refactoring'!$B$4:$B$12,$B22,'5 Refactoring'!$N$4:$N$12,TRUE())+COUNTIFS('6 Ethics + Requirements'!$B$4:$B$19,$B22,'6 Ethics + Requirements'!$N$4:$N$19,TRUE()) | E22: =IF(C22=0,0,D22/C22) | F22: =SUMIF('1 Structural Patterns'!$B$4:$B$14,$B22,'1 Structural Patterns'!$H$4:$H$14)+SUMIF('2 Behavioral Patterns'!$B$4:$B$21,$B22,'2 Behavioral Patterns'!$H$4:$H$21)+SUMIF('3 Process + Agile'!$B$4:$B$43,$B22,'3 Process + Agile'!$H$4:$H$43)+SUMIF('4 Unit Testing + Review'!$B$4:$B$19,$B22,'4 Unit Testing + Review'!$H$4:$H$19)+SUMIF('5 Refactoring'!$B$4:$B$12,$B22,'5 Refactoring'!$H$4:$H$12)+SUMIF('6 Ethics + Requirements'!$B$4:$B$19,$B22,'6 Ethics + Requirements'!$H$4:$H$19)
A23: 9 | B23: 2016-17 | C23: =COUNTIF('1 Structural Patterns'!$B$4:$B$14,$B23)+COUNTIF('2 Behavioral Patterns'!$B$4:$B$21,$B23)+COUNTIF('3 Process + Agile'!$B$4:$B$43,$B23)+COUNTIF('4 Unit Testing + Review'!$B$4:$B$19,$B23)+COUNTIF('5 Refactoring'!$B$4:$B$12,$B23)+COUNTIF('6 Ethics + Requirements'!$B$4:$B$19,$B23) | D23: =COUNTIFS('1 Structural Patterns'!$B$4:$B$14,$B23,'1 Structural Patterns'!$N$4:$N$14,TRUE())+COUNTIFS('2 Behavioral Patterns'!$B$4:$B$21,$B23,'2 Behavioral Patterns'!$N$4:$N$21,TRUE())+COUNTIFS('3 Process + Agile'!$B$4:$B$43,$B23,'3 Process + Agile'!$N$4:$N$43,TRUE())+COUNTIFS('4 Unit Testing + Review'!$B$4:$B$19,$B23,'4 Unit Testing + Review'!$N$4:$N$19,TRUE())+COUNTIFS('5 Refactoring'!$B$4:$B$12,$B23,'5 Refactoring'!$N$4:$N$12,TRUE())+COUNTIFS('6 Ethics + Requirements'!$B$4:$B$19,$B23,'6 Ethics + Requirements'!$N$4:$N$19,TRUE()) | E23: =IF(C23=0,0,D23/C23) | F23: =SUMIF('1 Structural Patterns'!$B$4:$B$14,$B23,'1 Structural Patterns'!$H$4:$H$14)+SUMIF('2 Behavioral Patterns'!$B$4:$B$21,$B23,'2 Behavioral Patterns'!$H$4:$H$21)+SUMIF('3 Process + Agile'!$B$4:$B$43,$B23,'3 Process + Agile'!$H$4:$H$43)+SUMIF('4 Unit Testing + Review'!$B$4:$B$19,$B23,'4 Unit Testing + Review'!$H$4:$H$19)+SUMIF('5 Refactoring'!$B$4:$B$12,$B23,'5 Refactoring'!$H$4:$H$12)+SUMIF('6 Ethics + Requirements'!$B$4:$B$19,$B23,'6 Ethics + Requirements'!$H$4:$H$19)
A24: 10 | B24: 2014-15 | C24: =COUNTIF('1 Structural Patterns'!$B$4:$B$14,$B24)+COUNTIF('2 Behavioral Patterns'!$B$4:$B$21,$B24)+COUNTIF('3 Process + Agile'!$B$4:$B$43,$B24)+COUNTIF('4 Unit Testing + Review'!$B$4:$B$19,$B24)+COUNTIF('5 Refactoring'!$B$4:$B$12,$B24)+COUNTIF('6 Ethics + Requirements'!$B$4:$B$19,$B24) | D24: =COUNTIFS('1 Structural Patterns'!$B$4:$B$14,$B24,'1 Structural Patterns'!$N$4:$N$14,TRUE())+COUNTIFS('2 Behavioral Patterns'!$B$4:$B$21,$B24,'2 Behavioral Patterns'!$N$4:$N$21,TRUE())+COUNTIFS('3 Process + Agile'!$B$4:$B$43,$B24,'3 Process + Agile'!$N$4:$N$43,TRUE())+COUNTIFS('4 Unit Testing + Review'!$B$4:$B$19,$B24,'4 Unit Testing + Review'!$N$4:$N$19,TRUE())+COUNTIFS('5 Refactoring'!$B$4:$B$12,$B24,'5 Refactoring'!$N$4:$N$12,TRUE())+COUNTIFS('6 Ethics + Requirements'!$B$4:$B$19,$B24,'6 Ethics + Requirements'!$N$4:$N$19,TRUE()) | E24: =IF(C24=0,0,D24/C24) | F24: =SUMIF('1 Structural Patterns'!$B$4:$B$14,$B24,'1 Structural Patterns'!$H$4:$H$14)+SUMIF('2 Behavioral Patterns'!$B$4:$B$21,$B24,'2 Behavioral Patterns'!$H$4:$H$21)+SUMIF('3 Process + Agile'!$B$4:$B$43,$B24,'3 Process + Agile'!$H$4:$H$43)+SUMIF('4 Unit Testing + Review'!$B$4:$B$19,$B24,'4 Unit Testing + Review'!$H$4:$H$19)+SUMIF('5 Refactoring'!$B$4:$B$12,$B24,'5 Refactoring'!$H$4:$H$12)+SUMIF('6 Ethics + Requirements'!$B$4:$B$19,$B24,'6 Ethics + Requirements'!$H$4:$H$19)
A25: 11 | B25: 2013-14 | C25: =COUNTIF('1 Structural Patterns'!$B$4:$B$14,$B25)+COUNTIF('2 Behavioral Patterns'!$B$4:$B$21,$B25)+COUNTIF('3 Process + Agile'!$B$4:$B$43,$B25)+COUNTIF('4 Unit Testing + Review'!$B$4:$B$19,$B25)+COUNTIF('5 Refactoring'!$B$4:$B$12,$B25)+COUNTIF('6 Ethics + Requirements'!$B$4:$B$19,$B25) | D25: =COUNTIFS('1 Structural Patterns'!$B$4:$B$14,$B25,'1 Structural Patterns'!$N$4:$N$14,TRUE())+COUNTIFS('2 Behavioral Patterns'!$B$4:$B$21,$B25,'2 Behavioral Patterns'!$N$4:$N$21,TRUE())+COUNTIFS('3 Process + Agile'!$B$4:$B$43,$B25,'3 Process + Agile'!$N$4:$N$43,TRUE())+COUNTIFS('4 Unit Testing + Review'!$B$4:$B$19,$B25,'4 Unit Testing + Review'!$N$4:$N$19,TRUE())+COUNTIFS('5 Refactoring'!$B$4:$B$12,$B25,'5 Refactoring'!$N$4:$N$12,TRUE())+COUNTIFS('6 Ethics + Requirements'!$B$4:$B$19,$B25,'6 Ethics + Requirements'!$N$4:$N$19,TRUE()) | E25: =IF(C25=0,0,D25/C25) | F25: =SUMIF('1 Structural Patterns'!$B$4:$B$14,$B25,'1 Structural Patterns'!$H$4:$H$14)+SUMIF('2 Behavioral Patterns'!$B$4:$B$21,$B25,'2 Behavioral Patterns'!$H$4:$H$21)+SUMIF('3 Process + Agile'!$B$4:$B$43,$B25,'3 Process + Agile'!$H$4:$H$43)+SUMIF('4 Unit Testing + Review'!$B$4:$B$19,$B25,'4 Unit Testing + Review'!$H$4:$H$19)+SUMIF('5 Refactoring'!$B$4:$B$12,$B25,'5 Refactoring'!$H$4:$H$12)+SUMIF('6 Ethics + Requirements'!$B$4:$B$19,$B25,'6 Ethics + Requirements'!$H$4:$H$19)
A26: 12 | B26: 2012-13 | C26: =COUNTIF('1 Structural Patterns'!$B$4:$B$14,$B26)+COUNTIF('2 Behavioral Patterns'!$B$4:$B$21,$B26)+COUNTIF('3 Process + Agile'!$B$4:$B$43,$B26)+COUNTIF('4 Unit Testing + Review'!$B$4:$B$19,$B26)+COUNTIF('5 Refactoring'!$B$4:$B$12,$B26)+COUNTIF('6 Ethics + Requirements'!$B$4:$B$19,$B26) | D26: =COUNTIFS('1 Structural Patterns'!$B$4:$B$14,$B26,'1 Structural Patterns'!$N$4:$N$14,TRUE())+COUNTIFS('2 Behavioral Patterns'!$B$4:$B$21,$B26,'2 Behavioral Patterns'!$N$4:$N$21,TRUE())+COUNTIFS('3 Process + Agile'!$B$4:$B$43,$B26,'3 Process + Agile'!$N$4:$N$43,TRUE())+COUNTIFS('4 Unit Testing + Review'!$B$4:$B$19,$B26,'4 Unit Testing + Review'!$N$4:$N$19,TRUE())+COUNTIFS('5 Refactoring'!$B$4:$B$12,$B26,'5 Refactoring'!$N$4:$N$12,TRUE())+COUNTIFS('6 Ethics + Requirements'!$B$4:$B$19,$B26,'6 Ethics + Requirements'!$N$4:$N$19,TRUE()) | E26: =IF(C26=0,0,D26/C26) | F26: =SUMIF('1 Structural Patterns'!$B$4:$B$14,$B26,'1 Structural Patterns'!$H$4:$H$14)+SUMIF('2 Behavioral Patterns'!$B$4:$B$21,$B26,'2 Behavioral Patterns'!$H$4:$H$21)+SUMIF('3 Process + Agile'!$B$4:$B$43,$B26,'3 Process + Agile'!$H$4:$H$43)+SUMIF('4 Unit Testing + Review'!$B$4:$B$19,$B26,'4 Unit Testing + Review'!$H$4:$H$19)+SUMIF('5 Refactoring'!$B$4:$B$12,$B26,'5 Refactoring'!$H$4:$H$12)+SUMIF('6 Ethics + Requirements'!$B$4:$B$19,$B26,'6 Ethics + Requirements'!$H$4:$H$19)
... A28: 14 | B28: 2010-11 | C28: =COUNTIF('1 Structural Patterns'!$B$4:$B$14,$B28)+COUNTIF('2 Behavioral Patterns'!$B$4:$B$21,$B28)+COUNTIF('3 Process + Agile'!$B$4:$B$43,$B28)+COUNTIF('4 Unit Testing + Review'!$B$4:$B$19,$B28)+COUNTIF('5 Refactoring'!$B$4:$B$12,$B28)+COUNTIF('6 Ethics + Requirements'!$B$4:$B$19,$B28) | D28: =COUNTIFS('1 Structural Patterns'!$B$4:$B$14,$B28,'1 Structural Patterns'!$N$4:$N$14,TRUE())+COUNTIFS('2 Behavioral Patterns'!$B$4:$B$21,$B28,'2 Behavioral Patterns'!$N$4:$N$21,TRUE())+COUNTIFS('3 Process + Agile'!$B$4:$B$43,$B28,'3 Process + Agile'!$N$4:$N$43,TRUE())+COUNTIFS('4 Unit Testing + Review'!$B$4:$B$19,$B28,'4 Unit Testing + Review'!$N$4:$N$19,TRUE())+COUNTIFS('5 Refactoring'!$B$4:$B$12,$B28,'5 Refactoring'!$N$4:$N$12,TRUE())+COUNTIFS('6 Ethics + Requirements'!$B$4:$B$19,$B28,'6 Ethics + Requirements'!$N$4:$N$19,TRUE()) | E28: =IF(C28=0,0,D28/C28) | F28: =SUMIF('1 Structural Patterns'!$B$4:$B$14,$B28,'1 Structural Patterns'!$H$4:$H$14)+SUMIF('2 Behavioral Patterns'!$B$4:$B$21,$B28,'2 Behavioral Patterns'!$H$4:$H$21)+SUMIF('3 Process + Agile'!$B$4:$B$43,$B28,'3 Process + Agile'!$H$4:$H$43)+SUMIF('4 Unit Testing + Review'!$B$4:$B$19,$B28,'4 Unit Testing + Review'!$H$4:$H$19)+SUMIF('5 Refactoring'!$B$4:$B$12,$B28,'5 Refactoring'!$H$4:$H$12)+SUMIF('6 Ethics + Requirements'!$B$4:$B$19,$B28,'6 Ethics + Requirements'!$H$4:$H$19)
B29: Shaded years = ★★★ High priority (2019-20 onward).
B30: TF Page = page in 'CSE 213 All Past Papers.pdf' (70 p.). It contains everything in 'CSE 213 Question.pdf' (63 p.) plus the 2023-24 CSE 213 paper (21 batch) as pages 1–7, so Question.pdf page = All Past Papers page − 7.
B31: Papers do not split by teacher section; every question is assigned by topic. Topics in neither teacher's slides (EVM, CPM/PERT, COCOMO/FP, risk, security, architecture, DevOps, IS design) are in 'Outside Notes'.

Sheet 1 Structural Patterns
A1: Structural Design Patterns
A2: Note file: CSE213_IJ_Structural_Patterns_Notes.docx · Solve after finishing the matching lesson. Filter Priority → ★★★ High first.
A3: Q No. | B3: Year | C3: Course | D3: Ques No. | E3: Short Question | F3: Topic (slide PDF · slides) | G3: Lesson | H3: Marks | I3: TF Page | J3: Priority | K3: Type | L3: In Notes | M3: Same Type Also In | N3: Done | O3: Confidence | P3: Date | Q3: My Notes
A4: 1 | B4: 2021-22 | C4: CSE 307 | D4: 2(a) | E4: 5-layer network model: each layer adds header (and trailer) to Packet — identify pattern, implement, UML | F4: Decorator — Structural pp. 1–50 | G4: L1 | H4: 20 | I4: 14–15 | J4: ★★★ High | K4: Design | L4: ✔ Solved | M4: — | N4: FALSE
A5: 2 | B5: 2024-25 | C5: CSE 213 | D5: 2(a) | E5: FinCorp hierarchical reports (city/state/country) with optional tax/investment/compliance sections — Composite + Decorator in Java | F5: Composite — Structural pp. 51–60 | G5: L2 | H5: 20 | I5: 22 batch p.2 | J5: ★★★ High | K5: Design | L5: ✔ Solved | M5: 2020-21 3(a); 2019-20 2(a); 2011-12 1(a); 2010-11 4(d) | N5: FALSE
A6: 3 | B6: 2020-21 | C6: CSE 307 | D6: 3(a) | E6: Employee hierarchy with direct/indirect subordinates | F6: Composite — Structural pp. 51–60 | G6: L2 | H6: 15 | I6: 20 | J6: ★★★ High | K6: Design | L6: ✔ Solved | M6: 2024-25 2(a); 2019-20 2(a); 2011-12 1(a); 2010-11 4(d) | N6: FALSE
A7: 4 | B7: 2019-20 | C7: CSE 307 | D7: 2(a) | E7: MD → Technical/Admin/Finance managers → developers/executives/officers — Composite, show all employees under any employee | F7: Composite — Structural pp. 51–60 | G7: L2 | H7: 20 | I7: 22 | J7: ★★★ High | K7: Design | L7: ✔ Solved | M7: 2024-25 2(a); 2020-21 3(a); 2011-12 1(a); 2010-11 4(d) | N7: FALSE
A8: 5 | B8: 2011-12 | C8: CSE 307 | D8: 1(a) | E8: Implementation issues and consequences of Composite | F8: Composite — Structural pp. 51–60 | G8: L2 | H8: 14 | I8: 57 | J8: ★★ Medium | K8: Theory | L8: ✔ Solved | M8: 2024-25 2(a); 2020-21 3(a); 2019-20 2(a); 2010-11 4(d) | N8: FALSE
A9: 6 | B9: 2010-11 | C9: CSE 307 | D9: 4(d) | E9: A group can be a member of another group — pattern and extension | F9: Composite — Structural pp. 51–60 | G9: L2 | H9: 12.67 | I9: 68 | J9: ★★ Medium | K9: Design | L9: ✔ Solved | M9: 2024-25 2(a); 2020-21 3(a); 2019-20 2(a); 2011-12 1(a) | N9: FALSE
A10: 7 | B10: 2023-24 | C10: CSE 213 | D10: 5(b) | E10: One class acting as both Adapter and Facade: example + class diagram | F10: Adapter (+ Facade) — Structural pp. 61–95 | G10: L3 | H10: 12 | I10: 4 | J10: ★★★ High | K10: Design | L10: ✔ Solved | M10: 2022-23 1(a); 2018-19 4(b); 2016-17 5(d); 2010-11 4(e) | N10: FALSE
A11: 8 | B11: 2022-23 | C11: CSE 307 | D11: 1(a) | E11: Temperature by city, client passes zip code — class diagram + code | F11: Adapter (+ Facade) — Structural pp. 61–95 | G11: L3 | H11: 15 | I11: 8 | J11: ★★★ High | K11: Design | L11: ✔ Solved | M11: 2023-24 5(b); 2018-19 4(b); 2016-17 5(d); 2010-11 4(e) | N11: FALSE
A12: 9 | B12: 2018-19 | C12: CSE 307 | D12: 4(b) | E12: Bird / ToyDuck Adapter — class diagram + code | F12: Adapter (+ Facade) — Structural pp. 61–95 | G12: L3 | H12: 18 | I12: 27 | J12: ★★ Medium | K12: Design | L12: ✔ Solved | M12: 2023-24 5(b); 2022-23 1(a); 2016-17 5(d); 2010-11 4(e) | N12: FALSE
A13: 10 | B13: 2016-17 | C13: CSE 307 | D13: 5(d) | E13: Class adapter UML; pros/cons of object vs class adapter | F13: Adapter (+ Facade) — Structural pp. 61–95 | G13: L3 | H13: 6.67 | I13: 38 | J13: ★★ Medium | K13: Theory | L13: ✔ Solved | M13: 2023-24 5(b); 2022-23 1(a); 2018-19 4(b); 2010-11 4(e) | N13: FALSE
A14: 11 | B14: 2010-11 | C14: CSE 307 | D14: 4(e) | E14: LibX replaced by LibY with different interfaces — pattern + class diagram | F14: Adapter (+ Facade) — Structural pp. 61–95 | G14: L3 | H14: 7 | I14: 68 | J14: ★★ Medium | K14: Design | L14: ✔ Solved | M14: 2023-24 5(b); 2022-23 1(a); 2018-19 4(b); 2016-17 5(d) | N14: FALSE

Sheet 2 Behavioral Patterns
A1: Behavioral Design Patterns (+ Misc)
A2: Note file: CSE213_IJ_Behavioral_Patterns_Notes.docx · Solve after finishing the matching lesson. Filter Priority → ★★★ High first.
A3: Q No. | B3: Year | C3: Course | D3: Ques No. | E3: Short Question | F3: Topic (slide PDF · slides) | G3: Lesson | H3: Marks | I3: TF Page | J3: Priority | K3: Type | L3: In Notes | M3: Same Type Also In | N3: Done | O3: Confidence | P3: Date | Q3: My Notes
A4: 1 | B4: 2020-21 | C4: CSE 307 | D4: 2(a) | E4: Talk-time schemes added often: decouple UI programmers from scheme classes | F4: Strategy — Behavioral pp. 4–48 | G4: L5 | H4: 10 | I4: 19 | J4: ★★★ High | K4: Design | L4: ✔ Solved | M4: 2020-21 2(b); 2020-21 2(c); 2018-19 2(a) | N4: FALSE
A5: 2 | B5: 2020-21 | C5: CSE 307 | D5: 2(b) | E5: Strategy pattern for selection / insertion / quick sort | F5: Strategy — Behavioral pp. 4–48 | G5: L5 | H5: 10 | I5: 19 | J5: ★★★ High | K5: Design | L5: ✔ Solved | M5: 2020-21 2(a); 2020-21 2(c); 2018-19 2(a) | N5: FALSE
A6: 3 | B6: 2020-21 | C6: CSE 307 | D6: 2(c) | E6: Student IDs + marks → grades and merit list of top grade, using a pattern + code | F6: Strategy — Behavioral pp. 4–48 | G6: L5 | H6: 15 | I6: 19 | J6: ★★★ High | K6: Design | L6: ✔ Solved | M6: 2020-21 2(a); 2020-21 2(b); 2018-19 2(a) | N6: FALSE
A7: 4 | B7: 2018-19 | C7: CSE 307 | D7: 2(a) | E7: Robots with Aggressive/Defensive/Normal behaviour changed at run time — class diagram + code | F7: Strategy — Behavioral pp. 4–48 | G7: L5 | H7: 20 | I7: 26 | J7: ★★ Medium | K7: Design | L7: ✔ Solved | M7: 2020-21 2(a); 2020-21 2(b); 2020-21 2(c) | N7: FALSE
A8: 5 | B8: 2024-25 | C8: CSE 213 | D8: 8(a) | E8: Redesign DataParser with Template Method + Strategy (Java) | F8: Template Method — Behavioral pp. 49–81 | G8: L6 | H8: 15 | I8: 22 batch p.8 | J8: ★★★ High | K8: Design | L8: ✔ Solved | M8: — | N8: FALSE
A9: 6 | B9: 2024-25 | C9: CSE 213 | D9: 8(b) | E9: Breaking-news displays update automatically — pattern | F9: Observer — Behavioral pp. 82–128 | G9: L7 | H9: 10 | I9: 22 batch p.8 | J9: ★★★ High | K9: Design | L9: ✔ Solved | M9: 2023-24 2(a); 2022-23 4(a); 2020-21 3(b); 2017-18 8(b); 2010-11 4(c) | N9: FALSE
A10: 7 | B10: 2023-24 | C10: CSE 213 | D10: 2(a) | E10: StockMarket / StockGrabber: UML with pattern + code for StockGrabber and StockObserver | F10: Observer — Behavioral pp. 82–128 | G10: L7 | H10: 22 | I10: 2 | J10: ★★★ High | K10: Design | L10: ✔ Solved | M10: 2024-25 8(b); 2022-23 4(a); 2020-21 3(b); 2017-18 8(b); 2010-11 4(c) | N10: FALSE
A11: 8 | B11: 2022-23 | C11: CSE 307 | D11: 4(a) | E11: BUET alumni blog notifies subscribers — class diagram + code | F11: Observer — Behavioral pp. 82–128 | G11: L7 | H11: 15 | I11: 9 | J11: ★★★ High | K11: Design | L11: ✔ Solved | M11: 2024-25 8(b); 2023-24 2(a); 2020-21 3(b); 2017-18 8(b); 2010-11 4(c) | N11: FALSE
A12: 9 | B12: 2020-21 | C12: CSE 307 | D12: 3(b) | E12: Dashboard of max/avg temperature updated at end of day | F12: Observer — Behavioral pp. 82–128 | G12: L7 | H12: 10 | I12: 20 | J12: ★★★ High | K12: Design | L12: ✔ Solved | M12: 2024-25 8(b); 2023-24 2(a); 2022-23 4(a); 2017-18 8(b); 2010-11 4(c) | N12: FALSE
A13: 10 | B13: 2017-18 | C13: CSE 307 | D13: 8(b) | E13: Blog notifies registered users of new articles — class diagram + code | F13: Observer — Behavioral pp. 82–128 | G13: L7 | H13: 17 | I13: 34 | J13: ★★ Medium | K13: Design | L13: ✔ Solved | M13: 2024-25 8(b); 2023-24 2(a); 2022-23 4(a); 2020-21 3(b); 2010-11 4(c) | N13: FALSE
A14: 11 | B14: 2010-11 | C14: CSE 307 | D14: 4(c) | E14: Facebook group: join/leave, receive wall updates — pattern, class diagram, code | F14: Observer — Behavioral pp. 82–128 | G14: L7 | H14: 12 | I14: 67–68 | J14: ★★ Medium | K14: Design | L14: ✔ Solved | M14: 2024-25 8(b); 2023-24 2(a); 2022-23 4(a); 2020-21 3(b); 2017-18 8(b) | N14: FALSE
A15: 12 | B15: 2022-23 | C15: CSE 307 | D15: 2(a) | E15: Air-traffic control tower — class diagram + code | F15: Mediator — Behavioral pp. 129–167 | G15: L8 | H15: 15 | I15: 8 | J15: ★★★ High | K15: Design | L15: ✔ Solved | M15: 2019-20 1(b) | N15: FALSE
A16: 13 | B16: 2019-20 | C16: CSE 307 | D16: 1(b) | E16: Central broker forwards sorting requests to three servers, with a queue — Mediator | F16: Mediator — Behavioral pp. 129–167 | G16: L8 | H16: 20 | I16: 22 | J16: ★★★ High | K16: Design | L16: ✔ Solved | M16: 2022-23 2(a) | N16: FALSE
A17: 14 | B17: 2024-25 | C17: CSE 213 | D17: 5(b) | E17: Smart Home Hub: (i) Mediator vs direct links (ii) record/queue/replay actions — pattern | F17: Command — Behavioral pp. 168–202 | G17: L9 | H17: 10 | I17: 22 batch p.6 | J17: ★★★ High | K17: Design | L17: ✔ Solved | M17: — | N17: FALSE
A18: 15 | B18: 2024-25 | C18: CSE 213 | D18: 8(c) | E18: State vs Strategy pattern | F18: State — Behavioral pp. 203–260 | G18: L10 | H18: 10 | I18: 22 batch p.8 | J18: ★★★ High | K18: Theory | L18: ✔ Solved | M18: — | N18: FALSE
A19: 16 | B19: 2023-24 | C19: CSE 213 | D19: 2(b) | E19: HelpHandler / Widget / Button / Dialog / Application: UML using the pattern (help requests) | F19: Identify pattern, CoR, Interpreter — mixed | G19: L11 | H19: 8 | I19: 2–3 | J19: ★★★ High | K19: Design | L19: ✔ Solved | M19: — | N19: FALSE
A20: 17 | B20: 2021-22 | C20: CSE 307 | D20: 4(a) | E20: Identify patterns: (i) NuetFlix genre recommendations (ii) jit kommit/pussh/stashh (iii) BanglaPhone switch implementations (iv) R2-D2 anonymous reviews | F20: Identify pattern, CoR, Interpreter — mixed | G20: L11 | H20: 20 | I20: 16 | J20: ★★★ High | K20: Design | L20: ✔ Solved | M20: 2012-13 1(c) | N20: FALSE
A21: 18 | B21: 2012-13 | C21: CSE 307 | D21: 1(c) | E21: Evaluate 'A op1 B op2 C': choose a pattern and draw the class diagram | F21: Identify pattern, CoR, Interpreter — mixed | G21: L11 | H21: 14 | I21: 50 | J21: ★★ Medium | K21: Design | L21: ✔ Solved | M21: 2021-22 4(a) | N21: FALSE

Sheet 3 Process + Agile
A1: Process Models and Agile Development
A2: Note file: CSE213_IJ_Process_Agile_Notes.docx · Solve after finishing the matching lesson. Filter Priority → ★★★ High first.
A3: Q No. | B3: Year | C3: Course | D3: Ques No. | E3: Short Question | F3: Topic (slide PDF · slides) | G3: Lesson | H3: Marks | I3: TF Page | J3: Priority | K3: Type | L3: In Notes | M3: Same Type Also In | N3: Done | O3: Confidence | P3: Date | Q3: My Notes
A4: 1 | B4: 2022-23 | C4: CSE 307 | D4: 6(a) | E4: Core activities of the generic process model; waterfall + advantages/disadvantages | F4: Generic process model — Process pp. 2–16 | G4: L12 | H4: 10 | I4: 11 | J4: ★★★ High | K4: Theory | L4: ✔ Solved | M4: 2021-22 6(a); 2018-19 5(c); 2018-19 8(a); 2018-19 8(b); 2017-18 2(a); 2017-18 2(b) | N4: FALSE
A5: 2 | B5: 2018-19 | C5: CSE 307 | D5: 5(c) | E5: Framework activity; five PSP framework activities | F5: Generic process model — Process pp. 2–16 | G5: L12 | H5: 13 | I5: 28 | J5: ★★ Medium | K5: Theory | L5: ◐ Method | M5: 2022-23 6(a); 2021-22 6(a); 2018-19 8(a); 2018-19 8(b); 2017-18 2(a); 2017-18 2(b) | N5: FALSE
A6: 3 | B6: 2014-15 | C6: CSE 307 | D6: 4(a) | E6: Why framework activities do not suit every project | F6: Generic process model — Process pp. 2–16 | G6: L12 | H6: 6.67 | I6: 42 | J6: ★★ Medium | K6: Theory | L6: ◐ Method | M6: 2022-23 6(a); 2021-22 6(a); 2018-19 5(c); 2018-19 8(a); 2018-19 8(b); 2017-18 2(a) | N6: FALSE
A7: 4 | B7: 2013-14 | C7: CSE 307 | D7: 4(c) | E7: Framework and umbrella activities | F7: Generic process model — Process pp. 2–16 | G7: L12 | H7: 8 | I7: 47 | J7: ★★ Medium | K7: Theory | L7: ✔ Solved | M7: 2022-23 6(a); 2021-22 6(a); 2018-19 5(c); 2018-19 8(a); 2018-19 8(b); 2017-18 2(a) | N7: FALSE
A8: 5 | B8: 2024-25 | C8: CSE 213 | D8: 1(c) | E8: Mental-health companion app: is the incremental model suitable? Propose alternatives | F8: Prescriptive models — Process pp. 15–42 | G8: L13 | H8: 10 | I8: 22 batch p.1 | J8: ★★★ High | K8: Theory | L8: ✔ Solved | M8: 2023-24 8(a); 2013-14 4(d); 2011-12 8(a) | N8: FALSE
A9: 6 | B9: 2021-22 | C9: CSE 307 | D9: 6(a) | E9: How incremental and evolutionary models address waterfall shortcomings | F9: Prescriptive models — Process pp. 15–42 | G9: L13 | H9: 10 | I9: 17 | J9: ★★★ High | K9: Theory | L9: ✔ Solved | M9: 2022-23 6(a); 2018-19 5(c); 2018-19 8(a); 2018-19 8(b); 2017-18 2(a); 2017-18 2(b) | N9: FALSE
A10: 7 | B10: 2018-19 | C10: CSE 307 | D10: 8(a) | E10: V model | F10: Prescriptive models — Process pp. 15–42 | G10: L13 | H10: 7 | I10: 29 | J10: ★★ Medium | K10: Theory | L10: ◐ Method | M10: 2022-23 6(a); 2021-22 6(a); 2018-19 5(c); 2018-19 8(b); 2017-18 2(a); 2017-18 2(b) | N10: FALSE
A11: 8 | B11: 2018-19 | C11: CSE 307 | D11: 8(b) | E11: When incremental model; four problems of evolutionary models | F11: Prescriptive models — Process pp. 15–42 | G11: L13 | H11: 10 | I11: 29 | J11: ★★ Medium | K11: Theory | L11: ◐ Method | M11: 2022-23 6(a); 2021-22 6(a); 2018-19 5(c); 2018-19 8(a); 2017-18 2(a); 2017-18 2(b) | N11: FALSE
A12: 9 | B12: 2017-18 | C12: CSE 307 | D12: 2(a) | E12: Problems of the waterfall model and which models solve them | F12: Prescriptive models — Process pp. 15–42 | G12: L13 | H12: 7 | I12: 31 | J12: ★★ Medium | K12: Theory | L12: ✔ Solved | M12: 2022-23 6(a); 2021-22 6(a); 2018-19 5(c); 2018-19 8(a); 2018-19 8(b); 2017-18 2(b) | N12: FALSE
A13: 10 | B13: 2017-18 | C13: CSE 307 | D13: 2(b) | E13: Prototyping to elicit an SRS for a government organisation | F13: Prescriptive models — Process pp. 15–42 | G13: L13 | H13: 7 | I13: 31 | J13: ★★ Medium | K13: Theory | L13: ◐ Method | M13: 2022-23 6(a); 2021-22 6(a); 2018-19 5(c); 2018-19 8(a); 2018-19 8(b); 2017-18 2(a) | N13: FALSE
A14: 11 | B14: 2016-17 | C14: CSE 307 | D14: 5(b) | E14: Spiral model; arguments for and against | F14: Prescriptive models — Process pp. 15–42 | G14: L13 | H14: 15 | I14: 38 | J14: ★★ Medium | K14: Theory | L14: ✔ Solved | M14: 2022-23 6(a); 2021-22 6(a); 2018-19 5(c); 2018-19 8(a); 2018-19 8(b); 2017-18 2(a) | N14: FALSE
A15: 12 | B15: 2014-15 | C15: CSE 307 | D15: 4(b) | E15: Incremental vs spiral | F15: Prescriptive models — Process pp. 15–42 | G15: L13 | H15: 10 | I15: 42 | J15: ★★ Medium | K15: Theory | L15: ✔ Solved | M15: 2022-23 6(a); 2021-22 6(a); 2018-19 5(c); 2018-19 8(a); 2018-19 8(b); 2017-18 2(a) | N15: FALSE
A16: 13 | B16: 2014-15 | C16: CSE 307 | D16: 4(c) | E16: Unified process; concurrency and evolution | F16: Prescriptive models — Process pp. 15–42 | G16: L13 | H16: 10 | I16: 42 | J16: ★★ Medium | K16: Theory | L16: ◐ Method | M16: 2012-13 1(d); 2011-12 8(b) | N16: FALSE
A17: 14 | B17: 2014-15 | C17: CSE 307 | D17: 5(b) | E17: Disadvantages of prototyping | F17: Prescriptive models — Process pp. 15–42 | G17: L13 | H17: 10 | I17: 43 | J17: ★★ Medium | K17: Theory | L17: ✔ Solved | M17: 2022-23 6(a); 2021-22 6(a); 2018-19 5(c); 2018-19 8(a); 2018-19 8(b); 2017-18 2(a) | N17: FALSE
A18: 15 | B18: 2013-14 | C18: CSE 307 | D18: 4(d) | E18: Suitable process model for three cases | F18: Prescriptive models — Process pp. 15–42 | G18: L13 | H18: 9 | I18: 47 | J18: ★★ Medium | K18: Theory | L18: ✔ Solved | M18: 2024-25 1(c); 2023-24 8(a); 2011-12 8(a) | N18: FALSE
A19: 16 | B19: 2013-14 | C19: CSE 307 | D19: 5(c) | E19: Discovery prototyping | F19: Prescriptive models — Process pp. 15–42 | G19: L13 | H19: 5 | I19: 47 | J19: ★★ Medium | K19: Theory | L19: ◐ Method | M19: 2022-23 6(a); 2021-22 6(a); 2018-19 5(c); 2018-19 8(a); 2018-19 8(b); 2017-18 2(a) | N19: FALSE
A20: 17 | B20: 2012-13 | C20: CSE 307 | D20: 1(b) | E20: 'Waterfall may lead to blocking states' — agree? | F20: Prescriptive models — Process pp. 15–42 | G20: L13 | H20: 7 | I20: 50 | J20: ★★ Medium | K20: Theory | L20: ✔ Solved | M20: 2022-23 6(a); 2021-22 6(a); 2018-19 5(c); 2018-19 8(a); 2018-19 8(b); 2017-18 2(a) | N20: FALSE
... A43: 40 | B43: 2011-12 | C43: CSE 307 | D43: 5(c) | E43: Scrum vs plan-based project management | F43: Scrum, Kanban — Process pp. 64–84 | G43: L15 | H43: 18 | I43: 59 | J43: ★★ Medium | K43: Theory | L43: ◐ Method | M43: 2022-23 6(c); 2021-22 5(b); 2017-18 2(e); 2016-17 6(a); 2014-15 4(d) | N43: FALSE

Sheet 4 Unit Testing + Review
A1: Unit Testing and Code Reviews
A2: Note file: CSE213_IJ_UnitTesting_CodeReview_Notes.docx · Solve after finishing the matching lesson. Filter Priority → ★★★ High first.
A3: Q No. | B3: Year | C3: Course | D3: Ques No. | E3: Short Question | F3: Topic (slide PDF · slides) | G3: Lesson | H3: Marks | I3: TF Page | J3: Priority | K3: Type | L3: In Notes | M3: Same Type Also In | N3: Done | O3: Confidence | P3: Date | Q3: My Notes
A4: 1 | B4: 2024-25 | C4: CSE 213 | D4: 6(a) | E4: JUnit test class for isLeapYear (including invalid input) | F4: Unit testing, JUnit, TDD — Unit Testing pp. 1–24 | G4: L16 | H4: 15 | I4: 22 batch p.6 | J4: ★★★ High | K4: Code | L4: ✔ Solved | M4: 2019-20 7(a) | N4: FALSE
A5: 2 | B5: 2023-24 | C5: CSE 213 | D5: 3(a) | E5: Test-driven development and its benefits | F5: Unit testing, JUnit, TDD — Unit Testing pp. 1–24 | G5: L16 | H5: 12 | I5: 3 | J5: ★★★ High | K5: Theory | L5: ✔ Solved | M5: 2016-17 7(a) | N5: FALSE
A6: 3 | B6: 2019-20 | C6: CSE 307 | D6: 7(a) | E6: Fixtures in unit testing (3 examples); unit test for grading A > 80, B 70–80, C 60–70 with BVA | F6: Unit testing, JUnit, TDD — Unit Testing pp. 1–24 | G6: L16 | H6: 20 | I6: 25 | J6: ★★★ High | K6: Code | L6: ✔ Solved | M6: 2024-25 6(a) | N6: FALSE
A7: 4 | B7: 2016-17 | C7: CSE 307 | D7: 7(a) | E7: Five steps of TDD with an example | F7: Unit testing, JUnit, TDD — Unit Testing pp. 1–24 | G7: L16 | H7: 15 | I7: 39 | J7: ★★ Medium | K7: Code | L7: ✔ Solved | M7: 2023-24 3(a) | N7: FALSE
A8: 5 | B8: 2014-15 | C8: CSE 307 | D8: 2(c) | E8: Automated tester for a descending float sort: order + same data set | F8: Unit testing, JUnit, TDD — Unit Testing pp. 1–24 | G8: L16 | H8: 13 | I8: 41 | J8: ★★ Medium | K8: Code | L8: ✔ Solved | M8: 2013-14 3(c); 2010-11 6(e) | N8: FALSE
A9: 6 | B9: 2013-14 | C9: CSE 307 | D9: 3(c) | E9: Driver code generating data sets for an ascending float sort + the module | F9: Unit testing, JUnit, TDD — Unit Testing pp. 1–24 | G9: L16 | H9: 12 | I9: 46 | J9: ★★ Medium | K9: Code | L9: ◐ Method | M9: 2014-15 2(c); 2010-11 6(e) | N9: FALSE
A10: 7 | B10: 2010-11 | C10: CSE 307 | D10: 6(e) | E10: Test cases for a Queue class | F10: Unit testing, JUnit, TDD — Unit Testing pp. 1–24 | G10: L16 | H10: 15 | I10: 69 | J10: ★★ Medium | K10: Code | L10: ✔ Solved | M10: 2014-15 2(c); 2013-14 3(c) | N10: FALSE
A11: 8 | B11: 2022-23 | C11: CSE 307 | D11: 2(b) | E11: Issues commonly identified in code review — three examples | F11: Code reviews — CodeReviews pp. 1–21 | G11: L17 | H11: 12 | I11: 8 | J11: ★★★ High | K11: Theory | L11: ✔ Solved | M11: 2020-21 6(c) | N11: FALSE
A12: 9 | B12: 2021-22 | C12: CSE 307 | D12: 8(a) | E12: Driver and navigator in pair programming as code review | F12: Code reviews — CodeReviews pp. 1–21 | G12: L17 | H12: 10 | I12: 18 | J12: ★★★ High | K12: Theory | L12: ✔ Solved | M12: — | N12: FALSE
A13: 10 | B13: 2020-21 | C13: CSE 307 | D13: 6(c) | E13: Issues commonly identified during code review | F13: Code reviews — CodeReviews pp. 1–21 | G13: L17 | H13: 8 | I13: 21 | J13: ★★★ High | K13: Theory | L13: ✔ Solved | M13: 2022-23 2(b) | N13: FALSE
A14: 11 | B14: 2019-20 | C14: CSE 307 | D14: 3(b) | E14: Limited budget: hire reviewers or more testers? Justify | F14: Code reviews — CodeReviews pp. 1–21 | G14: L17 | H14: 15 | I14: 23 | J14: ★★★ High | K14: Theory | L14: ✔ Solved | M14: — | N14: FALSE
A15: 12 | B15: 2018-19 | C15: CSE 307 | D15: 1(c) | E15: Defect rate and defect density; why checklists in code review | F15: Code reviews — CodeReviews pp. 1–21 | G15: L17 | H15: 9 | I15: 26 | J15: ★★ Medium | K15: Theory | L15: ✔ Solved | M15: 2017-18 5(c); 2016-17 3(b); 2014-15 1(d); 2012-13 4(a) | N15: FALSE
A16: 13 | B16: 2017-18 | C16: CSE 307 | D16: 5(c) | E16: Indirect benefits of code review | F16: Code reviews — CodeReviews pp. 1–21 | G16: L17 | H16: 9 | I16: 33 | J16: ★★ Medium | K16: Theory | L16: ✔ Solved | M16: 2018-19 1(c); 2016-17 3(b); 2014-15 1(d); 2012-13 4(a) | N16: FALSE
... A19: 16 | B19: 2012-13 | C19: CSE 307 | D19: 4(a) | E19: Four data faults to check in a C-program inspection | F19: Code reviews — CodeReviews pp. 1–21 | G19: L17 | H19: 6 | I19: 52 | J19: ★★ Medium | K19: Theory | L19: ✔ Solved | M19: 2018-19 1(c); 2017-18 5(c); 2016-17 3(b); 2014-15 1(d) | N19: FALSE

Sheet 5 Refactoring
A1: Refactoring and Code Smells
A2: Note file: CSE213_IJ_Refactoring_Notes.docx · Solve after finishing the matching lesson. Filter Priority → ★★★ High first.
A3: Q No. | B3: Year | C3: Course | D3: Ques No. | E3: Short Question | F3: Topic (slide PDF · slides) | G3: Lesson | H3: Marks | I3: TF Page | J3: Priority | K3: Type | L3: In Notes | M3: Same Type Also In | N3: Done | O3: Confidence | P3: Date | Q3: My Notes
A4: 1 | B4: 2024-25 | C4: CSE 213 | D4: 4(b) | E4: Code smell vs technical debt vs refactoring; proactive vs reactive risk management | F4: Refactoring basics — Refactoring pp. 1–14 | G4: L18 | H4: 15 | I4: 22 batch p.5 | J4: ★★★ High | K4: Theory | L4: ✔ Solved | M4: 2022-23 5(a); 2021-22 6(c); 2019-20 6(a) | N4: FALSE
A5: 2 | B5: 2017-18 | C5: CSE 307 | D5: 2(c) | E5: Why refactoring is important in agile; examples | F5: Refactoring basics — Refactoring pp. 1–14 | G5: L18 | H5: 7 | I5: 31 | J5: ★ Low | K5: Theory | L5: ✔ Solved | M5: — | N5: FALSE
A6: 3 | B6: 2022-23 | C6: CSE 307 | D6: 5(a) | E6: Define with examples: shotgun surgery, parallel inheritance hierarchies, refused bequest, feature envy | F6: Code smells — Refactoring pp. 15–29 | G6: L19 | H6: 15 | I6: 9 | J6: ★★★ High | K6: Theory | L6: ✔ Solved | M6: 2024-25 4(b); 2021-22 6(c); 2019-20 6(a) | N6: FALSE
A7: 4 | B7: 2021-22 | C7: CSE 307 | D7: 6(c) | E7: Define code smell; three examples | F7: Code smells — Refactoring pp. 15–29 | G7: L19 | H7: 10 | I7: 17 | J7: ★★★ High | K7: Theory | L7: ✔ Solved | M7: 2024-25 4(b); 2022-23 5(a); 2019-20 6(a) | N7: FALSE
A8: 5 | B8: 2019-20 | C8: CSE 307 | D8: 6(a) | E8: Code snippets showing Data Clump and Refused Bequest | F8: Code smells — Refactoring pp. 15–29 | G8: L19 | H8: 20 | I8: 24 | J8: ★★★ High | K8: Code | L8: ✔ Solved | M8: 2024-25 4(b); 2022-23 5(a); 2021-22 6(c) | N8: FALSE
A9: 6 | B9: 2024-25 | C9: CSE 213 | D9: 4(a) | E9: Student / Scholarship code: identify five bad smells and refactor | F9: Refactoring catalogue, worked code — Refactoring pp. 30–47 | G9: L20 | H9: 20 | I9: 22 batch p.4–5 | J9: ★★★ High | K9: Code | L9: ✔ Solved | M9: 2023-24 8(c); 2022-23 5(b); 2021-22 1(b) | N9: FALSE
A10: 7 | B10: 2023-24 | C10: CSE 213 | D10: 8(c) | E10: DiscountCalculator / OrderProcessor: bad smells + refactor | F10: Refactoring catalogue, worked code — Refactoring pp. 30–47 | G10: L20 | H10: 20 | I10: 6–7 | J10: ★★★ High | K10: Code | L10: ✔ Solved | M10: 2024-25 4(a); 2022-23 5(b); 2021-22 1(b) | N10: FALSE
A11: 8 | B11: 2022-23 | C11: CSE 307 | D11: 5(b) | E11: Refactor: (i) renderBanner complex condition (ii) getSalary switch (iii) getPayAmount nested if | F11: Refactoring catalogue, worked code — Refactoring pp. 30–47 | G11: L20 | H11: 20 | I11: 9–10 | J11: ★★★ High | K11: Code | L11: ✔ Solved | M11: 2024-25 4(a); 2023-24 8(c); 2021-22 1(b) | N11: FALSE
A12: 9 | B12: 2021-22 | C12: CSE 307 | D12: 1(b) | E12: GetSuperHeroItem if-else chain → readable, O(1) amortised | F12: Refactoring catalogue, worked code — Refactoring pp. 30–47 | G12: L20 | H12: 13 | I12: 13–14 | J12: ★★★ High | K12: Code | L12: ✔ Solved | M12: 2024-25 4(a); 2023-24 8(c); 2022-23 5(b) | N12: FALSE

Sheet 6 Ethics + Requirements
A1: Software Ethics and Requirement Analysis
A2: Note file: CSE213_IJ_Ethics_Requirements_Notes.docx · Solve after finishing the matching lesson. Filter Priority → ★★★ High first.
A3: Q No. | B3: Year | C3: Course | D3: Ques No. | E3: Short Question | F3: Topic (slide PDF · slides) | G3: Lesson | H3: Marks | I3: TF Page | J3: Priority | K3: Type | L3: In Notes | M3: Same Type Also In | N3: Done | O3: Confidence | P3: Date | Q3: My Notes
A4: 1 | B4: 2024-25 | C4: CSE 213 | D4: 1(b) | E4: Security engineer leaks unpatched vulnerabilities to the media — which ethical principles are breached? | F4: Software ethics — Ethics pp. 1–12 | G4: L21 | H4: 10 | I4: 22 batch p.1 | J4: ★★★ High | K4: Theory | L4: ✔ Solved | M4: 2023-24 6(a) | N4: FALSE
A5: 2 | B5: 2023-24 | C5: CSE 213 | D5: 6(a) | E5: Health app: ethical breaches | F5: Software ethics — Ethics pp. 1–12 | G5: L21 | H5: 8 | I5: 4 | J5: ★★★ High | K5: Theory | L5: ✔ Solved | M5: 2024-25 1(b) | N5: FALSE
A6: 3 | B6: 2023-24 | C6: CSE 213 | D6: 6(b) | E6: 'Act consistently with the public interest' — explain | F6: Software ethics — Ethics pp. 1–12 | G6: L21 | H6: 7 | I6: 5 | J6: ★★★ High | K6: Theory | L6: ✔ Solved | M6: 2010-11 7(a) | N6: FALSE
A7: 4 | B7: 2010-11 | C7: CSE 307 | D7: 7(a) | E7: Professional and ethical responsibilities of a software engineer | F7: Software ethics — Ethics pp. 1–12 | G7: L21 | H7: 6.67 | I7: 69 | J7: ★★ Medium | K7: Theory | L7: ✔ Solved | M7: 2023-24 6(b) | N7: FALSE
A8: 5 | B8: 2024-25 | C8: CSE 213 | D8: 5(c) | E8: Startup with no SRS: how to prepare the requirement specification | F8: Requirement analysis — Requirements pp. 1–12 | G8: L22 | H8: 10 | I8: 22 batch p.6 | J8: ★★★ High | K8: Theory | L8: ✔ Solved | M8: 2021-22 2(c); 2021-22 4(b); 2011-12 5(a) | N8: FALSE
A9: 6 | B9: 2021-22 | C9: CSE 307 | D9: 2(c) | E9: Functional vs non-functional requirements | F9: Requirement analysis — Requirements pp. 1–12 | G9: L22 | H9: 5 | I9: 15 | J9: ★★★ High | K9: Theory | L9: ✔ Solved | M9: 2024-25 5(c); 2021-22 4(b); 2011-12 5(a) | N9: FALSE
A10: 7 | B10: 2021-22 | C10: CSE 307 | D10: 4(b) | E10: Assess the requirement 'update notification after a fixed time…' against quality measures | F10: Requirement analysis — Requirements pp. 1–12 | G10: L22 | H10: 10 | I10: 16 | J10: ★★★ High | K10: Theory | L10: ✔ Solved | M10: 2024-25 5(c); 2021-22 2(c); 2011-12 5(a) | N10: FALSE
A11: 8 | B11: 2014-15 | C11: CSE 307 | D11: 6(c) | E11: Training school: fact-finding approach | F11: Requirement analysis — Requirements pp. 1–12 | G11: L22 | H11: 15 | I11: 43 | J11: ★★ Medium | K11: Theory | L11: ◐ Method | M11: 2013-14 1(a); 2013-14 1(b); 2013-14 5(d); 2013-14 5(e); 2012-13 5(d); 2012-13 7(b) | N11: FALSE
A12: 9 | B12: 2013-14 | C12: CSE 307 | D12: 1(a) | E12: Government filing system: roles of fact finding, questionnaires, interviews | F12: Requirement analysis — Requirements pp. 1–12 | G12: L22 | H12: 12 | I12: 45 | J12: ★★ Medium | K12: Theory | L12: ◐ Method | M12: 2014-15 6(c); 2013-14 1(b); 2013-14 5(d); 2013-14 5(e); 2012-13 5(d); 2012-13 7(b) | N12: FALSE
A13: 10 | B13: 2013-14 | C13: CSE 307 | D13: 1(b) | E13: Design a JRP session: roles and responsibilities | F13: Requirement analysis — Requirements pp. 1–12 | G13: L22 | H13: 12 | I13: 45 | J13: ★★ Medium | K13: Theory | L13: ◐ Method | M13: 2014-15 6(c); 2013-14 1(a); 2013-14 5(d); 2013-14 5(e); 2012-13 5(d); 2012-13 7(b) | N13: FALSE
A14: 11 | B14: 2013-14 | C14: CSE 307 | D14: 5(d) | E14: Fact-finding methods | F14: Requirement analysis — Requirements pp. 1–12 | G14: L22 | H14: 14 | I14: 47 | J14: ★★ Medium | K14: Theory | L14: ✔ Solved | M14: 2014-15 6(c); 2013-14 1(a); 2013-14 1(b); 2013-14 5(e); 2012-13 5(d); 2012-13 7(b) | N14: FALSE
A15: 12 | B15: 2013-14 | C15: CSE 307 | D15: 5(e) | E15: JRP: advantages and disadvantages | F15: Requirement analysis — Requirements pp. 1–12 | G15: L22 | H15: 10.67 | I15: 47 | J15: ★★ Medium | K15: Theory | L15: ◐ Method | M15: 2014-15 6(c); 2013-14 1(a); 2013-14 1(b); 2013-14 5(d); 2012-13 5(d); 2012-13 7(b) | N15: FALSE
A16: 13 | B16: 2012-13 | C16: CSE 307 | D16: 5(d) | E16: JRP and its participants | F16: Requirement analysis — Requirements pp. 1–12 | G16: L22 | H16: 4.67 | I16: 54 | J16: ★★ Medium | K16: Theory | L16: ◐ Method | M16: 2014-15 6(c); 2013-14 1(a); 2013-14 1(b); 2013-14 5(d); 2013-14 5(e); 2012-13 7(b) | N16: FALSE
A17: 14 | B17: 2012-13 | C17: CSE 307 | D17: 7(b) | E17: Health centre: seven fact-finding methods per user | F17: Requirement analysis — Requirements pp. 1–12 | G17: L22 | H17: 15 | I17: 55 | J17: ★★ Medium | K17: Theory | L17: ◐ Method | M17: 2014-15 6(c); 2013-14 1(a); 2013-14 1(b); 2013-14 5(d); 2013-14 5(e); 2012-13 5(d) | N17: FALSE
A18: 15 | B18: 2011-12 | C18: CSE 307 | D18: 5(a) | E18: Classify ten requirement statements into seven categories | F18: Requirement analysis — Requirements pp. 1–12 | G18: L22 | H18: 10 | I18: 58–59 | J18: ★★ Medium | K18: Theory | L18: ✔ Solved | M18: 2024-25 5(c); 2021-22 2(c); 2021-22 4(b) | N18: FALSE
A19: 16 | B19: 2010-11 | C19: CSE 307 | D19: 7(b) | E19: Land-management computerisation: fact-finding techniques | F19: Requirement analysis — Requirements pp. 1–12 | G19: L22 | H19: 25 | I19: 69 | J19: ★★ Medium | K19: Theory | L19: ◐ Method | M19: 2014-15 6(c); 2013-14 1(a); 2013-14 1(b); 2013-14 5(d); 2013-14 5(e); 2012-13 5(d) | N19: FALSE

Sheet Outside Notes
A1: IJ-section questions on topics NOT in the current slides
A2: Mostly older papers. Ask sir/ma'am whether these topics are in this term's syllabus before practising them.
A3: Q No. | B3: Year | C3: Course | D3: Ques No. | E3: Short Question | F3: Topic Area | G3: Marks | H3: TF Page | I3: Done | J3: My Notes
A4: 1 | B4: 2024-25 | C4: CSE 213 | D4: 2(b) | E4: Online education: AI feature vs financial crisis — identify and categorise risks | F4: Risk management | G4: 15 | H4: 22 batch p.2 | I4: FALSE
A5: 2 | B5: 2024-25 | C5: CSE 213 | D5: 3(a) | E5: SmartHome EVM from Gantt data: officer's schedule claim; lower bound on AC | F5: Earned value analysis | G5: 20 | H5: 22 batch p.3 | I5: FALSE
A6: 3 | B6: 2024-25 | C6: CSE 213 | D6: 3(b) | E6: Online library: caching, sharding, CDN | F6: Performance / architecture | G6: 15 | H6: 22 batch p.3 | I6: FALSE
A7: 4 | B7: 2024-25 | C7: CSE 213 | D7: 6(b) | E7: Registration-night overload vs DoS attack: distinguish; two defences | F7: Security | G7: 10 | H7: 22 batch p.6 | I7: FALSE
A8: 5 | B8: 2024-25 | C8: CSE 213 | D8: 7(c) | E8: C login with strcpy: buffer-overflow vulnerabilities, attack input, safer alternatives | F8: Security (buffer overflow) | G8: 10 | H8: 22 batch p.7–8 | I8: FALSE
A9: 6 | B9: 2023-24 | C9: CSE 213 | D9: 1(b) | E9: Proper IT security policy? Design a password policy | F9: Security policy | G9: 14 | H9: 1 | I9: FALSE
A10: 7 | B10: 2023-24 | C10: CSE 213 | D10: 1(d) | E10: Assets, exposures, vulnerabilities table | F10: Security | G10: 6 | H10: 1 | I10: FALSE
A11: 8 | B11: 2023-24 | C11: CSE 213 | D11: 1(e) | E11: Weaknesses of password authentication; 2FA / 3FA | F11: Security | G11: 8 | H11: 1 | I11: FALSE
A12: 9 | B12: 2023-24 | C12: CSE 213 | D12: 4(a) | E12: Security threats on instructions and data per CIA triad | F12: Security | G12: 7 | H12: 4 | I12: FALSE
A13: 10 | B13: 2023-24 | C13: CSE 213 | D13: 4(b) | E13: Encryption policy diagram; symmetric vs asymmetric | F13: Security | G13: 8 | H13: 4 | I13: FALSE
A14: 11 | B14: 2023-24 | C14: CSE 213 | D14: 4(c) | E14: Residual risk: asset $200,000, EF 20 %, ARO 1/5 yr, $10,000 safeguard → EF 5 %: worth it? | F14: Security risk (numerical) | G14: 7 | H14: 4 | I14: FALSE
A15: 12 | B15: 2023-24 | C15: CSE 213 | D15: 4(d) | E15: Buffer overflow | F15: Security | G15: 8 | H15: 4 | I15: FALSE
A16: 13 | B16: 2023-24 | C16: CSE 213 | D16: 6(c) | E16: EVM: 20 % more work per dollar, BAC 1000, features A/B — ahead? | F16: Earned value analysis | G16: 20 | H16: 5 | I16: FALSE
A17: 14 | B17: 2023-24 | C17: CSE 213 | D17: 7(a) | E17: AI travel agency: risks; proactive / reactive strategies | F17: Risk management | G17: 15 | H17: 5 | I17: FALSE
A18: 15 | B18: 2023-24 | C18: CSE 213 | D18: 7(b) | E18: Results portal crashes despite more servers | F18: Performance / scalability | G18: 10 | H18: 5 | I18: FALSE
A19: 16 | B19: 2023-24 | C19: CSE 213 | D19: 7(c) | E19: Software profiling; resource metrics; scalability | F19: Performance / scalability | G19: 10 | H19: 5 | I19: FALSE
A20: 17 | B20: 2023-24 | C20: CSE 213 | D20: 8(b) | E20: Manager vs leader | F20: Project management (people) | G20: 7 | H20: 6 | I20: FALSE
... A31: 28 | B31: 2021-22 | C31: CSE 307 | D31: 6(b) | E31: EVM table A–E, AC $130: SPI, CPI, EAC + remarks | F31: Earned value analysis | G31: 15 | H31: 17 | I31: FALSE
A32: 29 | B32: 2021-22 | C32: CSE 307 | D32: 7(b) | E32: CPM table A–H: slack, critical path, strict deadline | F32: CPM / PERT | G32: 20 | H32: 17–18 | I32: FALSE
A33: 30 | B33: 2021-22 | C33: CSE 307 | D33: 7(c) | E33: Adding manpower to a late project | F33: Project management (Brooks' law) | G33: 5 | H33: 18 | I33: FALSE
A34: 31 | B34: 2021-22 | C34: CSE 307 | D34: 8(c) | E34: People and process components (project management) | F34: Project management (4 P's) | G34: 10 | H34: 18 | I34: FALSE
A35: 32 | B35: 2020-21 | C35: CSE 307 | D35: 3(c) | E35: COCOMO II | F35: Cost estimation | G35: 10 | H35: 20 | I35: FALSE
A36: 33 | B36: 2020-21 | C36: CSE 307 | D36: 4(a) | E36: SSC result processing: 5 risks, exposure, mitigation | F36: Risk management | G36: 10 | H36: 20 | I36: FALSE
A37: 34 | B37: 2020-21 | C37: CSE 307 | D37: 4(b) | E37: Team selection factors (Bangla spell checker) | F37: Team organisation | G37: 15 | H37: 20 | I37: FALSE
A38: 35 | B38: 2020-21 | C38: CSE 307 | D38: 4(c) | E38: Titas gas billing: decision tree buy vs reuse | F38: Decision tree (make/buy) | G38: 10 | H38: 20 | I38: FALSE
