Workbook

Sheet How to Use
B2: CSE 213 (Anindya Sir part) — TF Practice Tracker
B3: Every Anindya-part question in CSE 213 All Past Papers.pdf, mapped to the note file and lesson that teaches it.
B5: Workflow — after you finish a note file
B6: 1. Open its tab | C6: Tabs 1–7 follow the order of your note files. Q No. runs lesson by lesson, newest year first inside each lesson.
B7: 2. Filter | C7: Use the filter arrow on Priority → ★★★ High first (2019-20 onward). Then ★★ Medium, then ★ Low.
B8: 3. Solve | C8: Open CSE 213 All Past Papers.pdf at the TF Page shown. Solve on paper under exam time (≈1.5 min per mark). Do not read the note solution first.
B9: 4. Check | C9: In Notes tells you what the note has: ✔ Solved = same question worked out; ◐ Method = method / model answer you can apply; ○ Partly = notes cover most of it, finish the rest yourself.
B10: 5. Record | C10: Tick Done, pick Confidence, add the Date. Write mistakes in My Notes. Re-solve every 'Weak' row before the exam.
B11: 6. Repeats | C11: 'Same Type Also In' lists other papers with the same question type. Solve one, then try a repeat cold — that is the real test.
B13: Columns you edit (all others are fixed data)
B14: Done (col N) | C14: TRUE / FALSE. In Google Sheets: select N4 downward → Insert → Checkbox. The values stay; ticking turns the row green.
B15: Confidence (col O) | C15: Dropdown: Weak / OK / Strong. Weak rows turn the cell red.
B16: Date (col P) | C16: Date you solved it, e.g. 16-Oct-2026.
B17: My Notes (col Q) | C17: Mistakes, missing steps, formula you forgot.
B19: Legend
B20: ★★★ High | C20: Asked in 2019-20 or later (most important — current question style).
B21: ★★ Medium | C21: Older paper, but the same question type appears at least twice in TF.
B22: ★ Low | C22: Older paper, asked once.
B23: Type | C23: Numerical = calculation · Trace = tables / step-by-step simulation · Design = construct / draw · Proof = prove / disprove · Theory = explain.
B24: Course | C24: CSE 213 = current code (2023-24 onward); CSE 307 = old L-3/T-1 code for the same course. '2024-25' = the 22-batch paper (exam 10/05/2026, header says 2023-2024), separate file 'CSE 213 (22 batch).pdf' → TF Page '22 batch p.N'.
B25: Topic | C25: Note lesson title — slide PDF and slide numbers.
B26: Outside Notes tab | C26: Anindya-section questions from older papers on topics not in the current slides. Check with your teacher before spending time on them.

Sheet Dashboard
A1: Progress Dashboard
A2: Updates automatically when you tick Done / set Confidence in tabs 1–7.
A4: # | B4: Note file (tab) | C4: Questions | D4: Done | E4: % Done | F4: Marks (total) | G4: Marks done | H4: High-priority left | I4: Weak | J4: Next unsolved (top of tab)
A5: 1 | B5: 1 Design Principles | C5: =COUNTA('1 Design Principles'!$E$4:$E$11) | D5: =COUNTIF('1 Design Principles'!$N$4:$N$11,TRUE()) | E5: =IF(C5=0,0,D5/C5) | F5: =SUM('1 Design Principles'!$H$4:$H$11) | G5: =SUMIF('1 Design Principles'!$N$4:$N$11,TRUE(),'1 Design Principles'!$H$4:$H$11) | H5: =COUNTIFS('1 Design Principles'!$J$4:$J$11,"★★★ High",'1 Design Principles'!$N$4:$N$11,FALSE()) | I5: =COUNTIF('1 Design Principles'!$O$4:$O$11,"Weak") | J5: =IFERROR("Q"&INDEX('1 Design Principles'!$A$4:$A$11,MATCH(FALSE(),'1 Design Principles'!$N$4:$N$11,0))&" · "&INDEX('1 Design Principles'!$B$4:$B$11,MATCH(FALSE(),'1 Design Principles'!$N$4:$N$11,0))&" "&INDEX('1 Design Principles'!$D$4:$D$11,MATCH(FALSE(),'1 Design Principles'!$N$4:$N$11,0))&" · TF p."&INDEX('1 Design Principles'!$I$4:$I$11,MATCH(FALSE(),'1 Design Principles'!$N$4:$N$11,0)),"All done ✔")
A6: 2 | B6: 2 Creational Patterns | C6: =COUNTA('2 Creational Patterns'!$E$4:$E$21) | D6: =COUNTIF('2 Creational Patterns'!$N$4:$N$21,TRUE()) | E6: =IF(C6=0,0,D6/C6) | F6: =SUM('2 Creational Patterns'!$H$4:$H$21) | G6: =SUMIF('2 Creational Patterns'!$N$4:$N$21,TRUE(),'2 Creational Patterns'!$H$4:$H$21) | H6: =COUNTIFS('2 Creational Patterns'!$J$4:$J$21,"★★★ High",'2 Creational Patterns'!$N$4:$N$21,FALSE()) | I6: =COUNTIF('2 Creational Patterns'!$O$4:$O$21,"Weak") | J6: =IFERROR("Q"&INDEX('2 Creational Patterns'!$A$4:$A$21,MATCH(FALSE(),'2 Creational Patterns'!$N$4:$N$21,0))&" · "&INDEX('2 Creational Patterns'!$B$4:$B$21,MATCH(FALSE(),'2 Creational Patterns'!$N$4:$N$21,0))&" "&INDEX('2 Creational Patterns'!$D$4:$D$21,MATCH(FALSE(),'2 Creational Patterns'!$N$4:$N$21,0))&" · TF p."&INDEX('2 Creational Patterns'!$I$4:$I$21,MATCH(FALSE(),'2 Creational Patterns'!$N$4:$N$21,0)),"All done ✔")
A7: 3 | B7: 3 Class Diagrams | C7: =COUNTA('3 Class Diagrams'!$E$4:$E$17) | D7: =COUNTIF('3 Class Diagrams'!$N$4:$N$17,TRUE()) | E7: =IF(C7=0,0,D7/C7) | F7: =SUM('3 Class Diagrams'!$H$4:$H$17) | G7: =SUMIF('3 Class Diagrams'!$N$4:$N$17,TRUE(),'3 Class Diagrams'!$H$4:$H$17) | H7: =COUNTIFS('3 Class Diagrams'!$J$4:$J$17,"★★★ High",'3 Class Diagrams'!$N$4:$N$17,FALSE()) | I7: =COUNTIF('3 Class Diagrams'!$O$4:$O$17,"Weak") | J7: =IFERROR("Q"&INDEX('3 Class Diagrams'!$A$4:$A$17,MATCH(FALSE(),'3 Class Diagrams'!$N$4:$N$17,0))&" · "&INDEX('3 Class Diagrams'!$B$4:$B$17,MATCH(FALSE(),'3 Class Diagrams'!$N$4:$N$17,0))&" "&INDEX('3 Class Diagrams'!$D$4:$D$17,MATCH(FALSE(),'3 Class Diagrams'!$N$4:$N$17,0))&" · TF p."&INDEX('3 Class Diagrams'!$I$4:$I$17,MATCH(FALSE(),'3 Class Diagrams'!$N$4:$N$17,0)),"All done ✔")
A8: 4 | B8: 4 State Diagrams | C8: =COUNTA('4 State Diagrams'!$E$4:$E$8) | D8: =COUNTIF('4 State Diagrams'!$N$4:$N$8,TRUE()) | E8: =IF(C8=0,0,D8/C8) | F8: =SUM('4 State Diagrams'!$H$4:$H$8) | G8: =SUMIF('4 State Diagrams'!$N$4:$N$8,TRUE(),'4 State Diagrams'!$H$4:$H$8) | H8: =COUNTIFS('4 State Diagrams'!$J$4:$J$8,"★★★ High",'4 State Diagrams'!$N$4:$N$8,FALSE()) | I8: =COUNTIF('4 State Diagrams'!$O$4:$O$8,"Weak") | J8: =IFERROR("Q"&INDEX('4 State Diagrams'!$A$4:$A$8,MATCH(FALSE(),'4 State Diagrams'!$N$4:$N$8,0))&" · "&INDEX('4 State Diagrams'!$B$4:$B$8,MATCH(FALSE(),'4 State Diagrams'!$N$4:$N$8,0))&" "&INDEX('4 State Diagrams'!$D$4:$D$8,MATCH(FALSE(),'4 State Diagrams'!$N$4:$N$8,0))&" · TF p."&INDEX('4 State Diagrams'!$I$4:$I$8,MATCH(FALSE(),'4 State Diagrams'!$N$4:$N$8,0)),"All done ✔")
A9: 5 | B9: 5 Interaction Diagrams | C9: =COUNTA('5 Interaction Diagrams'!$E$4:$E$11) | D9: =COUNTIF('5 Interaction Diagrams'!$N$4:$N$11,TRUE()) | E9: =IF(C9=0,0,D9/C9) | F9: =SUM('5 Interaction Diagrams'!$H$4:$H$11) | G9: =SUMIF('5 Interaction Diagrams'!$N$4:$N$11,TRUE(),'5 Interaction Diagrams'!$H$4:$H$11) | H9: =COUNTIFS('5 Interaction Diagrams'!$J$4:$J$11,"★★★ High",'5 Interaction Diagrams'!$N$4:$N$11,FALSE()) | I9: =COUNTIF('5 Interaction Diagrams'!$O$4:$O$11,"Weak") | J9: =IFERROR("Q"&INDEX('5 Interaction Diagrams'!$A$4:$A$11,MATCH(FALSE(),'5 Interaction Diagrams'!$N$4:$N$11,0))&" · "&INDEX('5 Interaction Diagrams'!$B$4:$B$11,MATCH(FALSE(),'5 Interaction Diagrams'!$N$4:$N$11,0))&" "&INDEX('5 Interaction Diagrams'!$D$4:$D$11,MATCH(FALSE(),'5 Interaction Diagrams'!$N$4:$N$11,0))&" · TF p."&INDEX('5 Interaction Diagrams'!$I$4:$I$11,MATCH(FALSE(),'5 Interaction Diagrams'!$N$4:$N$11,0)),"All done ✔")
A10: 6 | B10: 6 Use Case + BPMN | C10: =COUNTA('6 Use Case + BPMN'!$E$4:$E$18) | D10: =COUNTIF('6 Use Case + BPMN'!$N$4:$N$18,TRUE()) | E10: =IF(C10=0,0,D10/C10) | F10: =SUM('6 Use Case + BPMN'!$H$4:$H$18) | G10: =SUMIF('6 Use Case + BPMN'!$N$4:$N$18,TRUE(),'6 Use Case + BPMN'!$H$4:$H$18) | H10: =COUNTIFS('6 Use Case + BPMN'!$J$4:$J$18,"★★★ High",'6 Use Case + BPMN'!$N$4:$N$18,FALSE()) | I10: =COUNTIF('6 Use Case + BPMN'!$O$4:$O$18,"Weak") | J10: =IFERROR("Q"&INDEX('6 Use Case + BPMN'!$A$4:$A$18,MATCH(FALSE(),'6 Use Case + BPMN'!$N$4:$N$18,0))&" · "&INDEX('6 Use Case + BPMN'!$B$4:$B$18,MATCH(FALSE(),'6 Use Case + BPMN'!$N$4:$N$18,0))&" "&INDEX('6 Use Case + BPMN'!$D$4:$D$18,MATCH(FALSE(),'6 Use Case + BPMN'!$N$4:$N$18,0))&" · TF p."&INDEX('6 Use Case + BPMN'!$I$4:$I$18,MATCH(FALSE(),'6 Use Case + BPMN'!$N$4:$N$18,0)),"All done ✔")
A11: 7 | B11: 7 Software Testing | C11: =COUNTA('7 Software Testing'!$E$4:$E$43) | D11: =COUNTIF('7 Software Testing'!$N$4:$N$43,TRUE()) | E11: =IF(C11=0,0,D11/C11) | F11: =SUM('7 Software Testing'!$H$4:$H$43) | G11: =SUMIF('7 Software Testing'!$N$4:$N$43,TRUE(),'7 Software Testing'!$H$4:$H$43) | H11: =COUNTIFS('7 Software Testing'!$J$4:$J$43,"★★★ High",'7 Software Testing'!$N$4:$N$43,FALSE()) | I11: =COUNTIF('7 Software Testing'!$O$4:$O$43,"Weak") | J11: =IFERROR("Q"&INDEX('7 Software Testing'!$A$4:$A$43,MATCH(FALSE(),'7 Software Testing'!$N$4:$N$43,0))&" · "&INDEX('7 Software Testing'!$B$4:$B$43,MATCH(FALSE(),'7 Software Testing'!$N$4:$N$43,0))&" "&INDEX('7 Software Testing'!$D$4:$D$43,MATCH(FALSE(),'7 Software Testing'!$N$4:$N$43,0))&" · TF p."&INDEX('7 Software Testing'!$I$4:$I$43,MATCH(FALSE(),'7 Software Testing'!$N$4:$N$43,0)),"All done ✔")
B12: TOTAL | C12: =SUM(C5:C11) | D12: =SUM(D5:D11) | E12: =IF(C12=0,0,D12/C12) | F12: =SUM(F5:F11) | G12: =SUM(G5:G11) | H12: =SUM(H5:H11) | I12: =SUM(I5:I11)
A14: Questions by year (tabs 1–7)
A15: # | B15: Year | C15: Questions | D15: Done | E15: % Done | F15: Marks (total)
A16: 1 | B16: 2024-25 | C16: =COUNTIF('1 Design Principles'!$B$4:$B$11,$B16)+COUNTIF('2 Creational Patterns'!$B$4:$B$21,$B16)+COUNTIF('3 Class Diagrams'!$B$4:$B$17,$B16)+COUNTIF('4 State Diagrams'!$B$4:$B$8,$B16)+COUNTIF('5 Interaction Diagrams'!$B$4:$B$11,$B16)+COUNTIF('6 Use Case + BPMN'!$B$4:$B$18,$B16)+COUNTIF('7 Software Testing'!$B$4:$B$43,$B16) | D16: =COUNTIFS('1 Design Principles'!$B$4:$B$11,$B16,'1 Design Principles'!$N$4:$N$11,TRUE())+COUNTIFS('2 Creational Patterns'!$B$4:$B$21,$B16,'2 Creational Patterns'!$N$4:$N$21,TRUE())+COUNTIFS('3 Class Diagrams'!$B$4:$B$17,$B16,'3 Class Diagrams'!$N$4:$N$17,TRUE())+COUNTIFS('4 State Diagrams'!$B$4:$B$8,$B16,'4 State Diagrams'!$N$4:$N$8,TRUE())+COUNTIFS('5 Interaction Diagrams'!$B$4:$B$11,$B16,'5 Interaction Diagrams'!$N$4:$N$11,TRUE())+COUNTIFS('6 Use Case + BPMN'!$B$4:$B$18,$B16,'6 Use Case + BPMN'!$N$4:$N$18,TRUE())+COUNTIFS('7 Software Testing'!$B$4:$B$43,$B16,'7 Software Testing'!$N$4:$N$43,TRUE()) | E16: =IF(C16=0,0,D16/C16) | F16: =SUMIF('1 Design Principles'!$B$4:$B$11,$B16,'1 Design Principles'!$H$4:$H$11)+SUMIF('2 Creational Patterns'!$B$4:$B$21,$B16,'2 Creational Patterns'!$H$4:$H$21)+SUMIF('3 Class Diagrams'!$B$4:$B$17,$B16,'3 Class Diagrams'!$H$4:$H$17)+SUMIF('4 State Diagrams'!$B$4:$B$8,$B16,'4 State Diagrams'!$H$4:$H$8)+SUMIF('5 Interaction Diagrams'!$B$4:$B$11,$B16,'5 Interaction Diagrams'!$H$4:$H$11)+SUMIF('6 Use Case + BPMN'!$B$4:$B$18,$B16,'6 Use Case + BPMN'!$H$4:$H$18)+SUMIF('7 Software Testing'!$B$4:$B$43,$B16,'7 Software Testing'!$H$4:$H$43)
A17: 2 | B17: 2023-24 | C17: =COUNTIF('1 Design Principles'!$B$4:$B$11,$B17)+COUNTIF('2 Creational Patterns'!$B$4:$B$21,$B17)+COUNTIF('3 Class Diagrams'!$B$4:$B$17,$B17)+COUNTIF('4 State Diagrams'!$B$4:$B$8,$B17)+COUNTIF('5 Interaction Diagrams'!$B$4:$B$11,$B17)+COUNTIF('6 Use Case + BPMN'!$B$4:$B$18,$B17)+COUNTIF('7 Software Testing'!$B$4:$B$43,$B17) | D17: =COUNTIFS('1 Design Principles'!$B$4:$B$11,$B17,'1 Design Principles'!$N$4:$N$11,TRUE())+COUNTIFS('2 Creational Patterns'!$B$4:$B$21,$B17,'2 Creational Patterns'!$N$4:$N$21,TRUE())+COUNTIFS('3 Class Diagrams'!$B$4:$B$17,$B17,'3 Class Diagrams'!$N$4:$N$17,TRUE())+COUNTIFS('4 State Diagrams'!$B$4:$B$8,$B17,'4 State Diagrams'!$N$4:$N$8,TRUE())+COUNTIFS('5 Interaction Diagrams'!$B$4:$B$11,$B17,'5 Interaction Diagrams'!$N$4:$N$11,TRUE())+COUNTIFS('6 Use Case + BPMN'!$B$4:$B$18,$B17,'6 Use Case + BPMN'!$N$4:$N$18,TRUE())+COUNTIFS('7 Software Testing'!$B$4:$B$43,$B17,'7 Software Testing'!$N$4:$N$43,TRUE()) | E17: =IF(C17=0,0,D17/C17) | F17: =SUMIF('1 Design Principles'!$B$4:$B$11,$B17,'1 Design Principles'!$H$4:$H$11)+SUMIF('2 Creational Patterns'!$B$4:$B$21,$B17,'2 Creational Patterns'!$H$4:$H$21)+SUMIF('3 Class Diagrams'!$B$4:$B$17,$B17,'3 Class Diagrams'!$H$4:$H$17)+SUMIF('4 State Diagrams'!$B$4:$B$8,$B17,'4 State Diagrams'!$H$4:$H$8)+SUMIF('5 Interaction Diagrams'!$B$4:$B$11,$B17,'5 Interaction Diagrams'!$H$4:$H$11)+SUMIF('6 Use Case + BPMN'!$B$4:$B$18,$B17,'6 Use Case + BPMN'!$H$4:$H$18)+SUMIF('7 Software Testing'!$B$4:$B$43,$B17,'7 Software Testing'!$H$4:$H$43)
A18: 3 | B18: 2022-23 | C18: =COUNTIF('1 Design Principles'!$B$4:$B$11,$B18)+COUNTIF('2 Creational Patterns'!$B$4:$B$21,$B18)+COUNTIF('3 Class Diagrams'!$B$4:$B$17,$B18)+COUNTIF('4 State Diagrams'!$B$4:$B$8,$B18)+COUNTIF('5 Interaction Diagrams'!$B$4:$B$11,$B18)+COUNTIF('6 Use Case + BPMN'!$B$4:$B$18,$B18)+COUNTIF('7 Software Testing'!$B$4:$B$43,$B18) | D18: =COUNTIFS('1 Design Principles'!$B$4:$B$11,$B18,'1 Design Principles'!$N$4:$N$11,TRUE())+COUNTIFS('2 Creational Patterns'!$B$4:$B$21,$B18,'2 Creational Patterns'!$N$4:$N$21,TRUE())+COUNTIFS('3 Class Diagrams'!$B$4:$B$17,$B18,'3 Class Diagrams'!$N$4:$N$17,TRUE())+COUNTIFS('4 State Diagrams'!$B$4:$B$8,$B18,'4 State Diagrams'!$N$4:$N$8,TRUE())+COUNTIFS('5 Interaction Diagrams'!$B$4:$B$11,$B18,'5 Interaction Diagrams'!$N$4:$N$11,TRUE())+COUNTIFS('6 Use Case + BPMN'!$B$4:$B$18,$B18,'6 Use Case + BPMN'!$N$4:$N$18,TRUE())+COUNTIFS('7 Software Testing'!$B$4:$B$43,$B18,'7 Software Testing'!$N$4:$N$43,TRUE()) | E18: =IF(C18=0,0,D18/C18) | F18: =SUMIF('1 Design Principles'!$B$4:$B$11,$B18,'1 Design Principles'!$H$4:$H$11)+SUMIF('2 Creational Patterns'!$B$4:$B$21,$B18,'2 Creational Patterns'!$H$4:$H$21)+SUMIF('3 Class Diagrams'!$B$4:$B$17,$B18,'3 Class Diagrams'!$H$4:$H$17)+SUMIF('4 State Diagrams'!$B$4:$B$8,$B18,'4 State Diagrams'!$H$4:$H$8)+SUMIF('5 Interaction Diagrams'!$B$4:$B$11,$B18,'5 Interaction Diagrams'!$H$4:$H$11)+SUMIF('6 Use Case + BPMN'!$B$4:$B$18,$B18,'6 Use Case + BPMN'!$H$4:$H$18)+SUMIF('7 Software Testing'!$B$4:$B$43,$B18,'7 Software Testing'!$H$4:$H$43)
A19: 4 | B19: 2021-22 | C19: =COUNTIF('1 Design Principles'!$B$4:$B$11,$B19)+COUNTIF('2 Creational Patterns'!$B$4:$B$21,$B19)+COUNTIF('3 Class Diagrams'!$B$4:$B$17,$B19)+COUNTIF('4 State Diagrams'!$B$4:$B$8,$B19)+COUNTIF('5 Interaction Diagrams'!$B$4:$B$11,$B19)+COUNTIF('6 Use Case + BPMN'!$B$4:$B$18,$B19)+COUNTIF('7 Software Testing'!$B$4:$B$43,$B19) | D19: =COUNTIFS('1 Design Principles'!$B$4:$B$11,$B19,'1 Design Principles'!$N$4:$N$11,TRUE())+COUNTIFS('2 Creational Patterns'!$B$4:$B$21,$B19,'2 Creational Patterns'!$N$4:$N$21,TRUE())+COUNTIFS('3 Class Diagrams'!$B$4:$B$17,$B19,'3 Class Diagrams'!$N$4:$N$17,TRUE())+COUNTIFS('4 State Diagrams'!$B$4:$B$8,$B19,'4 State Diagrams'!$N$4:$N$8,TRUE())+COUNTIFS('5 Interaction Diagrams'!$B$4:$B$11,$B19,'5 Interaction Diagrams'!$N$4:$N$11,TRUE())+COUNTIFS('6 Use Case + BPMN'!$B$4:$B$18,$B19,'6 Use Case + BPMN'!$N$4:$N$18,TRUE())+COUNTIFS('7 Software Testing'!$B$4:$B$43,$B19,'7 Software Testing'!$N$4:$N$43,TRUE()) | E19: =IF(C19=0,0,D19/C19) | F19: =SUMIF('1 Design Principles'!$B$4:$B$11,$B19,'1 Design Principles'!$H$4:$H$11)+SUMIF('2 Creational Patterns'!$B$4:$B$21,$B19,'2 Creational Patterns'!$H$4:$H$21)+SUMIF('3 Class Diagrams'!$B$4:$B$17,$B19,'3 Class Diagrams'!$H$4:$H$17)+SUMIF('4 State Diagrams'!$B$4:$B$8,$B19,'4 State Diagrams'!$H$4:$H$8)+SUMIF('5 Interaction Diagrams'!$B$4:$B$11,$B19,'5 Interaction Diagrams'!$H$4:$H$11)+SUMIF('6 Use Case + BPMN'!$B$4:$B$18,$B19,'6 Use Case + BPMN'!$H$4:$H$18)+SUMIF('7 Software Testing'!$B$4:$B$43,$B19,'7 Software Testing'!$H$4:$H$43)
A20: 5 | B20: 2020-21 | C20: =COUNTIF('1 Design Principles'!$B$4:$B$11,$B20)+COUNTIF('2 Creational Patterns'!$B$4:$B$21,$B20)+COUNTIF('3 Class Diagrams'!$B$4:$B$17,$B20)+COUNTIF('4 State Diagrams'!$B$4:$B$8,$B20)+COUNTIF('5 Interaction Diagrams'!$B$4:$B$11,$B20)+COUNTIF('6 Use Case + BPMN'!$B$4:$B$18,$B20)+COUNTIF('7 Software Testing'!$B$4:$B$43,$B20) | D20: =COUNTIFS('1 Design Principles'!$B$4:$B$11,$B20,'1 Design Principles'!$N$4:$N$11,TRUE())+COUNTIFS('2 Creational Patterns'!$B$4:$B$21,$B20,'2 Creational Patterns'!$N$4:$N$21,TRUE())+COUNTIFS('3 Class Diagrams'!$B$4:$B$17,$B20,'3 Class Diagrams'!$N$4:$N$17,TRUE())+COUNTIFS('4 State Diagrams'!$B$4:$B$8,$B20,'4 State Diagrams'!$N$4:$N$8,TRUE())+COUNTIFS('5 Interaction Diagrams'!$B$4:$B$11,$B20,'5 Interaction Diagrams'!$N$4:$N$11,TRUE())+COUNTIFS('6 Use Case + BPMN'!$B$4:$B$18,$B20,'6 Use Case + BPMN'!$N$4:$N$18,TRUE())+COUNTIFS('7 Software Testing'!$B$4:$B$43,$B20,'7 Software Testing'!$N$4:$N$43,TRUE()) | E20: =IF(C20=0,0,D20/C20) | F20: =SUMIF('1 Design Principles'!$B$4:$B$11,$B20,'1 Design Principles'!$H$4:$H$11)+SUMIF('2 Creational Patterns'!$B$4:$B$21,$B20,'2 Creational Patterns'!$H$4:$H$21)+SUMIF('3 Class Diagrams'!$B$4:$B$17,$B20,'3 Class Diagrams'!$H$4:$H$17)+SUMIF('4 State Diagrams'!$B$4:$B$8,$B20,'4 State Diagrams'!$H$4:$H$8)+SUMIF('5 Interaction Diagrams'!$B$4:$B$11,$B20,'5 Interaction Diagrams'!$H$4:$H$11)+SUMIF('6 Use Case + BPMN'!$B$4:$B$18,$B20,'6 Use Case + BPMN'!$H$4:$H$18)+SUMIF('7 Software Testing'!$B$4:$B$43,$B20,'7 Software Testing'!$H$4:$H$43)
A21: 6 | B21: 2019-20 | C21: =COUNTIF('1 Design Principles'!$B$4:$B$11,$B21)+COUNTIF('2 Creational Patterns'!$B$4:$B$21,$B21)+COUNTIF('3 Class Diagrams'!$B$4:$B$17,$B21)+COUNTIF('4 State Diagrams'!$B$4:$B$8,$B21)+COUNTIF('5 Interaction Diagrams'!$B$4:$B$11,$B21)+COUNTIF('6 Use Case + BPMN'!$B$4:$B$18,$B21)+COUNTIF('7 Software Testing'!$B$4:$B$43,$B21) | D21: =COUNTIFS('1 Design Principles'!$B$4:$B$11,$B21,'1 Design Principles'!$N$4:$N$11,TRUE())+COUNTIFS('2 Creational Patterns'!$B$4:$B$21,$B21,'2 Creational Patterns'!$N$4:$N$21,TRUE())+COUNTIFS('3 Class Diagrams'!$B$4:$B$17,$B21,'3 Class Diagrams'!$N$4:$N$17,TRUE())+COUNTIFS('4 State Diagrams'!$B$4:$B$8,$B21,'4 State Diagrams'!$N$4:$N$8,TRUE())+COUNTIFS('5 Interaction Diagrams'!$B$4:$B$11,$B21,'5 Interaction Diagrams'!$N$4:$N$11,TRUE())+COUNTIFS('6 Use Case + BPMN'!$B$4:$B$18,$B21,'6 Use Case + BPMN'!$N$4:$N$18,TRUE())+COUNTIFS('7 Software Testing'!$B$4:$B$43,$B21,'7 Software Testing'!$N$4:$N$43,TRUE()) | E21: =IF(C21=0,0,D21/C21) | F21: =SUMIF('1 Design Principles'!$B$4:$B$11,$B21,'1 Design Principles'!$H$4:$H$11)+SUMIF('2 Creational Patterns'!$B$4:$B$21,$B21,'2 Creational Patterns'!$H$4:$H$21)+SUMIF('3 Class Diagrams'!$B$4:$B$17,$B21,'3 Class Diagrams'!$H$4:$H$17)+SUMIF('4 State Diagrams'!$B$4:$B$8,$B21,'4 State Diagrams'!$H$4:$H$8)+SUMIF('5 Interaction Diagrams'!$B$4:$B$11,$B21,'5 Interaction Diagrams'!$H$4:$H$11)+SUMIF('6 Use Case + BPMN'!$B$4:$B$18,$B21,'6 Use Case + BPMN'!$H$4:$H$18)+SUMIF('7 Software Testing'!$B$4:$B$43,$B21,'7 Software Testing'!$H$4:$H$43)
A22: 7 | B22: 2018-19 | C22: =COUNTIF('1 Design Principles'!$B$4:$B$11,$B22)+COUNTIF('2 Creational Patterns'!$B$4:$B$21,$B22)+COUNTIF('3 Class Diagrams'!$B$4:$B$17,$B22)+COUNTIF('4 State Diagrams'!$B$4:$B$8,$B22)+COUNTIF('5 Interaction Diagrams'!$B$4:$B$11,$B22)+COUNTIF('6 Use Case + BPMN'!$B$4:$B$18,$B22)+COUNTIF('7 Software Testing'!$B$4:$B$43,$B22) | D22: =COUNTIFS('1 Design Principles'!$B$4:$B$11,$B22,'1 Design Principles'!$N$4:$N$11,TRUE())+COUNTIFS('2 Creational Patterns'!$B$4:$B$21,$B22,'2 Creational Patterns'!$N$4:$N$21,TRUE())+COUNTIFS('3 Class Diagrams'!$B$4:$B$17,$B22,'3 Class Diagrams'!$N$4:$N$17,TRUE())+COUNTIFS('4 State Diagrams'!$B$4:$B$8,$B22,'4 State Diagrams'!$N$4:$N$8,TRUE())+COUNTIFS('5 Interaction Diagrams'!$B$4:$B$11,$B22,'5 Interaction Diagrams'!$N$4:$N$11,TRUE())+COUNTIFS('6 Use Case + BPMN'!$B$4:$B$18,$B22,'6 Use Case + BPMN'!$N$4:$N$18,TRUE())+COUNTIFS('7 Software Testing'!$B$4:$B$43,$B22,'7 Software Testing'!$N$4:$N$43,TRUE()) | E22: =IF(C22=0,0,D22/C22) | F22: =SUMIF('1 Design Principles'!$B$4:$B$11,$B22,'1 Design Principles'!$H$4:$H$11)+SUMIF('2 Creational Patterns'!$B$4:$B$21,$B22,'2 Creational Patterns'!$H$4:$H$21)+SUMIF('3 Class Diagrams'!$B$4:$B$17,$B22,'3 Class Diagrams'!$H$4:$H$17)+SUMIF('4 State Diagrams'!$B$4:$B$8,$B22,'4 State Diagrams'!$H$4:$H$8)+SUMIF('5 Interaction Diagrams'!$B$4:$B$11,$B22,'5 Interaction Diagrams'!$H$4:$H$11)+SUMIF('6 Use Case + BPMN'!$B$4:$B$18,$B22,'6 Use Case + BPMN'!$H$4:$H$18)+SUMIF('7 Software Testing'!$B$4:$B$43,$B22,'7 Software Testing'!$H$4:$H$43)
A23: 8 | B23: 2017-18 | C23: =COUNTIF('1 Design Principles'!$B$4:$B$11,$B23)+COUNTIF('2 Creational Patterns'!$B$4:$B$21,$B23)+COUNTIF('3 Class Diagrams'!$B$4:$B$17,$B23)+COUNTIF('4 State Diagrams'!$B$4:$B$8,$B23)+COUNTIF('5 Interaction Diagrams'!$B$4:$B$11,$B23)+COUNTIF('6 Use Case + BPMN'!$B$4:$B$18,$B23)+COUNTIF('7 Software Testing'!$B$4:$B$43,$B23) | D23: =COUNTIFS('1 Design Principles'!$B$4:$B$11,$B23,'1 Design Principles'!$N$4:$N$11,TRUE())+COUNTIFS('2 Creational Patterns'!$B$4:$B$21,$B23,'2 Creational Patterns'!$N$4:$N$21,TRUE())+COUNTIFS('3 Class Diagrams'!$B$4:$B$17,$B23,'3 Class Diagrams'!$N$4:$N$17,TRUE())+COUNTIFS('4 State Diagrams'!$B$4:$B$8,$B23,'4 State Diagrams'!$N$4:$N$8,TRUE())+COUNTIFS('5 Interaction Diagrams'!$B$4:$B$11,$B23,'5 Interaction Diagrams'!$N$4:$N$11,TRUE())+COUNTIFS('6 Use Case + BPMN'!$B$4:$B$18,$B23,'6 Use Case + BPMN'!$N$4:$N$18,TRUE())+COUNTIFS('7 Software Testing'!$B$4:$B$43,$B23,'7 Software Testing'!$N$4:$N$43,TRUE()) | E23: =IF(C23=0,0,D23/C23) | F23: =SUMIF('1 Design Principles'!$B$4:$B$11,$B23,'1 Design Principles'!$H$4:$H$11)+SUMIF('2 Creational Patterns'!$B$4:$B$21,$B23,'2 Creational Patterns'!$H$4:$H$21)+SUMIF('3 Class Diagrams'!$B$4:$B$17,$B23,'3 Class Diagrams'!$H$4:$H$17)+SUMIF('4 State Diagrams'!$B$4:$B$8,$B23,'4 State Diagrams'!$H$4:$H$8)+SUMIF('5 Interaction Diagrams'!$B$4:$B$11,$B23,'5 Interaction Diagrams'!$H$4:$H$11)+SUMIF('6 Use Case + BPMN'!$B$4:$B$18,$B23,'6 Use Case + BPMN'!$H$4:$H$18)+SUMIF('7 Software Testing'!$B$4:$B$43,$B23,'7 Software Testing'!$H$4:$H$43)
A24: 9 | B24: 2016-17 | C24: =COUNTIF('1 Design Principles'!$B$4:$B$11,$B24)+COUNTIF('2 Creational Patterns'!$B$4:$B$21,$B24)+COUNTIF('3 Class Diagrams'!$B$4:$B$17,$B24)+COUNTIF('4 State Diagrams'!$B$4:$B$8,$B24)+COUNTIF('5 Interaction Diagrams'!$B$4:$B$11,$B24)+COUNTIF('6 Use Case + BPMN'!$B$4:$B$18,$B24)+COUNTIF('7 Software Testing'!$B$4:$B$43,$B24) | D24: =COUNTIFS('1 Design Principles'!$B$4:$B$11,$B24,'1 Design Principles'!$N$4:$N$11,TRUE())+COUNTIFS('2 Creational Patterns'!$B$4:$B$21,$B24,'2 Creational Patterns'!$N$4:$N$21,TRUE())+COUNTIFS('3 Class Diagrams'!$B$4:$B$17,$B24,'3 Class Diagrams'!$N$4:$N$17,TRUE())+COUNTIFS('4 State Diagrams'!$B$4:$B$8,$B24,'4 State Diagrams'!$N$4:$N$8,TRUE())+COUNTIFS('5 Interaction Diagrams'!$B$4:$B$11,$B24,'5 Interaction Diagrams'!$N$4:$N$11,TRUE())+COUNTIFS('6 Use Case + BPMN'!$B$4:$B$18,$B24,'6 Use Case + BPMN'!$N$4:$N$18,TRUE())+COUNTIFS('7 Software Testing'!$B$4:$B$43,$B24,'7 Software Testing'!$N$4:$N$43,TRUE()) | E24: =IF(C24=0,0,D24/C24) | F24: =SUMIF('1 Design Principles'!$B$4:$B$11,$B24,'1 Design Principles'!$H$4:$H$11)+SUMIF('2 Creational Patterns'!$B$4:$B$21,$B24,'2 Creational Patterns'!$H$4:$H$21)+SUMIF('3 Class Diagrams'!$B$4:$B$17,$B24,'3 Class Diagrams'!$H$4:$H$17)+SUMIF('4 State Diagrams'!$B$4:$B$8,$B24,'4 State Diagrams'!$H$4:$H$8)+SUMIF('5 Interaction Diagrams'!$B$4:$B$11,$B24,'5 Interaction Diagrams'!$H$4:$H$11)+SUMIF('6 Use Case + BPMN'!$B$4:$B$18,$B24,'6 Use Case + BPMN'!$H$4:$H$18)+SUMIF('7 Software Testing'!$B$4:$B$43,$B24,'7 Software Testing'!$H$4:$H$43)
A25: 10 | B25: 2014-15 | C25: =COUNTIF('1 Design Principles'!$B$4:$B$11,$B25)+COUNTIF('2 Creational Patterns'!$B$4:$B$21,$B25)+COUNTIF('3 Class Diagrams'!$B$4:$B$17,$B25)+COUNTIF('4 State Diagrams'!$B$4:$B$8,$B25)+COUNTIF('5 Interaction Diagrams'!$B$4:$B$11,$B25)+COUNTIF('6 Use Case + BPMN'!$B$4:$B$18,$B25)+COUNTIF('7 Software Testing'!$B$4:$B$43,$B25) | D25: =COUNTIFS('1 Design Principles'!$B$4:$B$11,$B25,'1 Design Principles'!$N$4:$N$11,TRUE())+COUNTIFS('2 Creational Patterns'!$B$4:$B$21,$B25,'2 Creational Patterns'!$N$4:$N$21,TRUE())+COUNTIFS('3 Class Diagrams'!$B$4:$B$17,$B25,'3 Class Diagrams'!$N$4:$N$17,TRUE())+COUNTIFS('4 State Diagrams'!$B$4:$B$8,$B25,'4 State Diagrams'!$N$4:$N$8,TRUE())+COUNTIFS('5 Interaction Diagrams'!$B$4:$B$11,$B25,'5 Interaction Diagrams'!$N$4:$N$11,TRUE())+COUNTIFS('6 Use Case + BPMN'!$B$4:$B$18,$B25,'6 Use Case + BPMN'!$N$4:$N$18,TRUE())+COUNTIFS('7 Software Testing'!$B$4:$B$43,$B25,'7 Software Testing'!$N$4:$N$43,TRUE()) | E25: =IF(C25=0,0,D25/C25) | F25: =SUMIF('1 Design Principles'!$B$4:$B$11,$B25,'1 Design Principles'!$H$4:$H$11)+SUMIF('2 Creational Patterns'!$B$4:$B$21,$B25,'2 Creational Patterns'!$H$4:$H$21)+SUMIF('3 Class Diagrams'!$B$4:$B$17,$B25,'3 Class Diagrams'!$H$4:$H$17)+SUMIF('4 State Diagrams'!$B$4:$B$8,$B25,'4 State Diagrams'!$H$4:$H$8)+SUMIF('5 Interaction Diagrams'!$B$4:$B$11,$B25,'5 Interaction Diagrams'!$H$4:$H$11)+SUMIF('6 Use Case + BPMN'!$B$4:$B$18,$B25,'6 Use Case + BPMN'!$H$4:$H$18)+SUMIF('7 Software Testing'!$B$4:$B$43,$B25,'7 Software Testing'!$H$4:$H$43)
A26: 11 | B26: 2013-14 | C26: =COUNTIF('1 Design Principles'!$B$4:$B$11,$B26)+COUNTIF('2 Creational Patterns'!$B$4:$B$21,$B26)+COUNTIF('3 Class Diagrams'!$B$4:$B$17,$B26)+COUNTIF('4 State Diagrams'!$B$4:$B$8,$B26)+COUNTIF('5 Interaction Diagrams'!$B$4:$B$11,$B26)+COUNTIF('6 Use Case + BPMN'!$B$4:$B$18,$B26)+COUNTIF('7 Software Testing'!$B$4:$B$43,$B26) | D26: =COUNTIFS('1 Design Principles'!$B$4:$B$11,$B26,'1 Design Principles'!$N$4:$N$11,TRUE())+COUNTIFS('2 Creational Patterns'!$B$4:$B$21,$B26,'2 Creational Patterns'!$N$4:$N$21,TRUE())+COUNTIFS('3 Class Diagrams'!$B$4:$B$17,$B26,'3 Class Diagrams'!$N$4:$N$17,TRUE())+COUNTIFS('4 State Diagrams'!$B$4:$B$8,$B26,'4 State Diagrams'!$N$4:$N$8,TRUE())+COUNTIFS('5 Interaction Diagrams'!$B$4:$B$11,$B26,'5 Interaction Diagrams'!$N$4:$N$11,TRUE())+COUNTIFS('6 Use Case + BPMN'!$B$4:$B$18,$B26,'6 Use Case + BPMN'!$N$4:$N$18,TRUE())+COUNTIFS('7 Software Testing'!$B$4:$B$43,$B26,'7 Software Testing'!$N$4:$N$43,TRUE()) | E26: =IF(C26=0,0,D26/C26) | F26: =SUMIF('1 Design Principles'!$B$4:$B$11,$B26,'1 Design Principles'!$H$4:$H$11)+SUMIF('2 Creational Patterns'!$B$4:$B$21,$B26,'2 Creational Patterns'!$H$4:$H$21)+SUMIF('3 Class Diagrams'!$B$4:$B$17,$B26,'3 Class Diagrams'!$H$4:$H$17)+SUMIF('4 State Diagrams'!$B$4:$B$8,$B26,'4 State Diagrams'!$H$4:$H$8)+SUMIF('5 Interaction Diagrams'!$B$4:$B$11,$B26,'5 Interaction Diagrams'!$H$4:$H$11)+SUMIF('6 Use Case + BPMN'!$B$4:$B$18,$B26,'6 Use Case + BPMN'!$H$4:$H$18)+SUMIF('7 Software Testing'!$B$4:$B$43,$B26,'7 Software Testing'!$H$4:$H$43)
A27: 12 | B27: 2012-13 | C27: =COUNTIF('1 Design Principles'!$B$4:$B$11,$B27)+COUNTIF('2 Creational Patterns'!$B$4:$B$21,$B27)+COUNTIF('3 Class Diagrams'!$B$4:$B$17,$B27)+COUNTIF('4 State Diagrams'!$B$4:$B$8,$B27)+COUNTIF('5 Interaction Diagrams'!$B$4:$B$11,$B27)+COUNTIF('6 Use Case + BPMN'!$B$4:$B$18,$B27)+COUNTIF('7 Software Testing'!$B$4:$B$43,$B27) | D27: =COUNTIFS('1 Design Principles'!$B$4:$B$11,$B27,'1 Design Principles'!$N$4:$N$11,TRUE())+COUNTIFS('2 Creational Patterns'!$B$4:$B$21,$B27,'2 Creational Patterns'!$N$4:$N$21,TRUE())+COUNTIFS('3 Class Diagrams'!$B$4:$B$17,$B27,'3 Class Diagrams'!$N$4:$N$17,TRUE())+COUNTIFS('4 State Diagrams'!$B$4:$B$8,$B27,'4 State Diagrams'!$N$4:$N$8,TRUE())+COUNTIFS('5 Interaction Diagrams'!$B$4:$B$11,$B27,'5 Interaction Diagrams'!$N$4:$N$11,TRUE())+COUNTIFS('6 Use Case + BPMN'!$B$4:$B$18,$B27,'6 Use Case + BPMN'!$N$4:$N$18,TRUE())+COUNTIFS('7 Software Testing'!$B$4:$B$43,$B27,'7 Software Testing'!$N$4:$N$43,TRUE()) | E27: =IF(C27=0,0,D27/C27) | F27: =SUMIF('1 Design Principles'!$B$4:$B$11,$B27,'1 Design Principles'!$H$4:$H$11)+SUMIF('2 Creational Patterns'!$B$4:$B$21,$B27,'2 Creational Patterns'!$H$4:$H$21)+SUMIF('3 Class Diagrams'!$B$4:$B$17,$B27,'3 Class Diagrams'!$H$4:$H$17)+SUMIF('4 State Diagrams'!$B$4:$B$8,$B27,'4 State Diagrams'!$H$4:$H$8)+SUMIF('5 Interaction Diagrams'!$B$4:$B$11,$B27,'5 Interaction Diagrams'!$H$4:$H$11)+SUMIF('6 Use Case + BPMN'!$B$4:$B$18,$B27,'6 Use Case + BPMN'!$H$4:$H$18)+SUMIF('7 Software Testing'!$B$4:$B$43,$B27,'7 Software Testing'!$H$4:$H$43)
... A29: 14 | B29: 2010-11 | C29: =COUNTIF('1 Design Principles'!$B$4:$B$11,$B29)+COUNTIF('2 Creational Patterns'!$B$4:$B$21,$B29)+COUNTIF('3 Class Diagrams'!$B$4:$B$17,$B29)+COUNTIF('4 State Diagrams'!$B$4:$B$8,$B29)+COUNTIF('5 Interaction Diagrams'!$B$4:$B$11,$B29)+COUNTIF('6 Use Case + BPMN'!$B$4:$B$18,$B29)+COUNTIF('7 Software Testing'!$B$4:$B$43,$B29) | D29: =COUNTIFS('1 Design Principles'!$B$4:$B$11,$B29,'1 Design Principles'!$N$4:$N$11,TRUE())+COUNTIFS('2 Creational Patterns'!$B$4:$B$21,$B29,'2 Creational Patterns'!$N$4:$N$21,TRUE())+COUNTIFS('3 Class Diagrams'!$B$4:$B$17,$B29,'3 Class Diagrams'!$N$4:$N$17,TRUE())+COUNTIFS('4 State Diagrams'!$B$4:$B$8,$B29,'4 State Diagrams'!$N$4:$N$8,TRUE())+COUNTIFS('5 Interaction Diagrams'!$B$4:$B$11,$B29,'5 Interaction Diagrams'!$N$4:$N$11,TRUE())+COUNTIFS('6 Use Case + BPMN'!$B$4:$B$18,$B29,'6 Use Case + BPMN'!$N$4:$N$18,TRUE())+COUNTIFS('7 Software Testing'!$B$4:$B$43,$B29,'7 Software Testing'!$N$4:$N$43,TRUE()) | E29: =IF(C29=0,0,D29/C29) | F29: =SUMIF('1 Design Principles'!$B$4:$B$11,$B29,'1 Design Principles'!$H$4:$H$11)+SUMIF('2 Creational Patterns'!$B$4:$B$21,$B29,'2 Creational Patterns'!$H$4:$H$21)+SUMIF('3 Class Diagrams'!$B$4:$B$17,$B29,'3 Class Diagrams'!$H$4:$H$17)+SUMIF('4 State Diagrams'!$B$4:$B$8,$B29,'4 State Diagrams'!$H$4:$H$8)+SUMIF('5 Interaction Diagrams'!$B$4:$B$11,$B29,'5 Interaction Diagrams'!$H$4:$H$11)+SUMIF('6 Use Case + BPMN'!$B$4:$B$18,$B29,'6 Use Case + BPMN'!$H$4:$H$18)+SUMIF('7 Software Testing'!$B$4:$B$43,$B29,'7 Software Testing'!$H$4:$H$43)
B30: Shaded years = ★★★ High priority (2019-20 onward).
B31: TF Page = page in 'CSE 213 All Past Papers.pdf' (70 p.). It contains everything in 'CSE 213 Question.pdf' (63 p.) plus the 2023-24 CSE 213 paper (21 batch) as pages 1–7, so Question.pdf page = All Past Papers page − 7.
B32: Papers do not split by teacher section; every question is assigned by topic. Topics in neither teacher's slides (EVM, CPM/PERT, COCOMO/FP, risk, security, architecture, DevOps, IS design) are in 'Outside Notes'.

Sheet 1 Design Principles
A1: Lec 1–2 — Design Principles & Pattern Basics
A2: Note file: CSE213_Anindya_Design_Principles_Notes.docx · Solve after finishing the matching lesson. Filter Priority → ★★★ High first.
A3: Q No. | B3: Year | C3: Course | D3: Ques No. | E3: Short Question | F3: Topic (slide PDF · slides) | G3: Lesson | H3: Marks | I3: TF Page | J3: Priority | K3: Type | L3: In Notes | M3: Same Type Also In | N3: Done | O3: Confidence | P3: Date | Q3: My Notes
A4: 1 | B4: 2018-19 | C4: CSE 307 | D4: 3(c) | E4: Cohesion and coupling | F4: Encapsulation, interfaces, cohesion/coupling — Lec 1, sl. 2–9 | G4: L1 | H4: 8 | I4: 27 | J4: ★★ Medium | K4: Theory | L4: ✔ Solved | M4: 2017-18 7(c) | N4: FALSE
A5: 2 | B5: 2017-18 | C5: CSE 307 | D5: 7(c) | E5: Tight cohesion and loose coupling; influence on design | F5: Encapsulation, interfaces, cohesion/coupling — Lec 1, sl. 2–9 | G5: L1 | H5: 8 | I5: 34 | J5: ★★ Medium | K5: Theory | L5: ✔ Solved | M5: 2018-19 3(c) | N5: FALSE
A6: 3 | B6: 2010-11 | C6: CSE 307 | D6: 3(c) | E6: Subclassing vs delegation: names; which deserves preference? | F6: Encapsulation, interfaces, cohesion/coupling — Lec 1, sl. 2–9 | G6: L1 | H6: 5 | I6: 66 | J6: ★ Low | K6: Theory | L6: ✔ Solved | M6: — | N6: FALSE
A7: 4 | B7: 2016-17 | C7: CSE 307 | D7: 8(d) | E7: GraphicEditor.getArea by m_type: which principle is violated? Rewrite | F7: SRP, OCP — Lec 1, sl. 10–17 | G7: L2 | H7: 6.67 | I7: 40 | J7: ★ Low | K7: Code | L7: ✔ Solved | M7: — | N7: FALSE
A8: 5 | B8: 2022-23 | C8: CSE 307 | D8: 2(c) | E8: Example of the Interface Segregation Principle | F8: LSP, ISP, DIP — Lec 1, sl. 18–31 | G8: L3 | H8: 8 | I8: 8 | J8: ★★★ High | K8: Design | L8: ✔ Solved | M8: 2012-13 4(b) | N8: FALSE
A9: 6 | B9: 2012-13 | C9: CSE 307 | D9: 4(b) | E9: Motivation of ISP with a bad example | F9: LSP, ISP, DIP — Lec 1, sl. 18–31 | G9: L3 | H9: 14.67 | I9: 52 | J9: ★★ Medium | K9: Design | L9: ✔ Solved | M9: 2022-23 2(c) | N9: FALSE
A10: 7 | B10: 2014-15 | C10: CSE 307 | D10: 6(a) | E10: Structural vs behavioural patterns; classification criteria | F10: Pattern basics, GoF catalogue — Lec 2, sl. 1–10 | G10: L4 | H10: 10 | I10: 43 | J10: ★★ Medium | K10: Theory | L10: ✔ Solved | M10: 2011-12 4(c) | N10: FALSE
A11: 8 | B11: 2011-12 | C11: CSE 307 | D11: 4(c) | E11: Four essential elements of a design pattern | F11: Pattern basics, GoF catalogue — Lec 2, sl. 1–10 | G11: L4 | H11: 8 | I11: 58 | J11: ★★ Medium | K11: Theory | L11: ✔ Solved | M11: 2014-15 6(a) | N11: FALSE

Sheet 2 Creational Patterns
A1: Lec 3 — Creational Design Patterns
A2: Note file: CSE213_Anindya_Creational_Patterns_Notes.docx · Solve after finishing the matching lesson. Filter Priority → ★★★ High first.
A3: Q No. | B3: Year | C3: Course | D3: Ques No. | E3: Short Question | F3: Topic (slide PDF · slides) | G3: Lesson | H3: Marks | I3: TF Page | J3: Priority | K3: Type | L3: In Notes | M3: Same Type Also In | N3: Done | O3: Confidence | P3: Date | Q3: My Notes
A4: 1 | B4: 2024-25 | C4: CSE 213 | D4: 1(a) | E4: Travel packages (Adventure/Regular): centralised creation, client never names concrete class, add types without modifying — pattern + Java | F4: UML recap, Factory Method — Lec 3, sl. 2–16 | G4: L5 | H4: 15 | I4: 22 batch p.1 | J4: ★★★ High | K4: Design | L4: ✔ Solved | M4: 2016-17 5(c); 2010-11 3(d) | N4: FALSE
A5: 2 | B5: 2016-17 | C5: CSE 307 | D5: 5(c) | E5: Choose parser by file extension (.c, .cpp, .java, .html) — pattern + Java | F5: UML recap, Factory Method — Lec 3, sl. 2–16 | G5: L5 | H5: 10 | I5: 38 | J5: ★★ Medium | K5: Design | L5: ✔ Solved | M5: 2024-25 1(a); 2010-11 3(d) | N5: FALSE
A6: 3 | B6: 2010-11 | C6: CSE 307 | D6: 3(d) | E6: Does XMLReaderFactory implement the Factory pattern? | F6: UML recap, Factory Method — Lec 3, sl. 2–16 | G6: L5 | H6: 5 | I6: 67 | J6: ★★ Medium | K6: Theory | L6: ✔ Solved | M6: 2024-25 1(a); 2016-17 5(c) | N6: FALSE
A7: 4 | B7: 2023-24 | C7: CSE 213 | D7: 5(a) | E7: Pizza stores Italy / America with regional styles — pattern + code | F7: Abstract Factory — Lec 3, sl. 17–35 | G7: L6 | H7: 15 | I7: 4 | J7: ★★★ High | K7: Design | L7: ✔ Solved | M7: 2021-22 3(a); 2017-18 7(b); 2014-15 6(b) | N7: FALSE
A8: 5 | B8: 2021-22 | C8: CSE 307 | D8: 3(a) | E8: Restaurant set menus (Veggie Harvest, Chicken Delight, Beef Fiesta, Sea Shanty) from three kitchens — pattern + UML + code | F8: Abstract Factory — Lec 3, sl. 17–35 | G8: L6 | H8: 20 | I8: 15 | J8: ★★★ High | K8: Design | L8: ✔ Solved | M8: 2023-24 5(a); 2017-18 7(b); 2014-15 6(b) | N8: FALSE
A9: 6 | B9: 2017-18 | C9: CSE 307 | D9: 7(b) | E9: Uber / Pathao car and moto fare formulas — class diagram + code | F9: Abstract Factory — Lec 3, sl. 17–35 | G9: L6 | H9: 21 | I9: 33–34 | J9: ★★ Medium | K9: Design | L9: ✔ Solved | M9: 2023-24 5(a); 2021-22 3(a); 2014-15 6(b) | N9: FALSE
A10: 7 | B10: 2014-15 | C10: CSE 307 | D10: 6(b) | E10: Pattern that reduces dependence on hardware/software platforms | F10: Abstract Factory — Lec 3, sl. 17–35 | G10: L6 | H10: 12 | I10: 43 | J10: ★★ Medium | K10: Theory | L10: ✔ Solved | M10: 2023-24 5(a); 2021-22 3(a); 2017-18 7(b) | N10: FALSE
A11: 8 | B11: 2019-20 | C11: CSE 307 | D11: 1(a) | E11: Serial unique identifiers (userID, district, qualification, TxID) starting from 1 — suitable pattern | F11: Singleton — Lec 3, sl. 36–42 | G11: L7 | H11: 15 | I11: 22 | J11: ★★★ High | K11: Design | L11: ✔ Solved | M11: 2016-17 5(a); 2012-13 2(a); 2011-12 1(b); 2010-11 4(a) | N11: FALSE
A12: 9 | B12: 2016-17 | C12: CSE 307 | D12: 5(a) | E12: Eager vs lazy singleton; when lazy is preferred | F12: Singleton — Lec 3, sl. 36–42 | G12: L7 | H12: 15 | I12: 38 | J12: ★★ Medium | K12: Theory | L12: ✔ Solved | M12: 2019-20 1(a); 2012-13 2(a); 2011-12 1(b); 2010-11 4(a) | N12: FALSE
A13: 10 | B13: 2012-13 | C13: CSE 307 | D13: 2(a) | E13: Lazy vs eager singleton; structure | F13: Singleton — Lec 3, sl. 36–42 | G13: L7 | H13: 10 | I13: 50 | J13: ★★ Medium | K13: Theory | L13: ✔ Solved | M13: 2019-20 1(a); 2016-17 5(a); 2011-12 1(b); 2010-11 4(a) | N13: FALSE
A14: 11 | B14: 2011-12 | C14: CSE 307 | D14: 1(b) | E14: Base class with Derived1 (max 5 instances) and Derived2 (max 10) — Singleton-style Java | F14: Singleton — Lec 3, sl. 36–42 | G14: L7 | H14: 18.67 | I14: 57 | J14: ★★ Medium | K14: Code | L14: ✔ Solved | M14: 2019-20 1(a); 2016-17 5(a); 2012-13 2(a); 2010-11 4(a) | N14: FALSE
A15: 12 | B15: 2010-11 | C15: CSE 307 | D15: 4(a) | E15: Which singleton implementation (eager / holder) is valid? | F15: Singleton — Lec 3, sl. 36–42 | G15: L7 | H15: 5 | I15: 67 | J15: ★★ Medium | K15: Theory | L15: ✔ Solved | M15: 2019-20 1(a); 2016-17 5(a); 2012-13 2(a); 2011-12 1(b) | N15: FALSE
A16: 13 | B16: 2022-23 | C16: CSE 307 | D16: 3(a) | E16: HTMLPageDirector / HTMLPageBuilder — class diagram + code | F16: Builder, choosing a creational pattern — Lec 3, sl. 43–53 | G16: L8 | H16: 15 | I16: 8 | J16: ★★★ High | K16: Design | L16: ✔ Solved | M16: 2018-19 3(b); 2017-18 6(a) | N16: FALSE
A17: 14 | B17: 2021-22 | C17: CSE 307 | D17: 1(a) | E17: Differentiate use cases of Factory Method, Abstract Factory, Builder and Bridge | F17: Builder, choosing a creational pattern — Lec 3, sl. 43–53 | G17: L8 | H17: 16 | I17: 13 | J17: ★★★ High | K17: Theory | L17: ✔ Solved | M17: — | N17: FALSE
A18: 15 | B18: 2020-21 | C18: CSE 307 | D18: 1(a) | E18: Burger shop: pizzas + extra cheese + drinks + appetizers + meals — construct the four orders with three different patterns, with prices | F18: Builder, choosing a creational pattern — Lec 3, sl. 43–53 | G18: L8 | H18: 28 | I18: 19 | J18: ★★★ High | K18: Design | L18: ✔ Solved | M18: 2020-21 1(b) | N18: FALSE
A19: 16 | B19: 2020-21 | C19: CSE 307 | D19: 1(b) | E19: Advantages and disadvantages of the patterns used in 1(a) | F19: Builder, choosing a creational pattern — Lec 3, sl. 43–53 | G19: L8 | H19: 7 | I19: 19 | J19: ★★★ High | K19: Theory | L19: ✔ Solved | M19: 2020-21 1(a) | N19: FALSE
A20: 17 | B20: 2018-19 | C20: CSE 307 | D20: 3(b) | E20: Forms built per user type (Builder) — class diagram + code | F20: Builder, choosing a creational pattern — Lec 3, sl. 43–53 | G20: L8 | H20: 20 | I20: 27 | J20: ★★ Medium | K20: Design | L20: ✔ Solved | M20: 2022-23 3(a); 2017-18 6(a) | N20: FALSE
A21: 18 | B21: 2017-18 | C21: CSE 307 | D21: 6(a) | E21: Lalbagh set meals (rice + curries / bread + kebabs, optional drinks, bill) — class diagram + code | F21: Builder, choosing a creational pattern — Lec 3, sl. 43–53 | G21: L8 | H21: 22 | I21: 33 | J21: ★★ Medium | K21: Design | L21: ✔ Solved | M21: 2022-23 3(a); 2018-19 3(b) | N21: FALSE

Sheet 3 Class Diagrams
A1: Lec 4–6 — Class Diagrams & ERD to Class
A2: Note file: CSE213_Anindya_Class_Diagrams_Notes.docx · Solve after finishing the matching lesson. Filter Priority → ★★★ High first.
A3: Q No. | B3: Year | C3: Course | D3: Ques No. | E3: Short Question | F3: Topic (slide PDF · slides) | G3: Lesson | H3: Marks | I3: TF Page | J3: Priority | K3: Type | L3: In Notes | M3: Same Type Also In | N3: Done | O3: Confidence | P3: Date | Q3: My Notes
A4: 1 | B4: 2014-15 | C4: CSE 307 | D4: 8(a) | E4: Types of classes in a class diagram | F4: Class notation, kinds of classes — Lec 5, sl. 1–5 | G4: L9 | H4: 12.67 | I4: 44 | J4: ★ Low | K4: Theory | L4: ✔ Solved | M4: — | N4: FALSE
A5: 2 | B5: 2018-19 | C5: CSE 307 | D5: 4(c) | E5: Aggregation and composition — video rental store | F5: Relationships, aggregation vs composition — Lec 5, sl. 6–14 | G5: L10 | H5: 8 | I5: 27 | J5: ★★ Medium | K5: Design | L5: ✔ Solved | M5: 2017-18 8(c) | N5: FALSE
A6: 3 | B6: 2017-18 | C6: CSE 307 | D6: 8(c) | E6: Aggregation and composition example diagrams | F6: Relationships, aggregation vs composition — Lec 5, sl. 6–14 | G6: L10 | H6: 6 | I6: 34 | J6: ★★ Medium | K6: Design | L6: ✔ Solved | M6: 2018-19 4(c) | N6: FALSE
A7: 4 | B7: 2022-23 | C7: CSE 307 | D7: 4(b) | E7: Accounting software: Account / Debtor / Creditor / child & leaf accounts / 2-step authorisation — class diagram | F7: Scenario class diagrams — Lec 5, sl. 15–24 | G7: L11 | H7: 12 | I7: 9 | J7: ★★★ High | K7: Design | L7: ✔ Solved | M7: 2021-22 2(b); 2020-21 5(a); 2019-20 5(a); 2018-19 1(a); 2017-18 5(a); 2014-15 8(b) | N7: FALSE
A8: 5 | B8: 2021-22 | C8: CSE 307 | D8: 2(b) | E8: University: departments, faculties, head, courses, students — class diagram | F8: Scenario class diagrams — Lec 5, sl. 15–24 | G8: L11 | H8: 10 | I8: 15 | J8: ★★★ High | K8: Design | L8: ✔ Solved | M8: 2022-23 4(b); 2020-21 5(a); 2019-20 5(a); 2018-19 1(a); 2017-18 5(a); 2014-15 8(b) | N8: FALSE
A9: 6 | B9: 2020-21 | C9: CSE 307 | D9: 5(a) | E9: Media agency newspaper advertisements — class diagram | F9: Scenario class diagrams — Lec 5, sl. 15–24 | G9: L11 | H9: 16 | I9: 21 | J9: ★★★ High | K9: Design | L9: ✔ Solved | M9: 2022-23 4(b); 2021-22 2(b); 2019-20 5(a); 2018-19 1(a); 2017-18 5(a); 2014-15 8(b) | N9: FALSE
A10: 7 | B10: 2019-20 | C10: CSE 307 | D10: 5(a) | E10: Hospital wards, teams, consultant / junior doctors, patients — class diagram | F10: Scenario class diagrams — Lec 5, sl. 15–24 | G10: L11 | H10: 20 | I10: 24 | J10: ★★★ High | K10: Design | L10: ✔ Solved | M10: 2022-23 4(b); 2021-22 2(b); 2020-21 5(a); 2018-19 1(a); 2017-18 5(a); 2014-15 8(b) | N10: FALSE
A11: 8 | B11: 2018-19 | C11: CSE 307 | D11: 1(a) | E11: Bangladesh Shipping Management (shipped items, transportation events) — class diagram | F11: Scenario class diagrams — Lec 5, sl. 15–24 | G11: L11 | H11: 14 | I11: 26 | J11: ★★ Medium | K11: Design | L11: ◐ Method | M11: 2022-23 4(b); 2021-22 2(b); 2020-21 5(a); 2019-20 5(a); 2017-18 5(a); 2014-15 8(b) | N11: FALSE
A12: 9 | B12: 2017-18 | C12: CSE 307 | D12: 5(a) | E12: Hospital wards / teams — class diagram | F12: Scenario class diagrams — Lec 5, sl. 15–24 | G12: L11 | H12: 14 | I12: 32 | J12: ★★ Medium | K12: Design | L12: ✔ Solved | M12: 2022-23 4(b); 2021-22 2(b); 2020-21 5(a); 2019-20 5(a); 2018-19 1(a); 2014-15 8(b) | N12: FALSE
A13: 10 | B13: 2014-15 | C13: CSE 307 | D13: 8(b) | E13: Music-CD lending database — class and sequence diagrams | F13: Scenario class diagrams — Lec 5, sl. 15–24 | G13: L11 | H13: 22 | I13: 44 | J13: ★★ Medium | K13: Design | L13: ✔ Solved | M13: 2022-23 4(b); 2021-22 2(b); 2020-21 5(a); 2019-20 5(a); 2018-19 1(a); 2017-18 5(a) | N13: FALSE
A14: 11 | B14: 2013-14 | C14: CSE 307 | D14: 7(a) | E14: CSE 308 teams / assignments / midterm — class diagram | F14: Scenario class diagrams — Lec 5, sl. 15–24 | G14: L11 | H14: 20 | I14: 48 | J14: ★★ Medium | K14: Design | L14: ✔ Solved | M14: 2022-23 4(b); 2021-22 2(b); 2020-21 5(a); 2019-20 5(a); 2018-19 1(a); 2017-18 5(a) | N14: FALSE
A15: 12 | B15: 2012-13 | C15: CSE 307 | D15: 7(c) | E15: Library: librarians in shifts, copies, authors, publishers — class diagram | F15: Scenario class diagrams — Lec 5, sl. 15–24 | G15: L11 | H15: 12 | I15: 55 | J15: ★★ Medium | K15: Design | L15: ✔ Solved | M15: 2022-23 4(b); 2021-22 2(b); 2020-21 5(a); 2019-20 5(a); 2018-19 1(a); 2017-18 5(a) | N15: FALSE
... A17: 14 | B17: 2011-12 | C17: CSE 307 | D17: 2(d) | E17: CRC card and its usage | F17: ERD to class, CRC — Lec 6, sl. 1–10 | G17: L12 | H17: 10 | I17: 57 | J17: ★★ Medium | K17: Theory | L17: ✔ Solved | M17: 2012-13 8(b) | N17: FALSE

Sheet 4 State Diagrams
A1: Lec 7 — State Diagrams
A2: Note file: CSE213_Anindya_State_Diagrams_Notes.docx · Solve after finishing the matching lesson. Filter Priority → ★★★ High first.
A3: Q No. | B3: Year | C3: Course | D3: Ques No. | E3: Short Question | F3: Topic (slide PDF · slides) | G3: Lesson | H3: Marks | I3: TF Page | J3: Priority | K3: Type | L3: In Notes | M3: Same Type Also In | N3: Done | O3: Confidence | P3: Date | Q3: My Notes
A4: 1 | B4: 2011-12 | C4: CSE 307 | D4: 3(a) | E4: Types of events in a statechart | F4: States, events, transitions — Lec 7, sl. 1–11 | G4: L13 | H4: 8 | I4: 58 | J4: ★ Low | K4: Theory | L4: ✔ Solved | M4: — | N4: FALSE
A5: 2 | B5: 2012-13 | C5: CSE 307 | D5: 7(a) | E5: Passing a graduate course — concurrent state diagram | F5: Nested & concurrent states — Lec 7, sl. 12–24 | G5: L14 | H5: 15 | I5: 55 | J5: ★★ Medium | K5: Design | L5: ✔ Solved | M5: 2016-17 2(d); 2011-12 3(b); 2010-11 2(b) | N5: FALSE
A6: 3 | B6: 2016-17 | C6: CSE 307 | D6: 2(d) | E6: Entity classes; statechart of the most important entity class | F6: Worked statecharts — Lec 7, sl. 25–29 | G6: L15 | H6: 13 | I6: 35–36 | J6: ★★ Medium | K6: Design | L6: ✔ Solved | M6: 2012-13 7(a); 2011-12 3(b); 2010-11 2(b) | N6: FALSE
A7: 4 | B7: 2011-12 | C7: CSE 307 | D7: 3(b) | E7: Insurance customer (defaulter, cancelled, claim) — statechart | F7: Worked statecharts — Lec 7, sl. 25–29 | G7: L15 | H7: 14.67 | I7: 58 | J7: ★★ Medium | K7: Design | L7: ✔ Solved | M7: 2016-17 2(d); 2012-13 7(a); 2010-11 2(b) | N7: FALSE
A8: 5 | B8: 2010-11 | C8: CSE 307 | D8: 2(b) | E8: Lifetime of a video tape in a video store — statechart | F8: Worked statecharts — Lec 7, sl. 25–29 | G8: L15 | H8: 12.67 | I8: 65 | J8: ★★ Medium | K8: Design | L8: ✔ Solved | M8: 2016-17 2(d); 2012-13 7(a); 2011-12 3(b) | N8: FALSE

Sheet 5 Interaction Diagrams
A1: Lec 8–10 — Sequence & Collaboration
A2: Note file: CSE213_Anindya_Interaction_Diagrams_Notes.docx · Solve after finishing the matching lesson. Filter Priority → ★★★ High first.
A3: Q No. | B3: Year | C3: Course | D3: Ques No. | E3: Short Question | F3: Topic (slide PDF · slides) | G3: Lesson | H3: Marks | I3: TF Page | J3: Priority | K3: Type | L3: In Notes | M3: Same Type Also In | N3: Done | O3: Confidence | P3: Date | Q3: My Notes
A4: 1 | B4: 2011-12 | C4: CSE 307 | D4: 2(c) | E4: Types of messages in a sequence diagram | F4: Sequence diagram notation — Lec 8, sl. 1–10 | G4: L16 | H4: 12 | I4: 57 | J4: ★★ Medium | K4: Theory | L4: ✔ Solved | M4: 2016-17 2(c); 2013-14 7(b); 2010-11 2(a) | N4: FALSE
A5: 2 | B5: 2016-17 | C5: CSE 307 | D5: 2(c) | E5: Sequence diagram for 'Withdraw money' | F5: Use case → sequence diagram — Lec 9, sl. 1–5 | G5: L17 | H5: 13 | I5: 35–36 | J5: ★★ Medium | K5: Design | L5: ✔ Solved | M5: 2013-14 7(b); 2011-12 2(c); 2010-11 2(a) | N5: FALSE
A6: 3 | B6: 2013-14 | C6: CSE 307 | D6: 7(b) | E6: MRI centre referral — sequence diagram | F6: Use case → sequence diagram — Lec 9, sl. 1–5 | G6: L17 | H6: 16.67 | I6: 48 | J6: ★★ Medium | K6: Design | L6: ✔ Solved | M6: 2016-17 2(c); 2011-12 2(c); 2010-11 2(a) | N6: FALSE
A7: 4 | B7: 2010-11 | C7: CSE 307 | D7: 2(a) | E7: chapters.com book purchase — sequence diagram | F7: Use case → sequence diagram — Lec 9, sl. 1–5 | G7: L17 | H7: 12 | I7: 65 | J7: ★★ Medium | K7: Design | L7: ✔ Solved | M7: 2016-17 2(c); 2013-14 7(b); 2011-12 2(c) | N7: FALSE
A8: 5 | B8: 2014-15 | C8: CSE 307 | D8: 7(c) | E8: Two types of interaction diagrams with example | F8: Collaboration diagrams — Lec 9 sl. 6–8, Lec 10 | G8: L18 | H8: 9.67 | I8: 43 | J8: ★★ Medium | K8: Theory | L8: ✔ Solved | M8: 2012-13 5(c); 2012-13 6(a); 2010-11 1(a) | N8: FALSE
A9: 6 | B9: 2012-13 | C9: CSE 307 | D9: 5(c) | E9: Word processor / print spooler / printer — collaboration diagram + activity diagram of print file | F9: Collaboration diagrams — Lec 9 sl. 6–8, Lec 10 | G9: L18 | H9: 9 | I9: 54 | J9: ★★ Medium | K9: Design | L9: ◐ Method | M9: 2014-15 7(c); 2012-13 6(a); 2010-11 1(a) | N9: FALSE
A10: 7 | B10: 2012-13 | C10: CSE 307 | D10: 6(a) | E10: Grocery invoice collaboration diagram → sequence diagram, stereotypes, Invoice class | F10: Collaboration diagrams — Lec 9 sl. 6–8, Lec 10 | G10: L18 | H10: 16 | I10: 54 | J10: ★★ Medium | K10: Design | L10: ✔ Solved | M10: 2014-15 7(c); 2012-13 5(c); 2010-11 1(a) | N10: FALSE
A11: 8 | B11: 2010-11 | C11: CSE 307 | D11: 1(a) | E11: Check Out Books use case → collaboration and class diagrams | F11: Collaboration diagrams — Lec 9 sl. 6–8, Lec 10 | G11: L18 | H11: 24.67 | I11: 63–64 | J11: ★★ Medium | K11: Design | L11: ✔ Solved | M11: 2014-15 7(c); 2012-13 5(c); 2012-13 6(a) | N11: FALSE

Sheet 6 Use Case + BPMN
A1: Use case.pptx + BPMN.pptx
A2: Note file: CSE213_Anindya_UseCase_BPMN_Notes.docx · Solve after finishing the matching lesson. Filter Priority → ★★★ High first.
A3: Q No. | B3: Year | C3: Course | D3: Ques No. | E3: Short Question | F3: Topic (slide PDF · slides) | G3: Lesson | H3: Marks | I3: TF Page | J3: Priority | K3: Type | L3: In Notes | M3: Same Type Also In | N3: Done | O3: Confidence | P3: Date | Q3: My Notes
A4: 1 | B4: 2016-17 | C4: CSE 307 | D4: 1(a) | E4: Extensibility mechanisms of UML | F4: UML overview, use case relationships — Use case.pptx, sl. 1–16 | G4: L19 | H4: 12 | I4: 35 | J4: ★★ Medium | K4: Theory | L4: ◐ Method | M4: 2014-15 5(c); 2013-14 5(b); 2012-13 7(d); 2010-11 1(b) | N4: FALSE
A5: 2 | B5: 2014-15 | C5: CSE 307 | D5: 5(c) | E5: UML diagram types; static vs dynamic | F5: UML overview, use case relationships — Use case.pptx, sl. 1–16 | G5: L19 | H5: 10 | I5: 43 | J5: ★★ Medium | K5: Theory | L5: ✔ Solved | M5: 2016-17 1(a); 2013-14 5(b); 2012-13 7(d); 2010-11 1(b) | N5: FALSE
A6: 3 | B6: 2013-14 | C6: CSE 307 | D6: 1(c) | E6: <<extend>> and <<include>> (uses) relationships with examples | F6: UML overview, use case relationships — Use case.pptx, sl. 1–16 | G6: L19 | H6: 7.67 | I6: 45 | J6: ★ Low | K6: Theory | L6: ✔ Solved | M6: — | N6: FALSE
A7: 4 | B7: 2013-14 | C7: CSE 307 | D7: 5(b) | E7: Four kinds of things in UML | F7: UML overview, use case relationships — Use case.pptx, sl. 1–16 | G7: L19 | H7: 12 | I7: 47 | J7: ★★ Medium | K7: Theory | L7: ✔ Solved | M7: 2016-17 1(a); 2014-15 5(c); 2012-13 7(d); 2010-11 1(b) | N7: FALSE
A8: 5 | B8: 2012-13 | C8: CSE 307 | D8: 7(d) | E8: Kinds of things in UML | F8: UML overview, use case relationships — Use case.pptx, sl. 1–16 | G8: L19 | H8: 4.67 | I8: 55 | J8: ★★ Medium | K8: Theory | L8: ✔ Solved | M8: 2016-17 1(a); 2014-15 5(c); 2013-14 5(b); 2010-11 1(b) | N8: FALSE
A9: 6 | B9: 2010-11 | C9: CSE 307 | D9: 1(b) | E9: Behavioural UML diagrams and their purpose | F9: UML overview, use case relationships — Use case.pptx, sl. 1–16 | G9: L19 | H9: 8 | I9: 64 | J9: ★★ Medium | K9: Theory | L9: ✔ Solved | M9: 2016-17 1(a); 2014-15 5(c); 2013-14 5(b); 2012-13 7(d) | N9: FALSE
A10: 7 | B10: 2023-24 | C10: CSE 213 | D10: 1(a) | E10: Mentcare: use case diagram of the processes through which a criminal can access the system | F10: Use case diagrams & narratives — Use case.pptx (TF scenarios) | G10: L20 | H10: 7 | I10: 1 | J10: ★★★ High | K10: Design | L10: ✔ Solved | M10: 2016-17 2(a); 2014-15 6(d); 2013-14 6(d); 2012-13 8(a); 2010-11 2(c) | N10: FALSE
A11: 8 | B11: 2016-17 | C11: CSE 307 | D11: 2(a) | E11: Bank (normal / foreign users) — use case diagram | F11: Use case diagrams & narratives — Use case.pptx (TF scenarios) | G11: L20 | H11: 13 | I11: 35–36 | J11: ★★ Medium | K11: Design | L11: ✔ Solved | M11: 2023-24 1(a); 2014-15 6(d); 2013-14 6(d); 2012-13 8(a); 2010-11 2(c) | N11: FALSE
A12: 9 | B12: 2016-17 | C12: CSE 307 | D12: 2(b) | E12: Use case narrative for 'Withdraw money' | F12: Use case diagrams & narratives — Use case.pptx (TF scenarios) | G12: L20 | H12: 7.67 | I12: 35–36 | J12: ★★ Medium | K12: Design | L12: ✔ Solved | M12: 2013-14 1(d); 2011-12 2(a) | N12: FALSE
A13: 10 | B13: 2014-15 | C13: CSE 307 | D13: 6(d) | E13: Book / author / publisher / bookstore / reader — use case diagram | F13: Use case diagrams & narratives — Use case.pptx (TF scenarios) | G13: L20 | H13: 9.67 | I13: 43 | J13: ★★ Medium | K13: Design | L13: ✔ Solved | M13: 2023-24 1(a); 2016-17 2(a); 2013-14 6(d); 2012-13 8(a); 2010-11 2(c) | N13: FALSE
A14: 11 | B14: 2013-14 | C14: CSE 307 | D14: 1(d) | E14: Bank teller, exam-fee deposit queue — extended use case | F14: Use case diagrams & narratives — Use case.pptx (TF scenarios) | G14: L20 | H14: 15 | I14: 45 | J14: ★★ Medium | K14: Design | L14: ◐ Method | M14: 2016-17 2(b); 2011-12 2(a) | N14: FALSE
A15: 12 | B15: 2013-14 | C15: CSE 307 | D15: 6(d) | E15: Online bus reservation — use case diagram | F15: Use case diagrams & narratives — Use case.pptx (TF scenarios) | G15: L20 | H15: 22 | I15: 47 | J15: ★★ Medium | K15: Design | L15: ✔ Solved | M15: 2023-24 1(a); 2016-17 2(a); 2014-15 6(d); 2012-13 8(a); 2010-11 2(c) | N15: FALSE
A16: 13 | B16: 2012-13 | C16: CSE 307 | D16: 8(a) | E16: Northeast Hotel reservations — use case diagram + use case dependency diagram | F16: Use case diagrams & narratives — Use case.pptx (TF scenarios) | G16: L20 | H16: 20 | I16: 55–56 | J16: ★★ Medium | K16: Design | L16: ✔ Solved | M16: 2023-24 1(a); 2016-17 2(a); 2014-15 6(d); 2013-14 6(d); 2010-11 2(c) | N16: FALSE
A17: 14 | B17: 2011-12 | C17: CSE 307 | D17: 2(a) | E17: ABC Car Rentals: use case narrative 'Rent a Car' | F17: Use case diagrams & narratives — Use case.pptx (TF scenarios) | G17: L20 | H17: 18.67 | I17: 57 | J17: ★★ Medium | K17: Design | L17: ✔ Solved | M17: 2016-17 2(b); 2013-14 1(d) | N17: FALSE
A18: 15 | B18: 2010-11 | C18: CSE 307 | D18: 2(c) | E18: Book / author / publisher / store / reader — use case diagram | F18: Use case diagrams & narratives — Use case.pptx (TF scenarios) | G18: L20 | H18: 8 | I18: 65 | J18: ★★ Medium | K18: Design | L18: ✔ Solved | M18: 2023-24 1(a); 2016-17 2(a); 2014-15 6(d); 2013-14 6(d); 2012-13 8(a) | N18: FALSE

Sheet 7 Software Testing
A1: Lec 11 + Coverage + Equivalence Partitioning
A2: Note file: CSE213_Anindya_Software_Testing_Notes.docx · Solve after finishing the matching lesson. Filter Priority → ★★★ High first.
A3: Q No. | B3: Year | C3: Course | D3: Ques No. | E3: Short Question | F3: Topic (slide PDF · slides) | G3: Lesson | H3: Marks | I3: TF Page | J3: Priority | K3: Type | L3: In Notes | M3: Same Type Also In | N3: Done | O3: Confidence | P3: Date | Q3: My Notes
A4: 1 | B4: 2021-22 | C4: CSE 307 | D4: 3(c) | E4: 'Less cost to fix a bug found later in the SDLC' — agree? | F4: Testing basics, black/white box — Lec 11, sl. 1–13 | G4: L23 | H4: 5 | I4: 15 | J4: ★★★ High | K4: Theory | L4: ✔ Solved | M4: 2017-18 8(a); 2014-15 2(a); 2013-14 3(b); 2012-13 4(d); 2010-11 6(c) | N4: FALSE
A5: 2 | B5: 2017-18 | C5: CSE 307 | D5: 8(a) | E5: Black-box advantages/disadvantages; performance and regression testing | F5: Testing basics, black/white box — Lec 11, sl. 1–13 | G5: L23 | H5: 12 | I5: 34 | J5: ★★ Medium | K5: Theory | L5: ✔ Solved | M5: 2021-22 3(c); 2014-15 2(a); 2013-14 3(b); 2012-13 4(d); 2010-11 6(c) | N5: FALSE
A6: 3 | B6: 2014-15 | C6: CSE 307 | D6: 2(a) | E6: Example showing exhaustive testing is nearly impossible | F6: Testing basics, black/white box — Lec 11, sl. 1–13 | G6: L23 | H6: 6.67 | I6: 41 | J6: ★★ Medium | K6: Theory | L6: ✔ Solved | M6: 2021-22 3(c); 2017-18 8(a); 2013-14 3(b); 2012-13 4(d); 2010-11 6(c) | N6: FALSE
A7: 4 | B7: 2013-14 | C7: CSE 307 | D7: 3(b) | E7: Debugging process with diagram | F7: Testing basics, black/white box — Lec 11, sl. 1–13 | G7: L23 | H7: 8 | I7: 46 | J7: ★★ Medium | K7: Theory | L7: ◐ Method | M7: 2021-22 3(c); 2017-18 8(a); 2014-15 2(a); 2012-13 4(d); 2010-11 6(c) | N7: FALSE
A8: 5 | B8: 2012-13 | C8: CSE 307 | D8: 4(d) | E8: Verification vs validation; defect testing vs debugging | F8: Testing basics, black/white box — Lec 11, sl. 1–13 | G8: L23 | H8: 6 | I8: 53 | J8: ★★ Medium | K8: Theory | L8: ✔ Solved | M8: 2021-22 3(c); 2017-18 8(a); 2014-15 2(a); 2013-14 3(b); 2010-11 6(c) | N8: FALSE
A9: 6 | B9: 2010-11 | C9: CSE 307 | D9: 6(c) | E9: Verification vs validation; I/O faults for a banking module | F9: Testing basics, black/white box — Lec 11, sl. 1–13 | G9: L23 | H9: 7 | I9: 69 | J9: ★★ Medium | K9: Theory | L9: ✔ Solved | M9: 2021-22 3(c); 2017-18 8(a); 2014-15 2(a); 2013-14 3(b); 2012-13 4(d) | N9: FALSE
A10: 7 | B10: 2024-25 | C10: CSE 213 | D10: 6(c) | E10: Integration testing Display–Controller(missing)–Sensor: stubs/drivers, order | F10: Testing types, integration, performance — Lec 11, sl. 14–22 | G10: L24 | H10: 10 | I10: 22 batch p.6 | J10: ★★★ High | K10: Theory | L10: ✔ Solved | M10: 2022-23 1(c); 2019-20 5(b); 2014-15 2(d); 2014-15 2(e); 2013-14 3(a); 2011-12 8(d) | N10: FALSE
A11: 8 | B11: 2024-25 | C11: CSE 213 | D11: 7(a) | E11: Performance test plan: burst 10,000 users, collapse beyond capacity, slowdown after 8 h — test types + JMeter configuration | F11: Testing types, integration, performance — Lec 11, sl. 14–22 | G11: L24 | H11: 15 | I11: 22 batch p.7 | J11: ★★★ High | K11: Theory | L11: ✔ Solved | M11: 2019-20 8(b); 2017-18 7(a) | N11: FALSE
A12: 9 | B12: 2022-23 | C12: CSE 307 | D12: 1(c) | E12: Internal and external integration testing for a ride-sharing app | F12: Testing types, integration, performance — Lec 11, sl. 14–22 | G12: L24 | H12: 10 | I12: 8 | J12: ★★★ High | K12: Theory | L12: ✔ Solved | M12: 2024-25 6(c); 2019-20 5(b); 2014-15 2(d); 2014-15 2(e); 2013-14 3(a); 2011-12 8(d) | N12: FALSE
A13: 10 | B13: 2021-22 | C13: CSE 307 | D13: 3(b) | E13: Six testing types: unit, integration, non-functional, regression, acceptance, beta | F13: Testing types, integration, performance — Lec 11, sl. 14–22 | G13: L24 | H13: 10 | I13: 15 | J13: ★★★ High | K13: Theory | L13: ✔ Solved | M13: 2020-21 8(c); 2018-19 4(a); 2011-12 7(a) | N13: FALSE
A14: 11 | B14: 2020-21 | C14: CSE 307 | D14: 8(c) | E14: Smoke vs regression testing with example | F14: Testing types, integration, performance — Lec 11, sl. 14–22 | G14: L24 | H14: 8 | I14: 21 | J14: ★★★ High | K14: Theory | L14: ✔ Solved | M14: 2021-22 3(b); 2018-19 4(a); 2011-12 7(a) | N14: FALSE
A15: 12 | B15: 2019-20 | C15: CSE 307 | D15: 5(b) | E15: ERP HRM: 4 inter-component + 2 inter-module integration-test requirements | F15: Testing types, integration, performance — Lec 11, sl. 14–22 | G15: L24 | H15: 15 | I15: 24 | J15: ★★★ High | K15: Theory | L15: ✔ Solved | M15: 2024-25 6(c); 2022-23 1(c); 2014-15 2(d); 2014-15 2(e); 2013-14 3(a); 2011-12 8(d) | N15: FALSE
A16: 13 | B16: 2019-20 | C16: CSE 307 | D16: 8(b) | E16: Load vs stress testing for BIIS; is code review black-box testing? | F16: Testing types, integration, performance — Lec 11, sl. 14–22 | G16: L24 | H16: 15 | I16: 25 | J16: ★★★ High | K16: Theory | L16: ✔ Solved | M16: 2024-25 7(a); 2017-18 7(a) | N16: FALSE
A17: 14 | B17: 2018-19 | C17: CSE 307 | D17: 4(a) | E17: Integration, beta and usability testing | F17: Testing types, integration, performance — Lec 11, sl. 14–22 | G17: L24 | H17: 9 | I17: 27 | J17: ★★ Medium | K17: Theory | L17: ✔ Solved | M17: 2021-22 3(b); 2020-21 8(c); 2011-12 7(a) | N17: FALSE
A18: 15 | B18: 2017-18 | C18: CSE 307 | D18: 7(a) | E18: Spec 100 users; failed at 90, crashed at 150 — which two test types? | F18: Testing types, integration, performance — Lec 11, sl. 14–22 | G18: L24 | H18: 6 | I18: 33 | J18: ★★ Medium | K18: Theory | L18: ✔ Solved | M18: 2024-25 7(a); 2019-20 8(b) | N18: FALSE
A19: 16 | B19: 2014-15 | C19: CSE 307 | D19: 2(d) | E19: Components of the unit-test environment | F19: Testing types, integration, performance — Lec 11, sl. 14–22 | G19: L24 | H19: 7 | I19: 41 | J19: ★★ Medium | K19: Theory | L19: ✔ Solved | M19: 2024-25 6(c); 2022-23 1(c); 2019-20 5(b); 2014-15 2(e); 2013-14 3(a); 2011-12 8(d) | N19: FALSE
A20: 17 | B20: 2014-15 | C20: CSE 307 | D20: 2(e) | E20: Integration-testing strategies | F20: Testing types, integration, performance — Lec 11, sl. 14–22 | G20: L24 | H20: 8 | I20: 41 | J20: ★★ Medium | K20: Theory | L20: ✔ Solved | M20: 2024-25 6(c); 2022-23 1(c); 2019-20 5(b); 2014-15 2(d); 2013-14 3(a); 2011-12 8(d) | N20: FALSE
A21: 18 | B21: 2013-14 | C21: CSE 307 | D21: 3(a) | E21: Call-return tree 1–14: top-down integration order with stubs and drivers | F21: Testing types, integration, performance — Lec 11, sl. 14–22 | G21: L24 | H21: 10 | I21: 46 | J21: ★★ Medium | K21: Theory | L21: ✔ Solved | M21: 2024-25 6(c); 2022-23 1(c); 2019-20 5(b); 2014-15 2(d); 2014-15 2(e); 2011-12 8(d) | N21: FALSE
A22: 19 | B22: 2011-12 | C22: CSE 307 | D22: 7(a) | E22: Stock trading: unit, integration or system test for five cases | F22: Testing types, integration, performance — Lec 11, sl. 14–22 | G22: L24 | H22: 10 | I22: 60 | J22: ★★ Medium | K22: Theory | L22: ✔ Solved | M22: 2021-22 3(b); 2020-21 8(c); 2018-19 4(a) | N22: FALSE
A23: 20 | B23: 2011-12 | C23: CSE 307 | D23: 8(d) | E23: Depth-first top-down integration of ROOT / M1–M9 | F23: Testing types, integration, performance — Lec 11, sl. 14–22 | G23: L24 | H23: 9.67 | I23: 62 | J23: ★★ Medium | K23: Theory | L23: ✔ Solved | M23: 2024-25 6(c); 2022-23 1(c); 2019-20 5(b); 2014-15 2(d); 2014-15 2(e); 2013-14 3(a) | N23: FALSE
