Workbook

Sheet How to Use
B2: CSE 209 (Rifat Sir part) — TF Practice Tracker
B3: Every RS-part question in TF209.pdf, mapped to the note file and lesson that teaches it.
B5: Workflow — after you finish a note file
B6: 1. Open its tab | C6: Tabs 1–5 follow the order of your note files. Q No. runs lesson by lesson, newest year first inside each lesson.
B7: 2. Filter | C7: Use the filter arrow on Priority → ★★★ High first (2019-20 to 2023-24 papers). Then ★★ Medium, then ★ Low.
B8: 3. Solve | C8: Open TF209.pdf at the TF Page shown. Solve on paper under exam time (≈1.5 min per mark). Do not read the note solution first.
B9: 4. Check | C9: In Notes tells you what the note has: ✔ Solved = same question worked out; ◐ Method = method / model answer you can apply; ○ Partly = notes cover most of it, finish the rest yourself.
B10: 5. Record | C10: Tick Done, pick Confidence, add the Date. Write mistakes in My Notes. Re-solve every 'Weak' row before the exam.
B11: 6. Repeats | C11: 'Same Type Also In' lists other papers with the same question type. Solve one, then try a repeat cold — that is the real test.
B13: Columns you edit (all others are fixed data)
B14: Done (col N) | C14: TRUE / FALSE. In Google Sheets: select N4 downward → Insert → Checkbox. The values stay; ticking turns the row green.
B15: Confidence (col O) | C15: Dropdown: Weak / OK / Strong. Weak rows turn the cell red.
B16: Date (col P) | C16: Date you solved it, e.g. 16-Oct-2026.
B17: My Notes (col Q) | C17: Mistakes, missing steps, formula you forgot.
B19: Legend
B20: ★★★ High | C20: Asked in 2019-20 or later (most important — current question style).
B21: ★★ Medium | C21: Older paper, but the same question type appears at least twice in TF.
B22: ★ Low | C22: Older paper, asked once.
B23: Type | C23: Numerical = calculation · Trace = tables / pipeline or cache simulation · Design = draw / modify hardware · Theory = explain.
B24: Course | C24: CSE 209 = current course code; CSE 305 = old code for the same Rifat Sir content.
B25: Topic | C25: Note lesson title — slide PDF and slide numbers (Control Unit uses PDF page numbers).
B26: Outside Notes tab | C26: RS-section questions from older papers on topics not in the current slides (multiprocessors, I/O, RAID, single-bus CPU…). Check with sir before spending time on them.
B28: Example of a filled row
B29: Columns | C29: Q No. | Year | Course | Ques No. | Short Question | Done | Confidence | Date | My Notes
B30: Values | C30: 12 | 2023-24 | CSE 209 | 1(a) | Design a complete forwarding unit… | True | OK | 16-Oct-2026 | Forgot RegWrite check in MEM hazard condition

Sheet Dashboard
A1: Progress Dashboard
A2: Updates automatically when you tick Done / set Confidence in tabs 1–5.
A4: # | B4: Note file (tab) | C4: Questions | D4: Done | E4: % Done | F4: Marks (total) | G4: Marks done | H4: High-priority left | I4: Weak | J4: Next unsolved (top of tab)
A5: 1 | B5: 1 Ch4 P1 Single-Cycle | C5: =COUNTA('1 Ch4 P1 Single-Cycle'!$E$4:$E$31) -> 28 | D5: =COUNTIF('1 Ch4 P1 Single-Cycle'!$N$4:$N$31,TRUE()) -> 0 | E5: =IF(C5=0,0,D5/C5) -> 0 | F5: =SUM('1 Ch4 P1 Single-Cycle'!$H$4:$H$31) -> 307 | G5: =SUMIF('1 Ch4 P1 Single-Cycle'!$N$4:$N$31,TRUE(),'1 Ch4 P1 Single-Cycle'!$H$4:$H$31) -> 0 | H5: =COUNTIFS('1 Ch4 P1 Single-Cycle'!$J$4:$J$31,"★★★ High",'1 Ch4 P1 Single-Cycle'!$N$4:$N$31,FALSE()) -> 15 | I5: =COUNTIF('1 Ch4 P1 Single-Cycle'!$O$4:$O$31,"Weak") -> 0 | J5: =IFERROR("Q"&INDEX('1 Ch4 P1 Single-Cycle'!$A$4:$A$31,MATCH(FALSE(),'1 Ch4 P1 Single-Cycle'!$N$4:$N$31,0))&" · "&INDEX('1 Ch4 P1 Single-Cycle'!$B$4:$B$31,MATCH(FALSE(),'1 Ch4 P1 Single-Cycle'!$N$4:$N$31,0))&" "&INDEX('1 Ch4 P1 Single-Cycle'!$D$4:$D$31,MATCH(FALSE(),'1 Ch4 P1 Single-Cycle'!$N$4:$N$31,0))&" · TF p."&INDEX('1 Ch4 P1 Single-Cycle'!$I$4:$I$31,MATCH(FALSE(),'1 Ch4 P1 Single-Cycle'!$N$4:$N$31,0)),"All done ✔") -> Q1 · 2011-12 3(b) · TF p.84
A6: 2 | B6: 2 Ch4 P2 Pipelining | C6: =COUNTA('2 Ch4 P2 Pipelining'!$E$4:$E$66) -> 63 | D6: =COUNTIF('2 Ch4 P2 Pipelining'!$N$4:$N$66,TRUE()) -> 0 | E6: =IF(C6=0,0,D6/C6) -> 0 | F6: =SUM('2 Ch4 P2 Pipelining'!$H$4:$H$66) -> 642 | G6: =SUMIF('2 Ch4 P2 Pipelining'!$N$4:$N$66,TRUE(),'2 Ch4 P2 Pipelining'!$H$4:$H$66) -> 0 | H6: =COUNTIFS('2 Ch4 P2 Pipelining'!$J$4:$J$66,"★★★ High",'2 Ch4 P2 Pipelining'!$N$4:$N$66,FALSE()) -> 27 | I6: =COUNTIF('2 Ch4 P2 Pipelining'!$O$4:$O$66,"Weak") -> 0 | J6: =IFERROR("Q"&INDEX('2 Ch4 P2 Pipelining'!$A$4:$A$66,MATCH(FALSE(),'2 Ch4 P2 Pipelining'!$N$4:$N$66,0))&" · "&INDEX('2 Ch4 P2 Pipelining'!$B$4:$B$66,MATCH(FALSE(),'2 Ch4 P2 Pipelining'!$N$4:$N$66,0))&" "&INDEX('2 Ch4 P2 Pipelining'!$D$4:$D$66,MATCH(FALSE(),'2 Ch4 P2 Pipelining'!$N$4:$N$66,0))&" · TF p."&INDEX('2 Ch4 P2 Pipelining'!$I$4:$I$66,MATCH(FALSE(),'2 Ch4 P2 Pipelining'!$N$4:$N$66,0)),"All done ✔") -> Q1 · 2022-23 6(a) · TF p.18
A7: 3 | B7: 3 Ch5 Memory | C7: =COUNTA('3 Ch5 Memory'!$E$4:$E$82) -> 79 | D7: =COUNTIF('3 Ch5 Memory'!$N$4:$N$82,TRUE()) -> 0 | E7: =IF(C7=0,0,D7/C7) -> 0 | F7: =SUM('3 Ch5 Memory'!$H$4:$H$82) -> 825 | G7: =SUMIF('3 Ch5 Memory'!$N$4:$N$82,TRUE(),'3 Ch5 Memory'!$H$4:$H$82) -> 0 | H7: =COUNTIFS('3 Ch5 Memory'!$J$4:$J$82,"★★★ High",'3 Ch5 Memory'!$N$4:$N$82,FALSE()) -> 30 | I7: =COUNTIF('3 Ch5 Memory'!$O$4:$O$82,"Weak") -> 0 | J7: =IFERROR("Q"&INDEX('3 Ch5 Memory'!$A$4:$A$82,MATCH(FALSE(),'3 Ch5 Memory'!$N$4:$N$82,0))&" · "&INDEX('3 Ch5 Memory'!$B$4:$B$82,MATCH(FALSE(),'3 Ch5 Memory'!$N$4:$N$82,0))&" "&INDEX('3 Ch5 Memory'!$D$4:$D$82,MATCH(FALSE(),'3 Ch5 Memory'!$N$4:$N$82,0))&" · TF p."&INDEX('3 Ch5 Memory'!$I$4:$I$82,MATCH(FALSE(),'3 Ch5 Memory'!$N$4:$N$82,0)),"All done ✔") -> Q1 · 2017-18 3(a) · TF p.50
A8: 4 | B8: 4 GPU + Integration | C8: =COUNTA('4 GPU + Integration'!$E$4:$E$11) -> 8 | D8: =COUNTIF('4 GPU + Integration'!$N$4:$N$11,TRUE()) -> 0 | E8: =IF(C8=0,0,D8/C8) -> 0 | F8: =SUM('4 GPU + Integration'!$H$4:$H$11) -> 100 | G8: =SUMIF('4 GPU + Integration'!$N$4:$N$11,TRUE(),'4 GPU + Integration'!$H$4:$H$11) -> 0 | H8: =COUNTIFS('4 GPU + Integration'!$J$4:$J$11,"★★★ High",'4 GPU + Integration'!$N$4:$N$11,FALSE()) -> 6 | I8: =COUNTIF('4 GPU + Integration'!$O$4:$O$11,"Weak") -> 0 | J8: =IFERROR("Q"&INDEX('4 GPU + Integration'!$A$4:$A$11,MATCH(FALSE(),'4 GPU + Integration'!$N$4:$N$11,0))&" · "&INDEX('4 GPU + Integration'!$B$4:$B$11,MATCH(FALSE(),'4 GPU + Integration'!$N$4:$N$11,0))&" "&INDEX('4 GPU + Integration'!$D$4:$D$11,MATCH(FALSE(),'4 GPU + Integration'!$N$4:$N$11,0))&" · TF p."&INDEX('4 GPU + Integration'!$I$4:$I$11,MATCH(FALSE(),'4 GPU + Integration'!$N$4:$N$11,0)),"All done ✔") -> Q1 · 2023-24 4(a) · TF p.4
A9: 5 | B9: 5 Control Unit | C9: =COUNTA('5 Control Unit'!$E$4:$E$10) -> 7 | D9: =COUNTIF('5 Control Unit'!$N$4:$N$10,TRUE()) -> 0 | E9: =IF(C9=0,0,D9/C9) -> 0 | F9: =SUM('5 Control Unit'!$H$4:$H$10) -> 56 | G9: =SUMIF('5 Control Unit'!$N$4:$N$10,TRUE(),'5 Control Unit'!$H$4:$H$10) -> 0 | H9: =COUNTIFS('5 Control Unit'!$J$4:$J$10,"★★★ High",'5 Control Unit'!$N$4:$N$10,FALSE()) -> 0 | I9: =COUNTIF('5 Control Unit'!$O$4:$O$10,"Weak") -> 0 | J9: =IFERROR("Q"&INDEX('5 Control Unit'!$A$4:$A$10,MATCH(FALSE(),'5 Control Unit'!$N$4:$N$10,0))&" · "&INDEX('5 Control Unit'!$B$4:$B$10,MATCH(FALSE(),'5 Control Unit'!$N$4:$N$10,0))&" "&INDEX('5 Control Unit'!$D$4:$D$10,MATCH(FALSE(),'5 Control Unit'!$N$4:$N$10,0))&" · TF p."&INDEX('5 Control Unit'!$I$4:$I$10,MATCH(FALSE(),'5 Control Unit'!$N$4:$N$10,0)),"All done ✔") -> Q1 · 2016-17 2(b) · TF p.55
B10: TOTAL | C10: =SUM(C5:C9) -> 185 | D10: =SUM(D5:D9) -> 0 | E10: =IF(C10=0,0,D10/C10) -> 0 | F10: =SUM(F5:F9) -> 1930 | G10: =SUM(G5:G9) -> 0 | H10: =SUM(H5:H9) -> 78 | I10: =SUM(I5:I9) -> 0
A12: Questions by year (tabs 1–5)
A13: # | B13: Year | C13: Questions | D13: Done | E13: % Done | F13: Marks (total)
A14: 1 | B14: 2023-24 | C14: =COUNTIF('1 Ch4 P1 Single-Cycle'!$B$4:$B$31,$B14)+COUNTIF('2 Ch4 P2 Pipelining'!$B$4:$B$66,$B14)+COUNTIF('3 Ch5 Memory'!$B$4:$B$82,$B14)+COUNTIF('4 GPU + Integration'!$B$4:$B$11,$B14)+COUNTIF('5 Control Unit'!$B$4:$B$10,$B14) -> 18 | D14: =COUNTIFS('1 Ch4 P1 Single-Cycle'!$B$4:$B$31,$B14,'1 Ch4 P1 Single-Cycle'!$N$4:$N$31,TRUE())+COUNTIFS('2 Ch4 P2 Pipelining'!$B$4:$B$66,$B14,'2 Ch4 P2 Pipelining'!$N$4:$N$66,TRUE())+COUNTIFS('3 Ch5 Memory'!$B$4:$B$82,$B14,'3 Ch5 Memory'!$N$4:$N$82,TRUE())+COUNTIFS('4 GPU + Integration'!$B$4:$B$11,$B14,'4 GPU + Integration'!$N$4:$N$11,TRUE())+COUNTIFS('5 Control Unit'!$B$4:$B$10,$B14,'5 Control Unit'!$N$4:$N$10,TRUE()) -> 0 | E14: =IF(C14=0,0,D14/C14) -> 0 | F14: =SUMIF('1 Ch4 P1 Single-Cycle'!$B$4:$B$31,$B14,'1 Ch4 P1 Single-Cycle'!$H$4:$H$31)+SUMIF('2 Ch4 P2 Pipelining'!$B$4:$B$66,$B14,'2 Ch4 P2 Pipelining'!$H$4:$H$66)+SUMIF('3 Ch5 Memory'!$B$4:$B$82,$B14,'3 Ch5 Memory'!$H$4:$H$82)+SUMIF('4 GPU + Integration'!$B$4:$B$11,$B14,'4 GPU + Integration'!$H$4:$H$11)+SUMIF('5 Control Unit'!$B$4:$B$10,$B14,'5 Control Unit'!$H$4:$H$10) -> 180
A15: 2 | B15: 2022-23 | C15: =COUNTIF('1 Ch4 P1 Single-Cycle'!$B$4:$B$31,$B15)+COUNTIF('2 Ch4 P2 Pipelining'!$B$4:$B$66,$B15)+COUNTIF('3 Ch5 Memory'!$B$4:$B$82,$B15)+COUNTIF('4 GPU + Integration'!$B$4:$B$11,$B15)+COUNTIF('5 Control Unit'!$B$4:$B$10,$B15) -> 26 | D15: =COUNTIFS('1 Ch4 P1 Single-Cycle'!$B$4:$B$31,$B15,'1 Ch4 P1 Single-Cycle'!$N$4:$N$31,TRUE())+COUNTIFS('2 Ch4 P2 Pipelining'!$B$4:$B$66,$B15,'2 Ch4 P2 Pipelining'!$N$4:$N$66,TRUE())+COUNTIFS('3 Ch5 Memory'!$B$4:$B$82,$B15,'3 Ch5 Memory'!$N$4:$N$82,TRUE())+COUNTIFS('4 GPU + Integration'!$B$4:$B$11,$B15,'4 GPU + Integration'!$N$4:$N$11,TRUE())+COUNTIFS('5 Control Unit'!$B$4:$B$10,$B15,'5 Control Unit'!$N$4:$N$10,TRUE()) -> 0 | E15: =IF(C15=0,0,D15/C15) -> 0 | F15: =SUMIF('1 Ch4 P1 Single-Cycle'!$B$4:$B$31,$B15,'1 Ch4 P1 Single-Cycle'!$H$4:$H$31)+SUMIF('2 Ch4 P2 Pipelining'!$B$4:$B$66,$B15,'2 Ch4 P2 Pipelining'!$H$4:$H$66)+SUMIF('3 Ch5 Memory'!$B$4:$B$82,$B15,'3 Ch5 Memory'!$H$4:$H$82)+SUMIF('4 GPU + Integration'!$B$4:$B$11,$B15,'4 GPU + Integration'!$H$4:$H$11)+SUMIF('5 Control Unit'!$B$4:$B$10,$B15,'5 Control Unit'!$H$4:$H$10) -> 319
A16: 3 | B16: 2021-22 | C16: =COUNTIF('1 Ch4 P1 Single-Cycle'!$B$4:$B$31,$B16)+COUNTIF('2 Ch4 P2 Pipelining'!$B$4:$B$66,$B16)+COUNTIF('3 Ch5 Memory'!$B$4:$B$82,$B16)+COUNTIF('4 GPU + Integration'!$B$4:$B$11,$B16)+COUNTIF('5 Control Unit'!$B$4:$B$10,$B16) -> 15 | D16: =COUNTIFS('1 Ch4 P1 Single-Cycle'!$B$4:$B$31,$B16,'1 Ch4 P1 Single-Cycle'!$N$4:$N$31,TRUE())+COUNTIFS('2 Ch4 P2 Pipelining'!$B$4:$B$66,$B16,'2 Ch4 P2 Pipelining'!$N$4:$N$66,TRUE())+COUNTIFS('3 Ch5 Memory'!$B$4:$B$82,$B16,'3 Ch5 Memory'!$N$4:$N$82,TRUE())+COUNTIFS('4 GPU + Integration'!$B$4:$B$11,$B16,'4 GPU + Integration'!$N$4:$N$11,TRUE())+COUNTIFS('5 Control Unit'!$B$4:$B$10,$B16,'5 Control Unit'!$N$4:$N$10,TRUE()) -> 0 | E16: =IF(C16=0,0,D16/C16) -> 0 | F16: =SUMIF('1 Ch4 P1 Single-Cycle'!$B$4:$B$31,$B16,'1 Ch4 P1 Single-Cycle'!$H$4:$H$31)+SUMIF('2 Ch4 P2 Pipelining'!$B$4:$B$66,$B16,'2 Ch4 P2 Pipelining'!$H$4:$H$66)+SUMIF('3 Ch5 Memory'!$B$4:$B$82,$B16,'3 Ch5 Memory'!$H$4:$H$82)+SUMIF('4 GPU + Integration'!$B$4:$B$11,$B16,'4 GPU + Integration'!$H$4:$H$11)+SUMIF('5 Control Unit'!$B$4:$B$10,$B16,'5 Control Unit'!$H$4:$H$10) -> 145
A17: 4 | B17: 2020-21 | C17: =COUNTIF('1 Ch4 P1 Single-Cycle'!$B$4:$B$31,$B17)+COUNTIF('2 Ch4 P2 Pipelining'!$B$4:$B$66,$B17)+COUNTIF('3 Ch5 Memory'!$B$4:$B$82,$B17)+COUNTIF('4 GPU + Integration'!$B$4:$B$11,$B17)+COUNTIF('5 Control Unit'!$B$4:$B$10,$B17) -> 8 | D17: =COUNTIFS('1 Ch4 P1 Single-Cycle'!$B$4:$B$31,$B17,'1 Ch4 P1 Single-Cycle'!$N$4:$N$31,TRUE())+COUNTIFS('2 Ch4 P2 Pipelining'!$B$4:$B$66,$B17,'2 Ch4 P2 Pipelining'!$N$4:$N$66,TRUE())+COUNTIFS('3 Ch5 Memory'!$B$4:$B$82,$B17,'3 Ch5 Memory'!$N$4:$N$82,TRUE())+COUNTIFS('4 GPU + Integration'!$B$4:$B$11,$B17,'4 GPU + Integration'!$N$4:$N$11,TRUE())+COUNTIFS('5 Control Unit'!$B$4:$B$10,$B17,'5 Control Unit'!$N$4:$N$10,TRUE()) -> 0 | E17: =IF(C17=0,0,D17/C17) -> 0 | F17: =SUMIF('1 Ch4 P1 Single-Cycle'!$B$4:$B$31,$B17,'1 Ch4 P1 Single-Cycle'!$H$4:$H$31)+SUMIF('2 Ch4 P2 Pipelining'!$B$4:$B$66,$B17,'2 Ch4 P2 Pipelining'!$H$4:$H$66)+SUMIF('3 Ch5 Memory'!$B$4:$B$82,$B17,'3 Ch5 Memory'!$H$4:$H$82)+SUMIF('4 GPU + Integration'!$B$4:$B$11,$B17,'4 GPU + Integration'!$H$4:$H$11)+SUMIF('5 Control Unit'!$B$4:$B$10,$B17,'5 Control Unit'!$H$4:$H$10) -> 120
A18: 5 | B18: 2019-20 | C18: =COUNTIF('1 Ch4 P1 Single-Cycle'!$B$4:$B$31,$B18)+COUNTIF('2 Ch4 P2 Pipelining'!$B$4:$B$66,$B18)+COUNTIF('3 Ch5 Memory'!$B$4:$B$82,$B18)+COUNTIF('4 GPU + Integration'!$B$4:$B$11,$B18)+COUNTIF('5 Control Unit'!$B$4:$B$10,$B18) -> 11 | D18: =COUNTIFS('1 Ch4 P1 Single-Cycle'!$B$4:$B$31,$B18,'1 Ch4 P1 Single-Cycle'!$N$4:$N$31,TRUE())+COUNTIFS('2 Ch4 P2 Pipelining'!$B$4:$B$66,$B18,'2 Ch4 P2 Pipelining'!$N$4:$N$66,TRUE())+COUNTIFS('3 Ch5 Memory'!$B$4:$B$82,$B18,'3 Ch5 Memory'!$N$4:$N$82,TRUE())+COUNTIFS('4 GPU + Integration'!$B$4:$B$11,$B18,'4 GPU + Integration'!$N$4:$N$11,TRUE())+COUNTIFS('5 Control Unit'!$B$4:$B$10,$B18,'5 Control Unit'!$N$4:$N$10,TRUE()) -> 0 | E18: =IF(C18=0,0,D18/C18) -> 0 | F18: =SUMIF('1 Ch4 P1 Single-Cycle'!$B$4:$B$31,$B18,'1 Ch4 P1 Single-Cycle'!$H$4:$H$31)+SUMIF('2 Ch4 P2 Pipelining'!$B$4:$B$66,$B18,'2 Ch4 P2 Pipelining'!$H$4:$H$66)+SUMIF('3 Ch5 Memory'!$B$4:$B$82,$B18,'3 Ch5 Memory'!$H$4:$H$82)+SUMIF('4 GPU + Integration'!$B$4:$B$11,$B18,'4 GPU + Integration'!$H$4:$H$11)+SUMIF('5 Control Unit'!$B$4:$B$10,$B18,'5 Control Unit'!$H$4:$H$10) -> 140
A19: 6 | B19: 2018-19 | C19: =COUNTIF('1 Ch4 P1 Single-Cycle'!$B$4:$B$31,$B19)+COUNTIF('2 Ch4 P2 Pipelining'!$B$4:$B$66,$B19)+COUNTIF('3 Ch5 Memory'!$B$4:$B$82,$B19)+COUNTIF('4 GPU + Integration'!$B$4:$B$11,$B19)+COUNTIF('5 Control Unit'!$B$4:$B$10,$B19) -> 10 | D19: =COUNTIFS('1 Ch4 P1 Single-Cycle'!$B$4:$B$31,$B19,'1 Ch4 P1 Single-Cycle'!$N$4:$N$31,TRUE())+COUNTIFS('2 Ch4 P2 Pipelining'!$B$4:$B$66,$B19,'2 Ch4 P2 Pipelining'!$N$4:$N$66,TRUE())+COUNTIFS('3 Ch5 Memory'!$B$4:$B$82,$B19,'3 Ch5 Memory'!$N$4:$N$82,TRUE())+COUNTIFS('4 GPU + Integration'!$B$4:$B$11,$B19,'4 GPU + Integration'!$N$4:$N$11,TRUE())+COUNTIFS('5 Control Unit'!$B$4:$B$10,$B19,'5 Control Unit'!$N$4:$N$10,TRUE()) -> 0 | E19: =IF(C19=0,0,D19/C19) -> 0 | F19: =SUMIF('1 Ch4 P1 Single-Cycle'!$B$4:$B$31,$B19,'1 Ch4 P1 Single-Cycle'!$H$4:$H$31)+SUMIF('2 Ch4 P2 Pipelining'!$B$4:$B$66,$B19,'2 Ch4 P2 Pipelining'!$H$4:$H$66)+SUMIF('3 Ch5 Memory'!$B$4:$B$82,$B19,'3 Ch5 Memory'!$H$4:$H$82)+SUMIF('4 GPU + Integration'!$B$4:$B$11,$B19,'4 GPU + Integration'!$H$4:$H$11)+SUMIF('5 Control Unit'!$B$4:$B$10,$B19,'5 Control Unit'!$H$4:$H$10) -> 140
A20: 7 | B20: 2017-18 | C20: =COUNTIF('1 Ch4 P1 Single-Cycle'!$B$4:$B$31,$B20)+COUNTIF('2 Ch4 P2 Pipelining'!$B$4:$B$66,$B20)+COUNTIF('3 Ch5 Memory'!$B$4:$B$82,$B20)+COUNTIF('4 GPU + Integration'!$B$4:$B$11,$B20)+COUNTIF('5 Control Unit'!$B$4:$B$10,$B20) -> 16 | D20: =COUNTIFS('1 Ch4 P1 Single-Cycle'!$B$4:$B$31,$B20,'1 Ch4 P1 Single-Cycle'!$N$4:$N$31,TRUE())+COUNTIFS('2 Ch4 P2 Pipelining'!$B$4:$B$66,$B20,'2 Ch4 P2 Pipelining'!$N$4:$N$66,TRUE())+COUNTIFS('3 Ch5 Memory'!$B$4:$B$82,$B20,'3 Ch5 Memory'!$N$4:$N$82,TRUE())+COUNTIFS('4 GPU + Integration'!$B$4:$B$11,$B20,'4 GPU + Integration'!$N$4:$N$11,TRUE())+COUNTIFS('5 Control Unit'!$B$4:$B$10,$B20,'5 Control Unit'!$N$4:$N$10,TRUE()) -> 0 | E20: =IF(C20=0,0,D20/C20) -> 0 | F20: =SUMIF('1 Ch4 P1 Single-Cycle'!$B$4:$B$31,$B20,'1 Ch4 P1 Single-Cycle'!$H$4:$H$31)+SUMIF('2 Ch4 P2 Pipelining'!$B$4:$B$66,$B20,'2 Ch4 P2 Pipelining'!$H$4:$H$66)+SUMIF('3 Ch5 Memory'!$B$4:$B$82,$B20,'3 Ch5 Memory'!$H$4:$H$82)+SUMIF('4 GPU + Integration'!$B$4:$B$11,$B20,'4 GPU + Integration'!$H$4:$H$11)+SUMIF('5 Control Unit'!$B$4:$B$10,$B20,'5 Control Unit'!$H$4:$H$10) -> 140
A21: 8 | B21: 2016-17 | C21: =COUNTIF('1 Ch4 P1 Single-Cycle'!$B$4:$B$31,$B21)+COUNTIF('2 Ch4 P2 Pipelining'!$B$4:$B$66,$B21)+COUNTIF('3 Ch5 Memory'!$B$4:$B$82,$B21)+COUNTIF('4 GPU + Integration'!$B$4:$B$11,$B21)+COUNTIF('5 Control Unit'!$B$4:$B$10,$B21) -> 12 | D21: =COUNTIFS('1 Ch4 P1 Single-Cycle'!$B$4:$B$31,$B21,'1 Ch4 P1 Single-Cycle'!$N$4:$N$31,TRUE())+COUNTIFS('2 Ch4 P2 Pipelining'!$B$4:$B$66,$B21,'2 Ch4 P2 Pipelining'!$N$4:$N$66,TRUE())+COUNTIFS('3 Ch5 Memory'!$B$4:$B$82,$B21,'3 Ch5 Memory'!$N$4:$N$82,TRUE())+COUNTIFS('4 GPU + Integration'!$B$4:$B$11,$B21,'4 GPU + Integration'!$N$4:$N$11,TRUE())+COUNTIFS('5 Control Unit'!$B$4:$B$10,$B21,'5 Control Unit'!$N$4:$N$10,TRUE()) -> 0 | E21: =IF(C21=0,0,D21/C21) -> 0 | F21: =SUMIF('1 Ch4 P1 Single-Cycle'!$B$4:$B$31,$B21,'1 Ch4 P1 Single-Cycle'!$H$4:$H$31)+SUMIF('2 Ch4 P2 Pipelining'!$B$4:$B$66,$B21,'2 Ch4 P2 Pipelining'!$H$4:$H$66)+SUMIF('3 Ch5 Memory'!$B$4:$B$82,$B21,'3 Ch5 Memory'!$H$4:$H$82)+SUMIF('4 GPU + Integration'!$B$4:$B$11,$B21,'4 GPU + Integration'!$H$4:$H$11)+SUMIF('5 Control Unit'!$B$4:$B$10,$B21,'5 Control Unit'!$H$4:$H$10) -> 105
A22: 9 | B22: 2015-16 | C22: =COUNTIF('1 Ch4 P1 Single-Cycle'!$B$4:$B$31,$B22)+COUNTIF('2 Ch4 P2 Pipelining'!$B$4:$B$66,$B22)+COUNTIF('3 Ch5 Memory'!$B$4:$B$82,$B22)+COUNTIF('4 GPU + Integration'!$B$4:$B$11,$B22)+COUNTIF('5 Control Unit'!$B$4:$B$10,$B22) -> 13 | D22: =COUNTIFS('1 Ch4 P1 Single-Cycle'!$B$4:$B$31,$B22,'1 Ch4 P1 Single-Cycle'!$N$4:$N$31,TRUE())+COUNTIFS('2 Ch4 P2 Pipelining'!$B$4:$B$66,$B22,'2 Ch4 P2 Pipelining'!$N$4:$N$66,TRUE())+COUNTIFS('3 Ch5 Memory'!$B$4:$B$82,$B22,'3 Ch5 Memory'!$N$4:$N$82,TRUE())+COUNTIFS('4 GPU + Integration'!$B$4:$B$11,$B22,'4 GPU + Integration'!$N$4:$N$11,TRUE())+COUNTIFS('5 Control Unit'!$B$4:$B$10,$B22,'5 Control Unit'!$N$4:$N$10,TRUE()) -> 0 | E22: =IF(C22=0,0,D22/C22) -> 0 | F22: =SUMIF('1 Ch4 P1 Single-Cycle'!$B$4:$B$31,$B22,'1 Ch4 P1 Single-Cycle'!$H$4:$H$31)+SUMIF('2 Ch4 P2 Pipelining'!$B$4:$B$66,$B22,'2 Ch4 P2 Pipelining'!$H$4:$H$66)+SUMIF('3 Ch5 Memory'!$B$4:$B$82,$B22,'3 Ch5 Memory'!$H$4:$H$82)+SUMIF('4 GPU + Integration'!$B$4:$B$11,$B22,'4 GPU + Integration'!$H$4:$H$11)+SUMIF('5 Control Unit'!$B$4:$B$10,$B22,'5 Control Unit'!$H$4:$H$10) -> 110
A23: 10 | B23: 2014-15 | C23: =COUNTIF('1 Ch4 P1 Single-Cycle'!$B$4:$B$31,$B23)+COUNTIF('2 Ch4 P2 Pipelining'!$B$4:$B$66,$B23)+COUNTIF('3 Ch5 Memory'!$B$4:$B$82,$B23)+COUNTIF('4 GPU + Integration'!$B$4:$B$11,$B23)+COUNTIF('5 Control Unit'!$B$4:$B$10,$B23) -> 9 | D23: =COUNTIFS('1 Ch4 P1 Single-Cycle'!$B$4:$B$31,$B23,'1 Ch4 P1 Single-Cycle'!$N$4:$N$31,TRUE())+COUNTIFS('2 Ch4 P2 Pipelining'!$B$4:$B$66,$B23,'2 Ch4 P2 Pipelining'!$N$4:$N$66,TRUE())+COUNTIFS('3 Ch5 Memory'!$B$4:$B$82,$B23,'3 Ch5 Memory'!$N$4:$N$82,TRUE())+COUNTIFS('4 GPU + Integration'!$B$4:$B$11,$B23,'4 GPU + Integration'!$N$4:$N$11,TRUE())+COUNTIFS('5 Control Unit'!$B$4:$B$10,$B23,'5 Control Unit'!$N$4:$N$10,TRUE()) -> 0 | E23: =IF(C23=0,0,D23/C23) -> 0 | F23: =SUMIF('1 Ch4 P1 Single-Cycle'!$B$4:$B$31,$B23,'1 Ch4 P1 Single-Cycle'!$H$4:$H$31)+SUMIF('2 Ch4 P2 Pipelining'!$B$4:$B$66,$B23,'2 Ch4 P2 Pipelining'!$H$4:$H$66)+SUMIF('3 Ch5 Memory'!$B$4:$B$82,$B23,'3 Ch5 Memory'!$H$4:$H$82)+SUMIF('4 GPU + Integration'!$B$4:$B$11,$B23,'4 GPU + Integration'!$H$4:$H$11)+SUMIF('5 Control Unit'!$B$4:$B$10,$B23,'5 Control Unit'!$H$4:$H$10) -> 103
A24: 11 | B24: 2013-14 | C24: =COUNTIF('1 Ch4 P1 Single-Cycle'!$B$4:$B$31,$B24)+COUNTIF('2 Ch4 P2 Pipelining'!$B$4:$B$66,$B24)+COUNTIF('3 Ch5 Memory'!$B$4:$B$82,$B24)+COUNTIF('4 GPU + Integration'!$B$4:$B$11,$B24)+COUNTIF('5 Control Unit'!$B$4:$B$10,$B24) -> 13 | D24: =COUNTIFS('1 Ch4 P1 Single-Cycle'!$B$4:$B$31,$B24,'1 Ch4 P1 Single-Cycle'!$N$4:$N$31,TRUE())+COUNTIFS('2 Ch4 P2 Pipelining'!$B$4:$B$66,$B24,'2 Ch4 P2 Pipelining'!$N$4:$N$66,TRUE())+COUNTIFS('3 Ch5 Memory'!$B$4:$B$82,$B24,'3 Ch5 Memory'!$N$4:$N$82,TRUE())+COUNTIFS('4 GPU + Integration'!$B$4:$B$11,$B24,'4 GPU + Integration'!$N$4:$N$11,TRUE())+COUNTIFS('5 Control Unit'!$B$4:$B$10,$B24,'5 Control Unit'!$N$4:$N$10,TRUE()) -> 0 | E24: =IF(C24=0,0,D24/C24) -> 0 | F24: =SUMIF('1 Ch4 P1 Single-Cycle'!$B$4:$B$31,$B24,'1 Ch4 P1 Single-Cycle'!$H$4:$H$31)+SUMIF('2 Ch4 P2 Pipelining'!$B$4:$B$66,$B24,'2 Ch4 P2 Pipelining'!$H$4:$H$66)+SUMIF('3 Ch5 Memory'!$B$4:$B$82,$B24,'3 Ch5 Memory'!$H$4:$H$82)+SUMIF('4 GPU + Integration'!$B$4:$B$11,$B24,'4 GPU + Integration'!$H$4:$H$11)+SUMIF('5 Control Unit'!$B$4:$B$10,$B24,'5 Control Unit'!$H$4:$H$10) -> 110
A25: 12 | B25: 2012-13 | C25: =COUNTIF('1 Ch4 P1 Single-Cycle'!$B$4:$B$31,$B25)+COUNTIF('2 Ch4 P2 Pipelining'!$B$4:$B$66,$B25)+COUNTIF('3 Ch5 Memory'!$B$4:$B$82,$B25)+COUNTIF('4 GPU + Integration'!$B$4:$B$11,$B25)+COUNTIF('5 Control Unit'!$B$4:$B$10,$B25) -> 16 | D25: =COUNTIFS('1 Ch4 P1 Single-Cycle'!$B$4:$B$31,$B25,'1 Ch4 P1 Single-Cycle'!$N$4:$N$31,TRUE())+COUNTIFS('2 Ch4 P2 Pipelining'!$B$4:$B$66,$B25,'2 Ch4 P2 Pipelining'!$N$4:$N$66,TRUE())+COUNTIFS('3 Ch5 Memory'!$B$4:$B$82,$B25,'3 Ch5 Memory'!$N$4:$N$82,TRUE())+COUNTIFS('4 GPU + Integration'!$B$4:$B$11,$B25,'4 GPU + Integration'!$N$4:$N$11,TRUE())+COUNTIFS('5 Control Unit'!$B$4:$B$10,$B25,'5 Control Unit'!$N$4:$N$10,TRUE()) -> 0 | E25: =IF(C25=0,0,D25/C25) -> 0 | F25: =SUMIF('1 Ch4 P1 Single-Cycle'!$B$4:$B$31,$B25,'1 Ch4 P1 Single-Cycle'!$H$4:$H$31)+SUMIF('2 Ch4 P2 Pipelining'!$B$4:$B$66,$B25,'2 Ch4 P2 Pipelining'!$H$4:$H$66)+SUMIF('3 Ch5 Memory'!$B$4:$B$82,$B25,'3 Ch5 Memory'!$H$4:$H$82)+SUMIF('4 GPU + Integration'!$B$4:$B$11,$B25,'4 GPU + Integration'!$H$4:$H$11)+SUMIF('5 Control Unit'!$B$4:$B$10,$B25,'5 Control Unit'!$H$4:$H$10) -> 173
A26: 13 | B26: 2011-12 | C26: =COUNTIF('1 Ch4 P1 Single-Cycle'!$B$4:$B$31,$B26)+COUNTIF('2 Ch4 P2 Pipelining'!$B$4:$B$66,$B26)+COUNTIF('3 Ch5 Memory'!$B$4:$B$82,$B26)+COUNTIF('4 GPU + Integration'!$B$4:$B$11,$B26)+COUNTIF('5 Control Unit'!$B$4:$B$10,$B26) -> 18 | D26: =COUNTIFS('1 Ch4 P1 Single-Cycle'!$B$4:$B$31,$B26,'1 Ch4 P1 Single-Cycle'!$N$4:$N$31,TRUE())+COUNTIFS('2 Ch4 P2 Pipelining'!$B$4:$B$66,$B26,'2 Ch4 P2 Pipelining'!$N$4:$N$66,TRUE())+COUNTIFS('3 Ch5 Memory'!$B$4:$B$82,$B26,'3 Ch5 Memory'!$N$4:$N$82,TRUE())+COUNTIFS('4 GPU + Integration'!$B$4:$B$11,$B26,'4 GPU + Integration'!$N$4:$N$11,TRUE())+COUNTIFS('5 Control Unit'!$B$4:$B$10,$B26,'5 Control Unit'!$N$4:$N$10,TRUE()) -> 0 | E26: =IF(C26=0,0,D26/C26) -> 0 | F26: =SUMIF('1 Ch4 P1 Single-Cycle'!$B$4:$B$31,$B26,'1 Ch4 P1 Single-Cycle'!$H$4:$H$31)+SUMIF('2 Ch4 P2 Pipelining'!$B$4:$B$66,$B26,'2 Ch4 P2 Pipelining'!$H$4:$H$66)+SUMIF('3 Ch5 Memory'!$B$4:$B$82,$B26,'3 Ch5 Memory'!$H$4:$H$82)+SUMIF('4 GPU + Integration'!$B$4:$B$11,$B26,'4 GPU + Integration'!$H$4:$H$11)+SUMIF('5 Control Unit'!$B$4:$B$10,$B26,'5 Control Unit'!$H$4:$H$10) -> 145
B27: Shaded years = ★★★ High priority (2019-20 onward).
B28: Note: a question that spans two lessons is listed under the lesson that teaches its main part. 2016-17 2(b) (ALU control) is in both tab 1 and tab 5.

Sheet 1 Ch4 P1 Single-Cycle
A1: Chapter 4 Part 1 — Single-Cycle Datapath & Control
A2: Note file: CSE209_Ch4_SingleCycle_Notes.docx · Solve after finishing the matching lesson. Filter Priority → ★★★ High first.
A3: Q No. | B3: Year | C3: Course | D3: Ques No. | E3: Short Question | F3: Topic (slide PDF · slides) | G3: Lesson | H3: Marks | I3: TF Page | J3: Priority | K3: Type | L3: In Notes | M3: Same Type Also In | N3: Done | O3: Confidence | P3: Date | Q3: My Notes
A4: 1 | B4: 2011-12 | C4: CSE 305 | D4: 3(b) | E4: Purpose of the ALU for R-type, load/store and branch instructions | F4: Instruction execution & ALU roles — Ch 4 Part 1, sl. 3–4, 13–17 | G4: L1 | H4: 6 | I4: 84 | J4: ★ Low | K4: Theory | L4: ◐ Method | M4: — | N4: =FALSE() -> FALSE
A5: 2 | B5: 2023-24 | C5: CSE 209 | D5: 8(a)(i) | E5: Why is PC incremented by 4? | F5: Fetch, PC + 4, clocking — Ch 4 Part 1, sl. 9–13, 33 | G5: L2 | H5: 5 | I5: 7 | J5: ★★★ High | K5: Theory | L5: ◐ Method | M5: 2023-24 8(a)(iii); 2023-24 8(a)(ii); 2023-24 8(a)(iv) | N5: =FALSE() -> FALSE
A6: 3 | B6: 2019-20 | C6: CSE 305 | D6: 8(a) | E6: Values (0/1) of RegDst, Branch, MemRead, MemtoReg, MemWrite, ALUSrc, RegWrite for add, sw, beq (Fig. 8a) | F6: Register connections & basic control signals — Ch 4 Part 1, sl. 14–17, 21, 25–27 | G6: L3 | H6: 15 | I6: 40–41 | J6: ★★★ High | K6: Trace | L6: ◐ Method | M6: 2016-17 2(a); 2014-15 8(c) | N6: =FALSE() -> FALSE
A7: 4 | B7: 2016-17 | C7: CSE 305 | D7: 2(a) | E7: Functions of the control signals ALUSrc, ALUOp, RegDst, MemWrite, RegWrite | F7: Register connections & basic control signals — Ch 4 Part 1, sl. 14–17, 21, 25–27 | G7: L3 | H7: 5 | I7: 55 | J7: ★★ Medium | K7: Theory | L7: ◐ Method | M7: 2019-20 8(a); 2014-15 8(c) | N7: =FALSE() -> FALSE
A8: 5 | B8: 2016-17 | C8: CSE 305 | D8: 2(e) | E8: What are the two inputs of the MUX at the ALU input? | F8: Register connections & basic control signals — Ch 4 Part 1, sl. 14–17, 21, 25–27 | G8: L3 | H8: 5 | I8: 55 | J8: ★ Low | K8: Theory | L8: ◐ Method | M8: — | N8: =FALSE() -> FALSE
A9: 6 | B9: 2020-21 | C9: CSE 305 | D9: 3 | E9: Highlight the active datapath elements and set control bits for ori $t1, 100($t2) on the full datapath (Fig. 1) | F9: ALUOp, ALU control & instruction traces — Ch 4 Part 1, sl. 23–24, 28–29 | G9: L4 | H9: 15 | I9: 28 | J9: ★★★ High | K9: Trace | L9: ○ Partly | M9: 2016-17 2(c) | N9: =FALSE() -> FALSE
A10: 7 | B10: 2016-17 | C10: CSE 305 | D10: 2(b) | E10: How are the ALU control bits set from ALUOp and the R-type funct code? | F10: ALUOp, ALU control & instruction traces — Ch 4 Part 1, sl. 23–24, 28–29 | G10: L4 | H10: 10 | I10: 55 | J10: ★★ Medium | K10: Theory | L10: ◐ Method | M10: 2016-17 2(b) | N10: =FALSE() -> FALSE
A11: 8 | B11: 2016-17 | C11: CSE 305 | D11: 2(c) | E11: Describe the datapath for R-type instructions | F11: ALUOp, ALU control & instruction traces — Ch 4 Part 1, sl. 23–24, 28–29 | G11: L4 | H11: 10 | I11: 55 | J11: ★★ Medium | K11: Theory | L11: ◐ Method | M11: 2020-21 3 | N11: =FALSE() -> FALSE
A12: 9 | B12: 2022-23 | C12: CSE 305 | D12: 4(a) | E12: Branch format with 19-bit address field: formula for branch target; draw single-cycle datapath for beq (relevant parts only) | F12: beq: target, Zero, PCSrc — Ch 4 Part 1, sl. 18–19, 22, 30 | G12: L5 | H12: 16 | I12: 17 | J12: ★★★ High | K12: Design | L12: ◐ Method | M12: 2016-17 2(d) | N12: =FALSE() -> FALSE
A13: 10 | B13: 2016-17 | C13: CSE 305 | D13: 2(d) | E13: How is the PC updated for the beq instruction? | F13: beq: target, Zero, PCSrc — Ch 4 Part 1, sl. 18–19, 22, 30 | G13: L5 | H13: 5 | I13: 55 | J13: ★★ Medium | K13: Theory | L13: ◐ Method | M13: 2022-23 4(a) | N13: =FALSE() -> FALSE
A14: 11 | B14: 2014-15 | C14: CSE 305 | D14: 8(c) | E14: Design the control bits for 'beq rs, rt, address' on the given datapath/control table | F14: beq: target, Zero, PCSrc — Ch 4 Part 1, sl. 18–19, 22, 30 | G14: L5 | H14: 10 | I14: 73 | J14: ★★ Medium | K14: Trace | L14: ◐ Method | M14: 2019-20 8(a); 2016-17 2(a) | N14: =FALSE() -> FALSE
A15: 12 | B15: 2023-24 | C15: CSE 209 | D15: 8(a)(iii) | E15: Why are the upper 4 bits of PC + 4 concatenated in the jump address? | F15: Jump address & jump hardware — Ch 4 Part 1, sl. 31–32 | G15: L6 | H15: 5 | I15: 7 | J15: ★★★ High | K15: Theory | L15: ◐ Method | M15: 2023-24 8(a)(i); 2023-24 8(a)(ii); 2023-24 8(a)(iv) | N15: =FALSE() -> FALSE
A16: 13 | B16: 2023-24 | C16: CSE 209 | D16: 8(b) | E16: Components needed to add the jump instruction to the Fig. 8(a) datapath; draw only those parts | F16: Jump address & jump hardware — Ch 4 Part 1, sl. 31–32 | G16: L6 | H16: 10 | I16: 7 | J16: ★★★ High | K16: Design | L16: ◐ Method | M16: 2021-22 1(a) (CSE 305) | N16: =FALSE() -> FALSE
A17: 14 | B17: 2022-23 | C17: CSE 209 | D17: 12(c)(ii) | E17: PC = 0x00000000: can a single j reach the 32-bit constant 0x20014924? | F17: Jump address & jump hardware — Ch 4 Part 1, sl. 31–32 | G17: L6 | H17: 3 | I17: 14 | J17: ★★★ High | K17: Numerical | L17: ◐ Method | M17: 2021-22 6(b)(i) (CSE 305) | N17: =FALSE() -> FALSE
A18: 15 | B18: 2021-22 | C18: CSE 305 | D18: 1(a) | E18: Complete the incomplete single-cycle datapath for beq and j | F18: Jump address & jump hardware — Ch 4 Part 1, sl. 31–32 | G18: L6 | H18: 10 | I18: 21, 26 | J18: ★★★ High | K18: Design | L18: ◐ Method | M18: 2023-24 8(b) (CSE 209) | N18: =FALSE() -> FALSE
A19: 16 | B19: 2021-22 | C19: CSE 305 | D19: 6(b)(i) | E19: PC = 0x2000 0000: can j set PC to 0x4000 0000? Explain | F19: Jump address & jump hardware — Ch 4 Part 1, sl. 31–32 | G19: L6 | H19: 5 | I19: 24 | J19: ★★★ High | K19: Numerical | L19: ◐ Method | M19: 2022-23 12(c)(ii) (CSE 209) | N19: =FALSE() -> FALSE
A20: 17 | B20: 2023-24 | C20: CSE 209 | D20: 8(a)(ii) | E20: How is the clock-cycle length determined in single-cycle execution? | F20: Full datapath, timing & theory answers — Ch 4 Part 1, sl. 20–22, 26, 32–33 | G20: L7 | H20: 5 | I20: 7 | J20: ★★★ High | K20: Theory | L20: ◐ Method | M20: 2023-24 8(a)(i); 2023-24 8(a)(iii); 2023-24 8(a)(iv) | N20: =FALSE() -> FALSE
A21: 18 | B21: 2023-24 | C21: CSE 209 | D21: 8(a)(iv) | E21: 'One physical memory can implement both instruction and data memory in single-cycle' — agree/disagree? | F21: Full datapath, timing & theory answers — Ch 4 Part 1, sl. 20–22, 26, 32–33 | G21: L7 | H21: 5 | I21: 7 | J21: ★★★ High | K21: Theory | L21: ◐ Method | M21: 2023-24 8(a)(i); 2023-24 8(a)(iii); 2023-24 8(a)(ii) | N21: =FALSE() -> FALSE
A22: 19 | B22: 2018-19 | C22: CSE 305 | D22: 1(b) | E22: Why are single-cycle implementations not very efficient? | F22: Full datapath, timing & theory answers — Ch 4 Part 1, sl. 20–22, 26, 32–33 | G22: L7 | H22: 5 | I22: 42 | J22: ★ Low | K22: Theory | L22: ◐ Method | M22: — | N22: =FALSE() -> FALSE
A23: 20 | B23: 2017-18 | C23: CSE 305 | D23: 1(b) | E23: Draw the complete single-cycle datapath and control for add, lw, beq | F23: Full datapath, timing & theory answers — Ch 4 Part 1, sl. 20–22, 26, 32–33 | G23: L7 | H23: 15 | I23: 49 | J23: ★★ Medium | K23: Design | L23: ◐ Method | M23: 2013-14 7(c); 2011-12 3(a) | N23: =FALSE() -> FALSE
A24: 21 | B24: 2013-14 | C24: CSE 305 | D24: 7(c) | E24: Draw the complete single-cycle datapath and control for add, sw, beq | F24: Full datapath, timing & theory answers — Ch 4 Part 1, sl. 20–22, 26, 32–33 | G24: L7 | H24: 14 | I24: 76 | J24: ★★ Medium | K24: Design | L24: ◐ Method | M24: 2017-18 1(b); 2011-12 3(a) | N24: =FALSE() -> FALSE
A25: 22 | B25: 2011-12 | C25: CSE 305 | D25: 3(a) | E25: Single-cycle datapath + control for ADD, SW, JUMP with no redundant hardware | F25: Full datapath, timing & theory answers — Ch 4 Part 1, sl. 20–22, 26, 32–33 | G25: L7 | H25: 15 | I25: 84 | J25: ★★ Medium | K25: Design | L25: ◐ Method | M25: 2017-18 1(b); 2013-14 7(c) | N25: =FALSE() -> FALSE
A26: 23 | B26: 2022-23 | C26: CSE 209 | D26: 3 | E26: Add connections to support beq, bneq, j, jr with the minimum number of 2×1 MUXes | F26: Adding bne, jr, jal — Ch 4 Part 1, sl. 32 (modifications) | G26: L8A | H26: 15 | I26: 9 | J26: ★★★ High | K26: Design | L26: ◐ Method | M26: 2018-19 1(a) (CSE 305); 2012-13 2 (CSE 305) | N26: =FALSE() -> FALSE
A27: 24 | B27: 2022-23 | C27: CSE 209 | D27: 11(b) | E27: How does jal differ from an unconditional jump? (NOT part is ISA) | F27: Adding bne, jr, jal — Ch 4 Part 1, sl. 32 (modifications) | G27: L8A | H27: 8 | I27: 13 | J27: ★★★ High | K27: Theory | L27: ○ Partly | M27: — | N27: =FALSE() -> FALSE
A28: 25 | B28: 2018-19 | C28: CSE 305 | D28: 1(a) | E28: Update the single-cycle datapath (Fig. 1.A) for bne, j, jr, jal, slt, lui; explain updates | F28: Adding bne, jr, jal — Ch 4 Part 1, sl. 32 (modifications) | G28: L8A | H28: 30 | I28: 42, 47 | J28: ★★ Medium | K28: Design | L28: ◐ Method | M28: 2022-23 3 (CSE 209); 2012-13 2 | N28: =FALSE() -> FALSE
A29: 26 | B29: 2012-13 | C29: CSE 305 | D29: 2 | E29: Implement bne, j, jr, jal in the Fig. 2 datapath; give values of all (new) control lines | F29: Adding bne, jr, jal — Ch 4 Part 1, sl. 32 (modifications) | G29: L8A | H29: 35 | I29: 78, 82 | J29: ★★ Medium | K29: Design | L29: ◐ Method | M29: 2022-23 3 (CSE 209); 2018-19 1(a) | N29: =FALSE() -> FALSE
A30: 27 | B30: 2023-24 | C30: CSE 209 | D30: 5(a)(i) | E30: MIPS-v22 (changed R/I field order): connect instruction memory to Read reg 1, Read reg 2, Write reg with MUXes; show bit widths | F30: slt, lui & modified formats — Ch 4 Part 1, sl. 32 (modifications) | G30: L8B | H30: 10 | I30: 4–5 | J30: ★★★ High | K30: Design | L30: ◐ Method | M30: — | N30: =FALSE() -> FALSE
A31: 28 | B31: 2022-23 | C31: CSE 209 | D31: 6 | E31: Design an M-type (memory-operand) add/sub instruction: format + hardware changes | F31: slt, lui & modified formats — Ch 4 Part 1, sl. 32 (modifications) | G31: L8B | H31: 15 | I31: 10 | J31: ★★★ High | K31: Design | L31: ○ Partly | M31: — | N31: =FALSE() -> FALSE

Sheet 2 Ch4 P2 Pipelining
A1: Chapter 4 Part 2 — Pipelining
A2: Note file: CSE209_Ch4_Part2_Pipelining_Notes.docx · Solve after finishing the matching lesson. Filter Priority → ★★★ High first.
A3: Q No. | B3: Year | C3: Course | D3: Ques No. | E3: Short Question | F3: Topic (slide PDF · slides) | G3: Lesson | H3: Marks | I3: TF Page | J3: Priority | K3: Type | L3: In Notes | M3: Same Type Also In | N3: Done | O3: Confidence | P3: Date | Q3: My Notes
A4: 1 | B4: 2022-23 | C4: CSE 305 | D4: 6(a) | E4: Joey: 'number of cycles = number of instructions' — agree? | F4: Pipelining basics, speedup — Ch 4 Part 2, sl. 2–9 | G4: L9 | H4: 5 | I4: 18 | J4: ★★★ High | K4: Theory | L4: ✔ Solved | M4: — | N4: =FALSE() -> FALSE
A5: 2 | B5: 2017-18 | C5: CSE 305 | D5: 1(c) | E5: Speedup pipelined vs single-cycle for 3 lw (200/100/100/200/100 ps); then +3,000,000 lw | F5: Pipelining basics, speedup — Ch 4 Part 2, sl. 2–9 | G5: L9 | H5: 5 | I5: 49 | J5: ★★ Medium | K5: Numerical | L5: ✔ Solved | M5: 2015-16 2(b); 2013-14 7(d) | N5: =FALSE() -> FALSE
A6: 3 | B6: 2015-16 | C6: CSE 305 | D6: 2(b) | E6: Speedup pipelined vs single-cycle for 3 lw (200/100/200/200/100 ps); then +2,000,000 lw | F6: Pipelining basics, speedup — Ch 4 Part 2, sl. 2–9 | G6: L9 | H6: 5 | I6: 64 | J6: ★★ Medium | K6: Numerical | L6: ◐ Method | M6: 2017-18 1(c); 2013-14 7(d) | N6: =FALSE() -> FALSE
A7: 4 | B7: 2013-14 | C7: CSE 305 | D7: 7(d) | E7: States of the MIPS pipeline; speedup for 3 lw; then +1,000,000 lw | F7: Pipelining basics, speedup — Ch 4 Part 2, sl. 2–9 | G7: L9 | H7: 9 | I7: 76 | J7: ★★ Medium | K7: Numerical | L7: ◐ Method | M7: 2017-18 1(c); 2015-16 2(b) | N7: =FALSE() -> FALSE
A8: 5 | B8: 2016-17 | C8: CSE 305 | D8: 4(b) | E8: Convert the single-cycle datapath (Fig. 2) to pipelined: pipeline registers, forwarding unit, hazard detection unit | F8: Pipeline registers, datapath & control — Ch 4 Part 2, sl. 33–52 | G8: L10 | H8: 15 | I8: 56 | J8: ★★ Medium | K8: Design | L8: ◐ Method | M8: 2014-15 3(c) | N8: =FALSE() -> FALSE
A9: 6 | B9: 2015-16 | C9: CSE 305 | D9: 2(c) | E9: Draw the complete pipelined datapath and control for lw with pipeline registers | F9: Pipeline registers, datapath & control — Ch 4 Part 2, sl. 33–52 | G9: L10 | H9: 10 | I9: 64 | J9: ★★ Medium | K9: Design | L9: ◐ Method | M9: 2013-14 8(a) | N9: =FALSE() -> FALSE
A10: 7 | B10: 2014-15 | C10: CSE 305 | D10: 3(c) | E10: Convert the single-cycle datapath to pipelined: pipeline registers + forwarding unit | F10: Pipeline registers, datapath & control — Ch 4 Part 2, sl. 33–52 | G10: L10 | H10: 15 | I10: 69 | J10: ★★ Medium | K10: Design | L10: ◐ Method | M10: 2016-17 4(b) | N10: =FALSE() -> FALSE
A11: 8 | B11: 2013-14 | C11: CSE 305 | D11: 8(a) | E11: Draw the complete pipelined datapath and control for lw with pipeline registers | F11: Pipeline registers, datapath & control — Ch 4 Part 2, sl. 33–52 | G11: L10 | H11: 15 | I11: 76 | J11: ★★ Medium | K11: Design | L11: ◐ Method | M11: 2015-16 2(c) | N11: =FALSE() -> FALSE
A12: 9 | B12: 2011-12 | C12: CSE 305 | D12: 3(d) | E12: What do LW $6,36($1) and ADD $5,$5,$5 do in the EX and MEM stages? | F12: Pipeline registers, datapath & control — Ch 4 Part 2, sl. 33–52 | G12: L10 | H12: 8 | I12: 85 | J12: ★★ Medium | K12: Theory | L12: ◐ Method | M12: 2011-12 4(a) | N12: =FALSE() -> FALSE
A13: 10 | B13: 2011-12 | C13: CSE 305 | D13: 4(a) | E13: What values are stored in the IF/ID and ID/EX pipeline registers? | F13: Pipeline registers, datapath & control — Ch 4 Part 2, sl. 33–52 | G13: L10 | H13: 6 | I13: 85 | J13: ★★ Medium | K13: Theory | L13: ✔ Solved | M13: 2011-12 3(d) | N13: =FALSE() -> FALSE
A14: 11 | B14: 2022-23 | C14: CSE 305 | D14: 1(a) | E14: No forwarding: pipeline for sub/and/or with stalls; total clock cycles | F14: Hazards & stalls without forwarding — Ch 4 Part 2, sl. 10–15, 25 | G14: L11 | H14: 12 | I14: 16 | J14: ★★★ High | K14: Trace | L14: ✔ Solved | M14: 2011-12 4(d) | N14: =FALSE() -> FALSE
A15: 12 | B15: 2016-17 | C15: CSE 305 | D15: 4(a) | E15: Pipeline hazards; structural hazard time-space diagram; hazard type in lw/lw/add/sw/lw/add/sw and fix | F15: Hazards & stalls without forwarding — Ch 4 Part 2, sl. 10–15, 25 | G15: L11 | H15: 10 | I15: 55 | J15: ★★ Medium | K15: Theory | L15: ✔ Solved | M15: 2022-23 1(c) (CSE 209); 2021-22 1(b); 2019-20 5(a); 2019-20 5(b); 2019-20 5(c); 2017-18 1(a); 2015-16 2(d); 2014-15 3(a) | N15: =FALSE() -> FALSE
... A24: 21 | B24: 2021-22 | C24: CSE 305 | D24: 2(a) | E24: What is forwarding? Complete forwarding unit with equations (double data hazard) | F24: Forwarding & double data hazard — Ch 4 Part 2, sl. 16, 53–65 | G24: L12 | H24: 15 | I24: 22 | J24: ★★★ High | K24: Design | L24: ◐ Method | M24: 2023-24 1(a) (CSE 209); 2017-18 2(b); 2012-13 4(a) | N24: =FALSE() -> FALSE
A25: 22 | B25: 2020-21 | C25: CSE 305 | D25: 4 | E25: Identify data hazards (multi-cycle diagram), mark forwarding, write conditions; can forwarding solve all? | F25: Forwarding & double data hazard — Ch 4 Part 2, sl. 16, 53–65 | G25: L12 | H25: 15 | I25: 28–29 | J25: ★★★ High | K25: Trace | L25: ✔ Solved | M25: 2022-23 1(b); 2022-23 1(c); 2019-20 8(c) | N25: =FALSE() -> FALSE
A26: 23 | B26: 2019-20 | C26: CSE 305 | D26: 8(c) | E26: Forwarding conditions for sub→and (green) and sub→or (yellow) paths | F26: Forwarding & double data hazard — Ch 4 Part 2, sl. 16, 53–65 | G26: L12 | H26: 12 | I26: 41 | J26: ★★★ High | K26: Theory | L26: ✔ Solved | M26: 2022-23 1(b); 2022-23 1(c); 2020-21 4 | N26: =FALSE() -> FALSE
A27: 24 | B27: 2017-18 | C27: CSE 305 | D27: 2(b) | E27: Complete forwarding unit with equations (double data hazard) on the given figure | F27: Forwarding & double data hazard — Ch 4 Part 2, sl. 16, 53–65 | G27: L12 | H27: 15 | I27: 49–50 | J27: ★★ Medium | K27: Design | L27: ◐ Method | M27: 2023-24 1(a) (CSE 209); 2021-22 2(a); 2012-13 4(a) | N27: =FALSE() -> FALSE
A28: 25 | B28: 2015-16 | C28: CSE 305 | D28: 3(a) | E28: Double data hazard; forwarding equations with double hazard; how MIPS detects load-use hazard | F28: Forwarding & double data hazard — Ch 4 Part 2, sl. 16, 53–65 | G28: L12 | H28: 10 | I28: 64 | J28: ★★ Medium | K28: Theory | L28: ◐ Method | M28: 2017-18 2(a); 2011-12 4(c) | N28: =FALSE() -> FALSE
A29: 26 | B29: 2012-13 | C29: CSE 305 | D29: 4(a) | E29: Detect data hazards and solve them with a forwarding unit | F29: Forwarding & double data hazard — Ch 4 Part 2, sl. 16, 53–65 | G29: L12 | H29: 17 | I29: 79 | J29: ★★ Medium | K29: Theory | L29: ◐ Method | M29: 2023-24 1(a) (CSE 209); 2021-22 2(a); 2017-18 2(b) | N29: =FALSE() -> FALSE
A30: 27 | B30: 2011-12 | C30: CSE 305 | D30: 4(c) | E30: Give an example of a double data hazard | F30: Forwarding & double data hazard — Ch 4 Part 2, sl. 16, 53–65 | G30: L12 | H30: 3 | I30: 85 | J30: ★★ Medium | K30: Theory | L30: ✔ Solved | M30: 2017-18 2(a); 2015-16 3(a) | N30: =FALSE() -> FALSE
A31: 28 | B31: 2022-23 | C31: CSE 209 | D31: 2 | E31: Hazards in lw/addi/lw/sw; detection conditions; complete the hazard detection unit (all signals) | F31: Load-use hazard & hazard detection — Ch 4 Part 2, sl. 17–21, 66–76 | G31: L13 | H31: 15 | I31: 8–9 | J31: ★★★ High | K31: Design | L31: ✔ Solved | M31: — | N31: =FALSE() -> FALSE
A32: 29 | B32: 2017-18 | C32: CSE 305 | D32: 2(a) | E32: Double data hazard example; how MIPS detects load-use hazard and stalls the pipeline | F32: Load-use hazard & hazard detection — Ch 4 Part 2, sl. 17–21, 66–76 | G32: L13 | H32: 10 | I32: 49 | J32: ★★ Medium | K32: Theory | L32: ✔ Solved | M32: 2015-16 3(a); 2011-12 4(c) | N32: =FALSE() -> FALSE
A33: 30 | B33: 2012-13 | C33: CSE 305 | D33: 4(b) | E33: A data hazard forwarding cannot solve; what to do | F33: Load-use hazard & hazard detection — Ch 4 Part 2, sl. 17–21, 66–76 | G33: L13 | H33: 13 | I33: 79 | J33: ★ Low | K33: Theory | L33: ✔ Solved | M33: — | N33: =FALSE() -> FALSE
A34: 31 | B34: 2022-23 | C34: CSE 209 | D34: 1(c) | E34: A=B+C; D=A+E (offsets 0,4,8,12,16): MIPS code, cycles, reschedule and recount | F34: Timing diagrams & code scheduling — Ch 4 Part 2, sl. 22–24 | G34: L14 | H34: 10 | I34: 8 | J34: ★★★ High | K34: Trace | L34: ✔ Solved | M34: 2021-22 1(b) (CSE 305); 2019-20 5(a) (CSE 305); 2019-20 5(b) (CSE 305); 2019-20 5(c) (CSE 305); 2017-18 1(a) (CSE 305); 2016-17 4(a) (CSE 305); 2015-16 2(d) (CSE 305); 2014-15 3(a) (CSE 305) | N34: =FALSE() -> FALSE
A35: 32 | B35: 2021-22 | C35: CSE 305 | D35: 1(b) | E35: Cycles for lw/lw/add/sw/lw/add/sw (slide-22 code); reduce with code scheduling | F35: Timing diagrams & code scheduling — Ch 4 Part 2, sl. 22–24 | G35: L14 | H35: 10 | I35: 21 | J35: ★★★ High | K35: Trace | L35: ✔ Solved | M35: 2022-23 1(c) (CSE 209); 2019-20 5(a); 2019-20 5(b); 2019-20 5(c); 2017-18 1(a); 2016-17 4(a); 2015-16 2(d); 2014-15 3(a) | N35: =FALSE() -> FALSE
A36: 33 | B36: 2019-20 | C36: CSE 305 | D36: 5(a) | E36: A=B+C; D=A+D: draw pipeline with stalls and forwarding paths | F36: Timing diagrams & code scheduling — Ch 4 Part 2, sl. 22–24 | G36: L14 | H36: 15 | I36: 39 | J36: ★★★ High | K36: Trace | L36: ✔ Solved | M36: 2022-23 1(c) (CSE 209); 2021-22 1(b); 2019-20 5(b); 2019-20 5(c); 2017-18 1(a); 2016-17 4(a); 2015-16 2(d); 2014-15 3(a) | N36: =FALSE() -> FALSE
A37: 34 | B37: 2019-20 | C37: CSE 305 | D37: 5(b) | E37: Number of stalls and clock cycles for 5(a) | F37: Timing diagrams & code scheduling — Ch 4 Part 2, sl. 22–24 | G37: L14 | H37: 5 | I37: 39 | J37: ★★★ High | K37: Numerical | L37: ✔ Solved | M37: 2022-23 1(c) (CSE 209); 2021-22 1(b); 2019-20 5(a); 2019-20 5(c); 2017-18 1(a); 2016-17 4(a); 2015-16 2(d); 2014-15 3(a) | N37: =FALSE() -> FALSE
A38: 35 | B38: 2019-20 | C38: CSE 305 | D38: 5(c) | E38: Can the 5(a) code be rearranged to reduce stalls? New code, stalls, cycles | F38: Timing diagrams & code scheduling — Ch 4 Part 2, sl. 22–24 | G38: L14 | H38: 15 | I38: 39 | J38: ★★★ High | K38: Trace | L38: ✔ Solved | M38: 2022-23 1(c) (CSE 209); 2021-22 1(b); 2019-20 5(a); 2019-20 5(b); 2017-18 1(a); 2016-17 4(a); 2015-16 2(d); 2014-15 3(a) | N38: =FALSE() -> FALSE
A39: 36 | B39: 2017-18 | C39: CSE 305 | D39: 1(a) | E39: A=B+C; D=A+E (offsets A0 B4 C8 D12 E16): cycles; code scheduling; new cycles | F39: Timing diagrams & code scheduling — Ch 4 Part 2, sl. 22–24 | G39: L14 | H39: 10 | I39: 49 | J39: ★★ Medium | K39: Trace | L39: ✔ Solved | M39: 2022-23 1(c) (CSE 209); 2021-22 1(b); 2019-20 5(a); 2019-20 5(b); 2019-20 5(c); 2016-17 4(a); 2015-16 2(d); 2014-15 3(a) | N39: =FALSE() -> FALSE
A40: 37 | B40: 2015-16 | C40: CSE 305 | D40: 2(d) | E40: A=B+C; D=A+E (offsets A0 B4 C8 D12 E16): cycles; code scheduling; new cycles | F40: Timing diagrams & code scheduling — Ch 4 Part 2, sl. 22–24 | G40: L14 | H40: 10 | I40: 64 | J40: ★★ Medium | K40: Trace | L40: ✔ Solved | M40: 2022-23 1(c) (CSE 209); 2021-22 1(b); 2019-20 5(a); 2019-20 5(b); 2019-20 5(c); 2017-18 1(a); 2016-17 4(a); 2014-15 3(a) | N40: =FALSE() -> FALSE
A41: 38 | B41: 2023-24 | C41: CSE 209 | D41: 1(b) | E41: Code with beq/bne, branch in ID, forwarding: hazards; total stalls; cycles for 3 branch outcomes | F41: Branch hazards, flush/stall, jumps — Ch 4 Part 2, sl. 25–31, 77–81 | G41: L15 | H41: 15 | I41: 1 | J41: ★★★ High | K41: Trace | L41: ✔ Solved | M41: — | N41: =FALSE() -> FALSE
A42: 39 | B42: 2022-23 | C42: CSE 209 | D42: 5 | E42: Branch decided by ALU Zero: can flush and stall happen together? Issue and solution | F42: Branch hazards, flush/stall, jumps — Ch 4 Part 2, sl. 25–31, 77–81 | G42: L15 | H42: 15 | I42: 10 | J42: ★★★ High | K42: Theory | L42: ✔ Solved | M42: 2018-19 2(a) (CSE 305) | N42: =FALSE() -> FALSE
A43: 40 | B43: 2022-23 | C43: CSE 209 | D43: 7 | E43: Chandler/Joey/Ross: jump needs 1 stall? Move control to IF? Better solution | F43: Branch hazards, flush/stall, jumps — Ch 4 Part 2, sl. 25–31, 77–81 | G43: L15 | H43: 15 | I43: 10–11 | J43: ★★★ High | K43: Theory | L43: ✔ Solved | M43: — | N43: =FALSE() -> FALSE
A44: 41 | B44: 2022-23 | C44: CSE 305 | D44: 4(b) | E44: Name the four components added in ID to reduce branch stalls; how decision + target are ready by end of ID | F44: Branch hazards, flush/stall, jumps — Ch 4 Part 2, sl. 25–31, 77–81 | G44: L15 | H44: 12 | I44: 17 | J44: ★★★ High | K44: Theory | L44: ✔ Solved | M44: — | N44: =FALSE() -> FALSE
A45: 42 | B45: 2021-22 | C45: CSE 305 | D45: 1(c) | E45: Data hazards for branches: MIPS examples needing 0, 1 and 2 stalls | F45: Branch hazards, flush/stall, jumps — Ch 4 Part 2, sl. 25–31, 77–81 | G45: L15 | H45: 10 | I45: 21 | J45: ★★★ High | K45: Theory | L45: ✔ Solved | M45: 2017-18 2(c); 2013-14 8(c) | N45: =FALSE() -> FALSE
A46: 43 | B46: 2018-19 | C46: CSE 305 | D46: 2(a) | E46: Branch decided by ALU Zero: can flush and stall happen together? Single-cycle illustration; issue/solution | F46: Branch hazards, flush/stall, jumps — Ch 4 Part 2, sl. 25–31, 77–81 | G46: L15 | H46: 10 | I46: 42 | J46: ★★ Medium | K46: Theory | L46: ✔ Solved | M46: 2022-23 5 (CSE 209) | N46: =FALSE() -> FALSE
A47: 44 | B47: 2018-19 | C47: CSE 305 | D47: 2(b) | E47: lw $1 / add $1 / beq with early branch decision: issues (multicycle diagram) and number of cycles | F47: Branch hazards, flush/stall, jumps — Ch 4 Part 2, sl. 25–31, 77–81 | G47: L15 | H47: 10 | I47: 42 | J47: ★ Low | K47: Trace | L47: ✔ Solved | M47: — | N47: =FALSE() -> FALSE
A48: 45 | B48: 2017-18 | C48: CSE 305 | D48: 2(c) | E48: MIPS code for branch data hazards needing 1 and 2 stalls | F48: Branch hazards, flush/stall, jumps — Ch 4 Part 2, sl. 25–31, 77–81 | G48: L15 | H48: 5 | I48: 50 | J48: ★★ Medium | K48: Theory | L48: ✔ Solved | M48: 2021-22 1(c); 2013-14 8(c) | N48: =FALSE() -> FALSE
...

Sheet 3 Ch5 Memory
A1: Chapter 5 — Memory Hierarchy
A2: Note file: CSE209_Ch5_Memory_Hierarchy_Notes.docx · Solve after finishing the matching lesson. Filter Priority → ★★★ High first.
A3: Q No. | B3: Year | C3: Course | D3: Ques No. | E3: Short Question | F3: Topic (slide PDF · slides) | G3: Lesson | H3: Marks | I3: TF Page | J3: Priority | K3: Type | L3: In Notes | M3: Same Type Also In | N3: Done | O3: Confidence | P3: Date | Q3: My Notes
A4: 1 | B4: 2017-18 | C4: CSE 305 | D4: 3(a) | E4: Three sources of cache misses; ideal disk (1 MB sector, 10000 rpm, 5 ms seek, 100 MB/s, 0.5 ms) read time; improvement with 2 ms seek | F4: Locality, technologies, disk — Ch 5, sl. 2–16 | G4: L19 | H4: 10 | I4: 50 | J4: ★★ Medium | K4: Numerical | L4: ✔ Solved | M4: 2012-13 5(a); 2011-12 6(d) | N4: =FALSE() -> FALSE
A5: 2 | B5: 2016-17 | C5: CSE 305 | D5: 3(a) | E5: Principle of locality of reference; its role in designing the memory hierarchy | F5: Locality, technologies, disk — Ch 5, sl. 2–16 | G5: L19 | H5: 5 | I5: 55 | J5: ★★ Medium | K5: Theory | L5: ✔ Solved | M5: 2014-15 2(a); 2013-14 1(a) | N5: =FALSE() -> FALSE
A6: 3 | B6: 2014-15 | C6: CSE 305 | D6: 2(a) | E6: Principle of locality; role in memory hierarchy (key characteristics part is outside) | F6: Locality, technologies, disk — Ch 5, sl. 2–16 | G6: L19 | H6: 6 | I6: 68 | J6: ★★ Medium | K6: Theory | L6: ✔ Solved | M6: 2016-17 3(a); 2013-14 1(a) | N6: =FALSE() -> FALSE
A7: 4 | B7: 2014-15 | C7: CSE 305 | D7: 2(b)(i) | E7: Short note on flash storage | F7: Locality, technologies, disk — Ch 5, sl. 2–16 | G7: L19 | H7: 4 | I7: 68 | J7: ★★ Medium | K7: Theory | L7: ◐ Method | M7: 2012-13 5(c) | N7: =FALSE() -> FALSE
A8: 5 | B8: 2013-14 | C8: CSE 305 | D8: 1(a) | E8: State the principles of temporal and spatial locality | F8: Locality, technologies, disk — Ch 5, sl. 2–16 | G8: L19 | H8: 6 | I8: 74 | J8: ★★ Medium | K8: Theory | L8: ✔ Solved | M8: 2016-17 3(a); 2014-15 2(a) | N8: =FALSE() -> FALSE
A9: 6 | B9: 2012-13 | C9: CSE 305 | D9: 5(a) | E9: Average time to read/write a 512-byte sector (15,000 RPM, 4 ms seek, 100 MB/s, 0.2 ms) | F9: Locality, technologies, disk — Ch 5, sl. 2–16 | G9: L19 | H9: 10 | I9: 79 | J9: ★★ Medium | K9: Numerical | L9: ✔ Solved | M9: 2017-18 3(a); 2011-12 6(d) | N9: =FALSE() -> FALSE
A10: 7 | B10: 2012-13 | C10: CSE 305 | D10: 5(c) | E10: Differentiate NAND and NOR flash memories | F10: Locality, technologies, disk — Ch 5, sl. 2–16 | G10: L19 | H10: 5 | I10: 79 | J10: ★★ Medium | K10: Theory | L10: ✔ Solved | M10: 2014-15 2(b)(i) | N10: =FALSE() -> FALSE
A11: 8 | B11: 2011-12 | C11: CSE 305 | D11: 6(d) | E11: Components of disk data access time | F11: Locality, technologies, disk — Ch 5, sl. 2–16 | G11: L19 | H11: 5 | I11: 86 | J11: ★★ Medium | K11: Theory | L11: ✔ Solved | M11: 2017-18 3(a); 2012-13 5(a) | N11: =FALSE() -> FALSE
A12: 9 | B12: 2023-24 | C12: CSE 209 | D12: 2(b) | E12: DM cache (tag 31–10, index 9–5, offset 4–0), byte refs 0…2180: block size, entries, replacements, hit ratio, final state | F12: Direct-mapped caches & traces — Ch 5, sl. 17–27 | G12: L20 | H12: 15 | I12: 2 | J12: ★★★ High | K12: Trace | L12: ✔ Solved | M12: 2015-16 4(b) (CSE 305) | N12: =FALSE() -> FALSE
A13: 10 | B13: 2015-16 | C13: CSE 305 | D13: 4(b) | E13: DM cache (tag 31–10, index 9–5, offset 4–0), byte refs 0…2180: block size, entries, replacements, hit ratio | F13: Direct-mapped caches & traces — Ch 5, sl. 17–27 | G13: L20 | H13: 10 | I13: 65 | J13: ★★ Medium | K13: Trace | L13: ✔ Solved | M13: 2023-24 2(b) (CSE 209) | N13: =FALSE() -> FALSE
A14: 11 | B14: 2022-23 | C14: CSE 209 | D14: 9(b) | E14: Total size of a 4-way cache: 48-bit address, 64 KB data, 16-word blocks, tag/valid/dirty/protection bits, lb support | F14: Address fields & total cache bits — Ch 5, sl. 26–27, 44 | G14: L21 | H14: 10 | I14: 12 | J14: ★★★ High | K14: Numerical | L14: ✔ Solved | M14: 2022-23 2(b) (CSE 305); 2019-20 6(b) (CSE 305); 2019-20 7(a) (CSE 305); 2018-19 4(b) (CSE 305); 2013-14 1(e) (CSE 305); 2012-13 7(b) (CSE 305); 2011-12 8(a) (CSE 305) | N14: =FALSE() -> FALSE
A15: 12 | B15: 2022-23 | C15: CSE 305 | D15: 2(b) | E15: Total bits for an 8-way cache, 4K blocks, 4-word blocks, 32-bit address (sets and tag bits) | F15: Address fields & total cache bits — Ch 5, sl. 26–27, 44 | G15: L21 | H15: 15 | I15: 16 | J15: ★★★ High | K15: Numerical | L15: ✔ Solved | M15: 2022-23 9(b) (CSE 209); 2019-20 6(b); 2019-20 7(a); 2018-19 4(b); 2013-14 1(e); 2012-13 7(b); 2011-12 8(a) | N15: =FALSE() -> FALSE
... A39: 36 | B39: 2023-24 | C39: CSE 209 | D39: 2(a) | E39: CPI 1, 4 GHz, 200 ns, 5%: speedup with L2 (10 ns, 2%) and then L3 (40 ns, 1%) | F39: Cache performance, AMAT, multilevel — Ch 5, sl. 33–37, 46–49 | G39: L24 | H39: 10 | I39: 2 | J39: ★★★ High | K39: Numerical | L39: ✔ Solved | M39: 2022-23 3(a) (CSE 305); 2021-22 3(a) (CSE 305); 2017-18 4(a) (CSE 305); 2015-16 4(d) (CSE 305); 2012-13 7(c) (CSE 305) | N39: =FALSE() -> FALSE
A40: 37 | B40: 2022-23 | C40: CSE 209 | D40: 9(a) | E40: P1 (L1+L2) vs P2 (L1+L2+L3): effective CPI, faster one, L2 miss rate needed to match | F40: Cache performance, AMAT, multilevel — Ch 5, sl. 33–37, 46–49 | G40: L24 | H40: 15 | I40: 11–12 | J40: ★★★ High | K40: Numerical | L40: ✔ Solved | M40: 2018-19 4(a) (CSE 305) | N40: =FALSE() -> FALSE
A41: 38 | B41: 2022-23 | C41: CSE 305 | D41: 3(a) | E41: CPI 2, 0.5 ns, 150 ns, 5%: one-level CPI, ideal speedup; L2 (15 ns, 0.5%) CPI; speedup | F41: Cache performance, AMAT, multilevel — Ch 5, sl. 33–37, 46–49 | G41: L24 | H41: 25 | I41: 17 | J41: ★★★ High | K41: Numerical | L41: ✔ Solved | M41: 2023-24 2(a) (CSE 209); 2021-22 3(a); 2017-18 4(a); 2015-16 4(d); 2012-13 7(c) | N41: =FALSE() -> FALSE
A42: 39 | B42: 2021-22 | C42: CSE 305 | D42: 3(a) | E42: CPI 1, 4 GHz, 200 ns, 4%: speedup with L2 (10 ns, 1%) and L3 (40 ns, 0.5%) | F42: Cache performance, AMAT, multilevel — Ch 5, sl. 33–37, 46–49 | G42: L24 | H42: 10 | I42: 22 | J42: ★★★ High | K42: Numerical | L42: ✔ Solved | M42: 2023-24 2(a) (CSE 209); 2022-23 3(a); 2017-18 4(a); 2015-16 4(d); 2012-13 7(c) | N42: =FALSE() -> FALSE
A43: 40 | B43: 2020-21 | C43: CSE 305 | D43: 7 | E43: Cache→RAM→SSD→HDD (5/15/25/0%, 1/10/100/1000 cycles): P(fetch from SSD), expected time, I-cache miss rate | F43: Cache performance, AMAT, multilevel — Ch 5, sl. 33–37, 46–49 | G43: L24 | H43: 15 | I43: 30 | J43: ★★★ High | K43: Numerical | L43: ✔ Solved | M43: — | N43: =FALSE() -> FALSE
A44: 41 | B44: 2018-19 | C44: CSE 305 | D44: 4(a) | E44: Three processors (cycle time, block size, I/D miss rates, penalty 6 + block): most miss cycles, fastest/slowest, processor-3 organization | F44: Cache performance, AMAT, multilevel — Ch 5, sl. 33–37, 46–49 | G44: L24 | H44: 19 | I44: 43 | J44: ★★ Medium | K44: Numerical | L44: ○ Partly | M44: 2022-23 9(a) (CSE 209) | N44: =FALSE() -> FALSE
A45: 42 | B45: 2017-18 | C45: CSE 305 | D45: 3(d) | E45: I-cache 3%, D-cache 5%, 40% ld/st, CPI 2, penalty 200: perfect-cache speedup; time on memory stalls | F45: Cache performance, AMAT, multilevel — Ch 5, sl. 33–37, 46–49 | G45: L24 | H45: 5 | I45: 51 | J45: ★★ Medium | K45: Numerical | L45: ✔ Solved | M45: 2015-16 4(a); 2011-12 6(b) | N45: =FALSE() -> FALSE
A46: 43 | B46: 2017-18 | C46: CSE 305 | D46: 4(a) | E46: CPI 1, 4 GHz, 200 ns, 4%: speedup with L2 (10 ns, 1%) and L3 (40 ns, 0.5%) | F46: Cache performance, AMAT, multilevel — Ch 5, sl. 33–37, 46–49 | G46: L24 | H46: 10 | I46: 51 | J46: ★★ Medium | K46: Numerical | L46: ✔ Solved | M46: 2023-24 2(a) (CSE 209); 2022-23 3(a); 2021-22 3(a); 2015-16 4(d); 2012-13 7(c) | N46: =FALSE() -> FALSE
A47: 44 | B47: 2015-16 | C47: CSE 305 | D47: 4(a) | E47: I-cache 3%, D-cache 5%, 40% ld/st, CPI 2, penalty 100: perfect-cache speedup; time on stalls | F47: Cache performance, AMAT, multilevel — Ch 5, sl. 33–37, 46–49 | G47: L24 | H47: 5 | I47: 65 | J47: ★★ Medium | K47: Numerical | L47: ◐ Method | M47: 2017-18 3(d); 2011-12 6(b) | N47: =FALSE() -> FALSE
A48: 45 | B48: 2015-16 | C48: CSE 305 | D48: 4(d) | E48: CPI 1, 4 GHz, 100 ns, 3%: speedup with L2 (5 ns, 1%) | F48: Cache performance, AMAT, multilevel — Ch 5, sl. 33–37, 46–49 | G48: L24 | H48: 5 | I48: 65 | J48: ★★ Medium | K48: Numerical | L48: ◐ Method | M48: 2023-24 2(a) (CSE 209); 2022-23 3(a); 2021-22 3(a); 2017-18 4(a); 2012-13 7(c) | N48: =FALSE() -> FALSE
A49: 46 | B49: 2012-13 | C49: CSE 305 | D49: 7(c) | E49: CPI 2, 1 GHz, 100 ns, L1 4%: CPI with L1 only, + DM L2 (10 cyc, 4%), + 8-way L2 (20 cyc, 1.6%) | F49: Cache performance, AMAT, multilevel — Ch 5, sl. 33–37, 46–49 | G49: L24 | H49: 12 | I49: 80 | J49: ★★ Medium | K49: Numerical | L49: ◐ Method | M49: 2023-24 2(a) (CSE 209); 2022-23 3(a); 2021-22 3(a); 2017-18 4(a); 2015-16 4(d) | N49: =FALSE() -> FALSE
A50: 47 | B50: 2011-12 | C50: CSE 305 | D50: 6(b) | E50: I-cache 2%, D-cache 4%, CPI 6, 100 ns, 4 GHz: perfect-cache speedup | F50: Cache performance, AMAT, multilevel — Ch 5, sl. 33–37, 46–49 | G50: L24 | H50: 10 | I50: 86 | J50: ★★ Medium | K50: Numerical | L50: ◐ Method | M50: 2017-18 3(d); 2015-16 4(a) | N50: =FALSE() -> FALSE
A51: 48 | B51: 2011-12 | C51: CSE 305 | D51: 5(d) | E51: What is a split cache? How is it different from a multilevel cache? | F51: Cache performance, AMAT, multilevel — Ch 5, sl. 33–37, 46–49 | G51: L24 | H51: 4 | I51: 86 | J51: ★ Low | K51: Theory | L51: ○ Partly | M51: — | N51: =FALSE() -> FALSE
A52: 49 | B52: 2022-23 | C52: CSE 209 | D52: 12(d) | E52: Radix sort vs quicksort: why the clock-cycle graph diverges from the instruction graph | F52: Software & the cache — Ch 5, sl. 50–55, 90–91 | G52: L25 | H52: 10 | I52: 14 | J52: ★★★ High | K52: Theory | L52: ✔ Solved | M52: — | N52: =FALSE() -> FALSE
... A82: 79 | B82: 2013-14 | C82: CSE 305 | D82: 1(c) | E82: Three conditions for a cache/memory to be coherent | F82: Cache coherence & snooping — Ch 5, sl. 80–86 | G82: L28 | H82: 9 | I82: 74 | J82: ★★ Medium | K82: Theory | L82: ✔ Solved | M82: 2023-24 3(c) (CSE 209); 2021-22 3(d); 2015-16 8(a) | N82: =FALSE() -> FALSE

Sheet 4 GPU + Integration
A1: GPUs & Final Integration
A2: Note file: CSE209_GPUs_Final_Integration_Notes.docx · Solve after finishing the matching lesson. Filter Priority → ★★★ High first.
A3: Q No. | B3: Year | C3: Course | D3: Ques No. | E3: Short Question | F3: Topic (slide PDF · slides) | G3: Lesson | H3: Marks | I3: TF Page | J3: Priority | K3: Type | L3: In Notes | M3: Same Type Also In | N3: Done | O3: Confidence | P3: Date | Q3: My Notes
A4: 1 | B4: 2023-24 | C4: CSE 209 | D4: 4(a) | E4: Block diagrams: contemporary Intel and AMD PCs with a separate GPU; how CPU and GPU access each other's memory | F4: GPU systems, CPU–GPU memory access — GPU Slides, sl. 2–4, 10–19 | G4: L33 | H4: 10 | I4: 4 | J4: ★★★ High | K4: Design | L4: ✔ Solved | M4: 2021-22 4(b) (CSE 305) | N4: =FALSE() -> FALSE
A5: 2 | B5: 2021-22 | C5: CSE 305 | D5: 4(b) | E5: Block diagrams: contemporary Intel and AMD PCs with a separate GPU; how CPU and GPU access each other's memory | F5: GPU systems, CPU–GPU memory access — GPU Slides, sl. 2–4, 10–19 | G5: L33 | H5: 10 | I5: 23 | J5: ★★★ High | K5: Design | L5: ✔ Solved | M5: 2023-24 4(a) (CSE 209) | N5: =FALSE() -> FALSE
A6: 3 | B6: 2023-24 | C6: CSE 209 | D6: 4(c) | E6: Kernel, grid, thread block in CUDA; how they map to SP cores and SMs | F6: CUDA: kernel, block, grid, mapping — GPU Slides, sl. 7–9, 27–34 | G6: L35 | H6: 10 | I6: 4 | J6: ★★★ High | K6: Theory | L6: ✔ Solved | M6: 2021-22 4(c) (CSE 305) | N6: =FALSE() -> FALSE
A7: 4 | B7: 2021-22 | C7: CSE 305 | D7: 4(c) | E7: Kernel, grid, thread block in CUDA; how they map to SP cores and SMs | F7: CUDA: kernel, block, grid, mapping — GPU Slides, sl. 7–9, 27–34 | G7: L35 | H7: 10 | I7: 23 | J7: ★★★ High | K7: Theory | L7: ✔ Solved | M7: 2023-24 4(c) (CSE 209) | N7: =FALSE() -> FALSE
A8: 5 | B8: 2020-21 | C8: CSE 305 | D8: 1 | E8: Eight great ideas: (a) code reordering, (b) separate data/instruction caches, (c) GPUs after the power wall | F8: Final integration: eight great ideas — all RS notes | G8: L36 | H8: 15 | I8: 28 | J8: ★★★ High | K8: Theory | L8: ✔ Solved | M8: 2016-17 5(a); 2014-15 5(a) | N8: =FALSE() -> FALSE
A9: 6 | B9: 2020-21 | C9: CSE 305 | D9: 2 | E9: Your favourite topic from processor, memory hierarchy and multiprocessors — describe briefly | F9: Final integration: eight great ideas — all RS notes | G9: L36 | H9: 15 | I9: 28 | J9: ★★★ High | K9: Theory | L9: ○ Partly | M9: — | N9: =FALSE() -> FALSE
A10: 7 | B10: 2016-17 | C10: CSE 305 | D10: 5(a) | E10: Eight great ideas behind: single-cycle design not used; prefetching | F10: Final integration: eight great ideas — all RS notes | G10: L36 | H10: 10 | I10: 57 | J10: ★★ Medium | K10: Theory | L10: ✔ Solved | M10: 2020-21 1; 2014-15 5(a) | N10: =FALSE() -> FALSE
A11: 8 | B11: 2014-15 | C11: CSE 305 | D11: 5(a) | E11: Eight great ideas behind: PC-relative branches, on-chip caches, 31-adder multiplier, procedures, prefetching | F11: Final integration: eight great ideas — all RS notes | G11: L36 | H11: 20 | I11: 70 | J11: ★★ Medium | K11: Theory | L11: ✔ Solved | M11: 2020-21 1; 2016-17 5(a) | N11: =FALSE() -> FALSE

Sheet 5 Control Unit
A1: Implementation of the MIPS Control Unit
A2: Note file: CSE209_Control_Unit_Notes.docx · Solve after finishing the matching lesson. Filter Priority → ★★★ High first.
A3: Q No. | B3: Year | C3: Course | D3: Ques No. | E3: Short Question | F3: Topic (slide PDF · slides) | G3: Lesson | H3: Marks | I3: TF Page | J3: Priority | K3: Type | L3: In Notes | M3: Same Type Also In | N3: Done | O3: Confidence | P3: Date | Q3: My Notes
A4: 1 | B4: 2016-17 | C4: CSE 305 | D4: 2(b) | E4: ALU control bits from ALUOp and funct (gate-level version: Lesson 29; table: Ch 4 P1 L4) | F4: Combinational control, PLA — Control Unit PDF, pp. 2–7 | G4: L29 | H4: 10 | I4: 55 | J4: ★★ Medium | K4: Theory | L4: ◐ Method | M4: 2016-17 2(b) | N4: =FALSE() -> FALSE
A5: 2 | B5: 2012-13 | C5: CSE 305 | D5: 3(d) | E5: Can PCWriteCond be safely replaced by PCSource[0]? Justify | F5: Output/next-state equations, ROM/PLA — Control Unit PDF, pp. 7–20 | G5: L31 | H5: 5 | I5: 79 | J5: ★ Low | K5: Theory | L5: ✔ Solved | M5: — | N5: =FALSE() -> FALSE
